Workbook
Name 阵营: 名称表!$H$2:$H$9
Name 怪物类型: 名称表!$A$3:$A$26
Name 是否: 名称表!$C$3:$C$4

Sheet monster_config
A1: 配置ID | B1: 0怪物ID | C1: 0名称 | D1: 0内部名 | E1: 0等级 | F1: 0怪物名字颜色 | G1: 区域编号 | H1: 地图内位置 | I1: 0归属场景 | J1: 0怪物身份 | K1: 0序号 | L1: 0序号（计算用） | M1: 0血条的条数 | N1: 0是否显示百分比 | O1: 碰撞半径 | P1: 0复活时间（ms） | Q1: 0脱战回血 | R1: 0掉落方案1 | S1: 0掉落方案2 | T1: 0掉落方案3 | U1: 0技能ID | V1: 0技能ID | W1: 0技能ID | X1: 0怪物职业 | Y1: 0怪物模型 | Z1: 0缩放比例 | AA1: 阴影宽度 | AB1: 阴影高度 | AC1: 阴影偏移量X | AD1: 阴影偏移量Y | AE1: 0近战/远程 | AF1: 0特效模型 | AG1: 0绑定特效 | AH1: 0绑定特效缩放 | AI1: 掉落经验 | AJ1: 属性名1 | AK1: 属性值1 | AL1: 属性名2 | AM1: 属性值2 | AN1: 属性名3 | AO1: 属性值3 | AP1: 属性名4 | AQ1: 属性值4 | AR1: 属性名5 | AS1: 属性值5 | AT1: 属性名6 | AU1: 属性值6 | AV1: 属性名7 | AW1: 属性值7 | AX1: 属性名8 | AY1: 属性值8 | AZ1: 属性名9 | BA1: 属性值9 | BB1: 属性名10 | BC1: 属性值10 | BD1: 属性名11 | BE1: 属性值11 | BF1: 属性名12 | BG1: 属性值12 | BH1: 属性名13 | BI1: 属性值13 | BJ1: 属性名14 | BK1: 属性值14 | BL1: 血条偏移量 | BM1: 血条名字偏移量 | BN1: 氛围音效 | BO1: 氛围音效概率 | BP1: 受击音效 | BQ1: 受击音效概率 | BR1: 大地图怪物TIPS
A2: ConfigID | B2: MonsterID | C2: MonsterName | E2: Level | F2: Color | I2: SceneId | J2: Dignity | M2: HPColorNumber | N2: ShowHPPercent | O2: Collision | P2: RefreshTime | Q2: ReturnHP | R2: DropMethod1 | S2: DropMethod2 | T2: DropMethod3 | U2: SkillID1 | V2: SkillID2 | W2: SkillID3 | X2: Profession | Y2: ModelID | Z2: UnitScale | AA2: ShadowW | AB2: ShadowH | AC2: ShadowX | AD2: ShadowY | AE2: AttackType | AF2: AttackEffect | AG2: Effect | AH2: EffectScale | AI2: ExpGift | AJ2: Prop1Name | AK2: Prop1Value | AL2: Prop2Name | AM2: Prop2Value | AN2: Prop3Name | AO2: Prop3Value | AP2: Prop4Name | AQ2: Prop4Value | AR2: Prop5Name | AS2: Prop5Value | AT2: Prop6Name | AU2: Prop6Value | AV2: Prop7Name | AW2: Prop7Value | AX2: Prop8Name | AY2: Prop8Value | AZ2: Prop9Name | BA2: Prop9Value | BB2: Prop10Name | BC2: Prop10Value | BD2: Prop11Name | BE2: Prop11Value | BF2: Prop12Name | BG2: Prop12Value | BH2: Prop13Name | BI2: Prop13Value | BJ2: Prop14Name | BK2: Prop14Value | BL2: lifeBarPd | BM2: lifeBarNamePd | BN2: AmbientSound | BO2: AmbientRate | BP2: HitSound | BQ2: HitRate | BR2: desc
A3: =60000000+INDEX(编号表!$B:$B,MATCH(I3,编号表!$A:$A,0))*10000+INDEX(编号表!$B:$B,MATCH(J3,编号表!$C:$C,0))*1000+K3 -> 60011000 | B3: a001 | C3: 鸡 | D3: 鸡 | E3: 5 | F3: {=INDEX(编号表!$E:$E,MATCH(J3,编号表!$C:$C,0))} -> 白色 | G3: 1 | H3: 比奇城内 | I3: 比奇城 | J3: 普通 | K3: 0 | L3: =COUNTIFS(I3:I$11,I3,J3:J$11,J3)-1 -> 4 | O3: 10 | P3: 100000 | Q3: 否 | R3: 40140001 | U3: 11010001 | V3: 11020001 | X3: 战士 | Y3: ani_monster_ji_01 | AA3: 30 | AB3: 30 | AC3: 10 | AD3: 20 | AE3: 近战 | AI3: 12 | AJ3: 生命值 | AK3: 15 | AL3: 物防下限 | AN3: 物防上限 | AP3: 魔防下限 | AR3: 魔防上限 | AT3: 攻击下限 | AU3: 1 | AV3: 攻击上限 | AW3: 2 | AX3: 魔法下限 | AY3: 1 | AZ3: 魔法上限 | BA3: 2 | BB3: 道术下限 | BC3: 1 | BD3: 道术上限 | BE3: 2 | BF3: 移动速度 | BG3: 100 | BH3: 攻击范围 | BI3: 10 | BJ3: 警戒范围 | BK3: 200 | BN3: 1 | BO3: 2500 | BP3: 2 | BQ3: 2500 | BR3: 怪物说明功能测试： 怪物身份颜色：|cffFF0000BOSS|r，|cff00FF00精英怪|r，普通怪 概率掉落以下物品： |cffFFA500美刀|r、|cffd9d919one刀乐|r、|cffA020F0two刀乐
A4: =60000000+INDEX(编号表!$B:$B,MATCH(I4,编号表!$A:$A,0))*10000+INDEX(编号表!$B:$B,MATCH(J4,编号表!$C:$C,0))*1000+K4 -> 60011001 | B4: a002 | C4: 鹿 | D4: 鹿 | E4: 12 | F4: {=INDEX(编号表!$E:$E,MATCH(J4,编号表!$C:$C,0))} -> 白色 | G4: 2 | H4: 比奇城-右下 | I4: 比奇城 | J4: 普通 | K4: 1 | L4: =COUNTIFS(I4:I$11,I4,J4:J$11,J4)-1 -> 3 | O4: 10 | P4: 150000 | Q4: 否 | R4: 40140002 | U4: 11010001 | V4: 11020001 | X4: 战士 | Y4: ani_monster_lu_01 | AA4: 50 | AB4: 50 | AC4: 20 | AD4: 30 | AE4: 近战 | AI4: 33 | AJ4: 生命值 | AK4: 28 | AL4: 物防下限 | AN4: 物防上限 | AP4: 魔防下限 | AR4: 魔防上限 | AT4: 攻击下限 | AU4: 1 | AV4: 攻击上限 | AW4: 2 | AX4: 魔法下限 | AY4: 1 | AZ4: 魔法上限 | BA4: 2 | BB4: 道术下限 | BC4: 1 | BD4: 道术上限 | BE4: 2 | BF4: 移动速度 | BG4: 100 | BH4: 攻击范围 | BI4: 10 | BJ4: 警戒范围 | BK4: 200 | BN4: 1 | BO4: 2500 | BP4: 2 | BQ4: 2500 | BR4: 怪物说明功能测试： 怪物身份颜色：|cffFF0000BOSS|r，|cff00FF00精英怪|r，普通怪 概率掉落以下物品： |cffFFA500美刀|r、|cffd9d919one刀乐|r、|cffA020F0two刀乐
A5: =60000000+INDEX(编号表!$B:$B,MATCH(I5,编号表!$A:$A,0))*10000+INDEX(编号表!$B:$B,MATCH(J5,编号表!$C:$C,0))*1000+K5 -> 60011002 | B5: a003 | C5: 羊 | D5: 羊 | E5: 13 | F5: {=INDEX(编号表!$E:$E,MATCH(J5,编号表!$C:$C,0))} -> 白色 | G5: 2 | H5: 比奇城-右下 | I5: 比奇城 | J5: 普通 | K5: 2 | L5: =COUNTIFS(I5:I$11,I5,J5:J$11,J5)-1 -> 2 | O5: 10 | P5: 300000 | Q5: 否 | R5: 40140002 | U5: 11010001 | V5: 11020001 | X5: 战士 | Y5: ani_monster_yang_01 | AA5: 50 | AB5: 50 | AC5: 20 | AD5: 30 | AE5: 近战 | AI5: 36 | AJ5: 生命值 | AK5: 39 | AL5: 物防下限 | AN5: 物防上限 | AP5: 魔防下限 | AR5: 魔防上限 | AT5: 攻击下限 | AU5: 1 | AV5: 攻击上限 | AW5: 2 | AX5: 魔法下限 | AY5: 1 | AZ5: 魔法上限 | BA5: 2 | BB5: 道术下限 | BC5: 1 | BD5: 道术上限 | BE5: 2 | BF5: 移动速度 | BG5: 100 | BH5: 攻击范围 | BI5: 10 | BJ5: 警戒范围 | BK5: 200 | BN5: 1 | BO5: 2500 | BP5: 2 | BQ5: 2500 | BR5: 怪物说明功能测试： 怪物身份颜色：|cffFF0000BOSS|r，|cff00FF00精英怪|r，普通怪 概率掉落以下物品： |cffFFA500美刀|r、|cffd9d919one刀乐|r、|cffA020F0two刀乐
A6: =60000000+INDEX(编号表!$B:$B,MATCH(I6,编号表!$A:$A,0))*10000+INDEX(编号表!$B:$B,MATCH(J6,编号表!$C:$C,0))*1000+K6 -> 60011003 | B6: a004 | C6: 稻草人 | D6: 稻草人 | E6: 10 | F6: {=INDEX(编号表!$E:$E,MATCH(J6,编号表!$C:$C,0))} -> 白色 | G6: 2 | H6: 比奇城-右下 | I6: 比奇城 | J6: 普通 | K6: 3 | L6: =COUNTIFS(I6:I$11,I6,J6:J$11,J6)-1 -> 1 | O6: 10 | P6: 150000 | Q6: 否 | R6: 40140002 | U6: 11010001 | V6: 11020001 | X6: 战士 | Y6: ani_monster_caoren_01 | Z6: 1.2 | AA6: 50 | AB6: 50 | AC6: 20 | AD6: 30 | AE6: 近战 | AI6: 26 | AJ6: 生命值 | AK6: 100 | AL6: 物防下限 | AM6: 2 | AN6: 物防上限 | AO6: 3 | AP6: 魔防下限 | AQ6: 2 | AR6: 魔防上限 | AS6: 3 | AT6: 攻击下限 | AU6: 5 | AV6: 攻击上限 | AW6: 7 | AX6: 魔法下限 | AY6: 5 | AZ6: 魔法上限 | BA6: 7 | BB6: 道术下限 | BC6: 0 | BD6: 道术上限 | BE6: 0 | BF6: 移动速度 | BG6: 100 | BH6: 攻击范围 | BI6: 10 | BJ6: 警戒范围 | BK6: 200 | BN6: 1 | BO6: 2500 | BP6: 2 | BQ6: 2500 | BR6: 怪物说明功能测试： 怪物身份颜色：|cffFF0000BOSS|r，|cff00FF00精英怪|r，普通怪 概率掉落以下物品： |cffFFA500美刀|r、|cffd9d919one刀乐|r、|cffA020F0two刀乐
A11: =60000000+INDEX(编号表!$B:$B,MATCH(I11,编号表!$A:$A,0))*10000+INDEX(编号表!$B:$B,MATCH(J11,编号表!$C:$C,0))*1000+K11 -> 60011000 | B11: a001 | C11: 鸡 | D11: 鸡 | E11: 5 | F11: {=INDEX(编号表!$E:$E,MATCH(J11,编号表!$C:$C,0))} -> 白色 | G11: 1 | H11: 比奇城内 | I11: 比奇城 | J11: 普通 | K11: 0 | L11: =COUNTIFS(I$11:I11,I11,J$11:J11,J11)-1 -> 0 | O11: 10 | P11: 100000 | Q11: 否 | R11: 40140001 | U11: 11010001 | V11: 11020001 | X11: 战士 | Y11: ani_monster_ji_01 | AA11: 30 | AB11: 30 | AC11: 10 | AD11: 20 | AE11: 近战 | AI11: 12 | AJ11: 生命值 | AK11: 15 | AL11: 物防下限 | AN11: 物防上限 | AP11: 魔防下限 | AR11: 魔防上限 | AT11: 攻击下限 | AU11: 1 | AV11: 攻击上限 | AW11: 2 | AX11: 魔法下限 | AY11: 1 | AZ11: 魔法上限 | BA11: 2 | BB11: 道术下限 | BC11: 1 | BD11: 道术上限 | BE11: 2 | BF11: 移动速度 | BG11: 100 | BH11: 攻击范围 | BI11: 10 | BJ11: 警戒范围 | BK11: 200 | BN11: 1 | BO11: 2500 | BP11: 2 | BQ11: 2500 | BR11: 怪物说明功能测试： 怪物身份颜色：|cffFF0000BOSS|r，|cff00FF00精英怪|r，普通怪 概率掉落以下物品： |cffFFA500美刀|r、|cffd9d919one刀乐|r、|cffA020F0two刀乐
A12: =60000000+INDEX(编号表!$B:$B,MATCH(I12,编号表!$A:$A,0))*10000+INDEX(编号表!$B:$B,MATCH(J12,编号表!$C:$C,0))*1000+K12 -> 60011001 | B12: a002 | C12: 鹿 | D12: 鹿 | E12: 12 | F12: {=INDEX(编号表!$E:$E,MATCH(J12,编号表!$C:$C,0))} -> 白色 | G12: 2 | H12: 比奇城-右下 | I12: 比奇城 | J12: 普通 | K12: 1 | L12: =COUNTIFS(I$11:I12,I12,J$11:J12,J12)-1 -> 1 | O12: 10 | P12: 150000 | Q12: 否 | R12: 40140002 | U12: 11010001 | V12: 11020001 | X12: 战士 | Y12: ani_monster_lu_01 | AA12: 50 | AB12: 50 | AC12: 20 | AD12: 30 | AE12: 近战 | AI12: 33 | AJ12: 生命值 | AK12: 28 | AL12: 物防下限 | AN12: 物防上限 | AP12: 魔防下限 | AR12: 魔防上限 | AT12: 攻击下限 | AU12: 1 | AV12: 攻击上限 | AW12: 2 | AX12: 魔法下限 | AY12: 1 | AZ12: 魔法上限 | BA12: 2 | BB12: 道术下限 | BC12: 1 | BD12: 道术上限 | BE12: 2 | BF12: 移动速度 | BG12: 100 | BH12: 攻击范围 | BI12: 10 | BJ12: 警戒范围 | BK12: 200 | BN12: 1 | BO12: 2500 | BP12: 2 | BQ12: 2500 | BR12: 怪物说明功能测试： 怪物身份颜色：|cffFF0000BOSS|r，|cff00FF00精英怪|r，普通怪 概率掉落以下物品： |cffFFA500美刀|r、|cffd9d919one刀乐|r、|cffA020F0two刀乐
A13: =60000000+INDEX(编号表!$B:$B,MATCH(I13,编号表!$A:$A,0))*10000+INDEX(编号表!$B:$B,MATCH(J13,编号表!$C:$C,0))*1000+K13 -> 60011002 | B13: a003 | C13: 羊 | D13: 羊 | E13: 13 | F13: {=INDEX(编号表!$E:$E,MATCH(J13,编号表!$C:$C,0))} -> 白色 | G13: 2 | H13: 比奇城-右下 | I13: 比奇城 | J13: 普通 | K13: 2 | L13: =COUNTIFS(I$11:I13,I13,J$11:J13,J13)-1 -> 2 | O13: 10 | P13: 300000 | Q13: 否 | R13: 40140002 | U13: 11010001 | V13: 11020001 | X13: 战士 | Y13: ani_monster_yang_01 | AA13: 50 | AB13: 50 | AC13: 20 | AD13: 30 | AE13: 近战 | AI13: 36 | AJ13: 生命值 | AK13: 39 | AL13: 物防下限 | AN13: 物防上限 | AP13: 魔防下限 | AR13: 魔防上限 | AT13: 攻击下限 | AU13: 1 | AV13: 攻击上限 | AW13: 2 | AX13: 魔法下限 | AY13: 1 | AZ13: 魔法上限 | BA13: 2 | BB13: 道术下限 | BC13: 1 | BD13: 道术上限 | BE13: 2 | BF13: 移动速度 | BG13: 100 | BH13: 攻击范围 | BI13: 10 | BJ13: 警戒范围 | BK13: 200 | BN13: 1 | BO13: 2500 | BP13: 2 | BQ13: 2500 | BR13: 怪物说明功能测试： 怪物身份颜色：|cffFF0000BOSS|r，|cff00FF00精英怪|r，普通怪 概率掉落以下物品： |cffFFA500美刀|r、|cffd9d919one刀乐|r、|cffA020F0two刀乐
A14: =60000000+INDEX(编号表!$B:$B,MATCH(I14,编号表!$A:$A,0))*10000+INDEX(编号表!$B:$B,MATCH(J14,编号表!$C:$C,0))*1000+K14 -> 60011003 | B14: a004 | C14: 稻草人 | D14: 稻草人 | E14: 10 | F14: {=INDEX(编号表!$E:$E,MATCH(J14,编号表!$C:$C,0))} -> 白色 | G14: 2 | H14: 比奇城-右下 | I14: 比奇城 | J14: 普通 | K14: 3 | L14: =COUNTIFS(I$11:I14,I14,J$11:J14,J14)-1 -> 3 | O14: 10 | P14: 150000 | Q14: 否 | R14: 40140002 | U14: 11010001 | V14: 11020001 | X14: 战士 | Y14: ani_monster_caoren_01 | Z14: 1.2 | AA14: 50 | AB14: 50 | AC14: 20 | AD14: 30 | AE14: 近战 | AI14: 26 | AJ14: 生命值 | AK14: 100 | AL14: 物防下限 | AM14: 2 | AN14: 物防上限 | AO14: 3 | AP14: 魔防下限 | AQ14: 2 | AR14: 魔防上限 | AS14: 3 | AT14: 攻击下限 | AU14: 5 | AV14: 攻击上限 | AW14: 7 | AX14: 魔法下限 | AY14: 5 | AZ14: 魔法上限 | BA14: 7 | BB14: 道术下限 | BC14: 0 | BD14: 道术上限 | BE14: 0 | BF14: 移动速度 | BG14: 100 | BH14: 攻击范围 | BI14: 10 | BJ14: 警戒范围 | BK14: 200 | BN14: 1 | BO14: 2500 | BP14: 2 | BQ14: 2500 | BR14: 怪物说明功能测试： 怪物身份颜色：|cffFF0000BOSS|r，|cff00FF00精英怪|r，普通怪 概率掉落以下物品： |cffFFA500美刀|r、|cffd9d919one刀乐|r、|cffA020F0two刀乐
A15: =60000000+INDEX(编号表!$B:$B,MATCH(I15,编号表!$A:$A,0))*10000+INDEX(编号表!$B:$B,MATCH(J15,编号表!$C:$C,0))*1000+K15 -> 60011004 | B15: a005 | C15: 蛤蟆 | D15: 蛤蟆 | E15: 12 | F15: {=INDEX(编号表!$E:$E,MATCH(J15,编号表!$C:$C,0))} -> 白色 | G15: 2 | H15: 比奇城-右下 | I15: 比奇城 | J15: 普通 | K15: 4 | L15: =COUNTIFS(I$11:I15,I15,J$11:J15,J15)-1 -> 4 | O15: 10 | P15: 150000 | Q15: 否 | R15: 40140002 | U15: 11010001 | V15: 11020001 | X15: 战士 | Y15: ani_monster_hama_01 | AA15: 50 | AB15: 50 | AC15: 20 | AD15: 30 | AE15: 近战 | AI15: 33 | AJ15: 生命值 | AK15: 125 | AL15: 物防下限 | AM15: 3 | AN15: 物防上限 | AO15: 4 | AP15: 魔防下限 | AQ15: 3 | AR15: 魔防上限 | AS15: 4 | AT15: 攻击下限 | AU15: 7 | AV15: 攻击上限 | AW15: 9 | AX15: 魔法下限 | AY15: 7 | AZ15: 魔法上限 | BA15: 9 | BB15: 道术下限 | BC15: 0 | BD15: 道术上限 | BE15: 0 | BF15: 移动速度 | BG15: 100 | BH15: 攻击范围 | BI15: 10 | BJ15: 警戒范围 | BK15: 200 | BN15: 1 | BO15: 2500 | BP15: 2 | BQ15: 2500 | BR15: 怪物说明功能测试： 怪物身份颜色：|cffFF0000BOSS|r，|cff00FF00精英怪|r，普通怪 概率掉落以下物品： |cffFFA500美刀|r、|cffd9d919one刀乐|r、|cffA020F0two刀乐
A16: =60000000+INDEX(编号表!$B:$B,MATCH(I16,编号表!$A:$A,0))*10000+INDEX(编号表!$B:$B,MATCH(J16,编号表!$C:$C,0))*1000+K16 -> 60011005 | B16: a007 | C16: 多钩猫 | D16: 多钩猫 | E16: 13 | F16: {=INDEX(编号表!$E:$E,MATCH(J16,编号表!$C:$C,0))} -> 白色 | G16: 3 | H16: 比奇城-左下 | I16: 比奇城 | J16: 普通 | K16: 5 | L16: =COUNTIFS(I$11:I16,I16,J$11:J16,J16)-1 -> 5 | O16: 10 | P16: 150000 | Q16: 否 | R16: 40140002 | U16: 11010001 | V16: 11020001 | X16: 战士 | Y16: ani_monster_duogoumao_01 | Z16: 1.2 | AA16: 80 | AB16: 80 | AC16: 20 | AD16: 30 | AE16: 近战 | AI16: 36 | AJ16: 生命值 | AK16: 140 | AL16: 物防下限 | AM16: 3 | AN16: 物防上限 | AO16: 5 | AP16: 魔防下限 | AQ16: 3 | AR16: 魔防上限 | AS16: 4 | AT16: 攻击下限 | AU16: 7 | AV16: 攻击上限 | AW16: 10 | AX16: 魔法下限 | AY16: 7 | AZ16: 魔法上限 | BA16: 10 | BB16: 道术下限 | BC16: 0 | BD16: 道术上限 | BE16: 0 | BF16: 移动速度 | BG16: 100 | BH16: 攻击范围 | BI16: 10 | BJ16: 警戒范围 | BK16: 200 | BN16: 1 | BO16: 2500 | BP16: 2 | BQ16: 2500 | BR16: 怪物说明功能测试： 怪物身份颜色：|cffFF0000BOSS|r，|cff00FF00精英怪|r，普通怪 概率掉落以下物品： |cffFFA500美刀|r、|cffd9d919one刀乐|r、|cffA020F0two刀乐
A17: =60000000+INDEX(编号表!$B:$B,MATCH(I17,编号表!$A:$A,0))*10000+INDEX(编号表!$B:$B,MATCH(J17,编号表!$C:$C,0))*1000+K17 -> 60011006 | B17: a008 | C17: 钉耙猫 | D17: 钉耙猫 | E17: 13 | F17: {=INDEX(编号表!$E:$E,MATCH(J17,编号表!$C:$C,0))} -> 白色 | G17: 3 | H17: 比奇城-左下 | I17: 比奇城 | J17: 普通 | K17: 6 | L17: =COUNTIFS(I$11:I17,I17,J$11:J17,J17)-1 -> 6 | O17: 10 | P17: 150000 | Q17: 否 | R17: 40140002 | U17: 11010001 | V17: 11020001 | X17: 战士 | Y17: ani_monster_dingpamao_01 | Z17: 1.2 | AA17: 80 | AB17: 80 | AC17: 20 | AD17: 30 | AE17: 近战 | AI17: 36 | AJ17: 生命值 | AK17: 140 | AL17: 物防下限 | AM17: 3 | AN17: 物防上限 | AO17: 5 | AP17: 魔防下限 | AQ17: 3 | AR17: 魔防上限 | AS17: 4 | AT17: 攻击下限 | AU17: 7 | AV17: 攻击上限 | AW17: 10 | AX17: 魔法下限 | AY17: 7 | AZ17: 魔法上限 | BA17: 10 | BB17: 道术下限 | BC17: 0 | BD17: 道术上限 | BE17: 0 | BF17: 移动速度 | BG17: 100 | BH17: 攻击范围 | BI17: 10 | BJ17: 警戒范围 | BK17: 200 | BN17: 1 | BO17: 2500 | BP17: 2 | BQ17: 2500 | BR17: 怪物说明功能测试： 怪物身份颜色：|cffFF0000BOSS|r，|cff00FF00精英怪|r，普通怪 概率掉落以下物品： |cffFFA500美刀|r、|cffd9d919one刀乐|r、|cffA020F0two刀乐
A18: =60000000+INDEX(编号表!$B:$B,MATCH(I18,编号表!$A:$A,0))*10000+INDEX(编号表!$B:$B,MATCH(J18,编号表!$C:$C,0))*1000+K18 -> 60011007 | B18: a009 | C18: 半兽人 | D18: 半兽人 | E18: 15 | F18: {=INDEX(编号表!$E:$E,MATCH(J18,编号表!$C:$C,0))} -> 白色 | G18: 3 | H18: 比奇城-左下 | I18: 比奇城 | J18: 普通 | K18: 7 | L18: =COUNTIFS(I$11:I18,I18,J$11:J18,J18)-1 -> 7 | O18: 10 | P18: 300000 | Q18: 否 | R18: 40140002 | U18: 11010001 | V18: 11020001 | X18: 战士 | Y18: ani_monster_banshouren_01 | Z18: 0.8 | AA18: 80 | AB18: 80 | AC18: 20 | AD18: 30 | AE18: 近战 | AI18: 44 | AJ18: 生命值 | AK18: 175 | AL18: 物防下限 | AM18: 4 | AN18: 物防上限 | AO18: 5 | AP18: 魔防下限 | AQ18: 3 | AR18: 魔防上限 | AS18: 5 | AT18: 攻击下限 | AU18: 9 | AV18: 攻击上限 | AW18: 12 | AX18: 魔法下限 | AY18: 9 | AZ18: 魔法上限 | BA18: 12 | BB18: 道术下限 | BC18: 1 | BD18: 道术上限 | BE18: 2 | BF18: 移动速度 | BG18: 100 | BH18: 攻击范围 | BI18: 10 | BJ18: 警戒范围 | BK18: 200 | BN18: 1 | BO18: 2500 | BP18: 2 | BQ18: 2500 | BR18: 怪物说明功能测试： 怪物身份颜色：|cffFF0000BOSS|r，|cff00FF00精英怪|r，普通怪 概率掉落以下物品： |cffFFA500美刀|r、|cffd9d919one刀乐|r、|cffA020F0two刀乐
A19: =60000000+INDEX(编号表!$B:$B,MATCH(I19,编号表!$A:$A,0))*10000+INDEX(编号表!$B:$B,MATCH(J19,编号表!$C:$C,0))*1000+K19 -> 60011008 | B19: a010 | C19: 毒蜘蛛 | D19: 毒蜘蛛 | E19: 16 | F19: {=INDEX(编号表!$E:$E,MATCH(J19,编号表!$C:$C,0))} -> 白色 | G19: 3 | H19: 比奇城-左下 | I19: 比奇城 | J19: 普通 | K19: 8 | L19: =COUNTIFS(I$11:I19,I19,J$11:J19,J19)-1 -> 8 | O19: 10 | P19: 150000 | Q19: 否 | R19: 40140002 | U19: 11010001 | V19: 11020001 | X19: 战士 | Y19: ani_monster_duzhizhu_01 | Z19: 0.8 | AA19: 80 | AB19: 80 | AC19: 20 | AD19: 30 | AE19: 近战 | AI19: 49 | AJ19: 生命值 | AK19: 190 | AL19: 物防下限 | AM19: 4 | AN19: 物防上限 | AO19: 6 | AP19: 魔防下限 | AQ19: 4 | AR19: 魔防上限 | AS19: 5 | AT19: 攻击下限 | AU19: 10 | AV19: 攻击上限 | AW19: 13 | AX19: 魔法下限 | AY19: 10 | AZ19: 魔法上限 | BA19: 13 | BB19: 道术下限 | BC19: 0 | BD19: 道术上限 | BE19: 0 | BF19: 移动速度 | BG19: 100 | BH19: 攻击范围 | BI19: 10 | BJ19: 警戒范围 | BK19: 200 | BN19: 1 | BO19: 2500 | BP19: 2 | BQ19: 2500 | BR19: 怪物说明功能测试： 怪物身份颜色：|cffFF0000BOSS|r，|cff00FF00精英怪|r，普通怪 概率掉落以下物品： |cffFFA500美刀|r、|cffd9d919one刀乐|r、|cffA020F0two刀乐
A20: =60000000+INDEX(编号表!$B:$B,MATCH(I20,编号表!$A:$A,0))*10000+INDEX(编号表!$B:$B,MATCH(J20,编号表!$C:$C,0))*1000+K20 -> 60011009 | B20: a012 | C20: 森林雪人 | D20: 森林雪人 | E20: 16 | F20: {=INDEX(编号表!$E:$E,MATCH(J20,编号表!$C:$C,0))} -> 白色 | G20: 4 | H20: 比奇城-右上 | I20: 比奇城 | J20: 普通 | K20: 9 | L20: =COUNTIFS(I$11:I20,I20,J$11:J20,J20)-1 -> 9 | O20: 10 | P20: 150000 | Q20: 否 | R20: 40140002 | U20: 11010001 | V20: 11020001 | X20: 战士 | Y20: ani_monster_senlinxueren_01 | Z20: 1.2 | AA20: 80 | AB20: 80 | AC20: 20 | AD20: 30 | AE20: 近战 | AI20: 49 | AJ20: 生命值 | AK20: 190 | AL20: 物防下限 | AM20: 4 | AN20: 物防上限 | AO20: 6 | AP20: 魔防下限 | AQ20: 4 | AR20: 魔防上限 | AS20: 5 | AT20: 攻击下限 | AU20: 9 | AV20: 攻击上限 | AW20: 12 | AX20: 魔法下限 | AY20: 9 | AZ20: 魔法上限 | BA20: 12 | BB20: 道术下限 | BC20: 0 | BD20: 道术上限 | BE20: 0 | BF20: 移动速度 | BG20: 100 | BH20: 攻击范围 | BI20: 10 | BJ20: 警戒范围 | BK20: 200 | BN20: 1 | BO20: 2500 | BP20: 2 | BQ20: 2500 | BR20: 怪物说明功能测试： 怪物身份颜色：|cffFF0000BOSS|r，|cff00FF00精英怪|r，普通怪 概率掉落以下物品： |cffFFA500美刀|r、|cffd9d919one刀乐|r、|cffA020F0two刀乐
A21: =60000000+INDEX(编号表!$B:$B,MATCH(I21,编号表!$A:$A,0))*10000+INDEX(编号表!$B:$B,MATCH(J21,编号表!$C:$C,0))*1000+K21 -> 60011010 | B21: a013 | C21: 食人花 | D21: 食人花 | E21: 18 | F21: {=INDEX(编号表!$E:$E,MATCH(J21,编号表!$C:$C,0))} -> 白色 | G21: 4 | H21: 比奇城-右上 | I21: 比奇城 | J21: 普通 | K21: 10 | L21: =COUNTIFS(I$11:I21,I21,J$11:J21,J21)-1 -> 10 | O21: 10 | P21: 300000 | Q21: 否 | R21: 40140002 | U21: 11010001 | V21: 11020001 | X21: 战士 | Y21: ani_monster_shirenhua_01 | Z21: 0.8 | AA21: 50 | AB21: 50 | AC21: 20 | AD21: 30 | AE21: 近战 | AI21: 58 | AJ21: 生命值 | AK21: 230 | AL21: 物防下限 | AM21: 5 | AN21: 物防上限 | AO21: 7 | AP21: 魔防下限 | AQ21: 4 | AR21: 魔防上限 | AS21: 6 | AT21: 攻击下限 | AU21: 11 | AV21: 攻击上限 | AW21: 14 | AX21: 魔法下限 | AY21: 11 | AZ21: 魔法上限 | BA21: 14 | BB21: 道术下限 | BC21: 1 | BD21: 道术上限 | BE21: 2 | BF21: 移动速度 | BG21: 100 | BH21: 攻击范围 | BI21: 10 | BJ21: 警戒范围 | BK21: 200 | BN21: 1 | BO21: 2500 | BP21: 2 | BQ21: 2500 | BR21: 怪物说明功能测试： 怪物身份颜色：|cffFF0000BOSS|r，|cff00FF00精英怪|r，普通怪 概率掉落以下物品： |cffFFA500美刀|r、|cffd9d919one刀乐|r、|cffA020F0two刀乐
A22: =60000000+INDEX(编号表!$B:$B,MATCH(I22,编号表!$A:$A,0))*10000+INDEX(编号表!$B:$B,MATCH(J22,编号表!$C:$C,0))*1000+K22 -> 60011011 | B22: a014 | C22: 红蛇 | D22: 红蛇 | E22: 17 | F22: {=INDEX(编号表!$E:$E,MATCH(J22,编号表!$C:$C,0))} -> 白色 | G22: 4 | H22: 比奇城-右上 | I22: 比奇城 | J22: 普通 | K22: 11 | L22: =COUNTIFS(I$11:I22,I22,J$11:J22,J22)-1 -> 11 | O22: 10 | P22: 300000 | Q22: 否 | R22: 40140002 | U22: 11010001 | V22: 11020001 | X22: 战士 | Y22: ani_monster_hongshe_01 | Z22: 0.8 | AA22: 80 | AB22: 80 | AC22: 20 | AD22: 30 | AE22: 近战 | AI22: 53 | AJ22: 生命值 | AK22: 210 | AL22: 物防下限 | AM22: 4 | AN22: 物防上限 | AO22: 6 | AP22: 魔防下限 | AQ22: 4 | AR22: 魔防上限 | AS22: 6 | AT22: 攻击下限 | AU22: 11 | AV22: 攻击上限 | AW22: 15 | AX22: 魔法下限 | AY22: 11 | AZ22: 魔法上限 | BA22: 15 | BB22: 道术下限 | BC22: 1 | BD22: 道术上限 | BE22: 2 | BF22: 移动速度 | BG22: 100 | BH22: 攻击范围 | BI22: 10 | BJ22: 警戒范围 | BK22: 200 | BN22: 1 | BO22: 2500 | BP22: 2 | BQ22: 2500 | BR22: 怪物说明功能测试： 怪物身份颜色：|cffFF0000BOSS|r，|cff00FF00精英怪|r，普通怪 概率掉落以下物品： |cffFFA500美刀|r、|cffd9d919one刀乐|r、|cffA020F0two刀乐
A23: =60000000+INDEX(编号表!$B:$B,MATCH(I23,编号表!$A:$A,0))*10000+INDEX(编号表!$B:$B,MATCH(J23,编号表!$C:$C,0))*1000+K23 -> 60011012 | B23: a015 | C23: 虎蛇 | D23: 虎蛇 | E23: 18 | F23: {=INDEX(编号表!$E:$E,MATCH(J23,编号表!$C:$C,0))} -> 白色 | G23: 4 | H23: 比奇城-右上 | I23: 比奇城 | J23: 普通 | K23: 12 | L23: =COUNTIFS(I$11:I23,I23,J$11:J23,J23)-1 -> 12 | O23: 10 | P23: 300000 | Q23: 否 | R23: 40140002 | U23: 11010001 | V23: 11020001 | X23: 战士 | Y23: ani_monster_hushe_01 | Z23: 0.8 | AA23: 80 | AB23: 80 | AC23: 20 | AD23: 30 | AE23: 近战 | AI23: 58 | AJ23: 生命值 | AK23: 230 | AL23: 物防下限 | AM23: 5 | AN23: 物防上限 | AO23: 7 | AP23: 魔防下限 | AQ23: 4 | AR23: 魔防上限 | AS23: 6 | AT23: 攻击下限 | AU23: 12 | AV23: 攻击上限 | AW23: 16 | AX23: 魔法下限 | AY23: 12 | AZ23: 魔法上限 | BA23: 16 | BB23: 道术下限 | BC23: 1 | BD23: 道术上限 | BE23: 2 | BF23: 移动速度 | BG23: 100 | BH23: 攻击范围 | BI23: 10 | BJ23: 警戒范围 | BK23: 200 | BN23: 1 | BO23: 2500 | BP23: 2 | BQ23: 2500 | BR23: 怪物说明功能测试： 怪物身份颜色：|cffFF0000BOSS|r，|cff00FF00精英怪|r，普通怪 概率掉落以下物品： |cffFFA500美刀|r、|cffd9d919one刀乐|r、|cffA020F0two刀乐
A24: =60000000+INDEX(编号表!$B:$B,MATCH(I24,编号表!$A:$A,0))*10000+INDEX(编号表!$B:$B,MATCH(J24,编号表!$C:$C,0))*1000+K24 -> 60011013 | B24: a016 | C24: 狼 | D24: 狼 | E24: 16 | F24: {=INDEX(编号表!$E:$E,MATCH(J24,编号表!$C:$C,0))} -> 白色 | G24: 4 | H24: 比奇城-右上 | I24: 比奇城 | J24: 普通 | K24: 13 | L24: =COUNTIFS(I$11:I24,I24,J$11:J24,J24)-1 -> 13 | O24: 10 | P24: 150000 | Q24: 否 | R24: 40140002 | U24: 11010001 | V24: 11020001 | X24: 战士 | Y24: ani_monster_lang_01 | AA24: 80 | AB24: 80 | AC24: 20 | AD24: 30 | AE24: 近战 | AI24: 49 | AJ24: 生命值 | AK24: 190 | AL24: 物防下限 | AM24: 4 | AN24: 物防上限 | AO24: 6 | AP24: 魔防下限 | AQ24: 4 | AR24: 魔防上限 | AS24: 5 | AT24: 攻击下限 | AU24: 9 | AV24: 攻击上限 | AW24: 12 | AX24: 魔法下限 | AY24: 9 | AZ24: 魔法上限 | BA24: 12 | BB24: 道术下限 | BC24: 0 | BD24: 道术上限 | BE24: 0 | BF24: 移动速度 | BG24: 100 | BH24: 攻击范围 | BI24: 10 | BJ24: 警戒范围 | BK24: 200 | BN24: 1 | BO24: 2500 | BP24: 2 | BQ24: 2500 | BR24: 怪物说明功能测试： 怪物身份颜色：|cffFF0000BOSS|r，|cff00FF00精英怪|r，普通怪 概率掉落以下物品： |cffFFA500美刀|r、|cffd9d919one刀乐|r、|cffA020F0two刀乐
A25: =60000000+INDEX(编号表!$B:$B,MATCH(I25,编号表!$A:$A,0))*10000+INDEX(编号表!$B:$B,MATCH(J25,编号表!$C:$C,0))*1000+K25 -> 60011014 | B25: a018 | C25: 虎卫 | D25: 虎卫 | E25: 18 | F25: {=INDEX(编号表!$E:$E,MATCH(J25,编号表!$C:$C,0))} -> 白色 | G25: 5 | H25: 比奇城-左上 | I25: 比奇城 | J25: 普通 | K25: 14 | L25: =COUNTIFS(I$11:I25,I25,J$11:J25,J25)-1 -> 14 | O25: 10 | P25: 300000 | Q25: 否 | R25: 40140002 | U25: 11010001 | V25: 11020001 | X25: 战士 | Y25: ani_monster_huwei_01 | Z25: 1.2 | AA25: 50 | AB25: 50 | AC25: 20 | AD25: 30 | AE25: 近战 | AI25: 58 | AJ25: 生命值 | AK25: 230 | AL25: 物防下限 | AM25: 5 | AN25: 物防上限 | AO25: 7 | AP25: 魔防下限 | AQ25: 4 | AR25: 魔防上限 | AS25: 6 | AT25: 攻击下限 | AU25: 11 | AV25: 攻击上限 | AW25: 14 | AX25: 魔法下限 | AY25: 11 | AZ25: 魔法上限 | BA25: 14 | BB25: 道术下限 | BC25: 1 | BD25: 道术上限 | BE25: 2 | BF25: 移动速度 | BG25: 100 | BH25: 攻击范围 | BI25: 10 | BJ25: 警戒范围 | BK25: 200 | BN25: 1 | BO25: 2500 | BP25: 2 | BQ25: 2500 | BR25: 怪物说明功能测试： 怪物身份颜色：|cffFF0000BOSS|r，|cff00FF00精英怪|r，普通怪 概率掉落以下物品： |cffFFA500美刀|r、|cffd9d919one刀乐|r、|cffA020F0two刀乐
A26: =60000000+INDEX(编号表!$B:$B,MATCH(I26,编号表!$A:$A,0))*10000+INDEX(编号表!$B:$B,MATCH(J26,编号表!$C:$C,0))*1000+K26 -> 60011015 | B26: a019 | C26: 鹰卫 | D26: 鹰卫 | E26: 18 | F26: {=INDEX(编号表!$E:$E,MATCH(J26,编号表!$C:$C,0))} -> 白色 | G26: 5 | H26: 比奇城-左上 | I26: 比奇城 | J26: 普通 | K26: 15 | L26: =COUNTIFS(I$11:I26,I26,J$11:J26,J26)-1 -> 15 | O26: 10 | P26: 300000 | Q26: 否 | R26: 40140002 | U26: 11010001 | V26: 11020001 | X26: 战士 | Y26: ani_monster_yingwei_01 | Z26: 1.2 | AA26: 50 | AB26: 50 | AC26: 20 | AD26: 30 | AE26: 远程 | AF26: ani_monster_yingwei_01_01 | AI26: 58 | AJ26: 生命值 | AK26: 230 | AL26: 物防下限 | AM26: 5 | AN26: 物防上限 | AO26: 7 | AP26: 魔防下限 | AQ26: 4 | AR26: 魔防上限 | AS26: 6 | AT26: 攻击下限 | AU26: 11 | AV26: 攻击上限 | AW26: 14 | AX26: 魔法下限 | AY26: 11 | AZ26: 魔法上限 | BA26: 14 | BB26: 道术下限 | BC26: 1 | BD26: 道术上限 | BE26: 2 | BF26: 移动速度 | BG26: 100 | BH26: 攻击范围 | BI26: 300 | BJ26: 警戒范围 | BK26: 200 | BN26: 1 | BO26: 2500 | BP26: 2 | BQ26: 2500 | BR26: 怪物说明功能测试： 怪物身份颜色：|cffFF0000BOSS|r，|cff00FF00精英怪|r，普通怪 概率掉落以下物品： |cffFFA500美刀|r、|cffd9d919one刀乐|r、|cffA020F0two刀乐
A27: =60000000+INDEX(编号表!$B:$B,MATCH(I27,编号表!$A:$A,0))*10000+INDEX(编号表!$B:$B,MATCH(J27,编号表!$C:$C,0))*1000+K27 -> 60011016 | B27: a020 | C27: 多角虫 | D27: 多角虫 | E27: 18 | F27: {=INDEX(编号表!$E:$E,MATCH(J27,编号表!$C:$C,0))} -> 白色 | G27: 5 | H27: 比奇城-左上 | I27: 比奇城 | J27: 普通 | K27: 16 | L27: =COUNTIFS(I$11:I27,I27,J$11:J27,J27)-1 -> 16 | O27: 10 | P27: 300000 | Q27: 否 | R27: 40140002 | U27: 11010001 | V27: 11020001 | X27: 战士 | Y27: ani_monster_duojiaochong_01 | Z27: 0.5 | AA27: 50 | AB27: 50 | AC27: 20 | AD27: 30 | AE27: 近战 | AI27: 58 | AJ27: 生命值 | AK27: 260 | AL27: 物防下限 | AM27: 5 | AN27: 物防上限 | AO27: 8 | AP27: 魔防下限 | AQ27: 5 | AR27: 魔防上限 | AS27: 7 | AT27: 攻击下限 | AU27: 11 | AV27: 攻击上限 | AW27: 15 | AX27: 魔法下限 | AY27: 11 | AZ27: 魔法上限 | BA27: 15 | BB27: 道术下限 | BC27: 1 | BD27: 道术上限 | BE27: 2 | BF27: 移动速度 | BG27: 100 | BH27: 攻击范围 | BI27: 10 | BJ27: 警戒范围 | BK27: 200 | BN27: 1 | BO27: 2500 | BP27: 2 | BQ27: 2500 | BR27: 怪物说明功能测试： 怪物身份颜色：|cffFF0000BOSS|r，|cff00FF00精英怪|r，普通怪 概率掉落以下物品： |cffFFA500美刀|r、|cffd9d919one刀乐|r、|cffA020F0two刀乐
A28: =60000000+INDEX(编号表!$B:$B,MATCH(I28,编号表!$A:$A,0))*10000+INDEX(编号表!$B:$B,MATCH(J28,编号表!$C:$C,0))*1000+K28 -> 60011017 | B28: a021 | C28: 盔甲虫 | D28: 盔甲虫 | E28: 18 | F28: {=INDEX(编号表!$E:$E,MATCH(J28,编号表!$C:$C,0))} -> 白色 | G28: 5 | H28: 比奇城-左上 | I28: 比奇城 | J28: 普通 | K28: 17 | L28: =COUNTIFS(I$11:I28,I28,J$11:J28,J28)-1 -> 17 | O28: 10 | P28: 150000 | Q28: 否 | R28: 40140002 | U28: 11010001 | V28: 11020001 | X28: 战士 | Y28: ani_moster_kuijiachong_01 | Z28: 0.8 | AA28: 80 | AB28: 80 | AC28: 20 | AD28: 30 | AE28: 近战 | AI28: 58 | AJ28: 生命值 | AK28: 260 | AL28: 物防下限 | AM28: 5 | AN28: 物防上限 | AO28: 8 | AP28: 魔防下限 | AQ28: 5 | AR28: 魔防上限 | AS28: 7 | AT28: 攻击下限 | AU28: 11 | AV28: 攻击上限 | AW28: 15 | AX28: 魔法下限 | AY28: 11 | AZ28: 魔法上限 | BA28: 15 | BB28: 道术下限 | BC28: 0 | BD28: 道术上限 | BE28: 0 | BF28: 移动速度 | BG28: 100 | BH28: 攻击范围 | BI28: 10 | BJ28: 警戒范围 | BK28: 200 | BN28: 1 | BO28: 2500 | BP28: 2 | BQ28: 2500 | BR28: 怪物说明功能测试： 怪物身份颜色：|cffFF0000BOSS|r，|cff00FF00精英怪|r，普通怪 概率掉落以下物品： |cffFFA500美刀|r、|cffd9d919one刀乐|r、|cffA020F0two刀乐
A29: =60000000+INDEX(编号表!$B:$B,MATCH(I29,编号表!$A:$A,0))*10000+INDEX(编号表!$B:$B,MATCH(J29,编号表!$C:$C,0))*1000+K29 -> 60011018 | B29: a022 | C29: 沙虫 | D29: 沙虫 | E29: 18 | F29: {=INDEX(编号表!$E:$E,MATCH(J29,编号表!$C:$C,0))} -> 白色 | G29: 5 | H29: 比奇城-左上 | I29: 比奇城 | J29: 普通 | K29: 18 | L29: =COUNTIFS(I$11:I29,I29,J$11:J29,J29)-1 -> 18 | O29: 10 | P29: 300000 | Q29: 否 | R29: 40140002 | U29: 11010001 | V29: 11020001 | X29: 战士 | Y29: ani_monster_shachong_01 | Z29: 0.6 | AA29: 50 | AB29: 50 | AC29: 20 | AD29: 30 | AE29: 近战 | AI29: 58 | AJ29: 生命值 | AK29: 250 | AL29: 物防下限 | AM29: 5 | AN29: 物防上限 | AO29: 7 | AP29: 魔防下限 | AQ29: 4 | AR29: 魔防上限 | AS29: 7 | AT29: 攻击下限 | AU29: 11 | AV29: 攻击上限 | AW29: 14 | AX29: 魔法下限 | AY29: 11 | AZ29: 魔法上限 | BA29: 14 | BB29: 道术下限 | BC29: 1 | BD29: 道术上限 | BE29: 2 | BF29: 移动速度 | BG29: 100 | BH29: 攻击范围 | BI29: 10 | BJ29: 警戒范围 | BK29: 200 | BN29: 1 | BO29: 2500 | BP29: 2 | BQ29: 2500 | BR29: 怪物说明功能测试： 怪物身份颜色：|cffFF0000BOSS|r，|cff00FF00精英怪|r，普通怪 概率掉落以下物品： |cffFFA500美刀|r、|cffd9d919one刀乐|r、|cffA020F0two刀乐
A30: =60000000+INDEX(编号表!$B:$B,MATCH(I30,编号表!$A:$A,0))*10000+INDEX(编号表!$B:$B,MATCH(J30,编号表!$C:$C,0))*1000+K30 -> 60011019 | B30: a023 | C30: 蝎子 | D30: 蝎子 | E30: 18 | F30: {=INDEX(编号表!$E:$E,MATCH(J30,编号表!$C:$C,0))} -> 白色 | G30: 5 | H30: 比奇城-左上 | I30: 比奇城 | J30: 普通 | K30: 19 | L30: =COUNTIFS(I$11:I30,I30,J$11:J30,J30)-1 -> 19 | O30: 10 | P30: 300000 | Q30: 否 | R30: 40140002 | U30: 11010001 | V30: 11020001 | X30: 战士 | Y30: ani_monster_xiezi_01 | AA30: 50 | AB30: 50 | AC30: 20 | AD30: 30 | AE30: 近战 | AI30: 58 | AJ30: 生命值 | AK30: 230 | AL30: 物防下限 | AM30: 5 | AN30: 物防上限 | AO30: 7 | AP30: 魔防下限 | AQ30: 4 | AR30: 魔防上限 | AS30: 6 | AT30: 攻击下限 | AU30: 12 | AV30: 攻击上限 | AW30: 16 | AX30: 魔法下限 | AY30: 12 | AZ30: 魔法上限 | BA30: 16 | BB30: 道术下限 | BC30: 1 | BD30: 道术上限 | BE30: 2 | BF30: 移动速度 | BG30: 100 | BH30: 攻击范围 | BI30: 10 | BJ30: 警戒范围 | BK30: 200 | BN30: 1 | BO30: 2500 | BP30: 2 | BQ30: 2500 | BR30: 怪物说明功能测试： 怪物身份颜色：|cffFF0000BOSS|r，|cff00FF00精英怪|r，普通怪 概率掉落以下物品： |cffFFA500美刀|r、|cffd9d919one刀乐|r、|cffA020F0two刀乐
A31: =60000000+INDEX(编号表!$B:$B,MATCH(I31,编号表!$A:$A,0))*10000+INDEX(编号表!$B:$B,MATCH(J31,编号表!$C:$C,0))*1000+K31 -> 60012000 | B31: a006 | C31: 蛤蟆 | D31: 蛤蟆 | E31: 12 | F31: {=INDEX(编号表!$E:$E,MATCH(J31,编号表!$C:$C,0))} -> 绿色 | G31: 2 | H31: 比奇城-右下 | I31: 比奇城 | J31: 精英 | K31: 0 | L31: =COUNTIFS(I$11:I31,I31,J$11:J31,J31)-1 -> 0 | O31: 10 | P31: 150000 | Q31: 否 | R31: 40140002 | U31: 11010001 | V31: 11020001 | X31: 战士 | Y31: ani_monster_hama_01 | AA31: 50 | AB31: 50 | AC31: 20 | AD31: 30 | AE31: 近战 | AG31: ain_effect_jinengtexiao_52 | AI31: 130 | AJ31: 生命值 | AK31: 590 | AL31: 物防下限 | AM31: 4 | AN31: 物防上限 | AO31: 6 | AP31: 魔防下限 | AQ31: 4 | AR31: 魔防上限 | AS31: 5 | AT31: 攻击下限 | AU31: 11 | AV31: 攻击上限 | AW31: 15 | AX31: 魔法下限 | AY31: 11 | AZ31: 魔法上限 | BA31: 15 | BB31: 道术下限 | BC31: 0 | BD31: 道术上限 | BE31: 0 | BF31: 移动速度 | BG31: 100 | BH31: 攻击范围 | BI31: 10 | BJ31: 警戒范围 | BK31: 200 | BN31: 1 | BO31: 2500 | BP31: 2 | BQ31: 2500 | BR31: 怪物说明功能测试： 怪物身份颜色：|cffFF0000BOSS|r，|cff00FF00精英怪|r，普通怪 概率掉落以下物品： |cffFFA500美刀|r、|cffd9d919one刀乐|r、|cffA020F0two刀乐
A32: =60000000+INDEX(编号表!$B:$B,MATCH(I32,编号表!$A:$A,0))*10000+INDEX(编号表!$B:$B,MATCH(J32,编号表!$C:$C,0))*1000+K32 -> 60012001 | B32: a011 | C32: 多钩猫 | D32: 多钩猫1 | E32: 13 | F32: {=INDEX(编号表!$E:$E,MATCH(J32,编号表!$C:$C,0))} -> 绿色 | G32: 3 | H32: 比奇城-左下 | I32: 比奇城 | J32: 精英 | K32: 1 | L32: =COUNTIFS(I$11:I32,I32,J$11:J32,J32)-1 -> 1 | O32: 10 | P32: 150000 | Q32: 否 | R32: 40140002 | U32: 11010001 | V32: 11020001 | X32: 战士 | Y32: ani_monster_duogoumao_01 | Z32: 1.2 | AA32: 80 | AB32: 80 | AC32: 20 | AD32: 30 | AE32: 近战 | AG32: ain_effect_jinengtexiao_52 | AI32: 145 | AJ32: 生命值 | AK32: 660 | AL32: 物防下限 | AM32: 4 | AN32: 物防上限 | AO32: 6 | AP32: 魔防下限 | AQ32: 4 | AR32: 魔防上限 | AS32: 6 | AT32: 攻击下限 | AU32: 12 | AV32: 攻击上限 | AW32: 16 | AX32: 魔法下限 | AY32: 12 | AZ32: 魔法上限 | BA32: 16 | BB32: 道术下限 | BC32: 0 | BD32: 道术上限 | BE32: 0 | BF32: 移动速度 | BG32: 100 | BH32: 攻击范围 | BI32: 10 | BJ32: 警戒范围 | BK32: 200 | BN32: 1 | BO32: 2500 | BP32: 2 | BQ32: 2500 | BR32: 怪物说明功能测试： 怪物身份颜色：|cffFF0000BOSS|r，|cff00FF00精英怪|r，普通怪 概率掉落以下物品： |cffFFA500美刀|r、|cffd9d919one刀乐|r、|cffA020F0two刀乐
A33: =60000000+INDEX(编号表!$B:$B,MATCH(I33,编号表!$A:$A,0))*10000+INDEX(编号表!$B:$B,MATCH(J33,编号表!$C:$C,0))*1000+K33 -> 60012002 | B33: a017 | C33: 森林雪人 | D33: 森林雪人10 | E33: 16 | F33: {=INDEX(编号表!$E:$E,MATCH(J33,编号表!$C:$C,0))} -> 绿色 | G33: 4 | H33: 比奇城-右上 | I33: 比奇城 | J33: 精英 | K33: 2 | L33: =COUNTIFS(I$11:I33,I33,J$11:J33,J33)-1 -> 2 | O33: 10 | P33: 150000 | Q33: 否 | R33: 40140002 | U33: 11010001 | V33: 11020001 | X33: 战士 | Y33: ani_monster_senlinxueren_01 | Z33: 1.2 | AA33: 80 | AB33: 80 | AC33: 20 | AD33: 30 | AE33: 近战 | AG33: ain_effect_jinengtexiao_52 | AI33: 195 | AJ33: 生命值 | AK33: 890 | AL33: 物防下限 | AM33: 5 | AN33: 物防上限 | AO33: 8 | AP33: 魔防下限 | AQ33: 5 | AR33: 魔防上限 | AS33: 7 | AT33: 攻击下限 | AU33: 15 | AV33: 攻击上限 | AW33: 21 | AX33: 魔法下限 | AY33: 15 | AZ33: 魔法上限 | BA33: 21 | BB33: 道术下限 | BC33: 0 | BD33: 道术上限 | BE33: 0 | BF33: 移动速度 | BG33: 100 | BH33: 攻击范围 | BI33: 10 | BJ33: 警戒范围 | BK33: 200 | BN33: 1 | BO33: 2500 | BP33: 2 | BQ33: 2500 | BR33: 怪物说明功能测试： 怪物身份颜色：|cffFF0000BOSS|r，|cff00FF00精英怪|r，普通怪 概率掉落以下物品： |cffFFA500美刀|r、|cffd9d919one刀乐|r、|cffA020F0two刀乐
A34: =60000000+INDEX(编号表!$B:$B,MATCH(I34,编号表!$A:$A,0))*10000+INDEX(编号表!$B:$B,MATCH(J34,编号表!$C:$C,0))*1000+K34 -> 60012003 | B34: a024 | C34: 威思而小虫 | D34: 威思而小虫 | E34: 18 | F34: {=INDEX(编号表!$E:$E,MATCH(J34,编号表!$C:$C,0))} -> 绿色 | G34: 5 | H34: 比奇城-左上 | I34: 比奇城 | J34: 精英 | K34: 3 | L34: =COUNTIFS(I$11:I34,I34,J$11:J34,J34)-1 -> 3 | O34: 10 | P34: 300000 | Q34: 否 | R34: 40140002 | U34: 11010001 | V34: 11020001 | X34: 战士 | Y34: ani_monster_xiaochong_01 | AA34: 50 | AB34: 50 | AC34: 20 | AD34: 30 | AE34: 近战 | AG34: ain_effect_jinengtexiao_52 | AI34: 230 | AJ34: 生命值 | AK34: 1200 | AL34: 物防下限 | AM34: 7 | AN34: 物防上限 | AO34: 10 | AP34: 魔防下限 | AQ34: 7 | AR34: 魔防上限 | AS34: 10 | AT34: 攻击下限 | AU34: 19 | AV34: 攻击上限 | AW34: 25 | AX34: 魔法下限 | AY34: 19 | AZ34: 魔法上限 | BA34: 25 | BB34: 道术下限 | BC34: 1 | BD34: 道术上限 | BE34: 2 | BF34: 移动速度 | BG34: 100 | BH34: 攻击范围 | BI34: 10 | BJ34: 警戒范围 | BK34: 200 | BN34: 1 | BO34: 2500 | BP34: 2 | BQ34: 2500 | BR34: 怪物说明功能测试： 怪物身份颜色：|cffFF0000BOSS|r，|cff00FF00精英怪|r，普通怪 概率掉落以下物品： |cffFFA500美刀|r、|cffd9d919one刀乐|r、|cffA020F0two刀乐
A35: =60000000+INDEX(编号表!$B:$B,MATCH(I35,编号表!$A:$A,0))*10000+INDEX(编号表!$B:$B,MATCH(J35,编号表!$C:$C,0))*1000+K35 -> 60012004 | B35: a025 | C35: 盔甲虫 | D35: 盔甲虫10 | E35: 18 | F35: {=INDEX(编号表!$E:$E,MATCH(J35,编号表!$C:$C,0))} -> 绿色 | G35: 5 | H35: 比奇城-左上 | I35: 比奇城 | J35: 精英 | K35: 4 | L35: =COUNTIFS(I$11:I35,I35,J$11:J35,J35)-1 -> 4 | O35: 10 | P35: 150000 | Q35: 否 | R35: 40140002 | U35: 11010001 | V35: 11020001 | X35: 战士 | Y35: ani_moster_kuijiachong_01 | Z35: 1.2 | AA35: 80 | AB35: 80 | AC35: 20 | AD35: 30 | AE35: 近战 | AG35: ain_effect_jinengtexiao_52 | AI35: 230 | AJ35: 生命值 | AK35: 1200 | AL35: 物防下限 | AM35: 7 | AN35: 物防上限 | AO35: 10 | AP35: 魔防下限 | AQ35: 7 | AR35: 魔防上限 | AS35: 10 | AT35: 攻击下限 | AU35: 19 | AV35: 攻击上限 | AW35: 25 | AX35: 魔法下限 | AY35: 19 | AZ35: 魔法上限 | BA35: 25 | BB35: 道术下限 | BC35: 0 | BD35: 道术上限 | BE35: 0 | BF35: 移动速度 | BG35: 100 | BH35: 攻击范围 | BI35: 10 | BJ35: 警戒范围 | BK35: 200 | BN35: 1 | BO35: 2500 | BP35: 2 | BQ35: 2500 | BR35: 怪物说明功能测试： 怪物身份颜色：|cffFF0000BOSS|r，|cff00FF00精英怪|r，普通怪 概率掉落以下物品： |cffFFA500美刀|r、|cffd9d919one刀乐|r、|cffA020F0two刀乐
A36: =60000000+INDEX(编号表!$B:$B,MATCH(I36,编号表!$A:$A,0))*10000+INDEX(编号表!$B:$B,MATCH(J36,编号表!$C:$C,0))*1000+K36 -> 60014000 | B36: b001 | C36: 盔甲虫 | D36: 盔甲虫10 | E36: 18 | F36: {=INDEX(编号表!$E:$E,MATCH(J36,编号表!$C:$C,0))} -> 橙色 | G36: 5 | H36: 比奇城-左上 | I36: 比奇城 | J36: BOSS | K36: 0 | L36: =COUNTIFS(I$11:I36,I36,J$11:J36,J36)-1 -> 0 | O36: 10 | P36: 150000 | Q36: 否 | R36: 40140002 | U36: 11010001 | V36: 11020001 | X36: 战士 | Y36: ani_moster_kuijiachong_01 | Z36: 1.5 | AA36: 50 | AB36: 50 | AC36: 20 | AD36: 30 | AE36: 近战 | AG36: ain_effect_jinengtexiao_58 | AI36: 1160 | AJ36: 生命值 | AK36: 5200 | AL36: 物防下限 | AM36: 9 | AN36: 物防上限 | AO36: 13 | AP36: 魔防下限 | AQ36: 9 | AR36: 魔防上限 | AS36: 13 | AT36: 攻击下限 | AU36: 28 | AV36: 攻击上限 | AW36: 38 | AX36: 魔法下限 | AY36: 28 | AZ36: 魔法上限 | BA36: 38 | BB36: 道术下限 | BC36: 0 | BD36: 道术上限 | BE36: 0 | BF36: 移动速度 | BG36: 100 | BH36: 攻击范围 | BI36: 10 | BJ36: 警戒范围 | BK36: 200 | BN36: 1 | BO36: 2500 | BP36: 2 | BQ36: 2500 | BR36: 怪物说明功能测试： 怪物身份颜色：|cffFF0000BOSS|r，|cff00FF00精英怪|r，普通怪 概率掉落以下物品： |cffFFA500美刀|r、|cffd9d919one刀乐|r、|cffA020F0two刀乐
A37: =60000000+INDEX(编号表!$B:$B,MATCH(I37,编号表!$A:$A,0))*10000+INDEX(编号表!$B:$B,MATCH(J37,编号表!$C:$C,0))*1000+K37 -> 60021000 | B37: a026 | C37: 山洞蝙蝠 | D37: 山洞蝙蝠 | E37: 18 | F37: {=INDEX(编号表!$E:$E,MATCH(J37,编号表!$C:$C,0))} -> 白色 | G37: 6 | H37: 古墓一层 | I37: 兽人古墓一层 | J37: 普通 | K37: 0 | L37: =COUNTIFS(I$11:I37,I37,J$11:J37,J37)-1 -> 0 | O37: 10 | P37: 150000 | Q37: 否 | R37: 40140002 | U37: 11010001 | V37: 11020001 | X37: 战士 | Y37: ani_monster_shandongbianfu_01 | AA37: 50 | AB37: 50 | AC37: 20 | AD37: 30 | AE37: 近战 | AI37: 59 | AJ37: 生命值 | AK37: 190 | AL37: 物防下限 | AM37: 4 | AN37: 物防上限 | AO37: 5 | AP37: 魔防下限 | AQ37: 3 | AR37: 魔防上限 | AS37: 5 | AT37: 攻击下限 | AU37: 12 | AV37: 攻击上限 | AW37: 16 | AX37: 魔法下限 | AY37: 12 | AZ37: 魔法上限 | BA37: 16 | BB37: 道术下限 | BC37: 0 | BD37: 道术上限 | BE37: 0 | BF37: 移动速度 | BG37: 100 | BH37: 攻击范围 | BI37: 10 | BJ37: 警戒范围 | BK37: 250 | BL37: 0.03 | BN37: 1 | BO37: 2500 | BP37: 2 | BQ37: 2500 | BR37: 怪物说明功能测试： 怪物身份颜色：|cffFF0000BOSS|r，|cff00FF00精英怪|r，普通怪 概率掉落以下物品： |cffFFA500美刀|r、|cffd9d919one刀乐|r、|cffA020F0two刀乐
A38: =60000000+INDEX(编号表!$B:$B,MATCH(I38,编号表!$A:$A,0))*10000+INDEX(编号表!$B:$B,MATCH(J38,编号表!$C:$C,0))*1000+K38 -> 60021001 | B38: a027 | C38: 洞蛆 | D38: 洞蛆 | E38: 18 | F38: {=INDEX(编号表!$E:$E,MATCH(J38,编号表!$C:$C,0))} -> 白色 | G38: 6 | H38: 古墓一层 | I38: 兽人古墓一层 | J38: 普通 | K38: 1 | L38: =COUNTIFS(I$11:I38,I38,J$11:J38,J38)-1 -> 1 | O38: 10 | P38: 150000 | Q38: 否 | R38: 40140002 | U38: 11010001 | V38: 11020001 | X38: 战士 | Y38: ani_monster_dongqu_01 | Z38: 0.5 | AA38: 50 | AB38: 50 | AC38: 20 | AD38: 30 | AE38: 近战 | AI38: 59 | AJ38: 生命值 | AK38: 240 | AL38: 物防下限 | AM38: 4 | AN38: 物防上限 | AO38: 6 | AP38: 魔防下限 | AQ38: 4 | AR38: 魔防上限 | AS38: 6 | AT38: 攻击下限 | AU38: 11 | AV38: 攻击上限 | AW38: 14 | AX38: 魔法下限 | AY38: 11 | AZ38: 魔法上限 | BA38: 14 | BB38: 道术下限 | BC38: 0 | BD38: 道术上限 | BE38: 0 | BF38: 移动速度 | BG38: 100 | BH38: 攻击范围 | BI38: 10 | BJ38: 警戒范围 | BK38: 250 | BN38: 1 | BO38: 2500 | BP38: 2 | BQ38: 2500 | BR38: 怪物说明功能测试： 怪物身份颜色：|cffFF0000BOSS|r，|cff00FF00精英怪|r，普通怪 概率掉落以下物品： |cffFFA500美刀|r、|cffd9d919one刀乐|r、|cffA020F0two刀乐
A39: =60000000+INDEX(编号表!$B:$B,MATCH(I39,编号表!$A:$A,0))*10000+INDEX(编号表!$B:$B,MATCH(J39,编号表!$C:$C,0))*1000+K39 -> 60021002 | B39: a028 | C39: 骷髅 | D39: 骷髅 | E39: 18 | F39: {=INDEX(编号表!$E:$E,MATCH(J39,编号表!$C:$C,0))} -> 白色 | G39: 6 | H39: 古墓一层 | I39: 兽人古墓一层 | J39: 普通 | K39: 2 | L39: =COUNTIFS(I$11:I39,I39,J$11:J39,J39)-1 -> 2 | O39: 10 | P39: 150000 | Q39: 否 | R39: 40140002 | U39: 11010001 | V39: 11020001 | X39: 战士 | Y39: ani_monster_kulou_01 | Z39: 1.5 | AA39: 80 | AB39: 80 | AC39: 20 | AD39: 30 | AE39: 近战 | AI39: 59 | AJ39: 生命值 | AK39: 250 | AL39: 物防下限 | AM39: 5 | AN39: 物防上限 | AO39: 7 | AP39: 魔防下限 | AQ39: 5 | AR39: 魔防上限 | AS39: 7 | AT39: 攻击下限 | AU39: 11 | AV39: 攻击上限 | AW39: 15 | AX39: 魔法下限 | AY39: 11 | AZ39: 魔法上限 | BA39: 15 | BB39: 道术下限 | BC39: 0 | BD39: 道术上限 | BE39: 0 | BF39: 移动速度 | BG39: 100 | BH39: 攻击范围 | BI39: 10 | BJ39: 警戒范围 | BK39: 250 | BN39: 1 | BO39: 2500 | BP39: 2 | BQ39: 2500 | BR39: 怪物说明功能测试： 怪物身份颜色：|cffFF0000BOSS|r，|cff00FF00精英怪|r，普通怪 概率掉落以下物品： |cffFFA500美刀|r、|cffd9d919one刀乐|r、|cffA020F0two刀乐
A40: =60000000+INDEX(编号表!$B:$B,MATCH(I40,编号表!$A:$A,0))*10000+INDEX(编号表!$B:$B,MATCH(J40,编号表!$C:$C,0))*1000+K40 -> 60021003 | B40: a029 | C40: 骷髅战士 | D40: 骷髅战士 | E40: 18 | F40: {=INDEX(编号表!$E:$E,MATCH(J40,编号表!$C:$C,0))} -> 白色 | G40: 6 | H40: 古墓一层 | I40: 兽人古墓一层 | J40: 普通 | K40: 3 | L40: =COUNTIFS(I$11:I40,I40,J$11:J40,J40)-1 -> 3 | O40: 10 | P40: 150000 | Q40: 否 | R40: 40140002 | U40: 11010001 | V40: 11020001 | X40: 战士 | Y40: ani_monster_kulouzhanshi_01 | Z40: 1.5 | AA40: 80 | AB40: 80 | AC40: 20 | AD40: 30 | AE40: 近战 | AI40: 59 | AJ40: 生命值 | AK40: 290 | AL40: 物防下限 | AM40: 6 | AN40: 物防上限 | AO40: 8 | AP40: 魔防下限 | AQ40: 5 | AR40: 魔防上限 | AS40: 8 | AT40: 攻击下限 | AU40: 12 | AV40: 攻击上限 | AW40: 16 | AX40: 魔法下限 | AY40: 12 | AZ40: 魔法上限 | BA40: 16 | BB40: 道术下限 | BC40: 0 | BD40: 道术上限 | BE40: 0 | BF40: 移动速度 | BG40: 100 | BH40: 攻击范围 | BI40: 10 | BJ40: 警戒范围 | BK40: 250 | BN40: 1 | BO40: 2500 | BP40: 2 | BQ40: 2500 | BR40: 怪物说明功能测试： 怪物身份颜色：|cffFF0000BOSS|r，|cff00FF00精英怪|r，普通怪 概率掉落以下物品： |cffFFA500美刀|r、|cffd9d919one刀乐|r、|cffA020F0two刀乐
A41: =60000000+INDEX(编号表!$B:$B,MATCH(I41,编号表!$A:$A,0))*10000+INDEX(编号表!$B:$B,MATCH(J41,编号表!$C:$C,0))*1000+K41 -> 60021004 | B41: a030 | C41: 骷髅战将 | D41: 骷髅战将 | E41: 18 | F41: {=INDEX(编号表!$E:$E,MATCH(J41,编号表!$C:$C,0))} -> 白色 | G41: 6 | H41: 古墓一层 | I41: 兽人古墓一层 | J41: 普通 | K41: 4 | L41: =COUNTIFS(I$11:I41,I41,J$11:J41,J41)-1 -> 4 | O41: 10 | P41: 150000 | Q41: 否 | R41: 40140002 | U41: 11010001 | V41: 11020001 | X41: 战士 | Y41: ani_monster_kulouzhanjiang_01 | Z41: 1.5 | AA41: 80 | AB41: 80 | AC41: 20 | AD41: 30 | AE41: 近战 | AI41: 59 | AJ41: 生命值 | AK41: 290 | AL41: 物防下限 | AM41: 6 | AN41: 物防上限 | AO41: 8 | AP41: 魔防下限 | AQ41: 5 | AR41: 魔防上限 | AS41: 8 | AT41: 攻击下限 | AU41: 12 | AV41: 攻击上限 | AW41: 16 | AX41: 魔法下限 | AY41: 12 | AZ41: 魔法上限 | BA41: 16 | BB41: 道术下限 | BC41: 0 | BD41: 道术上限 | BE41: 0 | BF41: 移动速度 | BG41: 100 | BH41: 攻击范围 | BI41: 10 | BJ41: 警戒范围 | BK41: 250 | BN41: 1 | BO41: 2500 | BP41: 2 | BQ41: 2500 | BR41: 怪物说明功能测试： 怪物身份颜色：|cffFF0000BOSS|r，|cff00FF00精英怪|r，普通怪 概率掉落以下物品： |cffFFA500美刀|r、|cffd9d919one刀乐|r、|cffA020F0two刀乐
A42: =60000000+INDEX(编号表!$B:$B,MATCH(I42,编号表!$A:$A,0))*10000+INDEX(编号表!$B:$B,MATCH(J42,编号表!$C:$C,0))*1000+K42 -> 60022000 | B42: a031 | C42: 骷髅战士 | D42: 骷髅战士10 | E42: 19 | F42: {=INDEX(编号表!$E:$E,MATCH(J42,编号表!$C:$C,0))} -> 绿色 | G42: 6 | H42: 古墓一层 | I42: 兽人古墓一层 | J42: 精英 | K42: 0 | L42: =COUNTIFS(I$11:I42,I42,J$11:J42,J42)-1 -> 0 | O42: 10 | P42: 150000 | Q42: 否 | R42: 40140002 | U42: 11010001 | V42: 11020001 | X42: 战士 | Y42: ani_monster_kulouzhanshi_01 | Z42: 1.5 | AA42: 80 | AB42: 80 | AC42: 20 | AD42: 30 | AE42: 近战 | AG42: ain_effect_jinengtexiao_52 | AI42: 255 | AJ42: 生命值 | AK42: 1500 | AL42: 物防下限 | AM42: 8 | AN42: 物防上限 | AO42: 12 | AP42: 魔防下限 | AQ42: 8 | AR42: 魔防上限 | AS42: 11 | AT42: 攻击下限 | AU42: 21 | AV42: 攻击上限 | AW42: 29 | AX42: 魔法下限 | AY42: 21 | AZ42: 魔法上限 | BA42: 29 | BB42: 道术下限 | BC42: 0 | BD42: 道术上限 | BE42: 0 | BF42: 移动速度 | BG42: 100 | BH42: 攻击范围 | BI42: 10 | BJ42: 警戒范围 | BK42: 250 | BN42: 1 | BO42: 2500 | BP42: 2 | BQ42: 2500 | BR42: 怪物说明功能测试： 怪物身份颜色：|cffFF0000BOSS|r，|cff00FF00精英怪|r，普通怪 概率掉落以下物品： |cffFFA500美刀|r、|cffd9d919one刀乐|r、|cffA020F0two刀乐
A43: =60000000+INDEX(编号表!$B:$B,MATCH(I43,编号表!$A:$A,0))*10000+INDEX(编号表!$B:$B,MATCH(J43,编号表!$C:$C,0))*1000+K43 -> 60024000 | B43: b002 | C43: 骷髅战士 | D43: 骷髅战士10 | E43: 19 | F43: {=INDEX(编号表!$E:$E,MATCH(J43,编号表!$C:$C,0))} -> 橙色 | G43: 6 | H43: 古墓一层 | I43: 兽人古墓一层 | J43: BOSS | K43: 0 | L43: =COUNTIFS(I$11:I43,I43,J$11:J43,J43)-1 -> 0 | O43: 10 | P43: 150000 | Q43: 否 | R43: 40140002 | U43: 11010001 | V43: 11020001 | X43: 战士 | Y43: ani_monster_kulouzhanshi_01 | Z43: 1.5 | AA43: 80 | AB43: 80 | AC43: 20 | AD43: 30 | AE43: 近战 | AG43: ain_effect_jinengtexiao_58 | AI43: 1280 | AJ43: 生命值 | AK43: 6500 | AL43: 物防下限 | AM43: 11 | AN43: 物防上限 | AO43: 15 | AP43: 魔防下限 | AQ43: 10 | AR43: 魔防上限 | AS43: 15 | AT43: 攻击下限 | AU43: 32 | AV43: 攻击上限 | AW43: 43 | AX43: 魔法下限 | AY43: 32 | AZ43: 魔法上限 | BA43: 43 | BB43: 道术下限 | BC43: 0 | BD43: 道术上限 | BE43: 0 | BF43: 移动速度 | BG43: 100 | BH43: 攻击范围 | BI43: 10 | BJ43: 警戒范围 | BK43: 250 | BN43: 1 | BO43: 2500 | BP43: 2 | BQ43: 2500 | BR43: 怪物说明功能测试： 怪物身份颜色：|cffFF0000BOSS|r，|cff00FF00精英怪|r，普通怪 概率掉落以下物品： |cffFFA500美刀|r、|cffd9d919one刀乐|r、|cffA020F0two刀乐
A44: =60000000+INDEX(编号表!$B:$B,MATCH(I44,编号表!$A:$A,0))*10000+INDEX(编号表!$B:$B,MATCH(J44,编号表!$C:$C,0))*1000+K44 -> 60031000 | B44: a032 | C44: 山洞蝙蝠 | D44: 山洞蝙蝠0 | E44: 19 | F44: {=INDEX(编号表!$E:$E,MATCH(J44,编号表!$C:$C,0))} -> 白色 | G44: 7 | H44: 古墓二层 | I44: 兽人古墓二层 | J44: 普通 | K44: 0 | L44: =COUNTIFS(I$11:I44,I44,J$11:J44,J44)-1 -> 0 | O44: 10 | P44: 150000 | Q44: 否 | R44: 40140002 | U44: 11010001 | V44: 11020001 | X44: 战士 | Y44: ani_monster_shandongbianfu_01 | AA44: 50 | AB44: 50 | AC44: 20 | AD44: 30 | AE44: 近战 | AI44: 65 | AJ44: 生命值 | AK44: 230 | AL44: 物防下限 | AM44: 4 | AN44: 物防上限 | AO44: 6 | AP44: 魔防下限 | AQ44: 4 | AR44: 魔防上限 | AS44: 6 | AT44: 攻击下限 | AU44: 13 | AV44: 攻击上限 | AW44: 18 | AX44: 魔法下限 | AY44: 13 | AZ44: 魔法上限 | BA44: 18 | BB44: 道术下限 | BC44: 0 | BD44: 道术上限 | BE44: 0 | BF44: 移动速度 | BG44: 100 | BH44: 攻击范围 | BI44: 10 | BJ44: 警戒范围 | BK44: 250 | BL44: 0.03 | BN44: 1 | BO44: 2500 | BP44: 2 | BQ44: 2500 | BR44: 怪物说明功能测试： 怪物身份颜色：|cffFF0000BOSS|r，|cff00FF00精英怪|r，普通怪 概率掉落以下物品： |cffFFA500美刀|r、|cffd9d919one刀乐|r、|cffA020F0two刀乐
...

Sheet 编号表
A1: 场景归属 | B1: 内部编号 | C1: 怪物身份 | D1: 内部编号 | E1: 颜色 | J1: 新手
A2: 比奇城 | B2: 1 | C2: 普通 | D2: 1 | E2: 白色 | J2: 沃玛级
A3: 兽人古墓一层 | B3: 2 | C3: 精英 | D3: 2 | E3: 绿色 | G3: 装备是5开头8位数 | J3: 祖玛级
A4: 兽人古墓二层 | B4: 3 | C4: 大精英 | D4: 3 | E4: 紫色 | G4: 第1位 | H4: 6开头代表怪物 | J4: 苍月级
A5: 国王陵墓 | B5: 4 | C5: BOSS | D5: 4 | E5: 橙色 | G5: 第2位 | H5: 用场景来代表级别。相当于装备的阶级，沃玛级，祖玛级，苍月级，赤月级等，2位应该够，暂时用3位保险。这个级别和场景区域配置严格匹配，相等。 | J5: 赤月级
A6: 废矿区东部 | B6: 5 | C6: 大BOSS | D6: 5 | E6: 红色 | G6: 第3位 | J6: 雷霆级
A7: 尸王殿 | B7: 6 | C7: 任务 | D7: 6 | E7: 橙色 | G7: 第4位 | J7: 战神级
A8: 地牢 | B8: 7 | C8: 活动 | D8: 7 | E8: 橙色 | G8: 第5位 | H8: 怪物身份，区分普通/精英怪/BOSS | J8: 星王级
A9: 黑暗地带 | B9: 8 | D9: 8 | G9: 第6位 | H9: 具体数字，填在正表E列，3位数总共1000个，代表本类别的具体序号。每个场景的每一类怪物分别计。比如比奇城的普通怪，从0开始计算1，2，3……比奇城的精英怪的序号，BOSS的序号也都是从0开始重新计算 | J9: 天龙级
A10: 死亡棺材 | B10: 9 | D10: 9 | G10: 第7位 | J10: 王者级
A11: 未知暗殿 | B11: 10 | D11: 10 | G11: 第8位 | J11: 皓天级
A12: 沃玛寺庙一层 | B12: 11 | D12: 11 | J12: 传奇级
A13: 沃玛寺庙二层 | B13: 12
A14: 沃玛教主大殿 | B14: 13
A15: 石墓一层 | B15: 14
A16: 石墓阵入口 | B16: 15
A17: 石墓阵出口 | B17: 16 | F17: 怪物的区分 | G17: 区域，代表等级范围或者说级别，决定掉落，经验，数值
A18: 石墓顶层 | B18: 17 | G18: 身份，决定掉落，经验，数值
A19: 桃源之门 | B19: 18
A20: 困惑殿堂 | B20: 19 | F20: ID使用公式的主要原因
A21: 祖玛寺庙一层 | B21: 20 | F21: 在配置内容频繁的变化，新增，尤其是插入新内容的改动时，确保对应ID的内在逻辑顺畅，方便在调用该ID的地方方便配置，减少出错也方便查错。同时保证在频繁变动的情况下，更好的保证ID的唯一性。
A22: 祖玛寺庙二层 | B22: 21 | F22: 比如，技能分战士，法师，道士，坐骑，翅膀等等N个大类，在后续新增了某翅膀和对应的技能，并在道具表，活动配置，装备表，掉落表等多地都要用到该ID时，使用公式算出来的ID填写，查错都会便捷非常多。
A23: 祖玛阁 | B23: 22 | F23: 按照变动频率来预估，变动最频繁的是掉落方案和技能表，状态表和物品表其次，装备表和怪物表的变动频率最低。
A24: 祖玛教主之家 | B24: 23
A25: 封魔矿区 | B25: 24 | F25: BOSS物编使用B开头，BNNN
A26: 光芒回廊 | B26: 25
A27: 封魔殿 | B27: 26
A28: 尸魔洞一层 | B28: 27
A29: 尸魔洞二层 | B29: 28
A30: 骨魔洞一层 | B30: 29
A31: 骨魔洞二层 | B31: 30
A32: 牛魔寺庙入口 | B32: 31
A33: 牛魔寺庙一层 | B33: 32
A34: 牛魔寺庙大厅 | B34: 33
A35: 丛林迷宫 | B35: 34
A36: 赤月峡谷西走廊 | B36: 35
A37: 赤月峡谷东二层 | B37: 36
... A41: 赤月魔穴 | B41: 40
B42: 41
B43: 42
...

Sheet 名称表
A1: Dignity | E1: OwnerMode | F1: 掉落类型 | H1: 阵营 | K1: 显示名字类型 | N1: 等级 | O1: 名字颜色 | Q1: 职业 | R1: 种族
A2: 怪物身份 | E2: 属主模型 | F2: 掉落_均可见属主拾取 | H2: 阵营_普通玩家 | K2: 名字_显示 | N2: 1 | O2: 绿色 | Q2: 职业_战士 | R2: 种族_风
A3: 怪物类型_普通 | C3: 是 | E3: 属主_首刀 | F3: 掉落_属主可见可拾取 | H3: 阵营_普通怪物 | K3: 名字_不显示 | N3: 2 | O3: 绿色 | Q3: 职业_法师 | R3: 种族_火
A4: 怪物类型_世界BOSS | C4: 否 | E4: 属主_组队伤害 | F4: 掉落_均可见均可拾取 | H4: 阵营_中立怪物 | K4: 名字_永久显示 | N4: 3 | O4: 绿色 | Q4: 职业_牧师 | R4: 种族_雷
A5: 怪物类型_人数值 | E5: 属主_组队伤害唯一 | F5: 掉落_均可见队伍拾取 | H5: 阵营_友好怪物 | N5: 4 | O5: 绿色 | Q5: 职业_萨满 | R5: 种族_水
A6: 怪物类型_宠数值 | E6: 属主_仇恨 | F6: 掉落_均可见区服拾取 | H6: 阵营_动画怪物 | N6: 5 | O6: 绿色
A7: 怪物类型_精英 | E7: 属主_普通 | H7: 阵营_动画怪物2 | N7: 6 | O7: 绿色
E8: 属主_末刀 | H8: 阵营_动画怪物3 | N8: 7 | O8: 绿色
E9: 属主_个人伤害 | H9: 阵营_动画怪物4 | N9: 8 | O9: 绿色
E10: 属主_个人伤害唯一 | N10: 9 | O10: 绿色
N11: 10 | O11: 绿色
N12: 11 | O12: 绿色
N13: 12 | O13: 绿色
N14: 13 | O14: 绿色
N15: 14 | O15: 绿色
N16: 15 | O16: 蓝色
N17: 16 | O17: 蓝色
N18: 17 | O18: 蓝色
N19: 18 | O19: 蓝色
N20: 19 | O20: 蓝色
A21: 怪物类型_首领 | N21: 20 | O21: 蓝色
A22: 怪物类型_世界PVPBOSS | N22: 21 | O22: 蓝色
A23: 怪物类型_散仙陷阱 | N23: 22 | O23: 蓝色
A24: 怪物类型_采集物 | N24: 23 | O24: 蓝色
A25: 怪物类型_琅琊福地NPC | N25: 24 | O25: 蓝色
A26: 怪物类型_阵营战炮台 | N26: 25 | O26: 蓝色
A27: 怪物类型_技能召唤 | N27: 26 | O27: 蓝色
A28: 怪物类型_前台怪 | N28: 27 | O28: 蓝色
A29: 怪物类型_受击掉落 | N29: 28 | O29: 紫色
N30: 29 | O30: 紫色
N31: 30 | O31: 紫色
N32: 31 | O32: 紫色
N33: 32 | O33: 紫色
N34: 33 | O34: 紫色
N35: 34 | O35: 紫色
N36: 35 | O36: 紫色
N37: 36 | O37: 紫色
N38: 37 | O38: 紫色
N39: 38 | O39: 紫色
N40: 39 | O40: 紫色
...

Sheet 版本变更
A1: 版本号 | B1: 改动内容
A2: V1.12 | B2: 1、删除金币掉落字段 2、更新怪物模型
A3: V1.13 | B3: 1、新增怪物缩放比例 2、更改盔甲虫模型
A4: V1.14 | B4: 1、更改了比奇城怪物攻击数值 2、更改的归属场景数据
A5: V1.15 | B5: 更新掉落方案
A6: V1.16 | B6: 更新怪物普攻和技能ID
A7: V1.17 | B7: 更改怪物的编号计算规则和对应的编号
A8: V1.18 | B8: 更新“蛤蟆”模型
A9: V1.19 | B9: 更新移动速度巡逻半径等数据
A10: V1.20 | B10: 所有蛤蟆模型放大到原5倍
A11: V1.21 | B11: 祖玛弓箭手模型更新
A12: V1.22 | B12: 怪物距离和速度属性更改
... A18: V1.28 | B18: 60371394 60371395，黑狐赤狐改为测试数值
A19: V1.29
A20: V1.30
A21: V1.31
A22: V1.32
A23: V1.33
A24: V1.34
A25: V1.35 | B25: 删掉视野半径和巡逻范围，新增属性警戒范围。
A26: V1.36 | B26: 调整掉落方案，对应调整怪物表
A27: V1.37 | B27: 怪物数据使用李鑫配置版本，同时所有的ID规则进行调整。困惑殿堂新增2普通2精英怪，封魔殿新增3精英物编ID用aa开头
A28: V1.38 | B28: 调整模型大小，1.36版本模型大小应该是对的，这个版本是之前复制李鑫的数据，模型大小可能比较原始，对所有＞0.5的基本都改成0.5了，持续修改 复制过来遗留的0全都删了，模型缩放不要配置0！！！ 所有模型改前缀，很多模型名字乱填的都改了，还有2个模型缺失，先用别的代替了。
A29: V1.39 | B29: 修改模型大小，沃玛战将模型用沃玛勇士暂替，碰撞体积20改为10
A30: V1.40 | B30: 新增任务掉落
A31: V1.41 | B31: 掉落方案出现BUG，把错误的掉落方案ID改正。增加一个木桩。所有怪物复活时间×10
A32: V1.42 | B32: 新增3个配置项，2个绑定特效+缩放，新增一个技能配置，改技能ID。修改警戒范围，
A33: V1.43 | B33: 增加NPC鸡
A34: V1.44
A35: V1.45
A36: V1.46
A37: V1.47
A38: V1.48
A39: V1.49
A40: V1.50

Sheet Sheet1
F1: a001 | G1: 比奇城 | R1: A107 | S1: 比奇城
F2: a002 | G2: 待定 | R2: A038 | S2: 比奇城
F3: a003 | G3: 待定 | R3: A120 | S3: 比奇城
F4: a004 | G4: 待定 | R4: A036 | S4: 比奇城
F5: a005 | G5: 待定 | R5: A033 | S5: 比奇城
F6: a006 | G6: 待定 | R6: A034 | S6: 比奇城
F7: a007 | G7: 待定 | R7: A013 | S7: 比奇城
F8: a008 | G8: 待定 | R8: A001 | S8: 比奇城
F9: a009 | G9: 待定 | R9: A106 | S9: 比奇城
F10: a010 | G10: 待定 | R10: A020 | S10: 比奇城
F11: a011 | G11: 待定 | R11: A029 | S11: 比奇城
F12: a012 | G12: 待定 | R12: A027 | S12: 比奇城
... F20: a020 | G20: 比奇城 | R20: A082 | S20: 比奇城
F21: a021 | G21: 待定
F22: a022 | G22: 待定
F23: a023 | G23: 比奇城
F24: a024 | G24: 待定
F25: a025 | G25: 待定
F26: a026 | G26: 待定
F27: a027 | G27: 比奇城
F28: a028 | G28: 待定
F29: a029 | G29: 比奇城
F30: a030 | G30: 待定
F31: a031 | G31: 待定
F32: a032 | G32: 待定
... F540: a540 | G540: 待定
