Workbook

Sheet item_config
A1: 道具ID | B1: 0名称 | C1: 0颜色 | D1: 0ID编号 | E1: 存在时间 | F1: 0大类 | G1: 0大类 | H1: 0子类 | I1: 0档次 | J1: 0显示分类 | K1: 属性限制 | L1: 存在时间 | M1: 0是否可丢弃 | N1: 是否可以自动使用 | O1: 0使用级别下限 | P1: 0职业限制 | Q1: 0堆叠上限 | R1: 0功能类型 | S1: 0功能ID | T1: 0功能数值 | U1: 0说明 | V1: 0获得说明 | W1: 0背包图标 | X1: 0地表模型 | Y1: 掉落光柱模型 | Z1: 静态边框 | AA1: 动态边框 | AB1: 标签1 | AC1: 标签2 | AD1: 标签3 | AE1: 标签4
A2: ID | B2: Name | C2: Color | E2: DurT | G2: MainClass | H2: SubClass | I2: DropLevel | J2: DisplayType | K2: attrLimit | L2: durT | M2: isDrop | N2: isAutoUse | O2: RequiredLevel | P2: Prof | Q2: PileMax | R2: FunctionType | S2: FunctionID | T2: FunctionValue | U2: Desc | V2: SpecDesc | W2: IconID | X2: mdxID | Y2: LightEffId | Z2: Border1 | AA2: Border2 | AB2: Tag1 | AC2: Tag2 | AD2: Tag3 | AE2: Tag4
A3: 31010001 | B3: 一小袋金币 | C3: 白色 | D3: 1 | E3: 60 | F3: 货币 | G3: 大类_基础 | H3: 子类_货币 | I3: 1 | J3: 货币 | L3: 30000 | M3: 否 | O3: 1 | P3: 无 | Q3: 999 | R3: 货币_金币 | T3: 50 | U3: ="|cff00FF00"&B3&"，打开后可以获得"&T3&"金币。" -> |cff00FF00一小袋金币，打开后可以获得50金币。 | V3: 击杀所有怪物，出售道具装备可获得 | W3: 31010001 | X3: fall_coin | AB3: 货币 | AC3: 金币
A4: 31010002 | B4: 一小袋灵符 | C4: 白色 | D4: 2 | E4: 60 | F4: 货币 | G4: 大类_基础 | H4: 子类_货币 | I4: 2 | J4: 货币 | L4: 30000 | M4: 否 | O4: 1 | P4: 无 | Q4: 999 | R4: 货币_灵符 | T4: 5 | U4: ="|cff00FF00"&B4&"，打开后可以获得"&T4&"灵符。" -> |cff00FF00一小袋灵符，打开后可以获得5灵符。 | V4: 击杀所有怪物，出售道具装备可获得 | W4: 31010002 | X4: fall_lingfu | AB4: 货币 | AC4: 灵符
A5: 31010003 | B5: 一袋金币 | C5: 白色 | D5: 3 | E5: 60 | F5: 货币 | G5: 大类_基础 | H5: 子类_货币 | I5: 3 | J5: 货币 | L5: 30000 | M5: 否 | O5: 1 | P5: 无 | Q5: 999 | R5: 货币_金币 | T5: 100 | U5: ="|cff00FF00"&B5&"，打开后可以获得"&T5&"金币。" -> |cff00FF00一袋金币，打开后可以获得100金币。 | V5: 击杀所有怪物，出售道具装备可获得 | W5: 31010001 | X5: fall_coin | AB5: 货币 | AC5: 金币
A6: 31010004 | B6: 一袋灵符 | C6: 白色 | D6: 4 | E6: 60 | F6: 货币 | G6: 大类_基础 | H6: 子类_货币 | I6: 4 | J6: 货币 | L6: 30000 | M6: 否 | O6: 1 | P6: 无 | Q6: 999 | R6: 货币_灵符 | T6: 10 | U6: ="|cff00FF00"&B6&"，打开后可以获得"&T6&"灵符。" -> |cff00FF00一袋灵符，打开后可以获得10灵符。 | V6: 击杀所有怪物，出售道具装备可获得 | W6: 31010002 | X6: fall_lingfu | AB6: 货币 | AC6: 灵符
A7: 31010005 | B7: 一大袋金币 | C7: 白色 | D7: 5 | E7: 60 | F7: 货币 | G7: 大类_基础 | H7: 子类_货币 | I7: 5 | J7: 货币 | L7: 30000 | M7: 否 | O7: 1 | P7: 无 | Q7: 999 | R7: 货币_金币 | T7: 500 | U7: ="|cff00FF00"&B7&"，打开后可以获得"&T7&"金币。" -> |cff00FF00一大袋金币，打开后可以获得500金币。 | V7: 击杀所有怪物，出售道具装备可获得 | W7: 31010001 | X7: fall_coin | AB7: 货币 | AC7: 金币
A8: 31010006 | B8: 一大袋灵符 | C8: 白色 | D8: 6 | E8: 60 | F8: 货币 | G8: 大类_基础 | H8: 子类_货币 | I8: 6 | J8: 货币 | L8: 30000 | M8: 否 | O8: 1 | P8: 无 | Q8: 999 | R8: 货币_灵符 | T8: 50 | U8: ="|cff00FF00"&B8&"，打开后可以获得"&T8&"灵符。" -> |cff00FF00一大袋灵符，打开后可以获得50灵符。 | V8: 击杀所有怪物，出售道具装备可获得 | W8: 31010002 | X8: fall_lingfu | AB8: 货币 | AC8: 灵符
A9: 31010007 | B9: 一箱金币 | C9: 白色 | D9: 7 | E9: 60 | F9: 货币 | G9: 大类_基础 | H9: 子类_货币 | I9: 7 | J9: 货币 | L9: 30000 | M9: 否 | O9: 1 | P9: 无 | Q9: 999 | R9: 货币_金币 | T9: 1000 | U9: ="|cff00FF00"&B9&"，打开后可以获得"&T9&"金币。" -> |cff00FF00一箱金币，打开后可以获得1000金币。 | V9: 击杀所有怪物，出售道具装备可获得 | W9: 31010001 | X9: fall_coin | AB9: 货币 | AC9: 金币
A10: 31010008 | B10: 一箱灵符 | C10: 白色 | D10: 8 | E10: 60 | F10: 货币 | G10: 大类_基础 | H10: 子类_货币 | I10: 8 | J10: 货币 | L10: 30000 | M10: 否 | O10: 1 | P10: 无 | Q10: 999 | R10: 货币_灵符 | T10: 100 | U10: ="|cff00FF00"&B10&"，打开后可以获得"&T10&"灵符。" -> |cff00FF00一箱灵符，打开后可以获得100灵符。 | V10: 击杀所有怪物，出售道具装备可获得 | W10: 31010002 | X10: fall_lingfu | AB10: 货币 | AC10: 灵符
A11: 31010009 | B11: 一大箱金币 | C11: 白色 | D11: 9 | E11: 60 | F11: 货币 | G11: 大类_基础 | H11: 子类_货币 | I11: 9 | J11: 货币 | L11: 30000 | M11: 否 | O11: 1 | P11: 无 | Q11: 999 | R11: 货币_金币 | T11: 5000 | U11: ="|cff00FF00"&B11&"，打开后可以获得"&T11&"金币。" -> |cff00FF00一大箱金币，打开后可以获得5000金币。 | V11: 击杀所有怪物，出售道具装备可获得 | W11: 31010001 | X11: fall_coin | AB11: 货币 | AC11: 金币
A12: 31010010 | B12: 一大箱灵符 | C12: 白色 | D12: 10 | E12: 60 | F12: 货币 | G12: 大类_基础 | H12: 子类_货币 | I12: 10 | J12: 货币 | L12: 30000 | M12: 否 | O12: 1 | P12: 无 | Q12: 999 | R12: 货币_灵符 | T12: 500 | U12: ="|cff00FF00"&B12&"，打开后可以获得"&T12&"灵符。" -> |cff00FF00一大箱灵符，打开后可以获得500灵符。 | V12: 击杀所有怪物，出售道具装备可获得 | W12: 31010002 | X12: fall_lingfu | AB12: 货币 | AC12: 灵符
A13: 31010011 | B13: 一车金币 | C13: 白色 | D13: 11 | E13: 60 | F13: 货币 | G13: 大类_基础 | H13: 子类_货币 | I13: 11 | J13: 货币 | L13: 30000 | M13: 否 | O13: 1 | P13: 无 | Q13: 999 | R13: 货币_金币 | T13: 10000 | U13: ="|cff00FF00"&B13&"，打开后可以获得"&T13&"金币。" -> |cff00FF00一车金币，打开后可以获得10000金币。 | V13: 击杀所有怪物，出售道具装备可获得 | W13: 31010001 | X13: fall_coin | AB13: 货币 | AC13: 金币
A14: 31010012 | B14: 一车灵符 | C14: 白色 | D14: 12 | E14: 60 | F14: 货币 | G14: 大类_基础 | H14: 子类_货币 | I14: 12 | J14: 货币 | L14: 30000 | M14: 否 | O14: 1 | P14: 无 | Q14: 999 | R14: 货币_灵符 | T14: 100 | U14: ="|cff00FF00"&B14&"，打开后可以获得"&T14&"灵符。" -> |cff00FF00一车灵符，打开后可以获得100灵符。 | V14: 击杀所有怪物，出售道具装备可获得 | W14: 31010002 | X14: fall_lingfu | AB14: 货币 | AC14: 灵符
A15: 31010013 | B15: 一卡车金币 | C15: 白色 | D15: 13 | E15: 60 | F15: 货币 | G15: 大类_基础 | H15: 子类_货币 | I15: 13 | J15: 货币 | L15: 30000 | M15: 否 | O15: 1 | P15: 无 | Q15: 999 | R15: 货币_金币 | T15: 50000 | U15: ="|cff00FF00"&B15&"，打开后可以获得"&T15&"金币。" -> |cff00FF00一卡车金币，打开后可以获得50000金币。 | V15: 击杀所有怪物，出售道具装备可获得 | W15: 31010001 | X15: fall_coin | AB15: 货币 | AC15: 金币
A16: 31010014 | B16: 一卡车灵符 | C16: 白色 | D16: 14 | E16: 60 | F16: 货币 | G16: 大类_基础 | H16: 子类_货币 | I16: 14 | J16: 货币 | L16: 30000 | M16: 否 | O16: 1 | P16: 无 | Q16: 999 | R16: 货币_灵符 | T16: 500 | U16: ="|cff00FF00"&B16&"，打开后可以获得"&T16&"灵符。" -> |cff00FF00一卡车灵符，打开后可以获得500灵符。 | V16: 击杀所有怪物，出售道具装备可获得 | W16: 31010002 | X16: fall_lingfu | AB16: 货币 | AC16: 灵符
A17: 31010015 | B17: 活跃丹 | C17: 紫色 | D17: 15 | E17: 60 | F17: 货币 | G17: 大类_基础 | H17: 子类_货币 | I17: 15 | J17: 货币 | L17: 30000 | M17: 否 | O17: 1 | P17: 无 | Q17: 999 | R17: 货币_活跃点 | T17: 1000 | U17: ="|cff00FF00"&B17&"，打开后可以获得"&T17&"活跃点。" -> |cff00FF00活跃丹，打开后可以获得1000活跃点。 | V17: 系统赠送获得 | X17: fall_lingfu | Y17: ain_effect_ziseguangzhu_85 | Z17: BK_J_zi | AA17: BK_D_zi | AB17: 货币 | AC17: 活跃点
A18: 31010016 | B18: 声望丹 | C18: 紫色 | D18: 16 | E18: 60 | F18: 货币 | G18: 大类_基础 | H18: 子类_货币 | I18: 16 | J18: 货币 | L18: 30000 | M18: 否 | O18: 1 | P18: 无 | Q18: 999 | R18: 货币_声望点 | T18: 1000 | U18: ="|cff00FF00"&B18&"，打开后可以获得"&T18&"声望点。" -> |cff00FF00声望丹，打开后可以获得1000声望点。 | V18: 系统赠送获得 | X18: fall_lingfu | Y18: ain_effect_ziseguangzhu_85 | Z18: BK_J_zi | AA18: BK_D_zi | AB18: 货币 | AC18: 声望点
A19: 34020001 | B19: 基础剑术 | C19: 绿色 | D19: 1 | E19: 60 | F19: 技能 | G19: 大类_基础 | H19: 子类_技能书 | I19: 绿色 | J19: 技能书 | L19: 30000 | M19: 是 | O19: 7 | P19: 战士 | Q19: 999 | R19: 技能书 | S19: 10010001 | U19: ="|cff00FF00达到"&O19&"级后可以学习技能"&B19&"，也可以在当前技能经验满后对该技能进行升级。" -> |cff00FF00达到7级后可以学习技能基础剑术，也可以在当前技能经验满后对该技能进行升级。 | V19: 击杀沃玛怪物获得 | W19: 34020001 | X19: fall_jinengshu_01 | Y19: ain_effect_lvseguangzhu_88 | Z19: BK_J_lv | AA19: BK_D_lv | AB19: 材料 | AC19: 战士技能书
A20: 34020002 | B20: 攻杀剑术 | C20: 绿色 | D20: 2 | E20: 60 | F20: 技能 | G20: 大类_基础 | H20: 子类_技能书 | I20: 绿色 | J20: 技能书 | L20: 30000 | M20: 是 | O20: 19 | P20: 战士 | Q20: 999 | R20: 技能书 | S20: 10020001 | U20: ="|cff00FF00达到"&O20&"级后可以学习技能"&B20&"，也可以在当前技能经验满后对该技能进行升级。" -> |cff00FF00达到19级后可以学习技能攻杀剑术，也可以在当前技能经验满后对该技能进行升级。 | V20: 击杀沃玛怪物获得 | W20: 34020001 | X20: fall_jinengshu_01 | Y20: ain_effect_lvseguangzhu_88 | Z20: BK_J_lv | AA20: BK_D_lv | AB20: 材料 | AC20: 战士技能书
A21: 34020003 | B21: 刺杀剑术 | C21: 绿色 | D21: 3 | E21: 60 | F21: 技能 | G21: 大类_基础 | H21: 子类_技能书 | I21: 绿色 | J21: 技能书 | L21: 30000 | M21: 是 | O21: 25 | P21: 战士 | Q21: 999 | R21: 技能书 | S21: 10030001 | U21: ="|cff00FF00达到"&O21&"级后可以学习技能"&B21&"，也可以在当前技能经验满后对该技能进行升级。" -> |cff00FF00达到25级后可以学习技能刺杀剑术，也可以在当前技能经验满后对该技能进行升级。 | V21: 击杀祖玛怪物获得 | W21: 34020001 | X21: fall_jinengshu_01 | Y21: ain_effect_lvseguangzhu_88 | Z21: BK_J_lv | AA21: BK_D_lv | AB21: 材料 | AC21: 战士技能书
A22: 34020004 | B22: 半月弯刀 | C22: 绿色 | D22: 4 | E22: 60 | F22: 技能 | G22: 大类_基础 | H22: 子类_技能书 | I22: 绿色 | J22: 技能书 | L22: 30000 | M22: 是 | O22: 28 | P22: 战士 | Q22: 999 | R22: 技能书 | S22: 10040001 | U22: ="|cff00FF00达到"&O22&"级后可以学习技能"&B22&"，也可以在当前技能经验满后对该技能进行升级。" -> |cff00FF00达到28级后可以学习技能半月弯刀，也可以在当前技能经验满后对该技能进行升级。 | V22: 击杀祖玛怪物获得 | W22: 34020001 | X22: fall_jinengshu_01 | Y22: ain_effect_lvseguangzhu_88 | Z22: BK_J_lv | AA22: BK_D_lv | AB22: 材料 | AC22: 战士技能书
A23: 34020005 | B23: 野蛮冲撞 | C23: 绿色 | D23: 5 | E23: 60 | F23: 技能 | G23: 大类_基础 | H23: 子类_技能书 | I23: 绿色 | J23: 技能书 | L23: 30000 | M23: 是 | O23: 30 | P23: 战士 | Q23: 999 | R23: 技能书 | S23: 10050001 | U23: ="|cff00FF00达到"&O23&"级后可以学习技能"&B23&"，也可以在当前技能经验满后对该技能进行升级。" -> |cff00FF00达到30级后可以学习技能野蛮冲撞，也可以在当前技能经验满后对该技能进行升级。 | V23: 击杀赤月怪物获得 | W23: 34020001 | X23: fall_jinengshu_01 | Y23: ain_effect_lvseguangzhu_88 | Z23: BK_J_lv | AA23: BK_D_lv | AB23: 材料 | AC23: 战士技能书
A24: 34020006 | B24: 烈火剑法 | C24: 绿色 | D24: 6 | E24: 60 | F24: 技能 | G24: 大类_基础 | H24: 子类_技能书 | I24: 绿色 | J24: 技能书 | L24: 30000 | M24: 是 | O24: 35 | P24: 战士 | Q24: 999 | R24: 技能书 | S24: 10060001 | U24: ="|cff00FF00达到"&O24&"级后可以学习技能"&B24&"，也可以在当前技能经验满后对该技能进行升级。" -> |cff00FF00达到35级后可以学习技能烈火剑法，也可以在当前技能经验满后对该技能进行升级。 | V24: 击杀赤月怪物获得 | W24: 34020001 | X24: fall_jinengshu_01 | Y24: ain_effect_lvseguangzhu_88 | Z24: BK_J_lv | AA24: BK_D_lv | AB24: 材料 | AC24: 战士技能书
A25: 34020031 | B25: 火球术 | C25: 绿色 | D25: 31 | E25: 60 | F25: 技能 | G25: 大类_基础 | H25: 子类_技能书 | I25: 绿色 | J25: 技能书 | L25: 30000 | M25: 是 | O25: 7 | P25: 法师 | Q25: 999 | R25: 技能书 | S25: 10310001 | U25: ="|cff00FF00达到"&O25&"级后可以学习技能"&B25&"，也可以在当前技能经验满后对该技能进行升级。" -> |cff00FF00达到7级后可以学习技能火球术，也可以在当前技能经验满后对该技能进行升级。 | V25: 击杀沃玛怪物获得 | W25: 34020001 | X25: fall_jinengshu_01 | Y25: ain_effect_lvseguangzhu_88 | Z25: BK_J_lv | AA25: BK_D_lv | AB25: 材料 | AC25: 法师技能书
A26: 34020032 | B26: 抗拒火环 | C26: 绿色 | D26: 32 | E26: 60 | F26: 技能 | G26: 大类_基础 | H26: 子类_技能书 | I26: 绿色 | J26: 技能书 | L26: 30000 | M26: 是 | O26: 12 | P26: 法师 | Q26: 999 | R26: 技能书 | S26: 10320001 | U26: ="|cff00FF00达到"&O26&"级后可以学习技能"&B26&"，也可以在当前技能经验满后对该技能进行升级。" -> |cff00FF00达到12级后可以学习技能抗拒火环，也可以在当前技能经验满后对该技能进行升级。 | V26: 击杀沃玛怪物获得 | W26: 34020001 | X26: fall_jinengshu_01 | Y26: ain_effect_lvseguangzhu_88 | Z26: BK_J_lv | AA26: BK_D_lv | AB26: 材料 | AC26: 法师技能书
A27: 34020033 | B27: 雷电术 | C27: 绿色 | D27: 33 | E27: 60 | F27: 技能 | G27: 大类_基础 | H27: 子类_技能书 | I27: 绿色 | J27: 技能书 | L27: 30000 | M27: 是 | O27: 17 | P27: 法师 | Q27: 999 | R27: 技能书 | S27: 10330001 | U27: ="|cff00FF00达到"&O27&"级后可以学习技能"&B27&"，也可以在当前技能经验满后对该技能进行升级。" -> |cff00FF00达到17级后可以学习技能雷电术，也可以在当前技能经验满后对该技能进行升级。 | V27: 击杀祖玛怪物获得 | W27: 34020001 | X27: fall_jinengshu_02 | Y27: ain_effect_lvseguangzhu_88 | Z27: BK_J_lv | AA27: BK_D_lv | AB27: 材料 | AC27: 法师技能书
A28: 34020034 | B28: 火墙 | C28: 绿色 | D28: 34 | E28: 60 | F28: 技能 | G28: 大类_基础 | H28: 子类_技能书 | I28: 绿色 | J28: 技能书 | L28: 30000 | M28: 是 | O28: 22 | P28: 法师 | Q28: 999 | R28: 技能书 | S28: 10340001 | U28: ="|cff00FF00达到"&O28&"级后可以学习技能"&B28&"，也可以在当前技能经验满后对该技能进行升级。" -> |cff00FF00达到22级后可以学习技能火墙，也可以在当前技能经验满后对该技能进行升级。 | V28: 击杀祖玛怪物获得 | W28: 34020001 | X28: fall_jinengshu_02 | Y28: ain_effect_lvseguangzhu_88 | Z28: BK_J_lv | AA28: BK_D_lv | AB28: 材料 | AC28: 法师技能书
A29: 34020035 | B29: 疾光电影 | C29: 绿色 | D29: 35 | E29: 60 | F29: 技能 | G29: 大类_基础 | H29: 子类_技能书 | I29: 绿色 | J29: 技能书 | L29: 30000 | M29: 是 | O29: 26 | P29: 法师 | Q29: 999 | R29: 技能书 | S29: 10350001 | U29: ="|cff00FF00达到"&O29&"级后可以学习技能"&B29&"，也可以在当前技能经验满后对该技能进行升级。" -> |cff00FF00达到26级后可以学习技能疾光电影，也可以在当前技能经验满后对该技能进行升级。 | V29: 击杀赤月怪物获得 | W29: 34020001 | X29: fall_jinengshu_02 | Y29: ain_effect_lvseguangzhu_88 | Z29: BK_J_lv | AA29: BK_D_lv | AB29: 材料 | AC29: 法师技能书
A30: 34020036 | B30: 魔法盾 | C30: 绿色 | D30: 36 | E30: 60 | F30: 技能 | G30: 大类_基础 | H30: 子类_技能书 | I30: 绿色 | J30: 技能书 | L30: 30000 | M30: 是 | O30: 31 | P30: 法师 | Q30: 999 | R30: 技能书 | S30: 10360001 | U30: ="|cff00FF00达到"&O30&"级后可以学习技能"&B30&"，也可以在当前技能经验满后对该技能进行升级。" -> |cff00FF00达到31级后可以学习技能魔法盾，也可以在当前技能经验满后对该技能进行升级。 | V30: 击杀赤月怪物获得 | W30: 34020001 | X30: fall_jinengshu_02 | Y30: ain_effect_lvseguangzhu_88 | Z30: BK_J_lv | AA30: BK_D_lv | AB30: 材料 | AC30: 法师技能书
... A39: 34020068 | B39: 召唤神兽 | C39: 绿色 | D39: 68 | E39: 60 | F39: 技能 | G39: 大类_基础 | H39: 子类_技能书 | I39: 绿色 | J39: 技能书 | L39: 30000 | M39: 是 | O39: 35 | P39: 道士 | Q39: 999 | R39: 技能书 | S39: 10680001 | U39: ="|cff00FF00达到"&O39&"级后可以学习技能"&B39&"，也可以在当前技能经验满后对该技能进行升级。" -> |cff00FF00达到35级后可以学习技能召唤神兽，也可以在当前技能经验满后对该技能进行升级。 | V39: 击杀赤月怪物获得 | W39: 34020001 | X39: fall_jinengshu_02 | Y39: ain_effect_lvseguangzhu_88 | Z39: BK_J_lv | AA39: BK_D_lv | AB39: 材料 | AC39: 道士技能书
A40: 34020100 | B40: 技能书 | C40: 绿色 | D40: 100 | E40: 60 | F40: 技能 | G40: 大类_基础 | H40: 子类_技能书 | I40: 7 | J40: 技能书 | L40: 30000 | M40: 是 | O40: 1 | P40: 无 | Q40: 999 | R40: 技能经验 | U40: |cff00FF00增加技能的经验值 | V40: 参加特殊活动，击杀BOSS可得 | W40: 34020100 | X40: fall_jinengshu_02 | Y40: ain_effect_lvseguangzhu_88 | Z40: BK_J_lv | AA40: BK_D_lv | AB40: 材料 | AC40: 技能书
A41: 34040001 | B41: 祝福油 | C41: 绿色 | D41: 1 | E41: 60 | F41: 强化 | G41: 大类_基础 | H41: 子类_贵重品 | I41: 1 | J41: 强化道具 | L41: 60000 | M41: 是 | O41: 1 | P41: 无 | Q41: 999 | R41: 祝福_幸运 | U41: |cff00FF00使用祝福油有概率提升当前装备武器的幸运值，最高可以提升到7点。 | V41: 击杀赤月怪物获得 | W41: 34040001 | X41: fall_zhufuyou | Y41: ain_effect_lvseguangzhu_88 | Z41: BK_J_lv | AA41: BK_D_lv | AB41: 材料 | AC41: 祝福油
A42: 34040002 | B42: 强化石 | C42: 绿色 | D42: 2 | E42: 60 | F42: 强化 | G42: 大类_基础 | H42: 子类_贵重品 | I42: 2 | J42: 强化道具 | L42: 30000 | M42: 否 | O42: 1 | P42: 无 | Q42: 999 | R42: 系统_强化 | U42: |cff00FF00使用后可以进行装备强化 | V42: 参加特殊活动，击杀BOSS可得 | W42: 34040002 | X42: fall_qianghuashi | Y42: ain_effect_lvseguangzhu_88 | Z42: BK_J_lv | AA42: BK_D_lv | AB42: 材料 | AC42: 强化石
A43: 34040003 | B43: 强化特权 | C43: 紫色 | D43: 3 | E43: 60 | F43: 强化 | G43: 大类_基础 | H43: 子类_贵重品 | I43: 3 | J43: 强化道具 | L43: 30000 | M43: 否 | O43: 1 | P43: 无 | Q43: 999 | R43: 特权_强化 | U43: |cff00FF00使用后增加10%强化成功率 | V43: 参加特殊活动，击杀BOSS可得 | W43: 34040003 | X43: fall_qianghuatequan | Y43: ain_effect_ziseguangzhu_85 | Z43: BK_J_zi | AA43: BK_D_zi
A44: 34040004 | B44: 命格洗练石 | C44: 紫色 | D44: 4 | E44: 60 | F44: 强化 | G44: 大类_基础 | H44: 子类_贵重品 | I44: 4 | J44: 强化道具 | L44: 30000 | M44: 否 | O44: 1 | P44: 无 | Q44: 999 | R44: 命格_洗练 | U44: |cff00FF00使用后可以进行命格洗练 | V44: 参加特殊活动，击杀BOSS可得 | W44: 34040004 | X44: fall_minggeshi | Y44: ain_effect_ziseguangzhu_85 | Z44: BK_J_zi | AA44: BK_D_zi
A45: 34040005 | B45: 羽毛 | C45: 紫色 | D45: 5 | E45: 60 | F45: 强化 | G45: 大类_基础 | H45: 子类_贵重品 | I45: 5 | J45: 强化道具 | L45: 30000 | M45: 否 | O45: 1 | P45: 无 | Q45: 999 | R45: 系统_羽翼 | U45: |cff00FF00使用后可以进行羽翼升级 | V45: 参加特殊活动，击杀BOSS可得 | W45: 34040005 | X45: fall_yumao | Y45: ain_effect_ziseguangzhu_85 | Z45: BK_J_zi | AA45: BK_D_zi | AB45: 材料 | AC45: 羽毛
A46: 34040006 | B46: 背包解锁格 | C46: 紫色 | D46: 6 | E46: 60 | F46: 强化 | G46: 大类_基础 | H46: 子类_贵重品 | I46: 99 | J46: 强化道具 | M46: 否 | O46: 1 | P46: 无 | Q46: 999 | R46: 背包_解锁格 | U46: |cff00FF00使用后可以解锁背包格子 | V46: 参加特殊活动，击杀BOSS可得 | W46: 34040006 | X46: fall_beibaoge | Y46: ain_effect_ziseguangzhu_85 | Z46: BK_J_zi | AA46: BK_D_zi
A47: 34040007 | B47: 背包解锁页 | C47: 紫色 | D47: 7 | E47: 60 | F47: 强化 | G47: 大类_基础 | H47: 子类_贵重品 | I47: 99 | J47: 强化道具 | M47: 否 | O47: 1 | P47: 无 | Q47: 999 | R47: 背包_解锁页 | U47: |cff00FF00使用后可以大量解锁背包页 | V47: 参加特殊活动，击杀BOSS可得 | W47: 34040007 | X47: fall_beibaoye | Y47: ain_effect_ziseguangzhu_85 | Z47: BK_J_zi | AA47: BK_D_zi
A48: 34040008 | B48: 魂之精髓 | C48: 紫色 | D48: 8 | E48: 60 | F48: 强化 | G48: 大类_基础 | H48: 子类_贵重品 | I48: 99 | J48: 强化道具 | M48: 否 | O48: 1 | P48: 无 | Q48: 99 | U48: 打造小极品用|n|cff00FF00凝聚了天地战魂之力的血红结晶。将其投入锻造炉中，可唤醒兵器沉睡的凶性，会赋予其额外的属性或隐藏技能。|n|cffFF0000神物虽神，也看本体天性。 | V48: 参加特殊活动，击杀BOSS可得 | W48: 34040008 | X48: fall_jingsui | Y48: ain_effect_ziseguangzhu_85 | Z48: BK_J_zi | AA48: BK_D_zi
...

Sheet 编号表
A1: 内部名 | B1: 编号 | C1: 物编编号 | D1: 颜色 | E1: 编号 | G1: 从左数起
A2: 货币 | B2: 1 | C2: A | D2: 白色 | E2: 1 | G2: 第1位 | H2: 固定为3表示物品
A3: 技能 | B3: 2 | C3: B | D3: 绿色 | E3: 2 | G3: 第2位 | H3: 分大类
A4: 经验 | B4: 3 | C4: C | D4: 蓝色 | E4: 3 | G4: 第3位
A5: 强化 | B5: 4 | C5: D | D5: 紫色 | E5: 4 | G5: 第4位
A6: 药品 | B6: 5 | C6: E | D6: 橙色 | E6: 5 | G6: 第5位 | H6: 本分类下的序号
A7: 任务 | B7: 6 | D7: 红色 | E7: 6 | G7: 第6位
A8: 铭文 | B8: 7 | E8: 7 | G8: 第7位
A9: 外观 | B9: 8 | E9: 8 | G9: 第8位
A10: 特戒 | B10: 9 | E10: 9
B11: 10
B12: 11
B13: 12
B14: 13 | G14: 新物品ID编号计算规则=30000000+@INDEX(编号表!$B:$B,MATCH(C3,编号表!$A:$A,0))*10000+E3
B15: 14 | G15: 改动原因：因为现在的道具配置之后，品质有改动的可能，因此暂时把品质对ID的影响取消掉。
B16: 15
B17: 16
B18: 17
B19: 18
B20: 19
D22: 道具ID必须下拉，使用公式自动生成ID！！！

Sheet 更新说明
A1: 版本 | B1: 说明
A2: 1.12 | B2: 物品编号从2开头七位改为3开头8位 增加光柱配置
A3: 1.13 | B3: 掉落模型
A4: 1.14 | B4: 新增0显示分类DisplayType纯TIPS上显示用
A5: 1.15 | B5: 更新编号规则，增加颜色对应的品质，对应改物品ID
A6: 1.16 | B6: 更新图标
A7: 1.17 | B7: 新增血药蓝药对应功能ID配置
A8: 1.18 | B8: 新增小极品打造相关道具
A9: 1.19 | B9: 给小极品打造道具配置图标，临时使用
A10: 1.2 | B10: 新增双加药
A11: 1.21 | B11: 新增多种金币和灵符道具，打开获得的数量不同。同时更新道具描述
A12: 1.22 | B12: 更新掉落物，物品ID增加格式，重复显示红色
A13: 1.23 | B13: 新增静态边框和动态边框的配置项
A14: 1.24 | B14: 新增铭文ICON编号和对应掉落物模型，修改34040043为道神纹
A15: 1.25
A16: 1.26 | B16: 编号里新增了一类任务，对应新增的任务物品的大类颜色和序号都改了，对应物品的ID也变了
A17: 1.27 | B17: 对ID规则进行改动，在ID编号的计算中删掉了品质的影响。铭文使用新的ID计算规则计算，其他的老物品ID不变，删掉ID编号规则，直接粘贴老的ID | E17: 新物品ID编号计算规则=30000000+@INDEX(编号表!$B:$B,MATCH(C3,编号表!$A:$A,0))*10000+E3
A18: 1.28 | B18: 新增一类外观道具
A19: 1.29
A20: 1.3
A21: 1.31
A22: 1.32
A23: 1.33
A24: 1.34
