Workbook
Name 阵营: [1]名称表!$H$2:$H$9
Name 怪物类型: [1]名称表!$A$3:$A$26
Name 说明: [2]名称表!$A$3:$A$26

Sheet ConfigRefreshMonster
A1: 编号 | B1: 场景名称 | C1: 怪物类型 | D1: 怪物数量 | E1: 说明 | F1: 刷新位置 | G1: 怪物1配置ID | H1: 怪物1数量 | I1: 怪物2配置ID | J1: 怪物2数量 | K1: 怪物3配置ID | L1: 怪物3数量 | M1: 怪物4配置ID | N1: 怪物4数量 | O1: 怪物5配置ID | P1: 怪物5数量 | Q1: 怪物6配置ID | R1: 怪物6数量 | S1: 怪物7配置ID | T1: 怪物7数量 | U1: 怪物8配置ID | V1: 怪物8数量 | W1: 怪物9配置ID | X1: 怪物9数量 | Y1: 怪物10配置ID | Z1: 怪物10数量
A2: config_id | F2: position | G2: MonsterID1 | H2: MonsterCount1 | I2: MonsterID2 | J2: MonsterCount2 | K2: MonsterID3 | L2: MonsterCount3 | M2: MonsterID4 | N2: MonsterCount4 | O2: MonsterID5 | P2: MonsterCount5 | Q2: MonsterID6 | R2: MonsterCount6 | S2: MonsterID7 | T2: MonsterCount7 | U2: MonsterID8 | V2: MonsterCount8 | W2: MonsterID9 | X2: MonsterCount9 | Y2: MonsterID10 | Z2: MonsterCount10
A3: =1000000+INDEX(编号表!$B:$B,MATCH(B3,编号表!$A:$A,0))*1000+INDEX(编号表!$D:$D,MATCH(C3,编号表!$C:$C,0))*100+D3 -> 1001001 | B3: 银杏渔村 | C3: BOSS | D3: 1 | E3: 一个BOSS，数量表示不同BOSS | F3: 区域中心 | G3: 60011000 | H3: 1
A4: =1000000+INDEX(编号表!$B:$B,MATCH(B4,编号表!$A:$A,0))*1000+INDEX(编号表!$D:$D,MATCH(C4,编号表!$C:$C,0))*100+D4 -> 1001002 | B4: 银杏渔村 | C4: BOSS | D4: 2 | E4: 一个BOSS，数量表示不同BOSS | F4: 区域中心 | G4: 60011001 | H4: 2
A5: =1000000+INDEX(编号表!$B:$B,MATCH(B5,编号表!$A:$A,0))*1000+INDEX(编号表!$D:$D,MATCH(C5,编号表!$C:$C,0))*100+D5 -> 1001003 | B5: 银杏渔村 | C5: BOSS | D5: 3 | E5: 一个BOSS，数量表示不同BOSS | F5: 区域中心 | G5: 60011002 | H5: 3
A6: =1000000+INDEX(编号表!$B:$B,MATCH(B6,编号表!$A:$A,0))*1000+INDEX(编号表!$D:$D,MATCH(C6,编号表!$C:$C,0))*100+D6 -> 1001004 | B6: 银杏渔村 | C6: BOSS | D6: 4 | E6: 一个BOSS，数量表示不同BOSS | F6: 区域中心 | G6: 60014001 | H6: 1
A7: =1000000+INDEX(编号表!$B:$B,MATCH(B7,编号表!$A:$A,0))*1000+INDEX(编号表!$D:$D,MATCH(C7,编号表!$C:$C,0))*100+D7 -> 1001005 | B7: 银杏渔村 | C7: BOSS | D7: 5 | E7: 一个BOSS，数量表示不同BOSS | F7: 区域中心 | G7: 60014002 | H7: 1
A8: =1000000+INDEX(编号表!$B:$B,MATCH(B8,编号表!$A:$A,0))*1000+INDEX(编号表!$D:$D,MATCH(C8,编号表!$C:$C,0))*100+D8 -> 1001101 | B8: 银杏渔村 | C8: 精英 | D8: 1 | E8: 一个精英，数量表示不同精英 | F8: 区域中心 | G8: 60011003 | H8: 1
A9: =1000000+INDEX(编号表!$B:$B,MATCH(B9,编号表!$A:$A,0))*1000+INDEX(编号表!$D:$D,MATCH(C9,编号表!$C:$C,0))*100+D9 -> 1001201 | B9: 银杏渔村 | C9: 小怪0 | D9: =H9+J9+L9+N9+P9+R9+T9+V9+X9+Z9 -> 1 | E9: 鸡 | F9: 区域随机 | G9: 60011000 | H9: 1
A10: =1000000+INDEX(编号表!$B:$B,MATCH(B10,编号表!$A:$A,0))*1000+INDEX(编号表!$D:$D,MATCH(C10,编号表!$C:$C,0))*100+D10 -> 1001301 | B10: 银杏渔村 | C10: 小怪1 | D10: =H10+J10+L10+N10+P10+R10+T10+V10+X10+Z10 -> 1 | E10: 鹿 | F10: 区域随机 | G10: 60011001 | H10: 1
A11: =1000000+INDEX(编号表!$B:$B,MATCH(B11,编号表!$A:$A,0))*1000+INDEX(编号表!$D:$D,MATCH(C11,编号表!$C:$C,0))*100+D11 -> 1001401 | B11: 银杏渔村 | C11: 小怪2 | D11: =H11+J11+L11+N11+P11+R11+T11+V11+X11+Z11 -> 1 | E11: 羊 | F11: 区域随机 | G11: 60011002 | H11: 1
A12: =1000000+INDEX(编号表!$B:$B,MATCH(B12,编号表!$A:$A,0))*1000+INDEX(编号表!$D:$D,MATCH(C12,编号表!$C:$C,0))*100+D12 -> 1001501 | B12: 银杏渔村 | C12: 小怪3 | D12: =H12+J12+L12+N12+P12+R12+T12+V12+X12+Z12 -> 1 | E12: 稻草人 | F12: 区域随机 | G12: 60011003 | H12: 1
A13: =1000000+INDEX(编号表!$B:$B,MATCH(B13,编号表!$A:$A,0))*1000+INDEX(编号表!$D:$D,MATCH(C13,编号表!$C:$C,0))*100+D13 -> 1001601 | B13: 银杏渔村 | C13: 小怪4 | D13: =H13+J13+L13+N13+P13+R13+T13+V13+X13+Z13 -> 1 | E13: 蛤蟆 | F13: 区域随机 | G13: 60011004 | H13: 1
A14: =1000000+INDEX(编号表!$B:$B,MATCH(B14,编号表!$A:$A,0))*1000+INDEX(编号表!$D:$D,MATCH(C14,编号表!$C:$C,0))*100+D14 -> 1001202 | B14: 银杏渔村 | C14: 小怪0 | D14: =H14+J14+L14+N14+P14+R14+T14+V14+X14+Z14 -> 2 | E14: NPC鸡 | F14: 区域随机 | G14: 60011020 | H14: 2
A15: =1000000+INDEX(编号表!$B:$B,MATCH(B15,编号表!$A:$A,0))*1000+INDEX(编号表!$D:$D,MATCH(C15,编号表!$C:$C,0))*100+D15 -> 1001302 | B15: 银杏渔村 | C15: 小怪1 | D15: =H15+J15+L15+N15+P15+R15+T15+V15+X15+Z15 -> 2 | E15: 鹿 | F15: 区域随机 | G15: 60011001 | H15: 2
A16: =1000000+INDEX(编号表!$B:$B,MATCH(B16,编号表!$A:$A,0))*1000+INDEX(编号表!$D:$D,MATCH(C16,编号表!$C:$C,0))*100+D16 -> 1001402 | B16: 银杏渔村 | C16: 小怪2 | D16: =H16+J16+L16+N16+P16+R16+T16+V16+X16+Z16 -> 2 | E16: 羊 | F16: 区域随机 | G16: 60011002 | H16: 2
A17: =1000000+INDEX(编号表!$B:$B,MATCH(B17,编号表!$A:$A,0))*1000+INDEX(编号表!$D:$D,MATCH(C17,编号表!$C:$C,0))*100+D17 -> 1001502 | B17: 银杏渔村 | C17: 小怪3 | D17: =H17+J17+L17+N17+P17+R17+T17+V17+X17+Z17 -> 2 | E17: 稻草人 | F17: 区域随机 | G17: 60011003 | H17: 2
A18: =1000000+INDEX(编号表!$B:$B,MATCH(B18,编号表!$A:$A,0))*1000+INDEX(编号表!$D:$D,MATCH(C18,编号表!$C:$C,0))*100+D18 -> 1001602 | B18: 银杏渔村 | C18: 小怪4 | D18: =H18+J18+L18+N18+P18+R18+T18+V18+X18+Z18 -> 2 | E18: 蛤蟆 | F18: 区域随机 | G18: 60011004 | H18: 2
A19: =1000000+INDEX(编号表!$B:$B,MATCH(B19,编号表!$A:$A,0))*1000+INDEX(编号表!$D:$D,MATCH(C19,编号表!$C:$C,0))*100+D19 -> 1001203 | B19: 银杏渔村 | C19: 小怪0 | D19: =H19+J19+L19+N19+P19+R19+T19+V19+X19+Z19 -> 3 | E19: 鸡 | F19: 区域随机 | G19: 60011000 | H19: 3
A20: =1000000+INDEX(编号表!$B:$B,MATCH(B20,编号表!$A:$A,0))*1000+INDEX(编号表!$D:$D,MATCH(C20,编号表!$C:$C,0))*100+D20 -> 1001303 | B20: 银杏渔村 | C20: 小怪1 | D20: =H20+J20+L20+N20+P20+R20+T20+V20+X20+Z20 -> 3 | E20: 鹿 | F20: 区域随机 | G20: 60011001 | H20: 3
... A38: =1000000+INDEX(编号表!$B:$B,MATCH(B38,编号表!$A:$A,0))*1000+INDEX(编号表!$D:$D,MATCH(C38,编号表!$C:$C,0))*100+D38 -> 1001615 | B38: 银杏渔村 | C38: 小怪4 | D38: =H38+J38+L38+N38+P38+R38+T38+V38+X38+Z38 -> 15 | E38: 蛤蟆 | F38: 区域随机 | G38: 60011004 | H38: 15
A39: =1000000+INDEX(编号表!$B:$B,MATCH(B39,编号表!$A:$A,0))*1000+INDEX(编号表!$D:$D,MATCH(C39,编号表!$C:$C,0))*100+D39 -> 1002001 | B39: 比奇城 | C39: BOSS | D39: 1 | E39: 本图1个BOSS | F39: 区域中心 | G39: 60014001 | H39: 1
A40: =1000000+INDEX(编号表!$B:$B,MATCH(B40,编号表!$A:$A,0))*1000+INDEX(编号表!$D:$D,MATCH(C40,编号表!$C:$C,0))*100+D40 -> 1002101 | B40: 比奇城 | C40: 精英 | D40: 1 | E40: 一个精英，数量表示不同精英 | F40: 区域中心 | G40: 60012000 | H40: 1
A41: =1000000+INDEX(编号表!$B:$B,MATCH(B41,编号表!$A:$A,0))*1000+INDEX(编号表!$D:$D,MATCH(C41,编号表!$C:$C,0))*100+D41 -> 1002102 | B41: 比奇城 | C41: 精英 | D41: 2 | E41: 一个精英，数量表示不同精英 | F41: 区域中心 | G41: 60012001 | H41: 1
A42: =1000000+INDEX(编号表!$B:$B,MATCH(B42,编号表!$A:$A,0))*1000+INDEX(编号表!$D:$D,MATCH(C42,编号表!$C:$C,0))*100+D42 -> 1002103 | B42: 比奇城 | C42: 精英 | D42: 3 | E42: 一个精英，数量表示不同精英 | F42: 区域中心 | G42: 60012002 | H42: 1
A43: =1000000+INDEX(编号表!$B:$B,MATCH(B43,编号表!$A:$A,0))*1000+INDEX(编号表!$D:$D,MATCH(C43,编号表!$C:$C,0))*100+D43 -> 1002104 | B43: 比奇城 | C43: 精英 | D43: 4 | E43: 一个精英，数量表示不同精英 | F43: 区域中心 | G43: 60012003 | H43: 1
A44: =1000000+INDEX(编号表!$B:$B,MATCH(B44,编号表!$A:$A,0))*1000+INDEX(编号表!$D:$D,MATCH(C44,编号表!$C:$C,0))*100+D44 -> 1002105 | B44: 比奇城 | C44: 精英 | D44: 5 | E44: 一个精英，数量表示不同精英 | F44: 区域中心 | G44: 60012004 | H44: 1
A45: =1000000+INDEX(编号表!$B:$B,MATCH(B45,编号表!$A:$A,0))*1000+INDEX(编号表!$D:$D,MATCH(C45,编号表!$C:$C,0))*100+D45 -> 1002301 | B45: 比奇城 | C45: 小怪1 | D45: 1 | E45: 比奇城内鸡4 | F45: 区域随机 | G45: 60011020 | H45: 4
A46: =1000000+INDEX(编号表!$B:$B,MATCH(B46,编号表!$A:$A,0))*1000+INDEX(编号表!$D:$D,MATCH(C46,编号表!$C:$C,0))*100+D46 -> 1002302 | B46: 比奇城 | C46: 小怪1 | D46: 2 | E46: 鹿4只 | F46: 区域随机 | G46: 60011001 | H46: 1
A47: =1000000+INDEX(编号表!$B:$B,MATCH(B47,编号表!$A:$A,0))*1000+INDEX(编号表!$D:$D,MATCH(C47,编号表!$C:$C,0))*100+D47 -> 1002303 | B47: 比奇城 | C47: 小怪1 | D47: 3 | E47: 羊4只 | F47: 区域随机 | G47: 60011002 | H47: 1
A48: =1000000+INDEX(编号表!$B:$B,MATCH(B48,编号表!$A:$A,0))*1000+INDEX(编号表!$D:$D,MATCH(C48,编号表!$C:$C,0))*100+D48 -> 1002304 | B48: 比奇城 | C48: 小怪1 | D48: 4 | E48: 稻草人4 | F48: 区域随机 | G48: 60011003 | H48: 1
A49: =1000000+INDEX(编号表!$B:$B,MATCH(B49,编号表!$A:$A,0))*1000+INDEX(编号表!$D:$D,MATCH(C49,编号表!$C:$C,0))*100+D49 -> 1002305 | B49: 比奇城 | C49: 小怪1 | D49: 5 | E49: 蛤蟆4 | F49: 区域随机 | G49: 60011004 | H49: 1
A50: =1000000+INDEX(编号表!$B:$B,MATCH(B50,编号表!$A:$A,0))*1000+INDEX(编号表!$D:$D,MATCH(C50,编号表!$C:$C,0))*100+D50 -> 1002306 | B50: 比奇城 | C50: 小怪1 | D50: 6 | E50: 多钩猫4 | F50: 区域随机 | G50: 60011005 | H50: 1
... A143: =1000000+INDEX(编号表!$B:$B,MATCH(B143,编号表!$A:$A,0))*1000+INDEX(编号表!$D:$D,MATCH(C143,编号表!$C:$C,0))*100+D143 -> 1003101 | B143: 兽人古墓一层 | C143: 精英 | D143: 1 | E143: 一个精英，数量表示不同精英 | F143: 区域中心 | G143: 60022000 | H143: 1
A144: =1000000+INDEX(编号表!$B:$B,MATCH(B144,编号表!$A:$A,0))*1000+INDEX(编号表!$D:$D,MATCH(C144,编号表!$C:$C,0))*100+D144 -> 1003201 | B144: 兽人古墓一层 | C144: 小怪0 | D144: =H144+J144+L144+N144+P144+R144+T144+V144+X144+Z144 -> 1 | E144: 山洞蝙蝠 | F144: 区域随机 | G144: 60021000 | H144: 1
A145: =1000000+INDEX(编号表!$B:$B,MATCH(B145,编号表!$A:$A,0))*1000+INDEX(编号表!$D:$D,MATCH(C145,编号表!$C:$C,0))*100+D145 -> 1003301 | B145: 兽人古墓一层 | C145: 小怪1 | D145: =H145+J145+L145+N145+P145+R145+T145+V145+X145+Z145 -> 1 | E145: 洞蛆 | F145: 区域随机 | G145: 60021001 | H145: 1
A146: =1000000+INDEX(编号表!$B:$B,MATCH(B146,编号表!$A:$A,0))*1000+INDEX(编号表!$D:$D,MATCH(C146,编号表!$C:$C,0))*100+D146 -> 1003401 | B146: 兽人古墓一层 | C146: 小怪2 | D146: =H146+J146+L146+N146+P146+R146+T146+V146+X146+Z146 -> 1 | E146: 骷髅 | F146: 区域随机 | G146: 60021002 | H146: 1
A147: =1000000+INDEX(编号表!$B:$B,MATCH(B147,编号表!$A:$A,0))*1000+INDEX(编号表!$D:$D,MATCH(C147,编号表!$C:$C,0))*100+D147 -> 1003501 | B147: 兽人古墓一层 | C147: 小怪3 | D147: =H147+J147+L147+N147+P147+R147+T147+V147+X147+Z147 -> 1 | E147: 骷髅战士 | F147: 区域随机 | G147: 60021003 | H147: 1
A148: =1000000+INDEX(编号表!$B:$B,MATCH(B148,编号表!$A:$A,0))*1000+INDEX(编号表!$D:$D,MATCH(C148,编号表!$C:$C,0))*100+D148 -> 1003601 | B148: 兽人古墓一层 | C148: 小怪4 | D148: =H148+J148+L148+N148+P148+R148+T148+V148+X148+Z148 -> 1 | E148: 骷髅战将 | F148: 区域随机 | G148: 60021004 | H148: 1
A149: =1000000+INDEX(编号表!$B:$B,MATCH(B149,编号表!$A:$A,0))*1000+INDEX(编号表!$D:$D,MATCH(C149,编号表!$C:$C,0))*100+D149 -> 1003202 | B149: 兽人古墓一层 | C149: 小怪0 | D149: =H149+J149+L149+N149+P149+R149+T149+V149+X149+Z149 -> 2 | E149: 山洞蝙蝠 | F149: 区域随机 | G149: 60021000 | H149: 2
...

Sheet 更新说明
A1: 版本号 | B1: 内容
A2: V1.12 | B2: 减少数量
A3: V1.13 | B3: 增加刷怪场景
A4: V1.14 | B4: 增加两个测试木桩，30和31
A5: V1.15 | B5: 增加蛤蟆刷新场景
A6: V1.16 | B6: 重新整理怪物刷新配置，新增，改ID规则等
A7: V1.17 | B7: 新增新手村刷怪方案；比奇城boss怪物更改为木桩；
A8: V1.18
A9: V1.19
A10: V1.20
A11: V1.21
A12: V1.22
A13: V1.23
A14: V1.24
A15: V1.25
A16: V1.26
A17: V1.27
A18: V1.28
A19: V1.29
... A22: V1.32

Sheet Sheet1
A1: 编号 | B1: 场景名称 | C1: 刷新位置 | D1: 怪物1配置ID | E1: 怪物1数量 | F1: 怪物2配置ID | G1: 怪物2数量 | H1: 怪物3配置ID | I1: 怪物3数量 | J1: 怪物4配置ID | K1: 怪物4数量 | L1: 怪物5配置ID | M1: 怪物5数量 | N1: 怪物6配置ID | O1: 怪物6数量 | P1: 怪物7配置ID | Q1: 怪物7数量 | R1: 怪物8配置ID | S1: 怪物8数量 | T1: 怪物9配置ID | U1: 怪物9数量 | V1: 怪物10配置ID | W1: 怪物10数量
A2: config_id | C2: position | D2: MonsterID1 | E2: MonsterCount1 | F2: MonsterID2 | G2: MonsterCount2 | H2: MonsterID3 | I2: MonsterCount3 | J2: MonsterID4 | K2: MonsterCount4 | L2: MonsterID5 | M2: MonsterCount5 | N2: MonsterID6 | O2: MonsterCount6 | P2: MonsterID7 | Q2: MonsterCount7 | R2: MonsterID8 | S2: MonsterCount8 | T2: MonsterID9 | U2: MonsterCount9 | V2: MonsterID10 | W2: MonsterCount10
A3: 1 | B3: 比奇城 | C3: 区域随机 | D3: 60011037 | E3: 2 | F3: 60011090 | G3: 2 | H3: 60371001 | I3: 2 | J3: 60011033 | K3: 2 | L3: 60011035 | M3: 2 | N3: 60371009 | O3: 2 | P3: 60011016 | Q3: 2 | R3: 60011090 | S3: 2 | T3: 60011081 | U3: 2 | V3: 60371011 | W3: 2
A4: 2 | B4: 祖玛寺庙一层 | C4: 区域随机 | D4: 60011119 | E4: 1 | F4: 60011105 | G4: 1 | H4: 60371107 | I4: 1 | J4: 60011106 | K4: 1 | L4: 60011127 | M4: 1
A5: 3 | B5: 祖玛寺庙一层 | C5: 区域随机 | D5: 60011106 | E5: 1 | F5: 60011127 | G5: 1
A6: 4 | B6: 祖玛寺庙二层 | C6: 区域随机 | D6: 60011105 | E6: 1 | F6: 60371107 | G6: 1 | H6: 60011106 | I6: 1 | J6: 60011127 | K6: 1 | L6: 60011121 | M6: 1
A7: 5 | B7: 祖玛阁 | C7: 区域随机 | D7: 60011105 | E7: 6 | F7: 60371107 | G7: 6 | H7: 60011106 | I7: 6 | J7: 60011127 | K7: 6 | L7: 60011121 | M7: 6 | N7: 60371124 | O7: 6
A8: 6 | B8: 教主大殿 | C8: 区域中心 | D8: 60011132 | E8: 1
A9: 7 | B9: 教主大殿 | C9: 区域随机 | D9: 60011105 | E9: 4 | F9: 60371107 | G9: 4 | H9: 60011106 | I9: 4 | J9: 60011127 | K9: 4 | L9: 60011121 | M9: 4 | N9: 60371124 | O9: 4
A10: 8 | B10: 兽人古墓一层 | C10: 区域随机 | D10: 60011014 | E10: 1 | F10: 60011026 | G10: 1 | H10: 60011032 | I10: 1 | J10: 60371024 | K10: 1 | L10: 60011019 | M10: 1
A11: 9 | B11: 兽人古墓二层 | C11: 区域随机 | D11: 60011014 | E11: 1 | F11: 60011032 | G11: 1 | H11: 60371024 | I11: 1 | J11: 60011019 | K11: 1 | L11: 60011022 | M11: 1
A12: 10 | B12: 国王陵墓 | C12: 区域中心 | D12: 60011028 | E12: 1
A13: 11 | B13: 废矿区东部 | C13: 区域随机 | D13: 60011032 | E13: 1 | F13: 60371059 | G13: 1 | H13: 60371061 | I13: 1 | J13: 60371063 | K13: 1 | L13: 60371065 | M13: 1 | N13: 60371067 | O13: 1 | P13: 60371397 | Q13: 1
A14: 12 | B14: 尸王殿 | C14: 区域随机 | D14: 60371069 | E14: 5
A15: 13 | B15: 地牢 | C15: 区域随机 | D15: 60371091 | E15: 1 | F15: 60371101 | G15: 1 | H15: 60371103 | I15: 2 | J15: 60371094 | K15: 1 | L15: 60371096 | M15: 1
A16: 14 | B16: 黑暗地带 | C16: 区域随机 | D16: 60371091 | E16: 1 | F16: 60371101 | G16: 1 | H16: 60371094 | I16: 1 | J16: 60371096 | K16: 1
A17: 15 | B17: 死亡棺材 | C17: 区域随机 | D17: 60371091 | E17: 1 | F17: 60371101 | G17: 1 | H17: 60371103 | I17: 2 | J17: 60371094 | K17: 1 | L17: 60371096 | M17: 1
A18: 16 | B18: 死亡棺材 | C18: 区域中心 | D18: 60371093 | E18: 1
A19: 17 | B19: 未知暗殿 | C19: 区域随机 | D19: 60011121 | E19: 1 | F19: 60371124 | G19: 1 | H19: 60011127 | I19: 1 | J19: 60371002 | K19: 1
A20: 18 | B20: 未知暗殿 | C20: 区域中心 | D20: 60011132 | E20: 1
A21: 19 | B21: 沃玛寺庙一层 | C21: 区域随机 | D21: 60371057 | E21: 1 | F21: 60371040 | G21: 1 | H21: 60371042 | I21: 1 | J21: 60371044 | K21: 1
A22: 20 | B22: 沃玛寺庙二层 | C22: 区域随机 | D22: 60371042 | E22: 1 | F22: 60371044 | G22: 1 | H22: 60371046 | I22: 1 | J22: 60371055 | K22: 1
A23: 21 | B23: 沃玛教主大殿 | C23: 区域随机 | D23: 60371042 | E23: 1 | F23: 60371044 | G23: 1 | H23: 60371046 | I23: 1 | J23: 60371055 | K23: 1
A24: 22 | B24: 沃玛教主大殿 | C24: 区域中心 | D24: 60371053 | E24: 1
A25: 23 | B25: 石墓一层 | C25: 区域随机 | D25: 60371094 | E25: 1 | F25: 60371107 | G25: 1 | H25: 60371108 | I25: 1 | J25: 60371110 | K25: 1
A26: 24 | B26: 石墓阵入口 | C26: 区域随机 | D26: 60371107 | E26: 1 | F26: 60371108 | G26: 1 | H26: 60371110 | I26: 1 | J26: 60371115 | K26: 1 | L26: 60011105 | M26: 1 | N26: 60011106 | O26: 1
A27: 25 | B27: 石墓阵出口 | C27: 区域随机 | D27: 60371107 | E27: 1 | F27: 60371108 | G27: 1 | H27: 60371110 | I27: 1 | J27: 60371115 | K27: 1 | L27: 60011105 | M27: 1 | N27: 60011106 | O27: 1
A28: 26 | B28: 石墓阵顶层 | C28: 区域随机 | D28: 60371094 | E28: 1 | F28: 60371112 | G28: 2 | H28: 60011105 | I28: 1 | J28: 60011106 | K28: 1
A29: 27 | B29: 石墓阵顶层 | C29: 区域中心 | D29: 60371206 | E29: 1
A30: 28 | B30: 桃源之门 | C30: 区域随机 | D30: 60371207 | E30: 1 | F30: 60371140 | G30: 1 | H30: 60371075 | I30: 1
A31: 29 | B31: 困惑殿堂 | C31: 区域中心 | D31: 60371265 | E31: 1
A32: 30 | B32: 比奇城 | C32: 区域中心 | D32: 60371490 | E32: 1
A33: 31 | B33: 比奇城 | C33: 区域中心 | D33: 60371491 | E33: 1
A38: 1 | B38: 比奇城 | D38: 怪1 | F38: 1000000
A39: 2 | B39: 兽人古墓一层 | D39: 怪2
A40: 3 | B40: 兽人古墓二层 | D40: 怪3
A41: 4 | B41: 国王陵墓 | D41: 怪4
A42: 5 | B42: 废矿区东部 | D42: 怪5
A43: 6 | B43: 尸王殿 | D43: 怪6
A44: 7 | B44: 地牢 | D44: 精英
...

Sheet 编号表
A1: 场景名 | B1: 编号 | C1: 类型 | D1: 编号
A2: 银杏渔村 | B2: 1 | C2: BOSS | D2: 0
A3: 比奇城 | B3: 2 | C3: 精英 | D3: 1
A4: 兽人古墓一层 | B4: 3 | C4: 小怪0 | D4: 2 | G4: 1001205
A5: 兽人古墓二层 | B5: 4 | C5: 小怪1 | D5: 3 | G5: 怪物刷新配置1开头7位数
A6: 国王陵墓 | B6: 5 | C6: 小怪2 | D6: 4 | G6: 第1位 | H6: 1开头
A7: 废矿区东部 | B7: 6 | C7: 小怪3 | D7: 5 | G7: 第2位 | H7: 用场景来代表级别。相当于装备的阶级，沃玛级，祖玛级，苍月级，赤月级等，2位应该够，暂时用3位保险。这个级别和场景区域配置严格匹配，相等。和其他一样，表示在哪个地图
A8: 尸王殿 | B8: 7 | C8: 小怪4 | D8: 6 | G8: 第3位
A9: 地牢 | B9: 8 | C9: 小怪5 | D9: 7 | G9: 第4位
A10: 黑暗地带 | B10: 9 | C10: 小怪6 | D10: 8 | G10: 第5位 | H10: 怪物身份，区分普通/精英怪/BOSS
A11: 死亡棺材 | B11: 10 | C11: 小怪7 | D11: 9 | G11: 第6位 | H11: 具体数字表示这个怪物刷新配置里刷多少个怪100以内可以随便填 也可以用不同数字代表不同的BOSS，比如末位配置1，2，3，4表示都刷新一个，分别代表BOSS1,BOSS2,BOSS3,BOSS4
A12: 未知暗殿 | B12: 11 | G12: 第7位
A13: 沃玛寺庙一层 | B13: 12
A14: 沃玛寺庙二层 | B14: 13
A15: 沃玛教主大殿 | B15: 14
A16: 石墓一层 | B16: 15
A17: 石墓阵入口 | B17: 16
A18: 石墓阵出口 | B18: 17
A19: 石墓顶层 | B19: 18
A20: 桃源之门 | B20: 19
A21: 困惑殿堂 | B21: 20
A22: 祖玛寺庙一层 | B22: 21
A23: 祖玛寺庙二层 | B23: 22
A24: 祖玛阁 | B24: 23
... A42: 赤月魔穴 | B42: 41
