Workbook

Sheet ConfigAttrZhanshi
A1: 0等级 | B1: 属性名1 | C1: 属性值1 | D1: 属性名2 | E1: 属性值2 | F1: 属性名3 | G1: 属性值3 | H1: 属性名4 | I1: 属性值4 | J1: 属性名5 | K1: 属性值5 | L1: 属性名6 | M1: 属性值6 | N1: 0角色升级所需经验
A2: Level | B2: Prop1Name | C2: Prop1Value | D2: Prop2Name | E2: Prop2Value | F2: Prop3Name | G2: Prop3Value | H2: Prop4Name | I2: Prop4Value | J2: Prop5Name | K2: Prop5Value | L2: Prop6Name | M2: Prop6Value | N2: ExpLevelUp
A3: 1 | B3: 生命值 | C3: 60 | D3: 魔法值 | E3: =ROUND(C3*2/3,0) -> 40 | F3: 敏捷 | H3: 准确 | J3: 攻击下限 | K3: 0 | L3: 攻击上限 | N3: 10
A4: 2 | B4: 生命值 | C4: 6 | D4: 魔法值 | E4: =ROUND(C4*2/3,0) -> 4 | F4: 敏捷 | H4: 准确 | J4: 攻击下限 | K4: 0 | L4: 攻击上限 | N4: 15
A5: 3 | B5: 生命值 | C5: 6 | D5: 魔法值 | E5: =ROUND(C5*2/3,0) -> 4 | F5: 敏捷 | H5: 准确 | J5: 攻击下限 | K5: 0 | L5: 攻击上限 | N5: 25
A6: 4 | B6: 生命值 | C6: 6 | D6: 魔法值 | E6: =ROUND(C6*2/3,0) -> 4 | F6: 敏捷 | H6: 准确 | J6: 攻击下限 | K6: 0 | L6: 攻击上限 | N6: 35
A7: 5 | B7: 生命值 | C7: 6 | D7: 魔法值 | E7: =ROUND(C7*2/3,0) -> 4 | F7: 敏捷 | H7: 准确 | J7: 攻击下限 | K7: 0 | L7: 攻击上限 | M7: 1 | N7: 50
A8: 6 | B8: 生命值 | C8: 6 | D8: 魔法值 | E8: =ROUND(C8*2/3,0) -> 4 | F8: 敏捷 | H8: 准确 | J8: 攻击下限 | K8: 0 | L8: 攻击上限 | N8: 70
A9: 7 | B9: 生命值 | C9: 6 | D9: 魔法值 | E9: =ROUND(C9*2/3,0) -> 4 | F9: 敏捷 | H9: 准确 | J9: 攻击下限 | K9: 0 | L9: 攻击上限 | N9: 95
A10: 8 | B10: 生命值 | C10: 6 | D10: 魔法值 | E10: =ROUND(C10*2/3,0) -> 4 | F10: 敏捷 | H10: 准确 | J10: 攻击下限 | K10: 0 | L10: 攻击上限 | N10: 125
A11: 9 | B11: 生命值 | C11: 6 | D11: 魔法值 | E11: =ROUND(C11*2/3,0) -> 4 | F11: 敏捷 | H11: 准确 | J11: 攻击下限 | K11: 0 | L11: 攻击上限 | N11: 160
A12: 10 | B12: 生命值 | C12: 6 | D12: 魔法值 | E12: =ROUND(C12*2/3,0) -> 4 | F12: 敏捷 | H12: 准确 | J12: 攻击下限 | K12: 0 | L12: 攻击上限 | M12: 1 | N12: 210
A13: 11 | B13: 生命值 | C13: 8 | D13: 魔法值 | E13: =ROUND(C13*2/3,0) -> 5 | F13: 敏捷 | H13: 准确 | J13: 攻击下限 | K13: 0 | L13: 攻击上限 | N13: 270
A14: 12 | B14: 生命值 | C14: 8 | D14: 魔法值 | E14: =ROUND(C14*2/3,0) -> 5 | F14: 敏捷 | H14: 准确 | J14: 攻击下限 | K14: 0 | L14: 攻击上限 | N14: 340
A15: 13 | B15: 生命值 | C15: 8 | D15: 魔法值 | E15: =ROUND(C15*2/3,0) -> 5 | F15: 敏捷 | H15: 准确 | J15: 攻击下限 | K15: 0 | L15: 攻击上限 | N15: 420
A16: 14 | B16: 生命值 | C16: 8 | D16: 魔法值 | E16: =ROUND(C16*2/3,0) -> 5 | F16: 敏捷 | H16: 准确 | J16: 攻击下限 | K16: 0 | L16: 攻击上限 | N16: 520
A17: 15 | B17: 生命值 | C17: 8 | D17: 魔法值 | E17: =ROUND(C17*2/3,0) -> 5 | F17: 敏捷 | H17: 准确 | J17: 攻击下限 | K17: 0 | L17: 攻击上限 | N17: 640
A18: 16 | B18: 生命值 | C18: 8 | D18: 魔法值 | E18: =ROUND(C18*2/3,0) -> 5 | F18: 敏捷 | H18: 准确 | J18: 攻击下限 | K18: 0 | L18: 攻击上限 | N18: 780
A19: 17 | B19: 生命值 | C19: 8 | D19: 魔法值 | E19: =ROUND(C19*2/3,0) -> 5 | F19: 敏捷 | H19: 准确 | J19: 攻击下限 | K19: 0 | L19: 攻击上限 | N19: 950
A20: 18 | B20: 生命值 | C20: 8 | D20: 魔法值 | E20: =ROUND(C20*2/3,0) -> 5 | F20: 敏捷 | H20: 准确 | J20: 攻击下限 | K20: 0 | L20: 攻击上限 | N20: 1150
A21: 19 | B21: 生命值 | C21: 8 | D21: 魔法值 | E21: =ROUND(C21*2/3,0) -> 5 | F21: 敏捷 | H21: 准确 | J21: 攻击下限 | K21: 0 | L21: 攻击上限 | N21: 1380
A22: 20 | B22: 生命值 | C22: 8 | D22: 魔法值 | E22: =ROUND(C22*2/3,0) -> 5 | F22: 敏捷 | H22: 准确 | J22: 攻击下限 | K22: 0 | L22: 攻击上限 | M22: 2 | N22: 1650
A23: 21 | B23: 生命值 | C23: 10 | D23: 魔法值 | E23: =ROUND(C23*2/3,0) -> 7 | F23: 敏捷 | H23: 准确 | J23: 攻击下限 | K23: 0 | L23: 攻击上限 | N23: 1950
A24: 22 | B24: 生命值 | C24: 10 | D24: 魔法值 | E24: =ROUND(C24*2/3,0) -> 7 | F24: 敏捷 | H24: 准确 | J24: 攻击下限 | K24: 0 | L24: 攻击上限 | N24: 2300
A25: 23 | B25: 生命值 | C25: 10 | D25: 魔法值 | E25: =ROUND(C25*2/3,0) -> 7 | F25: 敏捷 | H25: 准确 | J25: 攻击下限 | K25: 0 | L25: 攻击上限 | N25: 2700
A26: 24 | B26: 生命值 | C26: 10 | D26: 魔法值 | E26: =ROUND(C26*2/3,0) -> 7 | F26: 敏捷 | H26: 准确 | J26: 攻击下限 | K26: 0 | L26: 攻击上限 | N26: 3150
A27: 25 | B27: 生命值 | C27: 10 | D27: 魔法值 | E27: =ROUND(C27*2/3,0) -> 7 | F27: 敏捷 | H27: 准确 | J27: 攻击下限 | K27: 0 | L27: 攻击上限 | M27: 2 | N27: 3650
A28: 26 | B28: 生命值 | C28: 10 | D28: 魔法值 | E28: =ROUND(C28*2/3,0) -> 7 | F28: 敏捷 | H28: 准确 | J28: 攻击下限 | K28: 0 | L28: 攻击上限 | N28: 4200
A29: 27 | B29: 生命值 | C29: 10 | D29: 魔法值 | E29: =ROUND(C29*2/3,0) -> 7 | F29: 敏捷 | H29: 准确 | J29: 攻击下限 | K29: 0 | L29: 攻击上限 | N29: 4800
A30: 28 | B30: 生命值 | C30: 10 | D30: 魔法值 | E30: =ROUND(C30*2/3,0) -> 7 | F30: 敏捷 | H30: 准确 | J30: 攻击下限 | K30: 0 | L30: 攻击上限 | N30: 5450
A31: 29 | B31: 生命值 | C31: 10 | D31: 魔法值 | E31: =ROUND(C31*2/3,0) -> 7 | F31: 敏捷 | H31: 准确 | J31: 攻击下限 | K31: 0 | L31: 攻击上限 | N31: 6150
A32: 30 | B32: 生命值 | C32: 10 | D32: 魔法值 | E32: =ROUND(C32*2/3,0) -> 7 | F32: 敏捷 | H32: 准确 | J32: 攻击下限 | K32: 0 | L32: 攻击上限 | M32: 2 | N32: 7200
A33: 31 | B33: 生命值 | C33: 16 | D33: 魔法值 | E33: =ROUND(C33*2/3,0) -> 11 | F33: 敏捷 | H33: 准确 | J33: 攻击下限 | K33: 0 | L33: 攻击上限 | N33: 8500
A34: 32 | B34: 生命值 | C34: 16 | D34: 魔法值 | E34: =ROUND(C34*2/3,0) -> 11 | F34: 敏捷 | H34: 准确 | J34: 攻击下限 | K34: 0 | L34: 攻击上限 | N34: 10000
A35: 33 | B35: 生命值 | C35: 16 | D35: 魔法值 | E35: =ROUND(C35*2/3,0) -> 11 | F35: 敏捷 | H35: 准确 | J35: 攻击下限 | K35: 0 | L35: 攻击上限 | N35: 11800
A36: 34 | B36: 生命值 | C36: 16 | D36: 魔法值 | E36: =ROUND(C36*2/3,0) -> 11 | F36: 敏捷 | H36: 准确 | J36: 攻击下限 | K36: 0 | L36: 攻击上限 | N36: 13800
A37: 35 | B37: 生命值 | C37: 16 | D37: 魔法值 | E37: =ROUND(C37*2/3,0) -> 11 | F37: 敏捷 | H37: 准确 | J37: 攻击下限 | K37: 0 | L37: 攻击上限 | M37: 2 | N37: 16200
A38: 36 | B38: 生命值 | C38: 16 | D38: 魔法值 | E38: =ROUND(C38*2/3,0) -> 11 | F38: 敏捷 | H38: 准确 | J38: 攻击下限 | K38: 0 | L38: 攻击上限 | N38: 19000
A39: 37 | B39: 生命值 | C39: 16 | D39: 魔法值 | E39: =ROUND(C39*2/3,0) -> 11 | F39: 敏捷 | H39: 准确 | J39: 攻击下限 | K39: 0 | L39: 攻击上限 | N39: 22200
A40: 38 | B40: 生命值 | C40: 16 | D40: 魔法值 | E40: =ROUND(C40*2/3,0) -> 11 | F40: 敏捷 | H40: 准确 | J40: 攻击下限 | K40: 0 | L40: 攻击上限 | N40: 26000
...

Sheet ConfigAttrFashi
A1: 0等级 | B1: 属性名1 | C1: 属性值1 | D1: 属性名2 | E1: 属性值2 | F1: 属性名3 | G1: 属性值3 | H1: 属性名4 | I1: 属性值4 | J1: 属性名5 | K1: 属性值5 | L1: 属性名6 | M1: 属性值6 | N1: 0角色升级所需经验
A2: Level | B2: Prop1Name | C2: Prop1Value | D2: Prop2Name | E2: Prop2Value | F2: Prop3Name | G2: Prop3Value | H2: Prop4Name | I2: Prop4Value | J2: Prop5Name | K2: Prop5Value | L2: Prop6Name | M2: Prop6Value | N2: ExpLevelUp
A3: 1 | B3: 生命值 | C3: =ROUND(ConfigAttrZhanshi!C3*2/3,0) -> 40 | D3: 魔法值 | E3: =C3 -> 40 | F3: 敏捷 | H3: 准确 | J3: 魔法下限 | K3: 0 | L3: 魔法上限 | M3: =ROUND(ConfigAttrZhanshi!M3*0.8,0) -> 0 | N3: 10
A4: 2 | B4: 生命值 | C4: =ROUND(ConfigAttrZhanshi!C4*2/3,0) -> 4 | D4: 魔法值 | E4: =C4 -> 4 | F4: 敏捷 | H4: 准确 | J4: 魔法下限 | K4: 0 | L4: 魔法上限 | M4: =ROUND(ConfigAttrZhanshi!M4*0.8,0) -> 0 | N4: 15
A5: 3 | B5: 生命值 | C5: =ROUND(ConfigAttrZhanshi!C5*2/3,0) -> 4 | D5: 魔法值 | E5: =C5 -> 4 | F5: 敏捷 | H5: 准确 | J5: 魔法下限 | K5: 0 | L5: 魔法上限 | M5: =ROUND(ConfigAttrZhanshi!M5*0.8,0) -> 0 | N5: 25
A6: 4 | B6: 生命值 | C6: =ROUND(ConfigAttrZhanshi!C6*2/3,0) -> 4 | D6: 魔法值 | E6: =C6 -> 4 | F6: 敏捷 | H6: 准确 | J6: 魔法下限 | K6: 0 | L6: 魔法上限 | M6: =ROUND(ConfigAttrZhanshi!M6*0.8,0) -> 0 | N6: 35
A7: 5 | B7: 生命值 | C7: =ROUND(ConfigAttrZhanshi!C7*2/3,0) -> 4 | D7: 魔法值 | E7: =C7 -> 4 | F7: 敏捷 | H7: 准确 | J7: 魔法下限 | K7: 0 | L7: 魔法上限 | M7: =ROUND(ConfigAttrZhanshi!M7*0.8,0) -> 1 | N7: 50
A8: 6 | B8: 生命值 | C8: =ROUND(ConfigAttrZhanshi!C8*2/3,0) -> 4 | D8: 魔法值 | E8: =C8 -> 4 | F8: 敏捷 | H8: 准确 | J8: 魔法下限 | K8: 0 | L8: 魔法上限 | M8: =ROUND(ConfigAttrZhanshi!M8*0.8,0) -> 0 | N8: 70
A9: 7 | B9: 生命值 | C9: =ROUND(ConfigAttrZhanshi!C9*2/3,0) -> 4 | D9: 魔法值 | E9: =C9 -> 4 | F9: 敏捷 | H9: 准确 | J9: 魔法下限 | K9: 0 | L9: 魔法上限 | M9: =ROUND(ConfigAttrZhanshi!M9*0.8,0) -> 0 | N9: 95
A10: 8 | B10: 生命值 | C10: =ROUND(ConfigAttrZhanshi!C10*2/3,0) -> 4 | D10: 魔法值 | E10: =C10 -> 4 | F10: 敏捷 | H10: 准确 | J10: 魔法下限 | K10: 0 | L10: 魔法上限 | M10: =ROUND(ConfigAttrZhanshi!M10*0.8,0) -> 0 | N10: 125
A11: 9 | B11: 生命值 | C11: =ROUND(ConfigAttrZhanshi!C11*2/3,0) -> 4 | D11: 魔法值 | E11: =C11 -> 4 | F11: 敏捷 | H11: 准确 | J11: 魔法下限 | K11: 0 | L11: 魔法上限 | M11: =ROUND(ConfigAttrZhanshi!M11*0.8,0) -> 0 | N11: 160
A12: 10 | B12: 生命值 | C12: =ROUND(ConfigAttrZhanshi!C12*2/3,0) -> 4 | D12: 魔法值 | E12: =C12 -> 4 | F12: 敏捷 | H12: 准确 | J12: 魔法下限 | K12: 0 | L12: 魔法上限 | M12: =ROUND(ConfigAttrZhanshi!M12*0.8,0) -> 1 | N12: 210
A13: 11 | B13: 生命值 | C13: =ROUND(ConfigAttrZhanshi!C13*2/3,0) -> 5 | D13: 魔法值 | E13: =C13 -> 5 | F13: 敏捷 | H13: 准确 | J13: 魔法下限 | K13: 0 | L13: 魔法上限 | M13: =ROUND(ConfigAttrZhanshi!M13*0.8,0) -> 0 | N13: 270
A14: 12 | B14: 生命值 | C14: =ROUND(ConfigAttrZhanshi!C14*2/3,0) -> 5 | D14: 魔法值 | E14: =C14 -> 5 | F14: 敏捷 | H14: 准确 | J14: 魔法下限 | K14: 0 | L14: 魔法上限 | M14: =ROUND(ConfigAttrZhanshi!M14*0.8,0) -> 0 | N14: 340
... A87: 85 | B87: 生命值 | C87: =ROUND(ConfigAttrZhanshi!C87*2/3,0) -> 53 | D87: 魔法值 | E87: =C87 -> 53 | F87: 敏捷 | H87: 准确 | J87: 魔法下限 | K87: 0 | L87: 魔法上限 | M87: =ROUND(ConfigAttrZhanshi!M87*0.8,0) -> 0 | N87: 720000

Sheet ConfigAttrDaoshi
A1: 0等级 | B1: 属性名1 | C1: 属性值1 | D1: 属性名2 | E1: 属性值2 | F1: 属性名3 | G1: 属性值3 | H1: 属性名4 | I1: 属性值4 | J1: 属性名5 | K1: 属性值5 | L1: 属性名6 | M1: 属性值6 | N1: 0角色升级所需经验
A2: Level | B2: Prop1Name | C2: Prop1Value | D2: Prop2Name | E2: Prop2Value | F2: Prop3Name | G2: Prop3Value | H2: Prop4Name | I2: Prop4Value | J2: Prop5Name | K2: Prop5Value | L2: Prop6Name | M2: Prop6Value | N2: ExpLevelUp
A3: 1 | B3: 生命值 | C3: =ConfigAttrFashi!C3 -> 40 | D3: 魔法值 | E3: =ROUND(C3*0.8,0) -> 32 | F3: 敏捷 | H3: 准确 | J3: 道术下限 | K3: 0 | L3: 道术上限 | M3: =ConfigAttrFashi!M3 -> 0 | N3: 10
A4: 2 | B4: 生命值 | C4: =ConfigAttrFashi!C4 -> 4 | D4: 魔法值 | E4: =ROUND(C4*0.8,0) -> 3 | F4: 敏捷 | H4: 准确 | J4: 道术下限 | K4: 0 | L4: 道术上限 | M4: =ConfigAttrFashi!M4 -> 0 | N4: 15
A5: 3 | B5: 生命值 | C5: =ConfigAttrFashi!C5 -> 4 | D5: 魔法值 | E5: =ROUND(C5*0.8,0) -> 3 | F5: 敏捷 | H5: 准确 | J5: 道术下限 | K5: 0 | L5: 道术上限 | M5: =ConfigAttrFashi!M5 -> 0 | N5: 25
A6: 4 | B6: 生命值 | C6: =ConfigAttrFashi!C6 -> 4 | D6: 魔法值 | E6: =ROUND(C6*0.8,0) -> 3 | F6: 敏捷 | H6: 准确 | J6: 道术下限 | K6: 0 | L6: 道术上限 | M6: =ConfigAttrFashi!M6 -> 0 | N6: 35
A7: 5 | B7: 生命值 | C7: =ConfigAttrFashi!C7 -> 4 | D7: 魔法值 | E7: =ROUND(C7*0.8,0) -> 3 | F7: 敏捷 | H7: 准确 | J7: 道术下限 | K7: 0 | L7: 道术上限 | M7: =ConfigAttrFashi!M7 -> 1 | N7: 50
A8: 6 | B8: 生命值 | C8: =ConfigAttrFashi!C8 -> 4 | D8: 魔法值 | E8: =ROUND(C8*0.8,0) -> 3 | F8: 敏捷 | H8: 准确 | J8: 道术下限 | K8: 0 | L8: 道术上限 | M8: =ConfigAttrFashi!M8 -> 0 | N8: 70
A9: 7 | B9: 生命值 | C9: =ConfigAttrFashi!C9 -> 4 | D9: 魔法值 | E9: =ROUND(C9*0.8,0) -> 3 | F9: 敏捷 | H9: 准确 | J9: 道术下限 | K9: 0 | L9: 道术上限 | M9: =ConfigAttrFashi!M9 -> 0 | N9: 95
A10: 8 | B10: 生命值 | C10: =ConfigAttrFashi!C10 -> 4 | D10: 魔法值 | E10: =ROUND(C10*0.8,0) -> 3 | F10: 敏捷 | H10: 准确 | J10: 道术下限 | K10: 0 | L10: 道术上限 | M10: =ConfigAttrFashi!M10 -> 0 | N10: 125
A11: 9 | B11: 生命值 | C11: =ConfigAttrFashi!C11 -> 4 | D11: 魔法值 | E11: =ROUND(C11*0.8,0) -> 3 | F11: 敏捷 | H11: 准确 | J11: 道术下限 | K11: 0 | L11: 道术上限 | M11: =ConfigAttrFashi!M11 -> 0 | N11: 160
A12: 10 | B12: 生命值 | C12: =ConfigAttrFashi!C12 -> 4 | D12: 魔法值 | E12: =ROUND(C12*0.8,0) -> 3 | F12: 敏捷 | H12: 准确 | J12: 道术下限 | K12: 0 | L12: 道术上限 | M12: =ConfigAttrFashi!M12 -> 1 | N12: 210
A13: 11 | B13: 生命值 | C13: =ConfigAttrFashi!C13 -> 5 | D13: 魔法值 | E13: =ROUND(C13*0.8,0) -> 4 | F13: 敏捷 | H13: 准确 | J13: 道术下限 | K13: 0 | L13: 道术上限 | M13: =ConfigAttrFashi!M13 -> 0 | N13: 270
A14: 12 | B14: 生命值 | C14: =ConfigAttrFashi!C14 -> 5 | D14: 魔法值 | E14: =ROUND(C14*0.8,0) -> 4 | F14: 敏捷 | H14: 准确 | J14: 道术下限 | K14: 0 | L14: 道术上限 | M14: =ConfigAttrFashi!M14 -> 0 | N14: 340
... A87: 85 | B87: 生命值 | C87: =ConfigAttrFashi!C87 -> 53 | D87: 魔法值 | E87: =ROUND(C87*0.8,0) -> 42 | F87: 敏捷 | H87: 准确 | J87: 道术下限 | K87: 0 | L87: 道术上限 | M87: =ConfigAttrFashi!M87 -> 0 | N87: 720000
