Workbook
Name 说明: [1]名称表!$A$3:$A$26

Sheet ConfigScene
A1: 场景ID | B1: 场景名 | C1: 镜头距离 | D1: 镜头旋转 | E1: 镜头初始角度 | F1: 小地图 | G1: 大地图 | H1: 场景等级
A2: config_id | B2: scene_name | C2: CameraDistance | D2: CameraRotate | E2: CameraAngle | F2: Minimap | G2: Bigmap | H2: Grade
A3: 1 | B3: 银杏渔村 | C3: 900 | D3: 90 | E3: 315.1 | F3: mini_yxyc | G3: big_yxyc | H3: 0
A4: 2 | B4: 比奇城 | C4: 900 | D4: 90 | E4: 315.1 | F4: mini_biqi | G4: big_biqi | H4: 1
A5: 3 | B5: 兽人古墓一层 | C5: 1000 | D5: 50 | E5: 303.7 | F5: mini_srgm1 | G5: big_srgm1 | H5: 1
A6: 4 | B6: 兽人古墓二层 | C6: 1000 | D6: 50 | E6: 303.7 | F6: mini_srgm2 | G6: big_srgm2 | H6: 1
A7: 5 | B7: 国王陵墓 | C7: 1000 | D7: 120 | E7: 303.7 | F7: mini_srgm3 | G7: big_srgm3 | H7: 1
A8: 6 | B8: 废矿区东部 | C8: 1000 | D8: 50 | E8: 303.7 | F8: mini_bqfk1 | G8: big_bqfk1 | H8: 1
A9: 7 | B9: 尸王殿 | C9: 1000 | D9: 60 | E9: 303.7 | F9: mini_bqfk2 | G9: big_bqfk2 | H9: 2
A10: 8 | B10: 地牢 | C10: 1000 | D10: 50 | E10: 303.7 | F10: mini_dl1 | G10: big_dl1 | H10: 2
A11: 9 | B11: 黑暗地带 | C11: 1000 | D11: 50 | E11: 303.7 | F11: mini_dl2 | G11: big_dl2 | H11: 2
A12: 10 | B12: 死亡棺材 | C12: 1000 | D12: 50 | E12: 303.7 | F12: mini_dl3 | G12: big_dl3 | H12: 2
A13: 11 | B13: 未知暗殿 | C13: 1000 | D13: 50 | E13: 303.7 | F13: mini_wzad | G13: big_wzad | H13: 2
A14: 12 | B14: 沃玛寺庙一层 | C14: 1000 | D14: 50 | E14: 303.7 | F14: mini_wmsm1 | G14: big_wmsm1 | H14: 2
... A43: 41 | B43: 赤月魔穴 | C43: 1000 | D43: 90 | E43: 303.7 | F43: mini_cyxg6 | G43: big_cyxg6 | H43: 5

Sheet ConfigRect
A1: 区域ID | B1: 区域名（传送才外显） | C1: 备注 | D1: 地编名 | E1: 所属区域ID | F1: 类型 | G1: 面积 | H1: 行 | I1: 序号 | J1: 是否场景主区域 | K1: 是否出生区域 | L1: 传送目标区域 | M1: 刷怪方案说明 | N1: 刷怪方案1 | O1: 刷怪方案2 | P1: 刷怪方案3 | Q1: 刷怪方案4 | R1: 刷怪方案5 | S1: 刷怪方案6 | T1: 刷怪方案7 | U1: 刷怪方案8
A2: config_id | B2: rect_name | D2: scene_name | E2: scene_id | J2: is_main_rect | K2: is_born_rect | L2: teleport_target | N2: RefreshMonsterPlan1 | O2: RefreshMonsterPlan2 | P2: RefreshMonsterPlan3 | Q2: RefreshMonsterPlan4 | R2: RefreshMonsterPlan5 | S2: RefreshMonsterPlan6 | T2: RefreshMonsterPlan7 | U2: RefreshMonsterPlan8
A3: =70000000+E3*10000+G3*1000+H3*100+I3 -> 70015101 | B3: 银杏渔村-怪物1 | D3: =E3&(VLOOKUP(F3,编号表!$E$1:$G$8,2,0))&G3&"_"&H3&"_"&I3 -> 1N5_1_1 | E3: 1 | F3: 怪物 | G3: 5 | H3: 1 | I3: =COUNTIFS($E$3:E3,E3,$H$3:H3,H3) -> 1 | N3: 1001302
A4: =70000000+E4*10000+G4*1000+H4*100+I4 -> 70015102 | B4: 银杏渔村-怪物2 | D4: =E4&(VLOOKUP(F4,编号表!$E$1:$G$8,2,0))&G4&"_"&H4&"_"&I4 -> 1N5_1_2 | E4: 1 | F4: 怪物 | G4: 5 | H4: 1 | I4: =COUNTIFS($E$3:E4,E4,$H$3:H4,H4) -> 2 | N4: 1001302
A5: =70000000+E5*10000+G5*1000+H5*100+I5 -> 70015103 | B5: 银杏渔村-怪物3 | D5: =E5&(VLOOKUP(F5,编号表!$E$1:$G$8,2,0))&G5&"_"&H5&"_"&I5 -> 1N5_1_3 | E5: 1 | F5: 怪物 | G5: 5 | H5: 1 | I5: =COUNTIFS($E$3:E5,E5,$H$3:H5,H5) -> 3 | N5: 1001302
A6: =70000000+E6*10000+G6*1000+H6*100+I6 -> 70015104 | B6: 银杏渔村-怪物4 | D6: =E6&(VLOOKUP(F6,编号表!$E$1:$G$8,2,0))&G6&"_"&H6&"_"&I6 -> 1N5_1_4 | E6: 1 | F6: 怪物 | G6: 5 | H6: 1 | I6: =COUNTIFS($E$3:E6,E6,$H$3:H6,H6) -> 4 | N6: 1001302
A7: =70000000+E7*10000+G7*1000+H7*100+I7 -> 70015105 | B7: 银杏渔村-怪物5 | D7: =E7&(VLOOKUP(F7,编号表!$E$1:$G$8,2,0))&G7&"_"&H7&"_"&I7 -> 1N5_1_5 | E7: 1 | F7: 怪物 | G7: 5 | H7: 1 | I7: =COUNTIFS($E$3:E7,E7,$H$3:H7,H7) -> 5 | N7: 1001302
A8: =70000000+E8*10000+G8*1000+H8*100+I8 -> 70015201 | B8: 银杏渔村-怪物6 | D8: =E8&(VLOOKUP(F8,编号表!$E$1:$G$8,2,0))&G8&"_"&H8&"_"&I8 -> 1N5_2_1 | E8: 1 | F8: 怪物 | G8: 5 | H8: 2 | I8: =COUNTIFS($E$3:E8,E8,$H$3:H8,H8) -> 1 | N8: 1001403
A9: =70000000+E9*10000+G9*1000+H9*100+I9 -> 70015202 | B9: 银杏渔村-怪物7 | D9: =E9&(VLOOKUP(F9,编号表!$E$1:$G$8,2,0))&G9&"_"&H9&"_"&I9 -> 1N5_2_2 | E9: 1 | F9: 怪物 | G9: 5 | H9: 2 | I9: =COUNTIFS($E$3:E9,E9,$H$3:H9,H9) -> 2 | N9: 1001403
A10: =70000000+E10*10000+G10*1000+H10*100+I10 -> 70015203 | B10: 银杏渔村-怪物8 | D10: =E10&(VLOOKUP(F10,编号表!$E$1:$G$8,2,0))&G10&"_"&H10&"_"&I10 -> 1N5_2_3 | E10: 1 | F10: 怪物 | G10: 5 | H10: 2 | I10: =COUNTIFS($E$3:E10,E10,$H$3:H10,H10) -> 3 | N10: 1001403
A11: =70000000+E11*10000+G11*1000+H11*100+I11 -> 70015204 | B11: 银杏渔村-怪物9 | D11: =E11&(VLOOKUP(F11,编号表!$E$1:$G$8,2,0))&G11&"_"&H11&"_"&I11 -> 1N5_2_4 | E11: 1 | F11: 怪物 | G11: 5 | H11: 2 | I11: =COUNTIFS($E$3:E11,E11,$H$3:H11,H11) -> 4 | N11: 1001403
A12: =70000000+E12*10000+G12*1000+H12*100+I12 -> 70015205 | B12: 银杏渔村-怪物10 | D12: =E12&(VLOOKUP(F12,编号表!$E$1:$G$8,2,0))&G12&"_"&H12&"_"&I12 -> 1N5_2_5 | E12: 1 | F12: 怪物 | G12: 5 | H12: 2 | I12: =COUNTIFS($E$3:E12,E12,$H$3:H12,H12) -> 5 | N12: 1001403
A13: =70000000+E13*10000+G13*1000+H13*100+I13 -> 70015301 | B13: 银杏渔村-怪物11 | D13: =E13&(VLOOKUP(F13,编号表!$E$1:$G$8,2,0))&G13&"_"&H13&"_"&I13 -> 1N5_3_1 | E13: 1 | F13: 怪物 | G13: 5 | H13: 3 | I13: =COUNTIFS($E$3:E13,E13,$H$3:H13,H13) -> 1 | N13: 1001203
A14: =70000000+E14*10000+G14*1000+H14*100+I14 -> 70015302 | B14: 银杏渔村-怪物12 | D14: =E14&(VLOOKUP(F14,编号表!$E$1:$G$8,2,0))&G14&"_"&H14&"_"&I14 -> 1N5_3_2 | E14: 1 | F14: 怪物 | G14: 5 | H14: 3 | I14: =COUNTIFS($E$3:E14,E14,$H$3:H14,H14) -> 2 | N14: 1001203
... A17: =70000000+E17*10000+G17*1000+H17*100+I17 -> 70015305 | B17: 银杏渔村-怪物15 | D17: =E17&(VLOOKUP(F17,编号表!$E$1:$G$8,2,0))&G17&"_"&H17&"_"&I17 -> 1N5_3_5 | E17: 1 | F17: 怪物 | G17: 5 | H17: 3 | I17: =COUNTIFS($E$3:E17,E17,$H$3:H17,H17) -> 5 | N17: 1001203
A18: =70000000+E18*10000+G18*1000+H18*100+I18 -> 70011306 | B18: 比奇城-银杏渔村 | D18: =E18&(VLOOKUP(F18,编号表!$E$1:$G$8,2,0))&G18&"_"&H18&"_"&I18 -> 1T1_3_6 | E18: 1 | F18: 传送 | G18: 1 | H18: 3 | I18: =COUNTIFS($E$3:E18,E18,$H$3:H18,H18) -> 6
A19: =70000000+E19*10000+G19*1000+H19*100+I19 -> 70011307 | B19: 比奇城 | C19: 银杏渔村-比奇城 | D19: =E19&(VLOOKUP(F19,编号表!$E$1:$G$8,2,0))&G19&"_"&H19&"_"&I19 -> 1T1_3_7 | E19: 1 | F19: 传送 | G19: 1 | H19: 3 | I19: =COUNTIFS($E$3:E19,E19,$H$3:H19,H19) -> 7 | L19: 187
A20: =70000000+E20*10000+G20*1000+H20*100+I20 -> 70011401 | B20: 银杏渔村-卫士1 | D20: =E20&(VLOOKUP(F20,编号表!$E$1:$G$8,2,0))&G20&"_"&H20&"_"&I20 -> 1P1_4_1 | E20: 1 | F20: NPC | G20: 1 | H20: 4 | I20: =COUNTIFS($E$3:E20,E20,$H$3:H20,H20) -> 1
A21: =70000000+E21*10000+G21*1000+H21*100+I21 -> 70011402 | B21: 银杏渔村-卫士2 | D21: =E21&(VLOOKUP(F21,编号表!$E$1:$G$8,2,0))&G21&"_"&H21&"_"&I21 -> 1P1_4_2 | E21: 1 | F21: NPC | G21: 1 | H21: 4 | I21: =COUNTIFS($E$3:E21,E21,$H$3:H21,H21) -> 2
A22: =70000000+E22*10000+G22*1000+H22*100+I22 -> 70013501 | B22: 银杏渔村-散步鸡1 | D22: =E22&(VLOOKUP(F22,编号表!$E$1:$G$8,2,0))&G22&"_"&H22&"_"&I22 -> 1P3_5_1 | E22: 1 | F22: NPC | G22: 3 | H22: 5 | I22: =COUNTIFS($E$3:E22,E22,$H$3:H22,H22) -> 1 | N22: 1001202
A23: =70000000+E23*10000+G23*1000+H23*100+I23 -> 70013502 | B23: 银杏渔村-散步鸡2 | D23: =E23&(VLOOKUP(F23,编号表!$E$1:$G$8,2,0))&G23&"_"&H23&"_"&I23 -> 1P3_5_2 | E23: 1 | F23: NPC | G23: 3 | H23: 5 | I23: =COUNTIFS($E$3:E23,E23,$H$3:H23,H23) -> 2 | N23: 1001202
A24: =70000000+E24*10000+G24*1000+H24*100+I24 -> 70011601 | B24: 银杏渔村-NPC1 | D24: =E24&(VLOOKUP(F24,编号表!$E$1:$G$8,2,0))&G24&"_"&H24&"_"&I24 -> 1P1_6_1 | E24: 1 | F24: NPC | G24: 1 | H24: 6 | I24: =COUNTIFS($E$3:E24,E24,$H$3:H24,H24) -> 1 | N24: 1001004
A25: =70000000+E25*10000+G25*1000+H25*100+I25 -> 70011602 | B25: 银杏渔村-出生 | D25: =E25&(VLOOKUP(F25,编号表!$E$1:$G$8,2,0))&G25&"_"&H25&"_"&I25 -> 1P1_6_2 | E25: 1 | F25: NPC | G25: 1 | H25: 6 | I25: =COUNTIFS($E$3:E25,E25,$H$3:H25,H25) -> 2 | K25: 1
A26: =70000000+E26*10000+G26*1000+H26*100+I26 -> 70011603 | B26: 银杏渔村-NPC2 | D26: =E26&(VLOOKUP(F26,编号表!$E$1:$G$8,2,0))&G26&"_"&H26&"_"&I26 -> 1P1_6_3 | E26: 1 | F26: NPC | G26: 1 | H26: 6 | I26: =COUNTIFS($E$3:E26,E26,$H$3:H26,H26) -> 3
A27: =70000000+E27*10000+G27*1000+H27*100+I27 -> 70011604 | B27: 银杏渔村-NPC3 | D27: =E27&(VLOOKUP(F27,编号表!$E$1:$G$8,2,0))&G27&"_"&H27&"_"&I27 -> 1P1_6_4 | E27: 1 | F27: NPC | G27: 1 | H27: 6 | I27: =COUNTIFS($E$3:E27,E27,$H$3:H27,H27) -> 4
A28: =70000000+E28*10000+G28*1000+H28*100+I28 -> 70013701 | B28: 散步鸡3 | D28: =E28&(VLOOKUP(F28,编号表!$E$1:$G$8,2,0))&G28&"_"&H28&"_"&I28 -> 1P3_7_1 | E28: 1 | F28: NPC | G28: 3 | H28: 7 | I28: =COUNTIFS($E$3:E28,E28,$H$3:H28,H28) -> 1 | N28: 1001202
A29: =70000000+E29*10000+G29*1000+H29*100+I29 -> 70011702 | B29: 银杏渔村-NPC4 | D29: =E29&(VLOOKUP(F29,编号表!$E$1:$G$8,2,0))&G29&"_"&H29&"_"&I29 -> 1P1_7_2 | E29: 1 | F29: NPC | G29: 1 | H29: 7 | I29: 2 | N29: 1001005
A30: =70000000+E30*10000+G30*1000+H30*100+I30 -> 70012703 | B30: 散步鸡4 | D30: =E30&(VLOOKUP(F30,编号表!$E$1:$G$8,2,0))&G30&"_"&H30&"_"&I30 -> 1P2_7_3 | E30: 1 | F30: NPC | G30: 2 | H30: 7 | I30: =COUNTIFS($E$3:E30,E30,$H$3:H30,H30) -> 3 | N30: 1001202
A31: =70000000+E31*10000+G31*1000+H31*100+I31 -> 70011704 | B31: 银杏渔村-NPC5 | D31: =E31&(VLOOKUP(F31,编号表!$E$1:$G$8,2,0))&G31&"_"&H31&"_"&I31 -> 1P1_7_4 | E31: 1 | F31: NPC | G31: 1 | H31: 7 | I31: =COUNTIFS($E$3:E31,E31,$H$3:H31,H31) -> 4
A32: =70000000+E32*10000+G32*1000+H32*100+I32 -> 70014705 | B32: 散步鸡5 | D32: =E32&(VLOOKUP(F32,编号表!$E$1:$G$8,2,0))&G32&"_"&H32&"_"&I32 -> 1P4_7_5 | E32: 1 | F32: NPC | G32: 4 | H32: 7 | I32: =COUNTIFS($E$3:E32,E32,$H$3:H32,H32) -> 5 | N32: 1001202
A33: =70000000+E33*10000+G33*1000+H33*100+I33 -> 70011706 | B33: 银杏渔村-NPC6 | D33: =E33&(VLOOKUP(F33,编号表!$E$1:$G$8,2,0))&G33&"_"&H33&"_"&I33 -> 1P1_7_6 | E33: 1 | F33: NPC | G33: 1 | H33: 7 | I33: =COUNTIFS($E$3:E33,E33,$H$3:H33,H33) -> 6
A34: =70000000+E34*10000+G34*1000+H34*100+I34 -> 70015707 | B34: 银杏渔村-怪物16 | D34: =E34&(VLOOKUP(F34,编号表!$E$1:$G$8,2,0))&G34&"_"&H34&"_"&I34 -> 1N5_7_7 | E34: 1 | F34: 怪物 | G34: 5 | H34: 7 | I34: =COUNTIFS($E$3:E34,E34,$H$3:H34,H34) -> 7 | N34: 1001302
A35: =70000000+E35*10000+G35*1000+H35*100+I35 -> 70014801 | B35: 银杏渔村-怪物17 | D35: =E35&(VLOOKUP(F35,编号表!$E$1:$G$8,2,0))&G35&"_"&H35&"_"&I35 -> 1N4_8_1 | E35: 1 | F35: 怪物 | G35: 4 | H35: 8 | I35: =COUNTIFS($E$3:E35,E35,$H$3:H35,H35) -> 1 | N35: 1001302
A36: =70000000+E36*10000+G36*1000+H36*100+I36 -> 70014802 | B36: 银杏渔村-怪物18 | D36: =E36&(VLOOKUP(F36,编号表!$E$1:$G$8,2,0))&G36&"_"&H36&"_"&I36 -> 1N4_8_2 | E36: 1 | F36: 怪物 | G36: 4 | H36: 8 | I36: =COUNTIFS($E$3:E36,E36,$H$3:H36,H36) -> 2 | N36: 1001203
A37: =70000000+E37*10000+G37*1000+H37*100+I37 -> 70016803 | B37: 银杏渔村-散步鸡6 | D37: =E37&(VLOOKUP(F37,编号表!$E$1:$G$8,2,0))&G37&"_"&H37&"_"&I37 -> 1P6_8_3 | E37: 1 | F37: NPC | G37: 6 | H37: 8 | I37: =COUNTIFS($E$3:E37,E37,$H$3:H37,H37) -> 3 | N37: 1001202
A38: =70000000+E38*10000+G38*1000+H38*100+I38 -> 70015804 | B38: 银杏渔村-怪物19 | D38: =E38&(VLOOKUP(F38,编号表!$E$1:$G$8,2,0))&G38&"_"&H38&"_"&I38 -> 1N5_8_4 | E38: 1 | F38: 怪物 | G38: 5 | H38: 8 | I38: =COUNTIFS($E$3:E38,E38,$H$3:H38,H38) -> 4 | N38: 1001403
A39: =70000000+E39*10000+G39*1000+H39*100+I39 -> 70014901 | B39: 银杏渔村-怪物20 | D39: =E39&(VLOOKUP(F39,编号表!$E$1:$G$8,2,0))&G39&"_"&H39&"_"&I39 -> 1N4_9_1 | E39: 1 | F39: 怪物 | G39: 4 | H39: 9 | I39: =COUNTIFS($E$3:E39,E39,$H$3:H39,H39) -> 1 | N39: 1001403
A40: =70000000+E40*10000+G40*1000+H40*100+I40 -> 70013902 | B40: 银杏渔村-散步鸡7 | D40: =E40&(VLOOKUP(F40,编号表!$E$1:$G$8,2,0))&G40&"_"&H40&"_"&I40 -> 1P3_9_2 | E40: 1 | F40: NPC | G40: 3 | H40: 9 | I40: =COUNTIFS($E$3:E40,E40,$H$3:H40,H40) -> 2 | N40: 1001202
A41: =70000000+E41*10000+G41*1000+H41*100+I41 -> 70013903 | B41: 银杏渔村-散步鸡8 | D41: =E41&(VLOOKUP(F41,编号表!$E$1:$G$8,2,0))&G41&"_"&H41&"_"&I41 -> 1P3_9_3 | E41: 1 | F41: NPC | G41: 3 | H41: 9 | I41: =COUNTIFS($E$3:E41,E41,$H$3:H41,H41) -> 3 | N41: 1001202
A42: =70000000+E42*10000+G42*1000+H42*100+I42 -> 70014904 | B42: 银杏渔村-散步鸡9 | D42: =E42&(VLOOKUP(F42,编号表!$E$1:$G$8,2,0))&G42&"_"&H42&"_"&I42 -> 1P4_9_4 | E42: 1 | F42: NPC | G42: 4 | H42: 9 | I42: =COUNTIFS($E$3:E42,E42,$H$3:H42,H42) -> 4 | N42: 1001202
...

Sheet 编号表
A1: 场景名 | B1: 序号 | C1: 地编名 | D1: 序号 | E1: 类型 | F1: 缩写 | G1: 序号
A2: 比奇城 | B2: 1 | C2: D1_1_ | D2: 1 | E2: 怪物 | F2: N | G2: 1 | I2: =F4&"-"&E3 -> P-传送
A3: 兽人古墓一层 | B3: 2 | C3: D1_2_ | D3: 2 | E3: 传送 | F3: T | G3: 2 | I3: =F3&"-"&E4 -> T-NPC
A4: 兽人古墓二层 | B4: 3 | C4: D1_3_ | D4: 3 | E4: NPC | F4: P | G4: 3 | I4: =F2&"-"&E2 -> N-怪物
A5: 国王陵墓 | B5: 4 | C5: D1_4_ | D5: 4 | E5: 音效 | F5: M | G5: 4 | I5: =F5&"-"&E5 -> M-音效
A6: 废矿区东部 | B6: 5 | C6: D1_5_ | D6: 5 | E6: 镜头 | F6: J | G6: 5 | I6: =F6&"-"&E6 -> J-镜头
A7: 尸王殿 | B7: 6 | C7: D1_6_ | D7: 6
A8: 地牢 | B8: 7 | C8: D2_1_ | D8: 7
A9: 黑暗地带 | B9: 8 | C9: D2_2_ | D9: 8
A10: 死亡棺材 | B10: 9 | C10: D2_3_ | D10: 9
A11: 未知暗殿 | B11: 10 | C11: D2_4_ | D11: 10
A12: 沃玛寺庙一层 | B12: 11 | C12: D2_5_ | D12: 11
A13: 沃玛寺庙二层 | B13: 12 | C13: D2_6_ | D13: 12
A14: 沃玛教主大殿 | B14: 13 | C14: D3_1_ | D14: 13
A15: 石墓一层 | B15: 14 | C15: D3_2_ | D15: 14
A16: 石墓阵入口 | B16: 15 | C16: D3_3_ | D16: 15
A17: 石墓阵出口 | B17: 16 | C17: D3_4_ | D17: 16
A18: 石墓顶层 | B18: 17 | C18: D3_5_ | D18: 17
... A25: 封魔矿区 | B25: 24 | C25: D4_6_ | D25: 24
A26: 光芒回廊 | B26: 25 | C26: D5_1_ | D26: 25 | M26: 编号命名 | N26: 1 | O26: 2 | P26: 3 | Q26: 4 | R26: 5 | S26: 6 | T26: 7 | U26: 8
A27: 封魔殿 | B27: 26 | C27: D5_2_ | D27: 26 | N27: 固定“7” | O27: 地图序号 | R27: 格子边长 | S27: 地图从上往下格子所在第x行 | T27: 格子所在行左起第x个
A28: 尸魔洞一层 | B28: 27 | C28: D5_3_ | D28: 27
A29: 尸魔洞二层 | B29: 28 | C29: D5_4_ | D29: 28 | M29: 示例：70015304，解释：序号1的地图边长为5的区域位置在地图从上往下第3行左数第4个
A30: 骨魔洞一层 | B30: 29 | C30: D5_5_ | D30: 29
A31: 骨魔洞二层 | B31: 30 | C31: D5_6_ | D31: 30 | M31: 比奇城按6区域划分行数，传送点-0，左上-1，右上-2，左下-3，右下4，城中-5
A32: 牛魔寺庙入口 | B32: 31 | C32: D6_1_ | D32: 31
A33: 牛魔寺庙一层 | B33: 32 | C33: D6_2_ | D33: 32
A34: 牛魔寺庙大厅 | B34: 33 | C34: D6_3_ | D34: 33 | M34: 地编命名 | N34: 1 | O34: 2 | P34: 3 | Q34: 4 | R34: 5
A35: 丛林迷宫 | B35: 34 | C35: D6_4_ | D35: 34 | N35: 地图序号 | O35: 区域类型 | P35: 格子边长 | Q35: 格子所在第x行 | R35: 格子所在行左起第x个
A36: 赤月峡谷西走廊 | B36: 35 | C36: D6_5_ | D36: 35 | O36: P-传送
A37: 赤月峡谷东二层 | B37: 36 | C37: D6_6_ | D37: 36 | O37: T-NPC
A38: 赤月峡谷广场 | B38: 37 | C38: M1 | D38: 37 | O38: N-怪物
A39: 抉择之地 | B39: 38 | C39: M2 | D39: 38 | O39: M-音效
A40: 恶魔祭坛 | B40: 39 | C40: M3 | D40: 39 | O40: J-镜头
A41: 赤月魔穴 | B41: 40 | C41: M4 | D41: 40 | M41: 示例：1N3_4_5，解释：序号1的地图边长为3的从上往下第4行左数第5个怪物区域
A42: 新手村 | B42: 41 | C42: M5 | D42: 41
D43: 42
D44: 43
D45: 44
D46: 45

Sheet 说明
A1: 版本 | B1: 内容
A2: V1.11 | B2: 新增场景区域
A3: V1.12 | B3: 修改兽人古墓、矿区传送、位置
A4: V1.13
A5: V1.14
A6: V1.15 | B6: 更新传送方案，刷怪方案
A7: V1.16 | B7: 增加两个测试木桩，biqi_77,biqi_78
A8: V1.17 | B8: 增加主场景区域-场景镜头区域
A9: V1.18 | B9: 增加场景小地图大地图
A10: V1.19 | B10: 按照新的怪物刷新配置，刷新场景内的怪物配置
A11: V1.20 | B11: 更新场景
A12: V1.21 | B12: 比奇城新增羊，鹿和狼的配置，测试任务用。
A13: V1.22 | B13: 新增新手村场景区域；比奇城22,77,78刷新木桩；
A14: V1.23 | B14: ① 新手村、比奇城各一个出生点 ② 新手村5个备用传送区域，5个落点区域，备用NPC区域10个，普通40，精英10，BOSS 5，音乐10，镜头1
A15: V1.24 | B15: 区域版本重制 1、传送落地点与传送起始点分开 2、区域密度提高，适配更多刷怪密度和位置策略 3、区域命名方式优化，附带区域信息
