Workbook

Sheet ConfigSuitCollect
A1: 图鉴属性id | B1: 套装id | C1: 套装名 | D1: 装备id1 | E1: 装备名策划填 | F1: 装备数量1 | G1: 装备id2 | H1: 装备名策划填 | I1: 装备数量2 | J1: 装备id3 | K1: 装备名策划填 | L1: 装备数量3 | M1: 装备id4 | N1: 装备名策划填 | O1: 装备数量4 | P1: 装备id5 | Q1: 装备名策划填 | R1: 装备数量5 | S1: 装备id6 | T1: 装备名策划填 | U1: 装备数量6 | V1: 属性名1 | W1: 属性值1 | X1: 属性名2 | Y1: 属性值2 | Z1: 属性名3 | AA1: 属性值3
A2: ID | B2: suitId | D2: eqId1 | F2: eqNum1 | G2: eqId2 | I2: eqNum2 | J2: eqId3 | L2: eqNum3 | M2: eqId4 | O2: eqNum4 | P2: eqId5 | R2: eqNum5 | S2: eqId6 | U2: eqNum6 | V2: attr1 | W2: val1 | X2: attr2 | Y2: val2 | Z2: attr3 | AA2: val3
A3: 1 | B3: 1 | C3: 祈祷套 | D3: {=INDEX(编号表!$A:$A,MATCH(E3,编号表!$B:$B,0))} -> 50500208 | E3: 祈祷之刃 | F3: 2 | G3: {=INDEX(编号表!$A:$A,MATCH(H3,编号表!$B:$B,0))} -> 50506202 | H3: 祈祷头盔 | I3: 2 | J3: {=INDEX(编号表!$A:$A,MATCH(K3,编号表!$B:$B,0))} -> 50501203 | K3: 祈祷项链 | L3: 2 | M3: {=INDEX(编号表!$A:$A,MATCH(N3,编号表!$B:$B,0))} -> 50502200 | N3: 祈祷手镯 | O3: 2 | P3: {=INDEX(编号表!$A:$A,MATCH(Q3,编号表!$B:$B,0))} -> 50503200 | Q3: 祈祷戒指 | R3: 2 | V3: 生命值 | W3: 10 | X3: 攻击下限 | Y3: 1 | Z3: 攻击上限 | AA3: 1
A4: 2 | B4: 1 | C4: 祈祷套 | D4: {=INDEX(编号表!$A:$A,MATCH(E4,编号表!$B:$B,0))} -> 50500208 | E4: 祈祷之刃 | F4: 4 | G4: {=INDEX(编号表!$A:$A,MATCH(H4,编号表!$B:$B,0))} -> 50506202 | H4: 祈祷头盔 | I4: 4 | J4: {=INDEX(编号表!$A:$A,MATCH(K4,编号表!$B:$B,0))} -> 50501203 | K4: 祈祷项链 | L4: 4 | M4: {=INDEX(编号表!$A:$A,MATCH(N4,编号表!$B:$B,0))} -> 50502200 | N4: 祈祷手镯 | O4: 4 | P4: {=INDEX(编号表!$A:$A,MATCH(Q4,编号表!$B:$B,0))} -> 50503200 | Q4: 祈祷戒指 | R4: 4 | V4: 生命值 | W4: 20 | X4: 攻击下限 | Y4: 2 | Z4: 攻击上限 | AA4: 2
A5: 3 | B5: 1 | C5: 祈祷套 | D5: {=INDEX(编号表!$A:$A,MATCH(E5,编号表!$B:$B,0))} -> 50500208 | E5: 祈祷之刃 | F5: 6 | G5: {=INDEX(编号表!$A:$A,MATCH(H5,编号表!$B:$B,0))} -> 50506202 | H5: 祈祷头盔 | I5: 6 | J5: {=INDEX(编号表!$A:$A,MATCH(K5,编号表!$B:$B,0))} -> 50501203 | K5: 祈祷项链 | L5: 6 | M5: {=INDEX(编号表!$A:$A,MATCH(N5,编号表!$B:$B,0))} -> 50502200 | N5: 祈祷手镯 | O5: 6 | P5: {=INDEX(编号表!$A:$A,MATCH(Q5,编号表!$B:$B,0))} -> 50503200 | Q5: 祈祷戒指 | R5: 6 | V5: 生命值 | W5: 30 | X5: 攻击下限 | Y5: 3 | Z5: 攻击上限 | AA5: 3
A6: 4 | B6: 2 | C6: 记忆套 | D6: {=INDEX(编号表!$A:$A,MATCH(E6,编号表!$B:$B,0))} -> 50506204 | E6: 记忆头盔 | F6: 2 | G6: {=INDEX(编号表!$A:$A,MATCH(H6,编号表!$B:$B,0))} -> 50502208 | H6: 记忆手镯 | I6: 2 | J6: {=INDEX(编号表!$A:$A,MATCH(K6,编号表!$B:$B,0))} -> 50503208 | K6: 记忆戒指 | L6: 2 | M6: {=INDEX(编号表!$A:$A,MATCH(N6,编号表!$B:$B,0))} -> 50501211 | N6: 记忆项链 | O6: 2 | V6: 生命值 | W6: 10 | X6: 攻击下限 | Y6: 1 | Z6: 攻击上限 | AA6: 1
A7: 5 | B7: 2 | C7: 记忆套 | D7: {=INDEX(编号表!$A:$A,MATCH(E7,编号表!$B:$B,0))} -> 50506204 | E7: 记忆头盔 | F7: 4 | G7: {=INDEX(编号表!$A:$A,MATCH(H7,编号表!$B:$B,0))} -> 50502208 | H7: 记忆手镯 | I7: 4 | J7: {=INDEX(编号表!$A:$A,MATCH(K7,编号表!$B:$B,0))} -> 50503208 | K7: 记忆戒指 | L7: 4 | M7: {=INDEX(编号表!$A:$A,MATCH(N7,编号表!$B:$B,0))} -> 50501211 | N7: 记忆项链 | O7: 4 | V7: 生命值 | W7: 20 | X7: 攻击下限 | Y7: 2 | Z7: 攻击上限 | AA7: 2
A8: 6 | B8: 2 | C8: 记忆套 | D8: {=INDEX(编号表!$A:$A,MATCH(E8,编号表!$B:$B,0))} -> 50506204 | E8: 记忆头盔 | F8: 6 | G8: {=INDEX(编号表!$A:$A,MATCH(H8,编号表!$B:$B,0))} -> 50502208 | H8: 记忆手镯 | I8: 6 | J8: {=INDEX(编号表!$A:$A,MATCH(K8,编号表!$B:$B,0))} -> 50503208 | K8: 记忆戒指 | L8: 6 | M8: {=INDEX(编号表!$A:$A,MATCH(N8,编号表!$B:$B,0))} -> 50501211 | N8: 记忆项链 | O8: 6 | V8: 生命值 | W8: 30 | X8: 攻击下限 | Y8: 3 | Z8: 攻击上限 | AA8: 3
A9: 7 | B9: 3 | C9: 齿虎套 | D9: {=INDEX(编号表!$A:$A,MATCH(E9,编号表!$B:$B,0))} -> 50501402 | E9: 白色虎齿项链 | F9: 2 | G9: {=INDEX(编号表!$A:$A,MATCH(H9,编号表!$B:$B,0))} -> 50502404 | H9: 黑金手镯 | I9: 2 | J9: {=INDEX(编号表!$A:$A,MATCH(K9,编号表!$B:$B,0))} -> 50503402 | K9: 龙之戒指 | L9: 2 | V9: 生命值 | W9: 10 | X9: 攻击下限 | Y9: 1 | Z9: 攻击上限 | AA9: 1
A10: 8 | B10: 3 | C10: 齿虎套 | D10: {=INDEX(编号表!$A:$A,MATCH(E10,编号表!$B:$B,0))} -> 50501402 | E10: 白色虎齿项链 | F10: 4 | G10: {=INDEX(编号表!$A:$A,MATCH(H10,编号表!$B:$B,0))} -> 50502404 | H10: 黑金手镯 | I10: 4 | J10: {=INDEX(编号表!$A:$A,MATCH(K10,编号表!$B:$B,0))} -> 50503402 | K10: 龙之戒指 | L10: 4 | V10: 生命值 | W10: 20 | X10: 攻击下限 | Y10: 2 | Z10: 攻击上限 | AA10: 2
A11: 9 | B11: 3 | C11: 齿虎套 | D11: {=INDEX(编号表!$A:$A,MATCH(E11,编号表!$B:$B,0))} -> 50501402 | E11: 白色虎齿项链 | F11: 6 | G11: {=INDEX(编号表!$A:$A,MATCH(H11,编号表!$B:$B,0))} -> 50502404 | H11: 黑金手镯 | I11: 6 | J11: {=INDEX(编号表!$A:$A,MATCH(K11,编号表!$B:$B,0))} -> 50503402 | K11: 龙之戒指 | L11: 6 | V11: 生命值 | W11: 30 | X11: 攻击下限 | Y11: 3 | Z11: 攻击上限 | AA11: 3
A12: 10 | B12: 4 | C12: 魔力套 | D12: {=INDEX(编号表!$A:$A,MATCH(E12,编号表!$B:$B,0))} -> 50501401 | E12: 生命项链 | F12: 2 | G12: {=INDEX(编号表!$A:$A,MATCH(H12,编号表!$B:$B,0))} -> 50502401 | H12: 魔力手镯 | I12: 2 | J12: {=INDEX(编号表!$A:$A,MATCH(K12,编号表!$B:$B,0))} -> 50503401 | K12: 红宝石戒指 | L12: 2 | V12: 生命值 | W12: 10 | X12: 攻击下限 | Y12: 1 | Z12: 攻击上限 | AA12: 1
A13: 11 | B13: 4 | C13: 魔力套 | D13: {=INDEX(编号表!$A:$A,MATCH(E13,编号表!$B:$B,0))} -> 50501401 | E13: 生命项链 | F13: 4 | G13: {=INDEX(编号表!$A:$A,MATCH(H13,编号表!$B:$B,0))} -> 50502401 | H13: 魔力手镯 | I13: 4 | J13: {=INDEX(编号表!$A:$A,MATCH(K13,编号表!$B:$B,0))} -> 50503401 | K13: 红宝石戒指 | L13: 4 | V13: 生命值 | W13: 20 | X13: 攻击下限 | Y13: 2 | Z13: 攻击上限 | AA13: 2
A14: 12 | B14: 4 | C14: 魔力套 | D14: {=INDEX(编号表!$A:$A,MATCH(E14,编号表!$B:$B,0))} -> 50501401 | E14: 生命项链 | F14: 6 | G14: {=INDEX(编号表!$A:$A,MATCH(H14,编号表!$B:$B,0))} -> 50502401 | H14: 魔力手镯 | I14: 6 | J14: {=INDEX(编号表!$A:$A,MATCH(K14,编号表!$B:$B,0))} -> 50503401 | K14: 红宝石戒指 | L14: 6 | V14: 生命值 | W14: 30 | X14: 攻击下限 | Y14: 3 | Z14: 攻击上限 | AA14: 3
A15: 13 | B15: 5 | C15: 天珠套 | D15: {=INDEX(编号表!$A:$A,MATCH(E15,编号表!$B:$B,0))} -> 50501400 | E15: 天珠项链 | F15: 2 | G15: {=INDEX(编号表!$A:$A,MATCH(H15,编号表!$B:$B,0))} -> 50502203 | H15: 避邪手镯 | I15: 2 | J15: {=INDEX(编号表!$A:$A,MATCH(K15,编号表!$B:$B,0))} -> 50503400 | K15: 降妖除魔戒指 | L15: 2 | V15: 生命值 | W15: 10 | X15: 攻击下限 | Y15: 1 | Z15: 攻击上限 | AA15: 1
A16: 14 | B16: 5 | C16: 天珠套 | D16: {=INDEX(编号表!$A:$A,MATCH(E16,编号表!$B:$B,0))} -> 50501400 | E16: 天珠项链 | F16: 4 | G16: {=INDEX(编号表!$A:$A,MATCH(H16,编号表!$B:$B,0))} -> 50502203 | H16: 避邪手镯 | I16: 4 | J16: {=INDEX(编号表!$A:$A,MATCH(K16,编号表!$B:$B,0))} -> 50503400 | K16: 降妖除魔戒指 | L16: 4 | V16: 生命值 | W16: 20 | X16: 攻击下限 | Y16: 2 | Z16: 攻击上限 | AA16: 2
A17: 15 | B17: 5 | C17: 天珠套 | D17: {=INDEX(编号表!$A:$A,MATCH(E17,编号表!$B:$B,0))} -> 50501400 | E17: 天珠项链 | F17: 6 | G17: {=INDEX(编号表!$A:$A,MATCH(H17,编号表!$B:$B,0))} -> 50502203 | H17: 避邪手镯 | I17: 6 | J17: {=INDEX(编号表!$A:$A,MATCH(K17,编号表!$B:$B,0))} -> 50503400 | K17: 降妖除魔戒指 | L17: 6 | V17: 生命值 | W17: 30 | X17: 攻击下限 | Y17: 3 | Z17: 攻击上限 | AA17: 3
A18: 16 | B18: 6 | C18: 幽灵套 | D18: {=INDEX(编号表!$A:$A,MATCH(E18,编号表!$B:$B,0))} -> 50501216 | E18: 幽灵项链 | F18: 2 | G18: {=INDEX(编号表!$A:$A,MATCH(H18,编号表!$B:$B,0))} -> 50502405 | H18: 幽灵手套 | I18: 2 | V18: 生命值 | W18: 10 | X18: 攻击下限 | Y18: 1 | Z18: 攻击上限 | AA18: 1
A19: 17 | B19: 6 | C19: 幽灵套 | D19: {=INDEX(编号表!$A:$A,MATCH(E19,编号表!$B:$B,0))} -> 50501216 | E19: 幽灵项链 | F19: 4 | G19: {=INDEX(编号表!$A:$A,MATCH(H19,编号表!$B:$B,0))} -> 50502405 | H19: 幽灵手套 | I19: 4 | V19: 生命值 | W19: 20 | X19: 攻击下限 | Y19: 2 | Z19: 攻击上限 | AA19: 2
A20: 18 | B20: 6 | C20: 幽灵套 | D20: {=INDEX(编号表!$A:$A,MATCH(E20,编号表!$B:$B,0))} -> 50501216 | E20: 幽灵项链 | F20: 6 | G20: {=INDEX(编号表!$A:$A,MATCH(H20,编号表!$B:$B,0))} -> 50502405 | H20: 幽灵手套 | I20: 6 | V20: 生命值 | W20: 30 | X20: 攻击下限 | Y20: 3 | Z20: 攻击上限 | AA20: 3
A21: 19 | B21: 7 | C21: 思贝套 | D21: {=INDEX(编号表!$A:$A,MATCH(E21,编号表!$B:$B,0))} -> 50506203 | E21: 黑铁头盔 | F21: 2 | G21: {=INDEX(编号表!$A:$A,MATCH(H21,编号表!$B:$B,0))} -> 50502403 | H21: 思贝儿手镯 | I21: 2 | V21: 生命值 | W21: 10 | X21: 攻击下限 | Y21: 1 | Z21: 攻击上限 | AA21: 1
A22: 20 | B22: 7 | C22: 思贝套 | D22: {=INDEX(编号表!$A:$A,MATCH(E22,编号表!$B:$B,0))} -> 50506203 | E22: 黑铁头盔 | F22: 4 | G22: {=INDEX(编号表!$A:$A,MATCH(H22,编号表!$B:$B,0))} -> 50502403 | H22: 思贝儿手镯 | I22: 4 | V22: 生命值 | W22: 20 | X22: 攻击下限 | Y22: 2 | Z22: 攻击上限 | AA22: 2
A23: 21 | B23: 7 | C23: 思贝套 | D23: {=INDEX(编号表!$A:$A,MATCH(E23,编号表!$B:$B,0))} -> 50506203 | E23: 黑铁头盔 | F23: 6 | G23: {=INDEX(编号表!$A:$A,MATCH(H23,编号表!$B:$B,0))} -> 50502403 | H23: 思贝儿手镯 | I23: 6 | V23: 生命值 | W23: 30 | X23: 攻击下限 | Y23: 3 | Z23: 攻击上限 | AA23: 3
A24: 22 | B24: 8 | C24: 三眼套 | D24: {=INDEX(编号表!$A:$A,MATCH(E24,编号表!$B:$B,0))} -> 50503204 | E24: 黄石戒指 | F24: 2 | G24: {=INDEX(编号表!$A:$A,MATCH(H24,编号表!$B:$B,0))} -> 50502402 | H24: 三眼手镯 | I24: 2 | V24: 生命值 | W24: 10 | X24: 攻击下限 | Y24: 1 | Z24: 攻击上限 | AA24: 1
A25: 23 | B25: 8 | C25: 三眼套 | D25: {=INDEX(编号表!$A:$A,MATCH(E25,编号表!$B:$B,0))} -> 50503204 | E25: 黄石戒指 | F25: 4 | G25: {=INDEX(编号表!$A:$A,MATCH(H25,编号表!$B:$B,0))} -> 50502402 | H25: 三眼手镯 | I25: 4 | V25: 生命值 | W25: 20 | X25: 攻击下限 | Y25: 2 | Z25: 攻击上限 | AA25: 2
A26: 24 | B26: 8 | C26: 三眼套 | D26: {=INDEX(编号表!$A:$A,MATCH(E26,编号表!$B:$B,0))} -> 50503204 | E26: 黄石戒指 | F26: 6 | G26: {=INDEX(编号表!$A:$A,MATCH(H26,编号表!$B:$B,0))} -> 50502402 | H26: 三眼手镯 | I26: 6 | V26: 生命值 | W26: 30 | X26: 攻击下限 | Y26: 3 | Z26: 攻击上限 | AA26: 3
A27: 25 | B27: 9 | C27: 修罗套 | D27: {=INDEX(编号表!$A:$A,MATCH(E27,编号表!$B:$B,0))} -> 50500402 | E27: 修罗 | F27: 2 | G27: {=INDEX(编号表!$A:$A,MATCH(H27,编号表!$B:$B,0))} -> 50505404 | H27: 苍山衣服 | I27: 2 | J27: {=INDEX(编号表!$A:$A,MATCH(K27,编号表!$B:$B,0))} -> 50505405 | K27: 翠林衣服 | L27: 2 | V27: 生命值 | W27: 10 | X27: 攻击下限 | Y27: 1 | Z27: 攻击上限 | AA27: 1
A28: 26 | B28: 9 | C28: 修罗套 | D28: {=INDEX(编号表!$A:$A,MATCH(E28,编号表!$B:$B,0))} -> 50500402 | E28: 修罗 | F28: 4 | G28: {=INDEX(编号表!$A:$A,MATCH(H28,编号表!$B:$B,0))} -> 50505404 | H28: 苍山衣服 | I28: 4 | J28: {=INDEX(编号表!$A:$A,MATCH(K28,编号表!$B:$B,0))} -> 50505405 | K28: 翠林衣服 | L28: 4 | V28: 生命值 | W28: 20 | X28: 攻击下限 | Y28: 2 | Z28: 攻击上限 | AA28: 2
A29: 27 | B29: 9 | C29: 修罗套 | D29: {=INDEX(编号表!$A:$A,MATCH(E29,编号表!$B:$B,0))} -> 50500402 | E29: 修罗 | F29: 6 | G29: {=INDEX(编号表!$A:$A,MATCH(H29,编号表!$B:$B,0))} -> 50505404 | H29: 苍山衣服 | I29: 6 | J29: {=INDEX(编号表!$A:$A,MATCH(K29,编号表!$B:$B,0))} -> 50505405 | K29: 翠林衣服 | L29: 6 | V29: 生命值 | W29: 30 | X29: 攻击下限 | Y29: 3 | Z29: 攻击上限 | AA29: 3
A30: 28 | B30: 10 | C30: 魔杖套 | D30: {=INDEX(编号表!$A:$A,MATCH(E30,编号表!$B:$B,0))} -> 50500401 | E30: 魔杖 | F30: 2 | G30: {=INDEX(编号表!$A:$A,MATCH(H30,编号表!$B:$B,0))} -> 50505403 | H30: 青云衣服 | I30: 2 | J30: {=INDEX(编号表!$A:$A,MATCH(K30,编号表!$B:$B,0))} -> 50505402 | K30: 碧溪衣服 | L30: 2 | V30: 生命值 | W30: 10 | X30: 攻击下限 | Y30: 1 | Z30: 攻击上限 | AA30: 1
A31: 29 | B31: 10 | C31: 魔杖套 | D31: {=INDEX(编号表!$A:$A,MATCH(E31,编号表!$B:$B,0))} -> 50500401 | E31: 魔杖 | F31: 4 | G31: {=INDEX(编号表!$A:$A,MATCH(H31,编号表!$B:$B,0))} -> 50505403 | H31: 青云衣服 | I31: 4 | J31: {=INDEX(编号表!$A:$A,MATCH(K31,编号表!$B:$B,0))} -> 50505402 | K31: 碧溪衣服 | L31: 4 | V31: 生命值 | W31: 20 | X31: 攻击下限 | Y31: 2 | Z31: 攻击上限 | AA31: 2
A32: 30 | B32: 10 | C32: 魔杖套 | D32: {=INDEX(编号表!$A:$A,MATCH(E32,编号表!$B:$B,0))} -> 50500401 | E32: 魔杖 | F32: 6 | G32: {=INDEX(编号表!$A:$A,MATCH(H32,编号表!$B:$B,0))} -> 50505403 | H32: 青云衣服 | I32: 6 | J32: {=INDEX(编号表!$A:$A,MATCH(K32,编号表!$B:$B,0))} -> 50505402 | K32: 碧溪衣服 | L32: 6 | V32: 生命值 | W32: 30 | X32: 攻击下限 | Y32: 3 | Z32: 攻击上限 | AA32: 3
A33: 31 | B33: 11 | C33: 银蛇套 | D33: {=INDEX(编号表!$A:$A,MATCH(E33,编号表!$B:$B,0))} -> 50500400 | E33: 银蛇 | F33: 2 | G33: {=INDEX(编号表!$A:$A,MATCH(H33,编号表!$B:$B,0))} -> 50505401 | H33: 丹霞衣服 | I33: 2 | J33: {=INDEX(编号表!$A:$A,MATCH(K33,编号表!$B:$B,0))} -> 50505400 | K33: 赤霞衣服 | L33: 2 | V33: 生命值 | W33: 10 | X33: 攻击下限 | Y33: 1 | Z33: 攻击上限 | AA33: 1
A34: 32 | B34: 11 | C34: 银蛇套 | D34: {=INDEX(编号表!$A:$A,MATCH(E34,编号表!$B:$B,0))} -> 50500400 | E34: 银蛇 | F34: 4 | G34: {=INDEX(编号表!$A:$A,MATCH(H34,编号表!$B:$B,0))} -> 50505401 | H34: 丹霞衣服 | I34: 4 | J34: {=INDEX(编号表!$A:$A,MATCH(K34,编号表!$B:$B,0))} -> 50505400 | K34: 赤霞衣服 | L34: 4 | V34: 生命值 | W34: 20 | X34: 攻击下限 | Y34: 2 | Z34: 攻击上限 | AA34: 2
A35: 33 | B35: 11 | C35: 银蛇套 | D35: {=INDEX(编号表!$A:$A,MATCH(E35,编号表!$B:$B,0))} -> 50500400 | E35: 银蛇 | F35: 6 | G35: {=INDEX(编号表!$A:$A,MATCH(H35,编号表!$B:$B,0))} -> 50505401 | H35: 丹霞衣服 | I35: 6 | J35: {=INDEX(编号表!$A:$A,MATCH(K35,编号表!$B:$B,0))} -> 50505400 | K35: 赤霞衣服 | L35: 6 | V35: 生命值 | W35: 30 | X35: 攻击下限 | Y35: 3 | Z35: 攻击上限 | AA35: 3
A36: 34 | B36: 12 | C36: 奔雷勋章套（战） | D36: {=INDEX(编号表!$A:$A,MATCH(E36,编号表!$B:$B,0))} -> 50508402 | E36: 奔雷战靴 | F36: 2 | G36: {=INDEX(编号表!$A:$A,MATCH(H36,编号表!$B:$B,0))} -> 50507402 | H36: 奔雷腰带 | I36: 2 | J36: {=INDEX(编号表!$A:$A,MATCH(K36,编号表!$B:$B,0))} -> 50506402 | K36: 奔雷头盔 | L36: 2 | V36: 生命值 | W36: 10 | X36: 攻击下限 | Y36: 1 | Z36: 攻击上限 | AA36: 1
A37: 35 | B37: 12 | C37: 奔雷勋章套（战） | D37: {=INDEX(编号表!$A:$A,MATCH(E37,编号表!$B:$B,0))} -> 50508402 | E37: 奔雷战靴 | F37: 4 | G37: {=INDEX(编号表!$A:$A,MATCH(H37,编号表!$B:$B,0))} -> 50507402 | H37: 奔雷腰带 | I37: 4 | J37: {=INDEX(编号表!$A:$A,MATCH(K37,编号表!$B:$B,0))} -> 50506402 | K37: 奔雷头盔 | L37: 4 | V37: 生命值 | W37: 20 | X37: 攻击下限 | Y37: 2 | Z37: 攻击上限 | AA37: 2
A38: 36 | B38: 12 | C38: 奔雷勋章套（战） | D38: {=INDEX(编号表!$A:$A,MATCH(E38,编号表!$B:$B,0))} -> 50508402 | E38: 奔雷战靴 | F38: 6 | G38: {=INDEX(编号表!$A:$A,MATCH(H38,编号表!$B:$B,0))} -> 50507402 | H38: 奔雷腰带 | I38: 6 | J38: {=INDEX(编号表!$A:$A,MATCH(K38,编号表!$B:$B,0))} -> 50506402 | K38: 奔雷头盔 | L38: 6 | V38: 生命值 | W38: 30 | X38: 攻击下限 | Y38: 3 | Z38: 攻击上限 | AA38: 3
... A44: 42 | B44: 14 | C44: 极光勋章套（道） | D44: {=INDEX(编号表!$A:$A,MATCH(E44,编号表!$B:$B,0))} -> 50508400 | E44: 极光道靴 | F44: 6 | G44: {=INDEX(编号表!$A:$A,MATCH(H44,编号表!$B:$B,0))} -> 50507400 | H44: 极光腰带 | I44: 6 | J44: {=INDEX(编号表!$A:$A,MATCH(K44,编号表!$B:$B,0))} -> 50506401 | K44: 极光头盔 | L44: 6 | V44: 生命值 | W44: 30 | X44: 攻击下限 | Y44: 3 | Z44: 攻击上限 | AA44: 3
A45: 43 | B45: 15 | C45: 蓝晶套 | D45: {=INDEX(编号表!$A:$A,MATCH(E45,编号表!$B:$B,0))} -> 51003404 | E45: 蓝色水晶戒指 | F45: 2 | G45: {=INDEX(编号表!$A:$A,MATCH(H45,编号表!$B:$B,0))} -> 51002402 | H45: 夏普儿手镯 | I45: 2 | V45: 生命值 | W45: 10 | X45: 攻击下限 | Y45: 1 | Z45: 攻击上限 | AA45: 1
...

Sheet 编号表
A1: 装备ID | B1: 名称
A2: ID | B2: Name
A3: 50000100 | B3: 木剑
A4: 50000101 | B4: 乌木剑 | E4: 装备表每次有更新，都必须对应更新这个表格，粘贴数值！！！
A5: 50000102 | B5: 鹤嘴锄
A6: 50000103 | B6: 矿铲
A7: 50000104 | B7: 青铜剑
A8: 50000105 | B8: 匕首
A9: 50001100 | B9: 金项链
A10: 50001101 | B10: 传统项链
A11: 50001102 | B11: 初级项链
A12: 50001103 | B12: 原始项链
A13: 50001104 | B13: 生铁项链
A14: 50001105 | B14: 花朵项链
A15: 50002100 | B15: 铁手镯
A16: 50002101 | B16: 小手镯
... A896: 52521600 | B896: 亡灵战马
