Workbook
Name 技能类型: [1]名称表!#REF!
Name 距离类型: [1]名称表!#REF!
Name 范围类型: [2]名称表!#REF!
Name 特效绑定位置: [2]名称表!#REF!

Sheet skill_config
A1: ##var | B1: id | C1: name | D1: internal_name | E1: skill_branch | F1: is_invoked | G1: skill_type | H1: skill_level | I1: identify_id | J1: skill_class | K1: color | L1: next_level_id | M1: required_skill_id | N1: description | O1: icon_id | P1: consumable_id | Q1: lingli_cost | R1: required_level | S1: exp_to_next | T1: exp_item_id | U1: effect_rate | V1: cast_distance | W1: acquire_range | X1: target_type | Y1: range_type | Z1: cast_range | AA1: side_length | AB1: facing_offset | AC1: dist_offset | AD1: sub_range_type | AE1: sub_range_radius | AF1: sub_range_angle | AG1: sub_range_facing | AH1: max_friendly | AI1: max_target | AJ1: damage_type | AK1: lingli_cost_2 | AL1: base_power | AM1: effect1_target | AN1: effect1_type | AO1: effect1_value | AP1: effect1_rate | AQ1: effect2_target | AR1: effect2_type | AS1: effect2_value | AT1: effect2_rate | AU1: effect3_target | AV1: effect3_type | AW1: effect3_value | AX1: effect3_rate | AY1: cast_time | AZ1: recovery_time | BA1: cast_action | BB1: cast_effect | BC1: projectile_effect | BD1: cast_point_effect | BE1: hurt_effect | BF1: stop_move | BG1: cooldown | BH1: cooldown_reduction_disabled | BI1: skill_delay | BJ1: hit_stun | BK1: cast_sound_id | BL1: hit_sound_id | BM1: passive_trigger | BN1: passive_skill_id | BO1: passive_icd | BP1: projectile_speed | BQ1: projectile_height | BR1: projectile_scale | BS1: displace_distance | BT1: displace_mode | BU1: summon_id | BV1: summon_duration | BW1: summon_count | BX1: summon_max | BY1: summon_init_level | BZ1: summon_max_level | CA1: summon_tao_rate | CB1: summon_def_rate | CC1: summon_hp_rate | CD1: summon_exp_rate
A2: ##type | B2: int | C2: string | D2: string | E2: string | F2: bool | G2: string | H2: int | I2: string | J2: string | K2: string | L2: int | M2: int | N2: string | O2: int | P2: int | Q2: int | R2: int | S2: int | T2: int | U2: int | V2: int | W2: int | X2: string | Y2: string | Z2: int | AA2: int | AB2: int | AC2: int | AD2: string | AE2: int | AF2: int | AG2: int | AH2: int | AI2: int | AJ2: string | AK2: int | AL2: int | AM2: string | AN2: string | AO2: int | AP2: int | AQ2: string | AR2: string | AS2: int | AT2: int | AU2: string | AV2: string | AW2: int | AX2: int | AY2: int | AZ2: int | BA2: string | BB2: string | BC2: string | BD2: string | BE2: string | BF2: bool | BG2: int | BH2: bool | BI2: int | BJ2: int | BK2: int | BL2: int | BM2: string | BN2: int | BO2: int | BP2: int | BQ2: int | BR2: float | BS2: int | BT2: string | BU2: int | BV2: int | BW2: int | BX2: int | BY2: int | BZ2: int | CA2: int | CB2: int | CC2: int | CD2: int
A3: ##group
A4: ## | B4: 技能ID | C4: 技能显示名称 | D4: 内部名称 | E4: 技能系别 | F4: 是否为被调用技能 | G4: 技能主被动类型 | H4: 技能等级 | I4: 技能识别ID | J4: 技能分类 | K4: 颜色标签 | L4: 下一级技能ID | M4: 前置技能ID | N4: 技能描述文本 | O4: 技能图标ID | P4: 施法消耗道具ID | Q4: 灵力消耗 | R4: 学习技能所需等级 | S4: 熟练度上限 | T4: 提升熟练度道具ID | U4: 技能触发概率 | V4: 施法距离 | W4: 选怪半径 | X4: 施法目标类型 | Y4: 效果范围类型 | Z4: 技能范围:半径或宽度 | AA4: 技能范围:角度或长度 | AB4: 范围面向角偏移 | AC4: 施法点偏移距离 | AD4: 子范围形状类型（复用 RangeType 枚举值），null = 无子范围 | AE4: 子范围半径，null = 继承主范围 CastRange | AF4: 子范围角度（仅扇形时有效），null = 继承主范围 SideLength | AG4: 子范围朝向 | AH4: 最大友方作用个数 | AI4: 最大敌方作用个数 | AJ4: 伤害类型 | AK4: 灵力消耗 | AL4: 技能威力基础值 | AM4: 效果1目标类型 | AN4: 效果1类型 | AO4: 效果1值 | AP4: 效果1触发概率 | AQ4: 效果2目标类型 | AR4: 效果2类型 | AS4: 效果2值 | AT4: 效果2触发概率 | AU4: 效果3目标类型 | AV4: 效果3类型 | AW4: 效果3值 | AX4: 效果3触发概率 | AY4: 前摇帧数 | AZ4: 后摇帧数 | BA4: 施法动作名称 | BB4: 施法特效路径 | BC4: 弹道特效 | BD4: 施法点特效路径 | BE4: 怪物受击特效路径 | BF4: 是否停止移动 | BG4: 冷却时间(秒) | BH4: 禁止冷却缩减 | BI4: 技能效果延迟(毫秒) | BJ4: 受击硬直时间(毫秒) | BK4: 施法音效ID | BL4: 受击音效ID | BM4: 被动触发事件类型 | BN4: 被动触发条件技能ID | BO4: 被动内置冷却(毫秒) | BP4: 弹道速度 | BQ4: 弹道高度 | BR4: 弹道模型缩放 | BS4: 位移距离 | BT4: 位移模式 | BU4: 召唤单位ID | BV4: 召唤持续时间 | BW4: 召唤数量 | BX4: 同类上限 | BY4: 初始等级 | BZ4: 等级上限 | CA4: 道术继承比例（万分比） | CB4: 防御继承比例（万分比） | CC4: 生命值继承比例（万分比） | CD4: 经验获取比例（万分比）
A5: {=10000000+INDEX(编号表!A:A,MATCH(B3,编号表!XFD:XFD,0))*10000+F3} -> #N/A | C5: 基础剑术 | D5: 基础剑术 | E5: 剑修 | F5: 否 | G5: 主动 | H5: 1 | I5: =LEFT(A3,6) -> ##grou | J5: 英雄技能 | K5: 绿色 | L5: 10010002 | N5: |cff00FF00是所有剑术的基础，习得后获得大量准确，并提升极少量伤害。 | O5: 10010001 | P5: 0 | Q5: 0 | R5: 1 | S5: 100 | T5: 34020001 | U5: 10000 | V5: 150 | W5: 150 | X5: 施法目标_目标点 | Y5: 范围类型_所选目标 | AB5: 0 | AC5: 0 | AH5: 1 | AI5: 1 | AJ5: 物理 | AK5: 0 | AL5: 10000 | AM5: 效果目标_范围内的敌对 | AN5: 技能效果_附带伤害 | AO5: 3 | AP5: 10000 | AY5: 10 | AZ5: 20 | BA5: Attack One | BB5: ain_effect_jinengtexiao_01 | BF5: 是 | BH5: 否 | BK5: Zs_Gongji1 | BN5: 0 | BO5: 0
A6: {=10000000+INDEX(编号表!A:A,MATCH(B4,编号表!XFD:XFD,0))*10000+F4} -> #N/A | C6: 基础剑术 | D6: 基础剑术 | E6: 剑修 | F6: 否 | G6: 主动 | H6: 2 | I6: =LEFT(A4,6) -> ## | J6: 英雄技能 | K6: 绿色 | L6: 10010003 | M6: 10010001 | N6: |cff00FF00是所有剑术的基础，习得后获得大量准确，并提升极少量伤害。 | O6: 10010001 | P6: 0 | Q6: 1 | R6: 7 | S6: 200 | T6: 34020001 | U6: 10000 | V6: 150 | W6: 150 | X6: 施法目标_目标点 | Y6: 范围类型_所选目标 | AB6: 0 | AC6: 0 | AH6: 1 | AI6: 1 | AJ6: 物理 | AK6: 1 | AL6: 10400 | AM6: 效果目标_范围内的敌对 | AN6: 技能效果_附带伤害 | AO6: 4 | AP6: 10000 | AY6: 10 | AZ6: 20 | BA6: Attack One | BB6: ain_effect_jinengtexiao_01 | BF6: 是 | BH6: 否 | BK6: Zs_Gongji1 | BN6: 0 | BO6: 0
A7: {=10000000+INDEX(编号表!A:A,MATCH(B5,编号表!XFD:XFD,0))*10000+F5} -> #N/A | C7: 基础剑术 | D7: 基础剑术 | E7: 剑修 | F7: 否 | G7: 主动 | H7: 3 | I7: =LEFT(A5,6) -> #N/A | J7: 英雄技能 | K7: 绿色 | L7: 10010004 | M7: 10010002 | N7: |cff00FF00是所有剑术的基础，习得后获得大量准确，并提升极少量伤害。 | O7: 10010001 | P7: 0 | Q7: 2 | R7: 11 | S7: 300 | T7: 34020001 | U7: 10000 | V7: 150 | W7: 150 | X7: 施法目标_目标点 | Y7: 范围类型_所选目标 | AB7: 0 | AC7: 0 | AH7: 1 | AI7: 1 | AJ7: 物理 | AK7: 2 | AL7: 10800 | AM7: 效果目标_范围内的敌对 | AN7: 技能效果_附带伤害 | AO7: 5 | AP7: 10000 | AY7: 10 | AZ7: 20 | BA7: Attack One | BB7: ain_effect_jinengtexiao_01 | BF7: 是 | BH7: 否 | BK7: Zs_Gongji1 | BN7: 0 | BO7: 0
A8: {=10000000+INDEX(编号表!A:A,MATCH(B6,编号表!XFD:XFD,0))*10000+F6} -> #N/A | C8: 基础剑术 | D8: 基础剑术 | E8: 剑修 | F8: 否 | G8: 主动 | H8: 4 | I8: =LEFT(A6,6) -> #N/A | J8: 英雄技能 | K8: 绿色 | L8: 10010005 | M8: 10010003 | N8: |cff00FF00是所有剑术的基础，习得后获得大量准确，并提升极少量伤害。 | O8: 10010001 | P8: 0 | Q8: 3 | R8: 16 | T8: 34020001 | U8: 10000 | V8: 150 | W8: 150 | X8: 施法目标_目标点 | Y8: 范围类型_所选目标 | AB8: 0 | AC8: 0 | AH8: 1 | AI8: 1 | AJ8: 物理 | AK8: 3 | AL8: 11200 | AM8: 效果目标_范围内的敌对 | AN8: 技能效果_附带伤害 | AO8: 6 | AP8: 10000 | AY8: 10 | AZ8: 20 | BA8: Attack One | BB8: ain_effect_jinengtexiao_01 | BF8: 是 | BH8: 否 | BK8: Zs_Gongji1 | BN8: 0 | BO8: 0
A9: {=10000000+INDEX(编号表!A:A,MATCH(B7,编号表!XFD:XFD,0))*10000+F7} -> #N/A | C9: 基础剑术 | D9: 基础剑术 | E9: 剑修 | F9: 否 | G9: 主动 | H9: 5 | I9: =LEFT(A7,6) -> #N/A | J9: 英雄技能 | K9: 绿色 | L9: 10010006 | M9: 10010004 | N9: |cff00FF00是所有剑术的基础，习得后获得大量准确，并提升极少量伤害。 | O9: 10010001 | P9: 0 | Q9: 3 | R9: 25 | T9: 34020001 | U9: 10000 | V9: 150 | W9: 150 | X9: 施法目标_目标点 | Y9: 范围类型_所选目标 | AB9: 0 | AC9: 0 | AH9: 1 | AI9: 1 | AJ9: 物理 | AK9: 3 | AL9: 11300 | AM9: 效果目标_范围内的敌对 | AN9: 技能效果_附带伤害 | AO9: 6 | AP9: 10000 | AY9: 10 | AZ9: 20 | BA9: Attack One | BB9: ain_effect_jinengtexiao_01 | BF9: 是 | BH9: 否 | BK9: Zs_Gongji1 | BN9: 0 | BO9: 0
A10: {=10000000+INDEX(编号表!A:A,MATCH(B8,编号表!XFD:XFD,0))*10000+F8} -> #N/A | C10: 基础剑术 | D10: 基础剑术 | E10: 剑修 | F10: 否 | G10: 主动 | H10: 6 | I10: =LEFT(A8,6) -> #N/A | J10: 英雄技能 | K10: 绿色 | L10: 10010007 | M10: 10010005 | N10: |cff00FF00是所有剑术的基础，习得后获得大量准确，并提升极少量伤害。 | O10: 10010001 | P10: 0 | Q10: 3 | R10: 30 | T10: 34020001 | U10: 10000 | V10: 150 | W10: 150 | X10: 施法目标_目标点 | Y10: 范围类型_所选目标 | AB10: 0 | AC10: 0 | AH10: 1 | AI10: 1 | AJ10: 物理 | AK10: 3 | AL10: 11600 | AM10: 效果目标_范围内的敌对 | AN10: 技能效果_附带伤害 | AO10: 7 | AP10: 10000 | AY10: 10 | AZ10: 20 | BA10: Attack One | BB10: ain_effect_jinengtexiao_01 | BF10: 是 | BH10: 否 | BK10: Zs_Gongji1 | BN10: 0 | BO10: 0
C11: 基础剑术 | D11: 基础剑术 | E11: 剑修 | F11: 否 | G11: 主动 | H11: 7 | I11: =LEFT(A9,6) -> #N/A | J11: 英雄技能 | K11: 绿色 | L11: 10010008 | M11: 10010006 | N11: |cff00FF00是所有剑术的基础，习得后获得大量准确，并提升极少量伤害。 | O11: 10010001 | P11: 0 | Q11: 3 | R11: 35 | T11: 34020001 | U11: 10000 | V11: 150 | W11: 150 | X11: 施法目标_目标点 | Y11: 范围类型_所选目标 | AB11: 0 | AC11: 0 | AH11: 1 | AI11: 1 | AJ11: 物理 | AK11: 3 | AL11: 11700 | AM11: 效果目标_范围内的敌对 | AN11: 技能效果_附带伤害 | AO11: 7 | AP11: 10000 | AY11: 10 | AZ11: 20 | BA11: Attack One | BB11: ain_effect_jinengtexiao_01 | BF11: 是 | BH11: 否 | BK11: Zs_Gongji1 | BN11: 0 | BO11: 0
C12: 基础剑术 | D12: 基础剑术 | E12: 剑修 | F12: 否 | G12: 主动 | H12: 8 | I12: =LEFT(A10,6) -> #N/A | J12: 英雄技能 | K12: 绿色 | L12: 10010009 | M12: 10010007 | N12: |cff00FF00是所有剑术的基础，习得后获得大量准确，并提升极少量伤害。 | O12: 10010001 | P12: 0 | Q12: 3 | R12: 40 | T12: 34020001 | U12: 10000 | V12: 150 | W12: 150 | X12: 施法目标_目标点 | Y12: 范围类型_所选目标 | AB12: 0 | AC12: 0 | AH12: 1 | AI12: 1 | AJ12: 物理 | AK12: 3 | AL12: 11800 | AM12: 效果目标_范围内的敌对 | AN12: 技能效果_附带伤害 | AO12: 7 | AP12: 10000 | AY12: 10 | AZ12: 20 | BA12: Attack One | BB12: ain_effect_jinengtexiao_01 | BF12: 是 | BH12: 否 | BK12: Zs_Gongji1 | BN12: 0 | BO12: 0

Sheet buff_config
A1: ##var | B1: id | C1: icon_name | D1: name | E1: target_type | F1: range_type | G1: cast_range | H1: side_length | I1: facing_offset | J1: dist_offset | K1: level | L1: description | M1: identify_id | N1: show_time | O1: time_override | P1: pile_type | Q1: pile_max | R1: duration | S1: interval | T1: display_position | U1: icon_id | V1: effect_path | W1: binding_position | X1: category | Y1: dispel_level | Z1: effect1_type | AA1: effect1_value | AB1: effect1_target | AC1: effect1_rate | AD1: effect2_type | AE1: effect2_value | AF1: effect2_target | AG1: effect2_rate | AH1: effect3_type | AI1: effect3_value | AJ1: effect3_target | AK1: effect3_rate | AL1: effect4_type | AM1: effect4_value | AN1: effect4_target | AO1: effect4_rate
A2: ##type | B2: int | C2: string | D2: string | E2: string | F2: string | G2: int | H2: int | I2: int | J2: int | K2: int | L2: string | M2: string | N2: bool | O2: string | P2: string | Q2: int | R2: int | S2: int | T2: string | U2: int | V2: string | W2: string | X2: string | Y2: int | Z2: string | AA2: int | AB2: string | AC2: int | AD2: string | AE2: int | AF2: string | AG2: int | AH2: string | AI2: int | AJ2: string | AK2: int | AL2: string | AM2: int | AN2: string | AO2: int
A3: ##group
A4: ## | B4: 状态ID | C4: 状态图标资源名称 | D4: 状态显示名称 | E4: 状态适用目标类型 | F4: 环境状态范围类型 | G4: 范围半径或宽度 | H4: 扇形角度或长度 | I4: 范围面向角偏移 | J4: 施法点偏移距离 | K4: 状态等级 | L4: 状态描述文本 | M4: 识别ID | N4: 显示剩余时间 | O4: 时间覆盖类型 | P4: 层数叠加类型 | Q4: 最大叠加层数 | R4: 持续时间(毫秒) | S4: 作用间隔(毫秒) | T4: 图标显示位置 | U4: 状态图标ID | V4: 状态特效路径 | W4: 特效绑定位置 | X4: Buff分类 | Y4: 驱散级别 | Z4: 效果1类型 | AA4: 效果1值 | AB4: 效果1对象 | AC4: 效果1概率 | AD4: 效果2类型 | AE4: 效果2值 | AF4: 效果2对象 | AG4: 效果2概率 | AH4: 效果3类型 | AI4: 效果3值 | AJ4: 效果3对象 | AK4: 效果3概率 | AL4: 效果4类型 | AM4: 效果4值 | AN4: 效果4对象 | AO4: 效果4概率
B5: =21000000+VLOOKUP(C3,编号表!$E:$F,2,FALSE)*100+J3 -> #N/A | C5: 眩晕 | D5: 眩晕 | E5: 角色状态 | K5: 1 | L5: 眩晕(无法行动)2秒 | M5: =LEFT(A3,6) -> ##grou | N5: 是 | O5: 覆盖 | P5: 不变 | Q5: 1 | R5: 2000 | S5: 0 | X5: 减益 | Z5: 状态效果_硬控|眩晕 | AB5: 状态对象_敌对 | AC5: 10000
B6: =21000000+VLOOKUP(C4,编号表!$E:$F,2,FALSE)*100+J4 -> #N/A | C6: 石化 | D6: 石化 | E6: 角色状态 | K6: 1 | L6: 石化(无法行动)2秒 | M6: =LEFT(A4,6) -> ## | N6: 是 | O6: 覆盖 | P6: 不变 | Q6: 1 | R6: 2000 | S6: 0 | X6: 减益 | Z6: 状态效果_硬控|石化 | AB6: 状态对象_敌对 | AC6: 10000
B7: =21000000+VLOOKUP(C5,编号表!$E:$F,2,FALSE)*100+J5 -> 21000300 | C7: 冰冻 | D7: 冰冻 | E7: 角色状态 | K7: 1 | L7: 目标被冰冻定身 | M7: =LEFT(A5,6) | N7: 是 | O7: 覆盖 | P7: 不变 | Q7: 1 | R7: 2000 | X7: 减益 | Z7: 状态效果_硬控|冰冻 | AB7: 状态对象_敌对 | AC7: 10000
B8: =21000000+VLOOKUP(C6,编号表!$E:$F,2,FALSE)*100+J6 -> 21000400 | C8: 虚弱 | D8: 虚弱 | E8: 角色状态 | K8: 1 | L8: 敌方伤害减免减20%，持续10秒 | M8: =LEFT(A6,6) | N8: 是 | O8: 覆盖 | P8: 不变 | Q8: 1 | R8: 10000 | S8: 0 | X8: 减益 | Z8: 状态效果_属性修正|伤害减免增幅 | AA8: -2000 | AB8: 状态对象_敌对 | AC8: 10000
B9: =21000000+VLOOKUP(C7,编号表!$E:$F,2,FALSE)*100+J7 -> 21000600 | C9: 中毒 | D9: 中毒 | E9: 角色状态 | K9: 1 | L9: 中毒状态，持续减少血量 | M9: =LEFT(A7,6) | N9: 是 | O9: 覆盖 | P9: 不变 | Q9: 1 | R9: 12000 | S9: 3000 | V9: ain_effect_jinengtexiao_22 | W9: origin | X9: 减益 | Z9: 状态效果_DOT伤害|道术 | AA9: 2200 | AB9: 状态对象_敌对 | AC9: 10000 | AD9: 状态效果_DOT伤害|道术整数 | AE9: 2 | AF9: 状态对象_敌对 | AG9: 10000
B10: =21000000+VLOOKUP(C8,编号表!$E:$F,2,FALSE)*100+J8 -> 21001000 | C10: 中毒 | D10: 中毒 | E10: 角色状态 | K10: 2 | L10: 中毒状态，持续减少血量 | M10: =LEFT(A8,6) | N10: 是 | O10: 覆盖 | P10: 不变 | Q10: 1 | R10: 12000 | S10: 3000 | V10: ain_effect_jinengtexiao_22 | W10: origin | X10: 减益 | Z10: 状态效果_DOT伤害|道术 | AA10: 2600 | AB10: 状态对象_敌对 | AC10: 10000 | AD10: 状态效果_DOT伤害|道术整数 | AE10: 3 | AF10: 状态对象_敌对 | AG10: 10000
B11: =21000000+VLOOKUP(C9,编号表!$E:$F,2,FALSE)*100+J9 -> 21000200 | C11: 中毒 | D11: 中毒 | E11: 角色状态 | K11: 3 | L11: 中毒状态，持续减少血量 | M11: =LEFT(A9,6) | N11: 是 | O11: 覆盖 | P11: 不变 | Q11: 1 | R11: 12000 | S11: 3000 | V11: ain_effect_jinengtexiao_22 | W11: origin | X11: 减益 | Z11: 状态效果_DOT伤害|道术 | AA11: 3000 | AB11: 状态对象_敌对 | AC11: 10000 | AD11: 状态效果_DOT伤害|道术整数 | AE11: 4 | AF11: 状态对象_敌对 | AG11: 10000
B12: =21000000+VLOOKUP(C10,编号表!$E:$F,2,FALSE)*100+J10 -> 21000200 | C12: 中毒 | D12: 中毒 | E12: 角色状态 | K12: 4 | L12: 中毒状态，持续减少血量 | M12: =LEFT(A10,6) | N12: 是 | O12: 覆盖 | P12: 不变 | Q12: 1 | R12: 12000 | S12: 3000 | V12: ain_effect_jinengtexiao_22 | W12: origin | X12: 减益 | Z12: 状态效果_DOT伤害|道术 | AA12: 3600 | AB12: 状态对象_敌对 | AC12: 10000 | AD12: 状态效果_DOT伤害|道术整数 | AE12: 6 | AF12: 状态对象_敌对 | AG12: 10000

Sheet 编号表
A1: 技能内部名 | B1: 内部名编号 | E1: 状态内部名 | F1: 编号
A2: 基础剑术 | B2: 1 | E2: 封印 | F2: 1
A3: 攻杀剑术 | B3: 2 | E3: 中毒 | F3: 2
A4: 刺杀剑术 | B4: 3 | E4: 眩晕 | F4: 3
A5: 半月弯刀 | B5: 4 | E5: 石化 | F5: 4
A6: 野蛮冲撞 | B6: 5 | E6: 免控 | F6: 5
A7: 烈火剑法 | B7: 6 | E7: 冰冻 | F7: 6
A8: 狮子吼​ | B8: 7 | E8: 增加怒气 | F8: 7
A9: 开天斩​ | B9: 8 | E9: 闪避 | F9: 8
A10: 逐日剑法​ | B10: 9 | E10: 减伤 | F10: 9
A11: 刺杀调用1 | B11: 10 | E11: 虚弱 | F11: 10
A12: 刺杀调用2 | B12: 11 | E12: 易伤 | F12: 11
A13: 半月调用1 | B13: 12 | E13: 火墙 | F13: 12
... A19: 刺杀调用2 | B19: 18 | E19: 蓝药 | F19: 18
B20: 19 | E20: 魔法盾 | F20: 19
B21: 20 | E21: 治愈术 | F21: 20
B22: 21 | E22: DOT | F22: 21
B23: 22 | E23: 隐身术 | F23: 22
B24: 23 | E24: 流血状态 | F24: 23
B25: 24 | E25: 强攻状态 | F25: 24
B26: 25 | E26: 迅捷状态 | F26: 25
B27: 26 | E27: 加攻速状态 | F27: 26
B28: 27 | E28: 双防增加状态 | F28: 27
B29: 28 | E29: 双防减少状态 | F29: 28
B30: 29 | E30: 暴击状态 | F30: 29
B31: 30 | E31: 召唤大雷电术 | F31: 30
A32: 火球术 | B32: 31 | E32: 元素削弱状态 | F32: 31
A33: 抗拒火环 | B33: 32 | E33: 加施法状态 | F33: 32
A34: 雷电术 | B34: 33 | E34: 麻痹状态 | F34: 33
A35: 火墙 | B35: 34 | F35: 34
A36: 疾光电影 | B36: 35 | E36: 毒伤状态 | F36: 35
A37: 魔法盾 | B37: 36 | E37: 加道术 | F37: 36
A38: 冰咆哮 | B38: 37 | E38: 瞬加药 | F38: 37
B39: 38 | F39: 38
B40: 39
B41: 40
B42: 41
B43: 42
A44: 火球术调用 | B44: 43
A45: 灵魂火符调用 | B45: 44
...

Sheet 名称表
A1: 施法目标 | C1: 范围类型 | F1: 效果目标 | H1: 特效绑定位置 | J1: 技能效果 | K1: 数据类型 | L1: 介绍 | M1: 状态效果 | N1: 数据类型 | O1: 介绍
A2: 施法目标_自身 | C2: 范围类型_所选目标 | D2: 单体 | F2: 效果目标_所选 | G2: 筛选的所有目标 | H2: BindingPosition | J2: 技能效果_技能增伤 | M2: 状态效果_眩晕 | N2: 不配数据 | O2: 引擎内置（BuffModuleswitch-case，War3未使用（持续时间走配置）
A3: 施法目标_敌对 | C3: 范围类型_目标圆形范围 | D3: 圆形范围 | F3: 效果目标_自身 | G3: 无视筛选，对自身施放 | H3: 脚底 | I3: origin | J3: 技能效果_忽视防御 | K3: 万分比 | M3: 状态效果_石化 | N3: 不配数据 | O3: 引擎内置（同上）未使用
A4: 施法目标_友方 | C4: 范围类型_目标矩形范围 | F4: 效果目标_范围内的敌对 | G4: 筛选的所有敌方目标 | H4: 胸部 | I4: chest | J4: 技能效果_调用技能 | M4: 状态效果_封印 | N4: 不配数据 | O4: 引擎内置（同上）未使用
A5: 施法目标_目标点 | C5: 范围类型_目标扇形范围 | F5: 效果目标_范围内的友方 | G5: 筛选的所有友方目标 | H5: 背部 | I5: rear | J5: 技能效果_调用状态 | M5: 状态效果_中毒 | O5: game层PoisonHandler每DOT
A6: 施法目标_主人 | C6: 范围类型_自身为中心矩形 | F6: 效果目标_目标点 | H6: 头顶上方 | I6: overhead | J6: 技能效果_召唤单位 | M6: 状态效果_火墙 | O6: game层PoisonHandler同上
C7: 范围类型_自身为圆心 | F7: 效果目标_主人 | H7: 头部 | I7: head | J7: 技能效果_弹道 | M7: 状态效果_火墙整数 | O7: game层PoisonHandler同上
F8: 效果目标_范围内的全部 | H8: 手 | I8: hand | J8: 技能效果_冲撞位移 | M8: 状态效果_虚弱 | N8: 万分比 | O8: game层AttrModHandler伤害减少的万分比
F9: 效果目标_范围内的队友 | H9: 左手 | I9: hand left | J9: 技能效果_火环位移 | M9: 状态效果_易伤 | N9: 万分比 | O9: game层AttrModHandler受伤增幅值
F10: 效果目标_范围内的中立 | H10: 右手 | I10: hand right | J10: 技能效果_隔位刺杀 | M10: 状态效果_物防上限整数增加 | N10: 整数 | O10: game层AttrModHandler平坦物防变化量（乘层数）
F11: 效果目标_范围内的敌对怪 | H11: 脚 | I11: foot | J11: 技能效果_被触发 | M11: 状态效果_魔防上限整数增加 | N11: 整数 | O11: game层AttrModHandler平坦魔防变化量（乘层数）
F12: 效果目标_友方生命值最低 | H12: 左脚 | I12: foot left | J12: 技能效果_被动增加准确 | L12: 未实现 | M12: 状态效果_物防上限万分比增加 | N12: 万分比 | O12: game层AttrModHandler基于施法者法术强度的万分比
H13: 右脚 | I13: foot right | J13: 技能效果_无 | L13: 枚举占位，无逻辑— | M13: 状态效果_魔防上限万分比增加 | N13: 万分比 | O13: game层AttrModHandler同上
A14: 施法逻辑 | H14: 武器 | I14: weapon | J14: 技能效果_刺杀近身 | M14: 状态效果_回血 | N14: 整数 | O14: game层HealHandler（瞬时）回复HP量（整数）
A15: 1、通过【施法目标】确定施法目标点(单位) | H15: 精灵绑定点 | I15: sprite | J15: 技能效果_刺杀隔位 | M15: 状态效果_回蓝 | N15: 整数 | O15: game层HealHandler（瞬时）回复MP量（整数）
A16: 2、在目标点以【范围类型】再次进行筛选 | H16: 模型中部 | I16: medium | J16: 技能效果_传送 | L16: 1，2，3分别是回城，随机，指定传送 | M16: 状态效果_治愈术 | N16: 万分比 | O16: game层HealHandler（DOT）施法者法术强度的万分比（每跳）
A17: 3、筛选的所有目标里，对符合【效果目标】的单位确定具体对谁施加（包括数量） | H17: 坐骑 | I17: mount | M17: 状态效果_治愈术整数 | N17: 万分比 | O17: game层HealHandler（DOT）每跳回血量（整数，乘层数）
A18: 3、对符合【效果目标】的单位施加技能效果 | I18: 只配置中文部分，英文是引擎使用，我们只要上面5个挂点，下面黄底色先不管，需要动作全部做一下挂点，这一点上我们具体跟动作同学聊。 | M18: 状态效果_魔法盾系数 | N18: 整数 | O18: game层MagicShieldHandler盾值系数（万分比，基于法力值）
A19: 4、如果【技能效果】是【调用技能B】，则技能B以【每个效果目标】作为【施法目标】(多个效果目标时，技能B会执行多次) | M19: 状态效果_魔法盾吸收伤害 | N19: 不配数据 | O19: game层MagicShieldHandler伤害吸收百分比（万分比）
A20: 5、技能B【跳过逻辑1】【执行逻辑2】 | M20: 状态效果_隐身 | N20: 整数 | O20: game层InvisibleHandler未使用
A21: 6.效果目标选择 效果目标_自身 时，无视前面说的，只对自己施放 | M21: 状态效果_隐身术 | N21: 整数 | O21: game层InvisibleHandler（别名）未使用
A22: 7.被调用的技能一般不需要配置施法目标。 | M22: 状态效果_盾破CD | N22: 整数 | O22: game层ShieldBreakCDHandler未使用（持续时间走配置）
M23: 状态效果_缓慢回血 | N23: 整数 | O23: game层HealHandler（BUFF按配置缓慢回）回复HP量（整数）
M24: 状态效果_缓慢回蓝 | N24: 整数 | O24: game层HealHandler（BUFF按配置缓慢回）回复MP量（整数）
M25: 状态效果_中毒 | N25: 计算自己道术属性，效果值相当于取值以后X万分比，是一个系数。算出来是整数DOT掉血（上面已有）
M26: 状态效果_战士DOT | N26: 计算自己攻击属性，效果值相当于取值以后X万分比，是一个系数。算出来是整数DOT掉血
M27: 状态效果_法师DOT | N27: 计算自己魔法属性，效果值相当于取值以后X万分比，是一个系数。算出来是整数DOT掉血（相当于火墙技能）
M28: 状态效果_攻击万分比
M29: 状态效果_魔法万分比
M30: 状态效果_道术万分比
M31: 状态效果_攻击速度 | O31: ？？
M32: 状态效果_施法速度 | O32: ？？
M33: 状态效果_施法速度 | O33: ？？
M34: 状态效果_物防上限整数降低
M35: 状态效果_魔防上限整数降低
M36: 状态效果_物防上限万分比降低
M37: 状态效果_魔防上限万分比降低
M38: 状态效果_暴击增加
M39: 状态效果_流血战 | N39: 每秒损失攻击力*X%的生命，每秒这个事情通过间隔配置，伤害计算上和前面不一样，攻击力单独算一次，考虑幸运值的情况，从上下限取值
M40: 状态效果_流血法 | N40: 每秒损失魔法*X%的生命，每秒这个事情通过间隔配置，伤害计算上和前面不一样，攻击力单独算一次，考虑幸运值的情况，从上下限取值
...
