Workbook

Sheet item_config
A1: ##var | B1: ID | C1: Name | D1: Color | F1: DurT | H1: MainClass | I1: SubClass | J1: DropLevel | K1: DisplayType | L1: attrLimit | M1: durT | N1: isDrop | O1: isAutoUse | P1: RequiredLevel | Q1: CultivationTags | R1: PileMax | S1: FunctionType | T1: FunctionID | U1: FunctionValue | V1: Desc | W1: SpecDesc | X1: IconID | Y1: mdxID | Z1: LightEffId | AA1: Border1 | AB1: Border2 | AC1: Tag1 | AD1: Tag2 | AE1: Tag3 | AF1: Tag4
A2: ##type | B2: int | C2: string | D2: string | F2: int | H2: string | I2: string | J2: int | K2: string | L2: int | M2: int | N2: bool | O2: bool | P2: int | Q2: string | R2: int | S2: string | T2: int | U2: int | V2: string | W2: string | X2: string | Y2: string | Z2: string | AA2: string | AB2: string | AC2: string | AD2: string | AE2: string | AF2: string
A3: ##group
A4: ## | B4: 道具ID | C4: 0名称 | D4: 0颜色 | E4: 0ID编号 | F4: 存在时间 | G4: 0大类 | H4: 0大类 | I4: 0子类 | J4: 0档次 | K4: 0显示分类 | L4: 属性限制 | M4: 存在时间 | N4: 0是否可丢弃 | O4: 是否可以自动使用 | P4: 0使用级别下限 | Q4: 修炼标签 | R4: 0堆叠上限 | S4: 0功能类型 | T4: 0功能ID | U4: 0功能数值 | V4: 0说明 | W4: 0获得说明 | X4: 0背包图标 | Y4: 0地表模型 | Z4: 掉落光柱模型 | AA4: 静态边框 | AB4: 动态边框 | AC4: 标签1 | AD4: 标签2 | AE4: 标签3 | AF4: 标签4
B5: 31010001 | C5: 一小袋金币 | D5: 白色 | E5: 1 | F5: 60 | G5: 货币 | H5: 大类_基础 | I5: 子类_货币 | J5: 1 | K5: 货币 | M5: 30000 | N5: 否 | P5: 1 | Q5: 无 | R5: 999 | S5: 货币_金币 | U5: 50 | V5: ="|cff00FF00"&C5&"，打开后可以获得"&U5&"金币。" | W5: 击杀所有怪物，出售道具装备可获得 | X5: 31010001 | Y5: fall_coin | AC5: 货币 | AD5: 金币
B6: 31010002 | C6: 一小袋灵符 | D6: 白色 | E6: 2 | F6: 60 | G6: 货币 | H6: 大类_基础 | I6: 子类_货币 | J6: 2 | K6: 货币 | M6: 30000 | N6: 否 | P6: 1 | Q6: 无 | R6: 999 | S6: 货币_灵符 | U6: 5 | V6: ="|cff00FF00"&C6&"，打开后可以获得"&U6&"灵符。" | W6: 击杀所有怪物，出售道具装备可获得 | X6: 31010002 | Y6: fall_lingfu | AC6: 货币 | AD6: 灵符
B7: 31010003 | C7: 一袋金币 | D7: 白色 | E7: 3 | F7: 60 | G7: 货币 | H7: 大类_基础 | I7: 子类_货币 | J7: 3 | K7: 货币 | M7: 30000 | N7: 否 | P7: 1 | Q7: 无 | R7: 999 | S7: 货币_金币 | U7: 100 | V7: ="|cff00FF00"&C7&"，打开后可以获得"&U7&"金币。" | W7: 击杀所有怪物，出售道具装备可获得 | X7: 31010001 | Y7: fall_coin | AC7: 货币 | AD7: 金币
B8: 31010004 | C8: 一袋灵符 | D8: 白色 | E8: 4 | F8: 60 | G8: 货币 | H8: 大类_基础 | I8: 子类_货币 | J8: 4 | K8: 货币 | M8: 30000 | N8: 否 | P8: 1 | Q8: 无 | R8: 999 | S8: 货币_灵符 | U8: 10 | V8: ="|cff00FF00"&C8&"，打开后可以获得"&U8&"灵符。" | W8: 击杀所有怪物，出售道具装备可获得 | X8: 31010002 | Y8: fall_lingfu | AC8: 货币 | AD8: 灵符
B9: 31010005 | C9: 一大袋金币 | D9: 白色 | E9: 5 | F9: 60 | G9: 货币 | H9: 大类_基础 | I9: 子类_货币 | J9: 5 | K9: 货币 | M9: 30000 | N9: 否 | P9: 1 | Q9: 无 | R9: 999 | S9: 货币_金币 | U9: 500 | V9: ="|cff00FF00"&C9&"，打开后可以获得"&U9&"金币。" | W9: 击杀所有怪物，出售道具装备可获得 | X9: 31010001 | Y9: fall_coin | AC9: 货币 | AD9: 金币
B10: 31010006 | C10: 一大袋灵符 | D10: 白色 | E10: 6 | F10: 60 | G10: 货币 | H10: 大类_基础 | I10: 子类_货币 | J10: 6 | K10: 货币 | M10: 30000 | N10: 否 | P10: 1 | Q10: 无 | R10: 999 | S10: 货币_灵符 | U10: 50 | V10: ="|cff00FF00"&C10&"，打开后可以获得"&U10&"灵符。" | W10: 击杀所有怪物，出售道具装备可获得 | X10: 31010002 | Y10: fall_lingfu | AC10: 货币 | AD10: 灵符
B11: 31010007 | C11: 一箱金币 | D11: 白色 | E11: 7 | F11: 60 | G11: 货币 | H11: 大类_基础 | I11: 子类_货币 | J11: 7 | K11: 货币 | M11: 30000 | N11: 否 | P11: 1 | Q11: 无 | R11: 999 | S11: 货币_金币 | U11: 1000 | V11: ="|cff00FF00"&C11&"，打开后可以获得"&U11&"金币。" | W11: 击杀所有怪物，出售道具装备可获得 | X11: 31010001 | Y11: fall_coin | AC11: 货币 | AD11: 金币
B12: 31010008 | C12: 一箱灵符 | D12: 白色 | E12: 8 | F12: 60 | G12: 货币 | H12: 大类_基础 | I12: 子类_货币 | J12: 8 | K12: 货币 | M12: 30000 | N12: 否 | P12: 1 | Q12: 无 | R12: 999 | S12: 货币_灵符 | U12: 100 | V12: ="|cff00FF00"&C12&"，打开后可以获得"&U12&"灵符。" | W12: 击杀所有怪物，出售道具装备可获得 | X12: 31010002 | Y12: fall_lingfu | AC12: 货币 | AD12: 灵符
B13: 31010009 | C13: 一大箱金币 | D13: 白色 | E13: 9 | F13: 60 | G13: 货币 | H13: 大类_基础 | I13: 子类_货币 | J13: 9 | K13: 货币 | M13: 30000 | N13: 否 | P13: 1 | Q13: 无 | R13: 999 | S13: 货币_金币 | U13: 5000 | V13: ="|cff00FF00"&C13&"，打开后可以获得"&U13&"金币。" | W13: 击杀所有怪物，出售道具装备可获得 | X13: 31010001 | Y13: fall_coin | AC13: 货币 | AD13: 金币
B14: 31010010 | C14: 一大箱灵符 | D14: 白色 | E14: 10 | F14: 60 | G14: 货币 | H14: 大类_基础 | I14: 子类_货币 | J14: 10 | K14: 货币 | M14: 30000 | N14: 否 | P14: 1 | Q14: 无 | R14: 999 | S14: 货币_灵符 | U14: 500 | V14: ="|cff00FF00"&C14&"，打开后可以获得"&U14&"灵符。" | W14: 击杀所有怪物，出售道具装备可获得 | X14: 31010002 | Y14: fall_lingfu | AC14: 货币 | AD14: 灵符
B15: 31010011 | C15: 一车金币 | D15: 白色 | E15: 11 | F15: 60 | G15: 货币 | H15: 大类_基础 | I15: 子类_货币 | J15: 11 | K15: 货币 | M15: 30000 | N15: 否 | P15: 1 | Q15: 无 | R15: 999 | S15: 货币_金币 | U15: 10000 | V15: ="|cff00FF00"&C15&"，打开后可以获得"&U15&"金币。" | W15: 击杀所有怪物，出售道具装备可获得 | X15: 31010001 | Y15: fall_coin | AC15: 货币 | AD15: 金币
B16: 31010012 | C16: 一车灵符 | D16: 白色 | E16: 12 | F16: 60 | G16: 货币 | H16: 大类_基础 | I16: 子类_货币 | J16: 12 | K16: 货币 | M16: 30000 | N16: 否 | P16: 1 | Q16: 无 | R16: 999 | S16: 货币_灵符 | U16: 100 | V16: ="|cff00FF00"&C16&"，打开后可以获得"&U16&"灵符。" | W16: 击杀所有怪物，出售道具装备可获得 | X16: 31010002 | Y16: fall_lingfu | AC16: 货币 | AD16: 灵符
B17: 31010013 | C17: 一卡车金币 | D17: 白色 | E17: 13 | F17: 60 | G17: 货币 | H17: 大类_基础 | I17: 子类_货币 | J17: 13 | K17: 货币 | M17: 30000 | N17: 否 | P17: 1 | Q17: 无 | R17: 999 | S17: 货币_金币 | U17: 50000 | V17: ="|cff00FF00"&C17&"，打开后可以获得"&U17&"金币。" | W17: 击杀所有怪物，出售道具装备可获得 | X17: 31010001 | Y17: fall_coin | AC17: 货币 | AD17: 金币
B18: 31010014 | C18: 一卡车灵符 | D18: 白色 | E18: 14 | F18: 60 | G18: 货币 | H18: 大类_基础 | I18: 子类_货币 | J18: 14 | K18: 货币 | M18: 30000 | N18: 否 | P18: 1 | Q18: 无 | R18: 999 | S18: 货币_灵符 | U18: 500 | V18: ="|cff00FF00"&C18&"，打开后可以获得"&U18&"灵符。" | W18: 击杀所有怪物，出售道具装备可获得 | X18: 31010002 | Y18: fall_lingfu | AC18: 货币 | AD18: 灵符
B19: 31010015 | C19: 活跃丹 | D19: 紫色 | E19: 15 | F19: 60 | G19: 货币 | H19: 大类_基础 | I19: 子类_货币 | J19: 15 | K19: 货币 | M19: 30000 | N19: 否 | P19: 1 | Q19: 无 | R19: 999 | S19: 货币_活跃点 | U19: 1000 | V19: ="|cff00FF00"&C19&"，打开后可以获得"&U19&"活跃点。" | W19: 系统赠送获得 | Y19: fall_lingfu | Z19: ain_effect_ziseguangzhu_85 | AA19: BK_J_zi | AB19: BK_D_zi | AC19: 货币 | AD19: 活跃点
B20: 31010016 | C20: 声望丹 | D20: 紫色 | E20: 16 | F20: 60 | G20: 货币 | H20: 大类_基础 | I20: 子类_货币 | J20: 16 | K20: 货币 | M20: 30000 | N20: 否 | P20: 1 | Q20: 无 | R20: 999 | S20: 货币_声望点 | U20: 1000 | V20: ="|cff00FF00"&C20&"，打开后可以获得"&U20&"声望点。" | W20: 系统赠送获得 | Y20: fall_lingfu | Z20: ain_effect_ziseguangzhu_85 | AA20: BK_J_zi | AB20: BK_D_zi | AC20: 货币 | AD20: 声望点
B21: 34020001 | C21: 基础剑术 | D21: 绿色 | E21: 1 | F21: 60 | G21: 技能 | H21: 大类_基础 | I21: 子类_技能书 | J21: 1 | K21: 技能书 | M21: 30000 | N21: 是 | P21: 7 | Q21: 体修 | R21: 999 | S21: 技能书 | T21: 10010001 | V21: ="|cff00FF00达到"&P21&"级后可以学习技能"&C21&"，也可以在当前技能经验满后对该技能进行升级。" | W21: 击杀沃玛怪物获得 | X21: 34020001 | Y21: fall_jinengshu_01 | Z21: ain_effect_lvseguangzhu_88 | AA21: BK_J_lv | AB21: BK_D_lv | AC21: 材料 | AD21: 战士技能书
B22: 34020002 | C22: 攻杀剑术 | D22: 绿色 | E22: 2 | F22: 60 | G22: 技能 | H22: 大类_基础 | I22: 子类_技能书 | J22: 1 | K22: 技能书 | M22: 30000 | N22: 是 | P22: 19 | Q22: 体修 | R22: 999 | S22: 技能书 | T22: 10020001 | V22: ="|cff00FF00达到"&P22&"级后可以学习技能"&C22&"，也可以在当前技能经验满后对该技能进行升级。" | W22: 击杀沃玛怪物获得 | X22: 34020001 | Y22: fall_jinengshu_01 | Z22: ain_effect_lvseguangzhu_88 | AA22: BK_J_lv | AB22: BK_D_lv | AC22: 材料 | AD22: 战士技能书
B23: 34020003 | C23: 刺杀剑术 | D23: 绿色 | E23: 3 | F23: 60 | G23: 技能 | H23: 大类_基础 | I23: 子类_技能书 | J23: 1 | K23: 技能书 | M23: 30000 | N23: 是 | P23: 25 | Q23: 体修 | R23: 999 | S23: 技能书 | T23: 10030001 | V23: ="|cff00FF00达到"&P23&"级后可以学习技能"&C23&"，也可以在当前技能经验满后对该技能进行升级。" | W23: 击杀祖玛怪物获得 | X23: 34020001 | Y23: fall_jinengshu_01 | Z23: ain_effect_lvseguangzhu_88 | AA23: BK_J_lv | AB23: BK_D_lv | AC23: 材料 | AD23: 战士技能书
B24: 34020004 | C24: 半月弯刀 | D24: 绿色 | E24: 4 | F24: 60 | G24: 技能 | H24: 大类_基础 | I24: 子类_技能书 | J24: 1 | K24: 技能书 | M24: 30000 | N24: 是 | P24: 28 | Q24: 体修 | R24: 999 | S24: 技能书 | T24: 10040001 | V24: ="|cff00FF00达到"&P24&"级后可以学习技能"&C24&"，也可以在当前技能经验满后对该技能进行升级。" | W24: 击杀祖玛怪物获得 | X24: 34020001 | Y24: fall_jinengshu_01 | Z24: ain_effect_lvseguangzhu_88 | AA24: BK_J_lv | AB24: BK_D_lv | AC24: 材料 | AD24: 战士技能书
B25: 34020005 | C25: 野蛮冲撞 | D25: 绿色 | E25: 5 | F25: 60 | G25: 技能 | H25: 大类_基础 | I25: 子类_技能书 | J25: 1 | K25: 技能书 | M25: 30000 | N25: 是 | P25: 30 | Q25: 体修 | R25: 999 | S25: 技能书 | T25: 10050001 | V25: ="|cff00FF00达到"&P25&"级后可以学习技能"&C25&"，也可以在当前技能经验满后对该技能进行升级。" | W25: 击杀赤月怪物获得 | X25: 34020001 | Y25: fall_jinengshu_01 | Z25: ain_effect_lvseguangzhu_88 | AA25: BK_J_lv | AB25: BK_D_lv | AC25: 材料 | AD25: 战士技能书
B26: 34020006 | C26: 烈火剑法 | D26: 绿色 | E26: 6 | F26: 60 | G26: 技能 | H26: 大类_基础 | I26: 子类_技能书 | J26: 1 | K26: 技能书 | M26: 30000 | N26: 是 | P26: 35 | Q26: 体修 | R26: 999 | S26: 技能书 | T26: 10060001 | V26: ="|cff00FF00达到"&P26&"级后可以学习技能"&C26&"，也可以在当前技能经验满后对该技能进行升级。" | W26: 击杀赤月怪物获得 | X26: 34020001 | Y26: fall_jinengshu_01 | Z26: ain_effect_lvseguangzhu_88 | AA26: BK_J_lv | AB26: BK_D_lv | AC26: 材料 | AD26: 战士技能书
B27: 34020031 | C27: 火球术 | D27: 绿色 | E27: 31 | F27: 60 | G27: 技能 | H27: 大类_基础 | I27: 子类_技能书 | J27: 1 | K27: 技能书 | M27: 30000 | N27: 是 | P27: 7 | Q27: 法修 | R27: 999 | S27: 技能书 | T27: 10310001 | V27: ="|cff00FF00达到"&P27&"级后可以学习技能"&C27&"，也可以在当前技能经验满后对该技能进行升级。" | W27: 击杀沃玛怪物获得 | X27: 34020001 | Y27: fall_jinengshu_01 | Z27: ain_effect_lvseguangzhu_88 | AA27: BK_J_lv | AB27: BK_D_lv | AC27: 材料 | AD27: 法师技能书
B28: 34020032 | C28: 抗拒火环 | D28: 绿色 | E28: 32 | F28: 60 | G28: 技能 | H28: 大类_基础 | I28: 子类_技能书 | J28: 1 | K28: 技能书 | M28: 30000 | N28: 是 | P28: 12 | Q28: 法修 | R28: 999 | S28: 技能书 | T28: 10320001 | V28: ="|cff00FF00达到"&P28&"级后可以学习技能"&C28&"，也可以在当前技能经验满后对该技能进行升级。" | W28: 击杀沃玛怪物获得 | X28: 34020001 | Y28: fall_jinengshu_01 | Z28: ain_effect_lvseguangzhu_88 | AA28: BK_J_lv | AB28: BK_D_lv | AC28: 材料 | AD28: 法师技能书
B29: 34020033 | C29: 雷电术 | D29: 绿色 | E29: 33 | F29: 60 | G29: 技能 | H29: 大类_基础 | I29: 子类_技能书 | J29: 1 | K29: 技能书 | M29: 30000 | N29: 是 | P29: 17 | Q29: 法修 | R29: 999 | S29: 技能书 | T29: 10330001 | V29: ="|cff00FF00达到"&P29&"级后可以学习技能"&C29&"，也可以在当前技能经验满后对该技能进行升级。" | W29: 击杀祖玛怪物获得 | X29: 34020001 | Y29: fall_jinengshu_02 | Z29: ain_effect_lvseguangzhu_88 | AA29: BK_J_lv | AB29: BK_D_lv | AC29: 材料 | AD29: 法师技能书
B30: 34020034 | C30: 火墙 | D30: 绿色 | E30: 34 | F30: 60 | G30: 技能 | H30: 大类_基础 | I30: 子类_技能书 | J30: 1 | K30: 技能书 | M30: 30000 | N30: 是 | P30: 22 | Q30: 法修 | R30: 999 | S30: 技能书 | T30: 10340001 | V30: ="|cff00FF00达到"&P30&"级后可以学习技能"&C30&"，也可以在当前技能经验满后对该技能进行升级。" | W30: 击杀祖玛怪物获得 | X30: 34020001 | Y30: fall_jinengshu_02 | Z30: ain_effect_lvseguangzhu_88 | AA30: BK_J_lv | AB30: BK_D_lv | AC30: 材料 | AD30: 法师技能书
B31: 34020035 | C31: 疾光电影 | D31: 绿色 | E31: 35 | F31: 60 | G31: 技能 | H31: 大类_基础 | I31: 子类_技能书 | J31: 1 | K31: 技能书 | M31: 30000 | N31: 是 | P31: 26 | Q31: 法修 | R31: 999 | S31: 技能书 | T31: 10350001 | V31: ="|cff00FF00达到"&P31&"级后可以学习技能"&C31&"，也可以在当前技能经验满后对该技能进行升级。" | W31: 击杀赤月怪物获得 | X31: 34020001 | Y31: fall_jinengshu_02 | Z31: ain_effect_lvseguangzhu_88 | AA31: BK_J_lv | AB31: BK_D_lv | AC31: 材料 | AD31: 法师技能书
B32: 34020036 | C32: 魔法盾 | D32: 绿色 | E32: 36 | F32: 60 | G32: 技能 | H32: 大类_基础 | I32: 子类_技能书 | J32: 1 | K32: 技能书 | M32: 30000 | N32: 是 | P32: 31 | Q32: 法修 | R32: 999 | S32: 技能书 | T32: 10360001 | V32: ="|cff00FF00达到"&P32&"级后可以学习技能"&C32&"，也可以在当前技能经验满后对该技能进行升级。" | W32: 击杀赤月怪物获得 | X32: 34020001 | Y32: fall_jinengshu_02 | Z32: ain_effect_lvseguangzhu_88 | AA32: BK_J_lv | AB32: BK_D_lv | AC32: 材料 | AD32: 法师技能书
... B41: 34020068 | C41: 召唤神兽 | D41: 绿色 | E41: 68 | F41: 60 | G41: 技能 | H41: 大类_基础 | I41: 子类_技能书 | J41: 1 | K41: 技能书 | M41: 30000 | N41: 是 | P41: 35 | Q41: 丹修 | R41: 999 | S41: 技能书 | T41: 10680001 | V41: ="|cff00FF00达到"&P41&"级后可以学习技能"&C41&"，也可以在当前技能经验满后对该技能进行升级。" | W41: 击杀赤月怪物获得 | X41: 34020001 | Y41: fall_jinengshu_02 | Z41: ain_effect_lvseguangzhu_88 | AA41: BK_J_lv | AB41: BK_D_lv | AC41: 材料 | AD41: 道士技能书
B42: 34020100 | C42: 技能书 | D42: 绿色 | E42: 100 | F42: 60 | G42: 技能 | H42: 大类_基础 | I42: 子类_技能书 | J42: 7 | K42: 技能书 | M42: 30000 | N42: 是 | P42: 1 | Q42: 无 | R42: 999 | S42: 技能经验 | V42: |cff00FF00增加技能的经验值 | W42: 参加特殊活动，击杀BOSS可得 | X42: 34020100 | Y42: fall_jinengshu_02 | Z42: ain_effect_lvseguangzhu_88 | AA42: BK_J_lv | AB42: BK_D_lv | AC42: 材料 | AD42: 技能书
B43: 34040001 | C43: 祝福油 | D43: 绿色 | E43: 1 | F43: 60 | G43: 强化 | H43: 大类_基础 | I43: 子类_贵重品 | J43: 1 | K43: 强化道具 | M43: 60000 | N43: 是 | P43: 1 | Q43: 无 | R43: 999 | S43: 祝福_幸运 | V43: |cff00FF00使用祝福油有概率提升当前装备武器的幸运值，最高可以提升到7点。 | W43: 击杀赤月怪物获得 | X43: 34040001 | Y43: fall_zhufuyou | Z43: ain_effect_lvseguangzhu_88 | AA43: BK_J_lv | AB43: BK_D_lv | AC43: 材料 | AD43: 祝福油
B44: 34040002 | C44: 强化石 | D44: 绿色 | E44: 2 | F44: 60 | G44: 强化 | H44: 大类_基础 | I44: 子类_贵重品 | J44: 2 | K44: 强化道具 | M44: 30000 | N44: 否 | P44: 1 | Q44: 无 | R44: 999 | S44: 系统_强化 | V44: |cff00FF00使用后可以进行装备强化 | W44: 参加特殊活动，击杀BOSS可得 | X44: 34040002 | Y44: fall_qianghuashi | Z44: ain_effect_lvseguangzhu_88 | AA44: BK_J_lv | AB44: BK_D_lv | AC44: 材料 | AD44: 强化石
B45: 34040003 | C45: 强化特权 | D45: 紫色 | E45: 3 | F45: 60 | G45: 强化 | H45: 大类_基础 | I45: 子类_贵重品 | J45: 3 | K45: 强化道具 | M45: 30000 | N45: 否 | P45: 1 | Q45: 无 | R45: 999 | S45: 特权_强化 | V45: |cff00FF00使用后增加10%强化成功率 | W45: 参加特殊活动，击杀BOSS可得 | X45: 34040003 | Y45: fall_qianghuatequan | Z45: ain_effect_ziseguangzhu_85 | AA45: BK_J_zi | AB45: BK_D_zi
B46: 34040004 | C46: 命格洗练石 | D46: 紫色 | E46: 4 | F46: 60 | G46: 强化 | H46: 大类_基础 | I46: 子类_贵重品 | J46: 4 | K46: 强化道具 | M46: 30000 | N46: 否 | P46: 1 | Q46: 无 | R46: 999 | S46: 命格_洗练 | V46: |cff00FF00使用后可以进行命格洗练 | W46: 参加特殊活动，击杀BOSS可得 | X46: 34040004 | Y46: fall_minggeshi | Z46: ain_effect_ziseguangzhu_85 | AA46: BK_J_zi | AB46: BK_D_zi
B47: 34040005 | C47: 羽毛 | D47: 紫色 | E47: 5 | F47: 60 | G47: 强化 | H47: 大类_基础 | I47: 子类_贵重品 | J47: 5 | K47: 强化道具 | M47: 30000 | N47: 否 | P47: 1 | Q47: 无 | R47: 999 | S47: 系统_羽翼 | V47: |cff00FF00使用后可以进行羽翼升级 | W47: 参加特殊活动，击杀BOSS可得 | X47: 34040005 | Y47: fall_yumao | Z47: ain_effect_ziseguangzhu_85 | AA47: BK_J_zi | AB47: BK_D_zi | AC47: 材料 | AD47: 羽毛
B48: 34040006 | C48: 背包解锁格 | D48: 紫色 | E48: 6 | F48: 60 | G48: 强化 | H48: 大类_基础 | I48: 子类_贵重品 | J48: 99 | K48: 强化道具 | N48: 否 | P48: 1 | Q48: 无 | R48: 999 | S48: 背包_解锁格 | V48: |cff00FF00使用后可以解锁背包格子 | W48: 参加特殊活动，击杀BOSS可得 | X48: 34040006 | Y48: fall_beibaoge | Z48: ain_effect_ziseguangzhu_85 | AA48: BK_J_zi | AB48: BK_D_zi
...

Sheet 编号表
A1: 内部名 | B1: 编号 | C1: 物编编号 | D1: 颜色 | E1: 编号 | G1: 从左数起
A2: 货币 | B2: 1 | C2: A | D2: 白色 | E2: 1 | G2: 第1位 | H2: 固定为3表示物品
A3: 技能 | B3: 2 | C3: B | D3: 绿色 | E3: 2 | G3: 第2位 | H3: 分大类
A4: 经验 | B4: 3 | C4: C | D4: 蓝色 | E4: 3 | G4: 第3位
A5: 强化 | B5: 4 | C5: D | D5: 紫色 | E5: 4 | G5: 第4位
A6: 药品 | B6: 5 | C6: E | D6: 橙色 | E6: 5 | G6: 第5位 | H6: 本分类下的序号
A7: 任务 | B7: 6 | D7: 红色 | E7: 6 | G7: 第6位
A8: 铭文 | B8: 7 | E8: 7 | G8: 第7位
A9: 外观 | B9: 8 | E9: 8 | G9: 第8位
A10: 特戒 | B10: 9 | E10: 9
B11: 10
B12: 11
B13: 12
B14: 13 | G14: 新物品ID编号计算规则=30000000+@INDEX(编号表!$B:$B,MATCH(C3,编号表!$A:$A,0))*10000+E3
B15: 14 | G15: 改动原因：因为现在的道具配置之后，品质有改动的可能，因此暂时把品质对ID的影响取消掉。
B16: 15
B17: 16
B18: 17
B19: 18
B20: 19
D22: 道具ID必须下拉，使用公式自动生成ID！！！

Sheet 更新说明
A1: 版本 | B1: 说明
A2: 1.12 | B2: 物品编号从2开头七位改为3开头8位 增加光柱配置
A3: 1.13 | B3: 掉落模型
A4: 1.14 | B4: 新增0显示分类DisplayType纯TIPS上显示用
A5: 1.15 | B5: 更新编号规则，增加颜色对应的品质，对应改物品ID
A6: 1.16 | B6: 更新图标
A7: 1.17 | B7: 新增血药蓝药对应功能ID配置
A8: 1.18 | B8: 新增小极品打造相关道具
A9: 1.19 | B9: 给小极品打造道具配置图标，临时使用
A10: 1.2 | B10: 新增双加药
A11: 1.21 | B11: 新增多种金币和灵符道具，打开获得的数量不同。同时更新道具描述
A12: 1.22 | B12: 更新掉落物，物品ID增加格式，重复显示红色
A13: 1.23 | B13: 新增静态边框和动态边框的配置项
A14: 1.24 | B14: 新增铭文ICON编号和对应掉落物模型，修改34040043为道神纹
A15: 1.25
A16: 1.26 | B16: 编号里新增了一类任务，对应新增的任务物品的大类颜色和序号都改了，对应物品的ID也变了
A17: 1.27 | B17: 对ID规则进行改动，在ID编号的计算中删掉了品质的影响。铭文使用新的ID计算规则计算，其他的老物品ID不变，删掉ID编号规则，直接粘贴老的ID | E17: 新物品ID编号计算规则=30000000+@INDEX(编号表!$B:$B,MATCH(C3,编号表!$A:$A,0))*10000+E3
A18: 1.28 | B18: 新增一类外观道具
A19: 1.29
A20: 1.3
A21: 1.31
A22: 1.32
A23: 1.33
A24: 1.34
