Workbook
Name 掉落方式: 名称表!$A$1:$A$3
Name 礼包类型: 名称表!$J$2:$J$135
Name 频率: 名称表!$D$2:$D$7
Name 是否礼包中心: 名称表!$Q$2:$Q$7
Name 显示方式: 名称表!$O$2:$O$7
Name 装备绑定类型: 名称表!$C$2:$C$4

Sheet drop_config
A1: 0掉落方案ID | B1: 0内部名 | C1: 0编号 | D1: 0方案说明 | E1: 0掉落方式 | F1: 0权重验证 | G1: 0掉落时间限制ID | H1: 0最小掉落数 | I1: 0最大掉落数 | J1: 0掉落物数量 | K1: 0掉落物ID1 | L1: 0掉落物名称1 | M1: 0掉落物大类 | N1: 0掉落物子类 | O1: 0掉落物档次1 | P1: 0掉落物概率1 | Q1: 0掉落物数量1 | R1: 0系统提示概率1 | S1: 0掉落物ID2 | T1: 0掉落物名称2 | U1: 0掉落物 | V1: 0掉落物 | W1: 0掉落物档次2 | X1: 0掉落物概率2 | Y1: 0掉落物数量2 | Z1: 0系统提示概率2 | AA1: 0掉落物ID3 | AB1: 0掉落物名称3 | AC1: 0掉落物 | AD1: 0掉落物 | AE1: 0掉落物档次3 | AF1: 0掉落物概率3 | AG1: 0掉落物数量3 | AH1: 0系统提示概率3 | AI1: 0掉落物ID4 | AJ1: 0掉落物名称4 | AK1: 0掉落物 | AL1: 0掉落物 | AM1: 0掉落物档次4 | AN1: 0掉落物概率4 | AO1: 0掉落物数量4 | AP1: 0系统提示概率4 | AQ1: 0掉落物ID5 | AR1: 0掉落物名称5 | AS1: 0掉落物 | AT1: 0掉落物 | AU1: 0掉落物档次5 | AV1: 0掉落物概率5 | AW1: 0掉落物数量5 | AX1: 0系统提示概率5 | AY1: 0掉落物ID6 | AZ1: 0掉落物名称6 | BA1: 0掉落物 | BB1: 0掉落物 | BC1: 0掉落物档次6 | BD1: 0掉落物概率6 | BE1: 0掉落物数量6 | BF1: 0系统提示概率6 | BG1: 0掉落物ID7 | BH1: 0掉落物名称7 | BI1: 0掉落物 | BJ1: 0掉落物 | BK1: 0掉落物档次7 | BL1: 0掉落物概率7 | BM1: 0掉落物数量7 | BN1: 0系统提示概率7 | BO1: 0掉落物ID8 | BP1: 0掉落物名称8 | BQ1: 0掉落物 | BR1: 0掉落物 | BS1: 0掉落物档次8 | BT1: 0掉落物概率8 | BU1: 0掉落物数量8 | BV1: 0系统提示概率8 | BW1: 0掉落物ID9 | BX1: 0掉落物名称9 | BY1: 0掉落物 | BZ1: 0掉落物 | CA1: 0掉落物档次9 | CB1: 0掉落物概率9 | CC1: 0掉落物数量9 | CD1: 0系统提示概率9 | CE1: 0掉落物ID10 | CF1: 0掉落物名称10 | CG1: 0掉落物 | CH1: 0掉落物 | CI1: 0掉落物档次10 | CJ1: 0掉落物概率10 | CK1: 0掉落物数量10 | CL1: 0系统提示概率10 | CM1: 0掉落物ID11 | CN1: 0掉落物名称11 | CO1: 0掉落物 | CP1: 0掉落物 | CQ1: 0掉落物档次11 | CR1: 0掉落物概率11 | CS1: 0掉落物数量11 | CT1: 0系统提示概率11 | CU1: 0掉落物ID12 | CV1: 0掉落物名称12 | CW1: 0掉落物 | CX1: 0掉落物 | CY1: 0掉落物档次12 | CZ1: 0掉落物概率12 | DA1: 0掉落物数量12 | DB1: 0系统提示概率12 | DC1: 0掉落物ID13 | DD1: 0掉落物名称13 | DE1: 0掉落物 | DF1: 0掉落物 | DG1: 0掉落物档次13 | DH1: 0掉落物概率13 | DI1: 0掉落物数量13 | DJ1: 0系统提示概率13 | DK1: 0掉落物ID14 | DL1: 0掉落物名称14 | DM1: 0掉落物 | DN1: 0掉落物 | DO1: 0掉落物档次14 | DP1: 0掉落物概率14 | DQ1: 0掉落物数量14 | DR1: 0系统提示概率14 | DS1: 0掉落物ID15 | DT1: 0掉落物名称15 | DU1: 0掉落物 | DV1: 0掉落物 | DW1: 0掉落物档次15 | DX1: 0掉落物概率15 | DY1: 0掉落物数量15 | DZ1: 0系统提示概率15 | EA1: 0掉落物ID16 | EB1: 0掉落物名称16 | EC1: 0掉落物 | ED1: 0掉落物 | EE1: 0掉落物档次16 | EF1: 0掉落物概率16 | EG1: 0掉落物数量16 | EH1: 0系统提示概率16 | EI1: 0掉落物ID17 | EJ1: 0掉落物名称17 | EK1: 0掉落物 | EL1: 0掉落物 | EM1: 0掉落物档次17 | EN1: 0掉落物概率17 | EO1: 0掉落物数量17 | EP1: 0系统提示概率17 | EQ1: 0掉落物ID18 | ER1: 0掉落物名称18 | ES1: 0掉落物 | ET1: 0掉落物 | EU1: 0掉落物档次18 | EV1: 0掉落物概率18 | EW1: 0掉落物数量18 | EX1: 0系统提示概率18 | EY1: 0掉落物ID19 | EZ1: 0掉落物名称19 | FA1: 0掉落物 | FB1: 0掉落物 | FC1: 0掉落物档次19 | FD1: 0掉落物概率19 | FE1: 0掉落物数量19 | FF1: 0系统提示概率19 | FG1: 0掉落物ID20 | FH1: 0掉落物名称20 | FI1: 0掉落物 | FJ1: 0掉落物 | FK1: 0掉落物档次20 | FL1: 0掉落物概率20 | FM1: 0掉落物数量20 | FN1: 0系统提示概率20 | FO1: 0掉落物ID21 | FP1: 0掉落物名称21 | FQ1: 0掉落物 | FR1: 0掉落物 | FS1: 0掉落物档次21 | FT1: 0掉落物概率21 | FU1: 0掉落物数量21 | FV1: 0系统提示概率21 | FW1: 0掉落物ID22 | FX1: 0掉落物名称22 | FY1: 0掉落物 | FZ1: 0掉落物 | GA1: 0掉落物档次22 | GB1: 0掉落物概率22 | GC1: 0掉落物数量22 | GD1: 0系统提示概率22 | GE1: 0掉落物ID23 | GF1: 0掉落物名称23 | GG1: 0掉落物 | GH1: 0掉落物 | GI1: 0掉落物档次23 | GJ1: 0掉落物概率23 | GK1: 0掉落物数量23 | GL1: 0系统提示概率23 | GM1: 0掉落物ID24 | GN1: 0掉落物名称24 | GO1: 0掉落物 | GP1: 0掉落物 | GQ1: 0掉落物档次24 | GR1: 0掉落物概率24 | GS1: 0掉落物数量24 | GT1: 0系统提示概率24 | GU1: 0掉落物ID25 | GV1: 0掉落物名称25 | GW1: 0掉落物 | GX1: 0掉落物 | GY1: 0掉落物档次25 | GZ1: 0掉落物概率25 | HA1: 0掉落物数量25 | HB1: 0系统提示概率25 | HC1: 0掉落物ID26 | HD1: 0掉落物名称26 | HE1: 0掉落物 | HF1: 0掉落物 | HG1: 0掉落物档次26 | HH1: 0掉落物概率26 | HI1: 0掉落物数量26 | HJ1: 0系统提示概率26 | HK1: 0掉落物ID27 | HL1: 0掉落物名称27 | HM1: 0掉落物 | HN1: 0掉落物 | HO1: 0掉落物档次27 | HP1: 0掉落物概率27 | HQ1: 0掉落物数量27 | HR1: 0系统提示概率27 | HS1: 0掉落物ID28 | HT1: 0掉落物名称28 | HU1: 0掉落物 | HV1: 0掉落物 | HW1: 0掉落物档次28 | HX1: 0掉落物概率28 | HY1: 0掉落物数量28 | HZ1: 0系统提示概率28 | IA1: 0掉落物ID29 | IB1: 0掉落物名称29 | IC1: 0掉落物 | ID1: 0掉落物 | IE1: 0掉落物档次29 | IF1: 0掉落物概率29 | IG1: 0掉落物数量29 | IH1: 0系统提示概率29 | II1: 0掉落物ID30 | IJ1: 0掉落物名称30 | IK1: 0掉落物 | IL1: 0掉落物 | IM1: 0掉落物档次30 | IN1: 0掉落物概率30 | IO1: 0掉落物数量30 | IP1: 0系统提示概率30 | IQ1: 0掉落物ID31 | IR1: 0掉落物名称31 | IS1: 0掉落物 | IT1: 0掉落物 | IU1: 0掉落物档次31 | IV1: 0掉落物概率31 | IW1: 0掉落物数量31 | IX1: 0系统提示概率31 | IY1: 0掉落物ID32 | IZ1: 0掉落物名称32 | JA1: 0掉落物 | JB1: 0掉落物 | JC1: 0掉落物档次32 | JD1: 0掉落物概率32 | JE1: 0掉落物数量32 | JF1: 0系统提示概率32
A2: ID | E2: DropType | G2: TimeLimitID | H2: MinDropNumber | I2: MaxDropNumber | J2: DropNumber | K2: Drop1ID | M2: Drop1MainClass | N2: Drop1SubClass | O2: Drop1Level | P2: Drop1Prob | Q2: Drop1Num | R2: Drop1TipsProb | S2: Drop2ID | U2: Drop2MainClass | V2: Drop2SubClass | W2: Drop2Level | X2: Drop2Prob | Y2: Drop2Num | Z2: Drop2TipsProb | AA2: Drop3ID | AC2: Drop3MainClass | AD2: Drop3SubClass | AE2: Drop3Level | AF2: Drop3Prob | AG2: Drop3Num | AH2: Drop3TipsProb | AI2: Drop4ID | AK2: Drop4MainClass | AL2: Drop4SubClass | AM2: Drop4Level | AN2: Drop4Prob | AO2: Drop4Num | AP2: Drop4TipsProb | AQ2: Drop5ID | AS2: Drop5MainClass | AT2: Drop5SubClass | AU2: Drop5Level | AV2: Drop5Prob | AW2: Drop5Num | AX2: Drop5TipsProb | AY2: Drop6ID | BA2: Drop6MainClass | BB2: Drop6SubClass | BC2: Drop6Level | BD2: Drop6Prob | BE2: Drop6Num | BF2: Drop6TipsProb | BG2: Drop7ID | BI2: Drop7MainClass | BJ2: Drop7SubClass | BK2: Drop7Level | BL2: Drop7Prob | BM2: Drop7Num | BN2: Drop7TipsProb | BO2: Drop8ID | BQ2: Drop8MainClass | BR2: Drop8SubClass | BS2: Drop8Level | BT2: Drop8Prob | BU2: Drop8Num | BV2: Drop8TipsProb | BW2: Drop9ID | BY2: Drop9MainClass | BZ2: Drop9SubClass | CA2: Drop9Level | CB2: Drop9Prob | CC2: Drop9Num | CD2: Drop9TipsProb | CE2: Drop10ID | CG2: Drop10MainClass | CH2: Drop10SubClass | CI2: Drop10Level | CJ2: Drop10Prob | CK2: Drop10Num | CL2: Drop10TipsProb | CM2: Drop11ID | CO2: Drop11MainClass | CP2: Drop11SubClass | CQ2: Drop11Level | CR2: Drop11Prob | CS2: Drop11Num | CT2: Drop11TipsProb | CU2: Drop12ID | CW2: Drop12MainClass | CX2: Drop12SubClass | CY2: Drop12Level | CZ2: Drop12Prob | DA2: Drop12Num | DB2: Drop12TipsProb | DC2: Drop13ID | DE2: Drop13MainClass | DF2: Drop13SubClass | DG2: Drop13Level | DH2: Drop13Prob | DI2: Drop13Num | DJ2: Drop13TipsProb | DK2: Drop14ID | DM2: Drop14MainClass | DN2: Drop14SubClass | DO2: Drop14Level | DP2: Drop14Prob | DQ2: Drop14Num | DR2: Drop14TipsProb | DS2: Drop15ID | DU2: Drop15MainClass | DV2: Drop15SubClass | DW2: Drop15Level | DX2: Drop15Prob | DY2: Drop15Num | DZ2: Drop15TipsProb | EA2: Drop16ID | EC2: Drop16MainClass | ED2: Drop16SubClass | EE2: Drop16Level | EF2: Drop16Prob | EG2: Drop16Num | EH2: Drop16TipsProb | EI2: Drop17ID | EK2: Drop17MainClass | EL2: Drop17SubClass | EM2: Drop17Level | EN2: Drop17Prob | EO2: Drop17Num | EP2: Drop17TipsProb | EQ2: Drop18ID | ES2: Drop18MainClass | ET2: Drop18SubClass | EU2: Drop18Level | EV2: Drop18Prob | EW2: Drop18Num | EX2: Drop18TipsProb | EY2: Drop19ID | FA2: Drop19MainClass | FB2: Drop19SubClass | FC2: Drop19Level | FD2: Drop19Prob | FE2: Drop19Num | FF2: Drop19TipsProb | FG2: Drop20ID | FI2: Drop20MainClass | FJ2: Drop20SubClass | FK2: Drop20Level | FL2: Drop20Prob | FM2: Drop20Num | FN2: Drop20TipsProb | FO2: Drop21ID | FQ2: Drop21MainClass | FR2: Drop21SubClass | FS2: Drop21Level | FT2: Drop21Prob | FU2: Drop21Num | FV2: Drop21TipsProb | FW2: Drop22ID | FY2: Drop22MainClass | FZ2: Drop22SubClass | GA2: Drop22Level | GB2: Drop22Prob | GC2: Drop22Num | GD2: Drop22TipsProb | GE2: Drop23ID | GG2: Drop23MainClass | GH2: Drop23SubClass | GI2: Drop23Level | GJ2: Drop23Prob | GK2: Drop23Num | GL2: Drop23TipsProb | GM2: Drop24ID | GO2: Drop24MainClass | GP2: Drop24SubClass | GQ2: Drop24Level | GR2: Drop24Prob | GS2: Drop24Num | GT2: Drop24TipsProb | GU2: Drop25ID | GW2: Drop25MainClass | GX2: Drop25SubClass | GY2: Drop25Level | GZ2: Drop25Prob | HA2: Drop25Num | HB2: Drop25TipsProb | HC2: Drop26ID | HE2: Drop26MainClass | HF2: Drop26SubClass | HG2: Drop26Level | HH2: Drop26Prob | HI2: Drop26Num | HJ2: Drop26TipsProb | HK2: Drop27ID | HM2: Drop27MainClass | HN2: Drop27SubClass | HO2: Drop27Level | HP2: Drop27Prob | HQ2: Drop27Num | HR2: Drop27TipsProb | HS2: Drop28ID | HU2: Drop28MainClass | HV2: Drop28SubClass | HW2: Drop28Level | HX2: Drop28Prob | HY2: Drop28Num | HZ2: Drop28TipsProb | IA2: Drop29ID | IC2: Drop29MainClass | ID2: Drop29SubClass | IE2: Drop29Level | IF2: Drop29Prob | IG2: Drop29Num | IH2: Drop29TipsProb | II2: Drop30ID | IK2: Drop30MainClass | IL2: Drop30SubClass | IM2: Drop30Level | IN2: Drop30Prob | IO2: Drop30Num | IP2: Drop30TipsProb | IQ2: Drop31ID | IS2: Drop31MainClass | IT2: Drop31SubClass | IU2: Drop31Level | IV2: Drop31Prob | IW2: Drop31Num | IX2: Drop31TipsProb | IY2: Drop32ID | JA2: Drop32MainClass | JB2: Drop32SubClass | JC2: Drop32Level | JD2: Drop32Prob | JE2: Drop32Num | JF2: Drop32TipsProb
A3: =40000000+INDEX(编号表!$B:$B,MATCH(B3,编号表!$A:$A,0))*10000+C3 -> 40010001 | B3: 金币 | C3: 1 | D3: 5级普怪金币50 | E3: 掉落方式_按概率 | F3: =P3+X3+AF3+AN3+AV3+BD3+BL3+BT3 -> 100000000 | J3: =COUNT(P3,X3,AF3,AN3,AV3,BD3,BL3,BT3,CB3,CJ3,CR3,CZ3,DH3,DP3,DX3,EF3,EN3,EV3,FD3,FL3,FT3,GB3,GJ3,GR3,GZ3,HH3,HP3,HX3,IF3,IN3,IV3,JD3) -> 1 | K3: 31010001 | L3: {=INDEX(编号表!$E:$E,MATCH(K3,编号表!$D:$D,0))} -> 一小袋金币 | P3: 100000000 | Q3: 1
A4: =40000000+INDEX(编号表!$B:$B,MATCH(B4,编号表!$A:$A,0))*10000+C4 -> 40010002 | B4: 金币 | C4: 2 | D4: 10级普怪金币100 | E4: 掉落方式_按概率 | F4: =P4+X4+AF4+AN4+AV4+BD4+BL4+BT4 -> 100000000 | J4: =COUNT(P4,X4,AF4,AN4,AV4,BD4,BL4,BT4,CB4,CJ4,CR4,CZ4,DH4,DP4,DX4,EF4,EN4,EV4,FD4,FL4,FT4,GB4,GJ4,GR4,GZ4,HH4,HP4,HX4,IF4,IN4,IV4,JD4) -> 1 | K4: 31010001 | L4: {=INDEX(编号表!$E:$E,MATCH(K4,编号表!$D:$D,0))} -> 一小袋金币 | P4: 100000000 | Q4: 2
A5: =40000000+INDEX(编号表!$B:$B,MATCH(B5,编号表!$A:$A,0))*10000+C5 -> 40010003 | B5: 金币 | C5: 3 | D5: 15级普怪金币150 | E5: 掉落方式_按概率 | F5: =P5+X5+AF5+AN5+AV5+BD5+BL5+BT5 -> 100000000 | J5: =COUNT(P5,X5,AF5,AN5,AV5,BD5,BL5,BT5,CB5,CJ5,CR5,CZ5,DH5,DP5,DX5,EF5,EN5,EV5,FD5,FL5,FT5,GB5,GJ5,GR5,GZ5,HH5,HP5,HX5,IF5,IN5,IV5,JD5) -> 1 | K5: 31010001 | L5: {=INDEX(编号表!$E:$E,MATCH(K5,编号表!$D:$D,0))} -> 一小袋金币 | P5: 100000000 | Q5: 3
A6: =40000000+INDEX(编号表!$B:$B,MATCH(B6,编号表!$A:$A,0))*10000+C6 -> 40010004 | B6: 金币 | C6: 4 | D6: 20级普怪金币200 | E6: 掉落方式_按概率 | F6: =P6+X6+AF6+AN6+AV6+BD6+BL6+BT6 -> 100000000 | J6: =COUNT(P6,X6,AF6,AN6,AV6,BD6,BL6,BT6,CB6,CJ6,CR6,CZ6,DH6,DP6,DX6,EF6,EN6,EV6,FD6,FL6,FT6,GB6,GJ6,GR6,GZ6,HH6,HP6,HX6,IF6,IN6,IV6,JD6) -> 1 | K6: 31010001 | L6: {=INDEX(编号表!$E:$E,MATCH(K6,编号表!$D:$D,0))} -> 一小袋金币 | P6: 100000000 | Q6: 4
A7: =40000000+INDEX(编号表!$B:$B,MATCH(B7,编号表!$A:$A,0))*10000+C7 -> 40010005 | B7: 金币 | C7: 5 | D7: 25级普怪金币250 | E7: 掉落方式_按概率 | F7: =P7+X7+AF7+AN7+AV7+BD7+BL7+BT7 -> 100000000 | J7: =COUNT(P7,X7,AF7,AN7,AV7,BD7,BL7,BT7,CB7,CJ7,CR7,CZ7,DH7,DP7,DX7,EF7,EN7,EV7,FD7,FL7,FT7,GB7,GJ7,GR7,GZ7,HH7,HP7,HX7,IF7,IN7,IV7,JD7) -> 1 | K7: 31010001 | L7: {=INDEX(编号表!$E:$E,MATCH(K7,编号表!$D:$D,0))} -> 一小袋金币 | P7: 100000000 | Q7: 5
A8: =40000000+INDEX(编号表!$B:$B,MATCH(B8,编号表!$A:$A,0))*10000+C8 -> 40010006 | B8: 金币 | C8: 6 | D8: 30级普怪金币300 | E8: 掉落方式_按概率 | F8: =P8+X8+AF8+AN8+AV8+BD8+BL8+BT8 -> 100000000 | J8: =COUNT(P8,X8,AF8,AN8,AV8,BD8,BL8,BT8,CB8,CJ8,CR8,CZ8,DH8,DP8,DX8,EF8,EN8,EV8,FD8,FL8,FT8,GB8,GJ8,GR8,GZ8,HH8,HP8,HX8,IF8,IN8,IV8,JD8) -> 1 | K8: 31010001 | L8: {=INDEX(编号表!$E:$E,MATCH(K8,编号表!$D:$D,0))} -> 一小袋金币 | P8: 100000000 | Q8: 6
A9: =40000000+INDEX(编号表!$B:$B,MATCH(B9,编号表!$A:$A,0))*10000+C9 -> 40010007 | B9: 金币 | C9: 7 | D9: 35级普怪金币350 | E9: 掉落方式_按概率 | F9: =P9+X9+AF9+AN9+AV9+BD9+BL9+BT9 -> 100000000 | J9: =COUNT(P9,X9,AF9,AN9,AV9,BD9,BL9,BT9,CB9,CJ9,CR9,CZ9,DH9,DP9,DX9,EF9,EN9,EV9,FD9,FL9,FT9,GB9,GJ9,GR9,GZ9,HH9,HP9,HX9,IF9,IN9,IV9,JD9) -> 1 | K9: 31010001 | L9: {=INDEX(编号表!$E:$E,MATCH(K9,编号表!$D:$D,0))} -> 一小袋金币 | P9: 100000000 | Q9: 7
A10: =40000000+INDEX(编号表!$B:$B,MATCH(B10,编号表!$A:$A,0))*10000+C10 -> 40010008 | B10: 金币 | C10: 8 | D10: 40级普怪金币400 | E10: 掉落方式_按概率 | F10: =P10+X10+AF10+AN10+AV10+BD10+BL10+BT10 -> 100000000 | J10: =COUNT(P10,X10,AF10,AN10,AV10,BD10,BL10,BT10,CB10,CJ10,CR10,CZ10,DH10,DP10,DX10,EF10,EN10,EV10,FD10,FL10,FT10,GB10,GJ10,GR10,GZ10,HH10,HP10,HX10,IF10,IN10,IV10,JD10) -> 1 | K10: 31010001 | L10: {=INDEX(编号表!$E:$E,MATCH(K10,编号表!$D:$D,0))} -> 一小袋金币 | P10: 100000000 | Q10: 8
A11: =40000000+INDEX(编号表!$B:$B,MATCH(B11,编号表!$A:$A,0))*10000+C11 -> 40010009 | B11: 金币 | C11: 9 | D11: 45级普怪金币450 | E11: 掉落方式_按概率 | F11: =P11+X11+AF11+AN11+AV11+BD11+BL11+BT11 -> 100000000 | J11: =COUNT(P11,X11,AF11,AN11,AV11,BD11,BL11,BT11,CB11,CJ11,CR11,CZ11,DH11,DP11,DX11,EF11,EN11,EV11,FD11,FL11,FT11,GB11,GJ11,GR11,GZ11,HH11,HP11,HX11,IF11,IN11,IV11,JD11) -> 1 | K11: 31010001 | L11: {=INDEX(编号表!$E:$E,MATCH(K11,编号表!$D:$D,0))} -> 一小袋金币 | P11: 100000000 | Q11: 9
A12: =40000000+INDEX(编号表!$B:$B,MATCH(B12,编号表!$A:$A,0))*10000+C12 -> 40010010 | B12: 金币 | C12: 10 | D12: 50级普怪金币500 | E12: 掉落方式_按概率 | F12: =P12+X12+AF12+AN12+AV12+BD12+BL12+BT12 -> 100000000 | J12: =COUNT(P12,X12,AF12,AN12,AV12,BD12,BL12,BT12,CB12,CJ12,CR12,CZ12,DH12,DP12,DX12,EF12,EN12,EV12,FD12,FL12,FT12,GB12,GJ12,GR12,GZ12,HH12,HP12,HX12,IF12,IN12,IV12,JD12) -> 1 | K12: 31010001 | L12: {=INDEX(编号表!$E:$E,MATCH(K12,编号表!$D:$D,0))} -> 一小袋金币 | P12: 100000000 | Q12: 10
A13: =40000000+INDEX(编号表!$B:$B,MATCH(B13,编号表!$A:$A,0))*10000+C13 -> 40010011 | B13: 金币 | C13: 11 | D13: 55级普怪金币550 | E13: 掉落方式_按概率 | F13: =P13+X13+AF13+AN13+AV13+BD13+BL13+BT13 -> 100000000 | J13: =COUNT(P13,X13,AF13,AN13,AV13,BD13,BL13,BT13,CB13,CJ13,CR13,CZ13,DH13,DP13,DX13,EF13,EN13,EV13,FD13,FL13,FT13,GB13,GJ13,GR13,GZ13,HH13,HP13,HX13,IF13,IN13,IV13,JD13) -> 1 | K13: 31010001 | L13: {=INDEX(编号表!$E:$E,MATCH(K13,编号表!$D:$D,0))} -> 一小袋金币 | P13: 100000000 | Q13: 11
A14: =40000000+INDEX(编号表!$B:$B,MATCH(B14,编号表!$A:$A,0))*10000+C14 -> 40010012 | B14: 金币 | C14: 12 | D14: 60级普怪金币600 | E14: 掉落方式_按概率 | F14: =P14+X14+AF14+AN14+AV14+BD14+BL14+BT14 -> 100000000 | J14: =COUNT(P14,X14,AF14,AN14,AV14,BD14,BL14,BT14,CB14,CJ14,CR14,CZ14,DH14,DP14,DX14,EF14,EN14,EV14,FD14,FL14,FT14,GB14,GJ14,GR14,GZ14,HH14,HP14,HX14,IF14,IN14,IV14,JD14) -> 1 | K14: 31010001 | L14: {=INDEX(编号表!$E:$E,MATCH(K14,编号表!$D:$D,0))} -> 一小袋金币 | P14: 100000000 | Q14: 12
... A33: =40000000+INDEX(编号表!$B:$B,MATCH(B33,编号表!$A:$A,0))*10000+C33 -> 40010031 | B33: 金币 | C33: 31 | D33: 70级精英金币2100 | E33: 掉落方式_按概率 | F33: =P33+X33+AF33+AN33+AV33+BD33+BL33+BT33 -> 100000000 | J33: =COUNT(P33,X33,AF33,AN33,AV33,BD33,BL33,BT33,CB33,CJ33,CR33,CZ33,DH33,DP33,DX33,EF33,EN33,EV33,FD33,FL33,FT33,GB33,GJ33,GR33,GZ33,HH33,HP33,HX33,IF33,IN33,IV33,JD33) -> 1 | K33: 31010001 | L33: {=INDEX(编号表!$E:$E,MATCH(K33,编号表!$D:$D,0))} -> 一小袋金币 | P33: 100000000 | Q33: 42
A34: =40000000+INDEX(编号表!$B:$B,MATCH(B34,编号表!$A:$A,0))*10000+C34 -> 40010032 | B34: 金币 | C34: 32 | D34: 75级精英金币2250 | E34: 掉落方式_按概率 | F34: =P34+X34+AF34+AN34+AV34+BD34+BL34+BT34 -> 100000000 | J34: =COUNT(P34,X34,AF34,AN34,AV34,BD34,BL34,BT34,CB34,CJ34,CR34,CZ34,DH34,DP34,DX34,EF34,EN34,EV34,FD34,FL34,FT34,GB34,GJ34,GR34,GZ34,HH34,HP34,HX34,IF34,IN34,IV34,JD34) -> 1 | K34: 31010001 | L34: {=INDEX(编号表!$E:$E,MATCH(K34,编号表!$D:$D,0))} -> 一小袋金币 | P34: 100000000 | Q34: =2250/50 -> 45
A35: =40000000+INDEX(编号表!$B:$B,MATCH(B35,编号表!$A:$A,0))*10000+C35 -> 40010033 | B35: 金币 | C35: 33 | D35: 80级精英金币2400 | E35: 掉落方式_按概率 | F35: =P35+X35+AF35+AN35+AV35+BD35+BL35+BT35 -> 100000000 | J35: =COUNT(P35,X35,AF35,AN35,AV35,BD35,BL35,BT35,CB35,CJ35,CR35,CZ35,DH35,DP35,DX35,EF35,EN35,EV35,FD35,FL35,FT35,GB35,GJ35,GR35,GZ35,HH35,HP35,HX35,IF35,IN35,IV35,JD35) -> 1 | K35: 31010001 | L35: {=INDEX(编号表!$E:$E,MATCH(K35,编号表!$D:$D,0))} -> 一小袋金币 | P35: 100000000 | Q35: 48
A36: =40000000+INDEX(编号表!$B:$B,MATCH(B36,编号表!$A:$A,0))*10000+C36 -> 40010034 | B36: 金币 | C36: 34 | D36: 85级精英金币2550 | E36: 掉落方式_按概率 | F36: =P36+X36+AF36+AN36+AV36+BD36+BL36+BT36 -> 100000000 | J36: =COUNT(P36,X36,AF36,AN36,AV36,BD36,BL36,BT36,CB36,CJ36,CR36,CZ36,DH36,DP36,DX36,EF36,EN36,EV36,FD36,FL36,FT36,GB36,GJ36,GR36,GZ36,HH36,HP36,HX36,IF36,IN36,IV36,JD36) -> 1 | K36: 31010001 | L36: {=INDEX(编号表!$E:$E,MATCH(K36,编号表!$D:$D,0))} -> 一小袋金币 | P36: 100000000 | Q36: 51
A37: =40000000+INDEX(编号表!$B:$B,MATCH(B37,编号表!$A:$A,0))*10000+C37 -> 40010035 | B37: 金币 | C37: 35 | D37: 5级BOSS金币450 | E37: 掉落方式_按概率 | F37: =P37+X37+AF37+AN37+AV37+BD37+BL37+BT37 -> 100000000 | J37: =COUNT(P37,X37,AF37,AN37,AV37,BD37,BL37,BT37,CB37,CJ37,CR37,CZ37,DH37,DP37,DX37,EF37,EN37,EV37,FD37,FL37,FT37,GB37,GJ37,GR37,GZ37,HH37,HP37,HX37,IF37,IN37,IV37,JD37) -> 1 | K37: 31010001 | L37: {=INDEX(编号表!$E:$E,MATCH(K37,编号表!$D:$D,0))} -> 一小袋金币 | P37: 100000000 | Q37: 9
A38: =40000000+INDEX(编号表!$B:$B,MATCH(B38,编号表!$A:$A,0))*10000+C38 -> 40010036 | B38: 金币 | C38: 36 | D38: 10级BOSS金币900 | E38: 掉落方式_按概率 | F38: =P38+X38+AF38+AN38+AV38+BD38+BL38+BT38 -> 100000000 | J38: =COUNT(P38,X38,AF38,AN38,AV38,BD38,BL38,BT38,CB38,CJ38,CR38,CZ38,DH38,DP38,DX38,EF38,EN38,EV38,FD38,FL38,FT38,GB38,GJ38,GR38,GZ38,HH38,HP38,HX38,IF38,IN38,IV38,JD38) -> 1 | K38: 31010001 | L38: {=INDEX(编号表!$E:$E,MATCH(K38,编号表!$D:$D,0))} -> 一小袋金币 | P38: 100000000 | Q38: 18
A39: =40000000+INDEX(编号表!$B:$B,MATCH(B39,编号表!$A:$A,0))*10000+C39 -> 40010037 | B39: 金币 | C39: 37 | D39: 15级BOSS金币1350 | E39: 掉落方式_按概率 | F39: =P39+X39+AF39+AN39+AV39+BD39+BL39+BT39 -> 100000000 | J39: =COUNT(P39,X39,AF39,AN39,AV39,BD39,BL39,BT39,CB39,CJ39,CR39,CZ39,DH39,DP39,DX39,EF39,EN39,EV39,FD39,FL39,FT39,GB39,GJ39,GR39,GZ39,HH39,HP39,HX39,IF39,IN39,IV39,JD39) -> 1 | K39: 31010001 | L39: {=INDEX(编号表!$E:$E,MATCH(K39,编号表!$D:$D,0))} -> 一小袋金币 | P39: 100000000 | Q39: 27
A40: =40000000+INDEX(编号表!$B:$B,MATCH(B40,编号表!$A:$A,0))*10000+C40 -> 40010038 | B40: 金币 | C40: 38 | D40: 20级BOSS金币1800 | E40: 掉落方式_按概率 | F40: =P40+X40+AF40+AN40+AV40+BD40+BL40+BT40 -> 100000000 | J40: =COUNT(P40,X40,AF40,AN40,AV40,BD40,BL40,BT40,CB40,CJ40,CR40,CZ40,DH40,DP40,DX40,EF40,EN40,EV40,FD40,FL40,FT40,GB40,GJ40,GR40,GZ40,HH40,HP40,HX40,IF40,IN40,IV40,JD40) -> 1 | K40: 31010001 | L40: {=INDEX(编号表!$E:$E,MATCH(K40,编号表!$D:$D,0))} -> 一小袋金币 | P40: 100000000 | Q40: 36
A41: =40000000+INDEX(编号表!$B:$B,MATCH(B41,编号表!$A:$A,0))*10000+C41 -> 40010039 | B41: 金币 | C41: 39 | D41: 25级BOSS金币2250 | E41: 掉落方式_按概率 | F41: =P41+X41+AF41+AN41+AV41+BD41+BL41+BT41 -> 100000000 | J41: =COUNT(P41,X41,AF41,AN41,AV41,BD41,BL41,BT41,CB41,CJ41,CR41,CZ41,DH41,DP41,DX41,EF41,EN41,EV41,FD41,FL41,FT41,GB41,GJ41,GR41,GZ41,HH41,HP41,HX41,IF41,IN41,IV41,JD41) -> 1 | K41: 31010001 | L41: {=INDEX(编号表!$E:$E,MATCH(K41,编号表!$D:$D,0))} -> 一小袋金币 | P41: 100000000 | Q41: 45
A42: =40000000+INDEX(编号表!$B:$B,MATCH(B42,编号表!$A:$A,0))*10000+C42 -> 40010040 | B42: 金币 | C42: 40 | D42: 30级BOSS金币2700 | E42: 掉落方式_按概率 | F42: =P42+X42+AF42+AN42+AV42+BD42+BL42+BT42 -> 100000000 | J42: =COUNT(P42,X42,AF42,AN42,AV42,BD42,BL42,BT42,CB42,CJ42,CR42,CZ42,DH42,DP42,DX42,EF42,EN42,EV42,FD42,FL42,FT42,GB42,GJ42,GR42,GZ42,HH42,HP42,HX42,IF42,IN42,IV42,JD42) -> 1 | K42: 31010001 | L42: {=INDEX(编号表!$E:$E,MATCH(K42,编号表!$D:$D,0))} -> 一小袋金币 | P42: 100000000 | Q42: 54
A43: =40000000+INDEX(编号表!$B:$B,MATCH(B43,编号表!$A:$A,0))*10000+C43 -> 40010041 | B43: 金币 | C43: 41 | D43: 35级BOSS金币3150 | E43: 掉落方式_按概率 | F43: =P43+X43+AF43+AN43+AV43+BD43+BL43+BT43 -> 100000000 | J43: =COUNT(P43,X43,AF43,AN43,AV43,BD43,BL43,BT43,CB43,CJ43,CR43,CZ43,DH43,DP43,DX43,EF43,EN43,EV43,FD43,FL43,FT43,GB43,GJ43,GR43,GZ43,HH43,HP43,HX43,IF43,IN43,IV43,JD43) -> 1 | K43: 31010001 | L43: {=INDEX(编号表!$E:$E,MATCH(K43,编号表!$D:$D,0))} -> 一小袋金币 | P43: 100000000 | Q43: 63
A44: =40000000+INDEX(编号表!$B:$B,MATCH(B44,编号表!$A:$A,0))*10000+C44 -> 40010042 | B44: 金币 | C44: 42 | D44: 40级BOSS金币3600 | E44: 掉落方式_按概率 | F44: =P44+X44+AF44+AN44+AV44+BD44+BL44+BT44 -> 100000000 | J44: =COUNT(P44,X44,AF44,AN44,AV44,BD44,BL44,BT44,CB44,CJ44,CR44,CZ44,DH44,DP44,DX44,EF44,EN44,EV44,FD44,FL44,FT44,GB44,GJ44,GR44,GZ44,HH44,HP44,HX44,IF44,IN44,IV44,JD44) -> 1 | K44: 31010001 | L44: {=INDEX(编号表!$E:$E,MATCH(K44,编号表!$D:$D,0))} -> 一小袋金币 | P44: 100000000 | Q44: 72
A45: =40000000+INDEX(编号表!$B:$B,MATCH(B45,编号表!$A:$A,0))*10000+C45 -> 40010043 | B45: 金币 | C45: 43 | D45: 45级BOSS金币4050 | E45: 掉落方式_按概率 | F45: =P45+X45+AF45+AN45+AV45+BD45+BL45+BT45 -> 100000000 | J45: =COUNT(P45,X45,AF45,AN45,AV45,BD45,BL45,BT45,CB45,CJ45,CR45,CZ45,DH45,DP45,DX45,EF45,EN45,EV45,FD45,FL45,FT45,GB45,GJ45,GR45,GZ45,HH45,HP45,HX45,IF45,IN45,IV45,JD45) -> 1 | K45: 31010001 | L45: {=INDEX(编号表!$E:$E,MATCH(K45,编号表!$D:$D,0))} -> 一小袋金币 | P45: 100000000 | Q45: 81
A46: =40000000+INDEX(编号表!$B:$B,MATCH(B46,编号表!$A:$A,0))*10000+C46 -> 40010044 | B46: 金币 | C46: 44 | D46: 50级BOSS金币4500 | E46: 掉落方式_按概率 | F46: =P46+X46+AF46+AN46+AV46+BD46+BL46+BT46 -> 100000000 | J46: =COUNT(P46,X46,AF46,AN46,AV46,BD46,BL46,BT46,CB46,CJ46,CR46,CZ46,DH46,DP46,DX46,EF46,EN46,EV46,FD46,FL46,FT46,GB46,GJ46,GR46,GZ46,HH46,HP46,HX46,IF46,IN46,IV46,JD46) -> 1 | K46: 31010001 | L46: {=INDEX(编号表!$E:$E,MATCH(K46,编号表!$D:$D,0))} -> 一小袋金币 | P46: 100000000 | Q46: 90
... A87: =40000000+INDEX(编号表!$B:$B,MATCH(B87,编号表!$A:$A,0))*10000+C87 -> 40020034 | B87: 灵符 | C87: 34 | D87: 85级BOSS灵符255 | E87: 掉落方式_按概率 | F87: =P87+X87+AF87+AN87+AV87+BD87+BL87+BT87 -> 100000000 | J87: =COUNT(P87,X87,AF87,AN87,AV87,BD87,BL87,BT87,CB87,CJ87,CR87,CZ87,DH87,DP87,DX87,EF87,EN87,EV87,FD87,FL87,FT87,GB87,GJ87,GR87,GZ87,HH87,HP87,HX87,IF87,IN87,IV87,JD87) -> 1 | K87: 31010002 | L87: {=INDEX(编号表!$E:$E,MATCH(K87,编号表!$D:$D,0))} -> 一小袋灵符 | P87: 100000000 | Q87: 51
A88: =40000000+INDEX(编号表!$B:$B,MATCH(B88,编号表!$A:$A,0))*10000+C88 -> 40050001 | B88: 六格 | C88: 1 | D88: 前10级六格 | E88: 掉落方式_按概率 | F88: =P88+X88+AF88+AN88+AV88+BD88+BL88+BT88 -> 1000000 | J88: =COUNT(P88,X88,AF88,AN88,AV88,BD88,BL88,BT88,CB88,CJ88,CR88,CZ88,DH88,DP88,DX88,EF88,EN88,EV88,FD88,FL88,FT88,GB88,GJ88,GR88,GZ88,HH88,HP88,HX88,IF88,IN88,IV88,JD88) -> 1 | M88: 大类_六格 | N88: 小类_B沃玛级C | O88: 白色 | P88: 1000000 | Q88: 1
A89: =40000000+INDEX(编号表!$B:$B,MATCH(B89,编号表!$A:$A,0))*10000+C89 -> 40050002 | B89: 六格 | C89: 2 | D89: 11到20级六格 | E89: 掉落方式_按概率 | F89: =P89+X89+AF89+AN89+AV89+BD89+BL89+BT89 -> 1000000 | J89: =COUNT(P89,X89,AF89,AN89,AV89,BD89,BL89,BT89,CB89,CJ89,CR89,CZ89,DH89,DP89,DX89,EF89,EN89,EV89,FD89,FL89,FT89,GB89,GJ89,GR89,GZ89,HH89,HP89,HX89,IF89,IN89,IV89,JD89) -> 1 | M89: 大类_六格 | N89: 小类_B沃玛级C | O89: 白色 | P89: 1000000 | Q89: 1
A90: =40000000+INDEX(编号表!$B:$B,MATCH(B90,编号表!$A:$A,0))*10000+C90 -> 40050003 | B90: 六格 | C90: 3 | D90: 21到30级六格 | E90: 掉落方式_按概率 | F90: =P90+X90+AF90+AN90+AV90+BD90+BL90+BT90 -> 1000000 | J90: =COUNT(P90,X90,AF90,AN90,AV90,BD90,BL90,BT90,CB90,CJ90,CR90,CZ90,DH90,DP90,DX90,EF90,EN90,EV90,FD90,FL90,FT90,GB90,GJ90,GR90,GZ90,HH90,HP90,HX90,IF90,IN90,IV90,JD90) -> 1 | M90: 大类_六格 | N90: 小类_B沃玛级C | O90: 白色 | P90: 1000000 | Q90: 1
A91: =40000000+INDEX(编号表!$B:$B,MATCH(B91,编号表!$A:$A,0))*10000+C91 -> 40050004 | B91: 六格 | C91: 4 | D91: 31到35级六格 | E91: 掉落方式_按概率 | F91: =P91+X91+AF91+AN91+AV91+BD91+BL91+BT91 -> 1000000 | J91: =COUNT(P91,X91,AF91,AN91,AV91,BD91,BL91,BT91,CB91,CJ91,CR91,CZ91,DH91,DP91,DX91,EF91,EN91,EV91,FD91,FL91,FT91,GB91,GJ91,GR91,GZ91,HH91,HP91,HX91,IF91,IN91,IV91,JD91) -> 1 | M91: 大类_六格 | N91: 小类_B沃玛级C | O91: 白色 | P91: 1000000 | Q91: 1
A92: =40000000+INDEX(编号表!$B:$B,MATCH(B92,编号表!$A:$A,0))*10000+C92 -> 40050005 | B92: 六格 | C92: 5 | D92: 35到40级六格 | E92: 掉落方式_按概率 | F92: =P92+X92+AF92+AN92+AV92+BD92+BL92+BT92 -> 1000000 | J92: =COUNT(P92,X92,AF92,AN92,AV92,BD92,BL92,BT92,CB92,CJ92,CR92,CZ92,DH92,DP92,DX92,EF92,EN92,EV92,FD92,FL92,FT92,GB92,GJ92,GR92,GZ92,HH92,HP92,HX92,IF92,IN92,IV92,JD92) -> 1 | M92: 大类_六格 | N92: 小类_C祖玛级A | O92: 绿色 | P92: 1000000 | Q92: 1
A93: =40000000+INDEX(编号表!$B:$B,MATCH(B93,编号表!$A:$A,0))*10000+C93 -> 40050006 | B93: 六格 | C93: 6 | D93: 41到45级六格 | E93: 掉落方式_按概率 | F93: =P93+X93+AF93+AN93+AV93+BD93+BL93+BT93 -> 1000000 | J93: =COUNT(P93,X93,AF93,AN93,AV93,BD93,BL93,BT93,CB93,CJ93,CR93,CZ93,DH93,DP93,DX93,EF93,EN93,EV93,FD93,FL93,FT93,GB93,GJ93,GR93,GZ93,HH93,HP93,HX93,IF93,IN93,IV93,JD93) -> 1 | M93: 大类_六格 | N93: 小类_C祖玛级A | O93: 绿色 | P93: 1000000 | Q93: 1
A94: =40000000+INDEX(编号表!$B:$B,MATCH(B94,编号表!$A:$A,0))*10000+C94 -> 40050007 | B94: 六格 | C94: 7 | D94: 46到50级六格 | E94: 掉落方式_按概率 | F94: =P94+X94+AF94+AN94+AV94+BD94+BL94+BT94 -> 1000000 | J94: =COUNT(P94,X94,AF94,AN94,AV94,BD94,BL94,BT94,CB94,CJ94,CR94,CZ94,DH94,DP94,DX94,EF94,EN94,EV94,FD94,FL94,FT94,GB94,GJ94,GR94,GZ94,HH94,HP94,HX94,IF94,IN94,IV94,JD94) -> 1 | M94: 大类_六格 | N94: 小类_D苍月级 | O94: 紫色 | P94: 1000000 | Q94: 1
A95: =40000000+INDEX(编号表!$B:$B,MATCH(B95,编号表!$A:$A,0))*10000+C95 -> 40050008 | B95: 六格 | C95: 8 | D95: 51到55级六格 | E95: 掉落方式_按概率 | F95: =P95+X95+AF95+AN95+AV95+BD95+BL95+BT95 -> 1000000 | J95: =COUNT(P95,X95,AF95,AN95,AV95,BD95,BL95,BT95,CB95,CJ95,CR95,CZ95,DH95,DP95,DX95,EF95,EN95,EV95,FD95,FL95,FT95,GB95,GJ95,GR95,GZ95,HH95,HP95,HX95,IF95,IN95,IV95,JD95) -> 1 | M95: 大类_六格 | N95: 小类_E赤月级 | O95: 紫色 | P95: 1000000 | Q95: 1
A96: =40000000+INDEX(编号表!$B:$B,MATCH(B96,编号表!$A:$A,0))*10000+C96 -> 40050009 | B96: 六格 | C96: 9 | D96: 56到60级六格 | E96: 掉落方式_按概率 | F96: =P96+X96+AF96+AN96+AV96+BD96+BL96+BT96 -> 1000000 | J96: =COUNT(P96,X96,AF96,AN96,AV96,BD96,BL96,BT96,CB96,CJ96,CR96,CZ96,DH96,DP96,DX96,EF96,EN96,EV96,FD96,FL96,FT96,GB96,GJ96,GR96,GZ96,HH96,HP96,HX96,IF96,IN96,IV96,JD96) -> 1 | M96: 大类_六格 | N96: 小类_F魔龙级 | O96: 橙色 | P96: 1000000 | Q96: 1
A97: =40000000+INDEX(编号表!$B:$B,MATCH(B97,编号表!$A:$A,0))*10000+C97 -> 40050010 | B97: 六格 | C97: 10 | D97: 61到65级六格 | E97: 掉落方式_按概率 | F97: =P97+X97+AF97+AN97+AV97+BD97+BL97+BT97 -> 1000000 | J97: =COUNT(P97,X97,AF97,AN97,AV97,BD97,BL97,BT97,CB97,CJ97,CR97,CZ97,DH97,DP97,DX97,EF97,EN97,EV97,FD97,FL97,FT97,GB97,GJ97,GR97,GZ97,HH97,HP97,HX97,IF97,IN97,IV97,JD97) -> 1 | M97: 大类_六格 | N97: 小类_G雷炎级 | O97: 橙色 | P97: 1000000 | Q97: 1
A98: =40000000+INDEX(编号表!$B:$B,MATCH(B98,编号表!$A:$A,0))*10000+C98 -> 40050011 | B98: 六格 | C98: 11 | D98: 66到70级六格 | E98: 掉落方式_按概率 | F98: =P98+X98+AF98+AN98+AV98+BD98+BL98+BT98 -> 1000000 | J98: =COUNT(P98,X98,AF98,AN98,AV98,BD98,BL98,BT98,CB98,CJ98,CR98,CZ98,DH98,DP98,DX98,EF98,EN98,EV98,FD98,FL98,FT98,GB98,GJ98,GR98,GZ98,HH98,HP98,HX98,IF98,IN98,IV98,JD98) -> 1 | M98: 大类_六格 | N98: 小类_H卧龙级 | O98: 红色 | P98: 1000000 | Q98: 1
...

Sheet 编号表
A1: 内部名 | B1: 编号 | D1: 道具ID | E1: 0名称
A2: 金币 | B2: 1 | D2: ID | E2: Name
A3: 灵符 | B3: 2 | D3: 31010001 | E3: 一小袋金币
A4: 基础装备 | B4: 3 | D4: 31010002 | E4: 一小袋灵符
A5: 四格 | B5: 4 | D5: 31010003 | E5: 一袋金币
A6: 六格 | B6: 5 | D6: 31010004 | E6: 一袋灵符
A7: 配饰 | B7: 6 | D7: 31010005 | E7: 一大袋金币
A8: 斗盾 | B8: 7 | D8: 31010006 | E8: 一大袋灵符
A9: 低级药品 | B9: 8 | D9: 31010007 | E9: 一箱金币
A10: 中级药品 | B10: 9 | D10: 31010008 | E10: 一箱灵符
A11: 高级药品 | B11: 10 | D11: 31010009 | E11: 一大箱金币
A12: 普通道具 | B12: 11 | D12: 31010010 | E12: 一大箱灵符 | H12: 道具ID必须下拉，使用公式自动生成ID！！！
A13: BOSS掉落 | B13: 12 | D13: 31010011 | E13: 一车金币
A14: 精英掉落 | B14: 13 | D14: 31010012 | E14: 一车灵符
A15: 普通掉落 | B15: 14 | D15: 31010013 | E15: 一卡车金币
A16: 任务掉落 | B16: 15 | D16: 31010014 | E16: 一卡车灵符
A17: 珍惜道具 | B17: 16 | D17: 31010015 | E17: 活跃丹
B18: 17 | D18: 31010016 | E18: 声望丹
B19: 18 | D19: 34020001 | E19: 基础剑术
B20: 19 | D20: 34020002 | E20: 攻杀剑术
B21: 20 | D21: 34020003 | E21: 刺杀剑术
B22: 21 | D22: 34020004 | E22: 半月弯刀
B23: 22 | D23: 34020005 | E23: 野蛮冲撞
B24: 23 | D24: 34020006 | E24: 烈火剑法
B25: 24 | D25: 34020031 | E25: 火球术
B26: 25 | D26: 34020032 | E26: 抗拒火环
B27: 26 | D27: 34020033 | E27: 雷电术
B28: 27 | D28: 34020034 | E28: 火墙
B29: 28 | D29: 34020035 | E29: 疾光电影
... B74: 73 | D74: 30070017 | E74: 法神纹
D75: 30070018 | E75: 火符铭文
D76: 30070019 | E76: 治愈铭文
D77: 30070020 | E77: 施毒铭文
D78: 30070021 | E78: 骷髅铭文
D79: 30070022 | E79: 隐身铭文
D80: 30070023 | E80: 幽灵铭文
D81: 30070024 | E81: 神圣铭文
D82: 30070025 | E82: 神兽铭文
D83: 30070026 | E83: 困魔铭文
D84: 30070027 | E84: 道神纹
...

Sheet 名称表
A1: 掉落方式_按概率 | C1: 随机装备绑定类型 | D1: 频率 | E1: 怪物等级开始 | F1: 怪物等级结束 | G1: 怪物等级 | J1: 礼包类型 | L1: 副本等级 | M1: 掉落方案尾数 | O1: 显示方式 | Q1: 是否礼包中心
A2: 掉落方式_按个数和概率可重复 | C2: 不绑定 | D2: 一日 | E2: 1 | F2: 4 | G2: =E2&"-"&F2&"级" -> 1-4级 | J2: 礼包类型_升级礼包 | L2: 3 | M2: 1 | O2: 显示为系统消息 | Q2: 是
A3: 掉落方式_按个数和概率不可重复 | C3: 拾取绑定 | D3: 一周 | E3: 5 | F3: 9 | G3: =E3&"-"&F3&"级" -> 5-9级 | J3: 礼包类型_每周礼包 | L3: 8 | M3: 2 | O3: 显示为提示消息 | Q3: 否
C4: 使用绑定 | D4: 一月 | E4: 10 | F4: 14 | G4: =E4&"-"&F4&"级" -> 10-14级 | J4: 礼包类型_特别礼包 | L4: =E4 -> 10 | M4: 3 | O4: 左下角显示为系统消息
D5: 一年 | E5: 15 | F5: 19 | G5: =E5&"-"&F5&"级" -> 15-19级 | J5: 礼包类型_每日赠送 | L5: =E5 -> 15 | M5: 4 | O5: 中间滚动显示系统消息
E6: 20 | F6: 24 | G6: =E6&"-"&F6&"级" -> 20-24级 | J6: 礼包类型_充值狂欢大返利 | L6: =E6 -> 20 | M6: 5 | O6: 中间显示信息
E7: 25 | F7: 29 | G7: =E7&"-"&F7&"级" -> 25-29级 | J7: 礼包类型_首次充值赠好礼 | L7: =E7 -> 25 | M7: 6
E8: 30 | F8: 34 | G8: =E8&"-"&F8&"级" -> 30-34级 | L8: =E8 -> 30 | M8: 7
E9: 35 | F9: 39 | G9: =E9&"-"&F9&"级" -> 35-39级 | J9: 礼包类型_在线奖励拿不完 | L9: =E9 -> 35 | M9: 8
E10: 40 | F10: 44 | G10: =E10&"-"&F10&"级" -> 40-44级 | J10: 礼包类型_收藏桌面喜开怀 | L10: =E10 -> 40 | M10: 9
E11: 45 | F11: 49 | G11: =E11&"-"&F11&"级" -> 45-49级 | J11: 礼包类型_累积签到礼包 | L11: =E11 -> 45 | M11: 10
E12: 50 | F12: 54 | G12: =E12&"-"&F12&"级" -> 50-54级 | L12: =E12 -> 50 | M12: 11
E13: 55 | F13: 59 | G13: =E13&"-"&F13&"级" -> 55-59级 | J13: 礼包类型_开服签到 | L13: 52 | M13: 12
E14: 60 | F14: 64 | G14: =E14&"-"&F14&"级" -> 60-64级 | J14: 礼包类型_消费狂欢大返利 | L14: 60 | M14: 13
E15: 65 | F15: 69 | G15: =E15&"-"&F15&"级" -> 65-69级 | J15: 礼包类型_360卫士特权礼包 | L15: 62 | M15: 14
E16: 70 | F16: 74 | G16: =E16&"-"&F16&"级" -> 70-74级 | L16: 70 | M16: 15
E17: 75 | F17: 79 | G17: =E17&"-"&F17&"级" -> 75-79级 | L17: 72 | M17: 16
E18: 80 | F18: 84 | G18: =E18&"-"&F18&"级" -> 80-84级 | L18: 80 | M18: 17
E19: 85 | F19: 89 | G19: =E19&"-"&F19&"级" -> 85-89级 | L19: 82 | M19: 18
E20: 90 | F20: 94 | G20: =E20&"-"&F20&"级" -> 90-94级 | L20: 90 | M20: 19
E21: 95 | F21: 99 | G21: =E21&"-"&F21&"级" -> 95-99级 | L21: 92 | M21: 20
L22: 100 | M22: 21
L23: 102 | M23: 22

Sheet 字段说明
C1: 转表
A2: 掉落方案ID | B2: 掉落方案的唯一标识ID | C2: √ | G2: 分类 | H2: 部位 | I2: 开放等级来约束前期基础数值（参考） | J2: 级别 | N2: 大类_基础装备 | O2: 小类_A新手 | P2: 0-9 | Q2: 白色
A3: 方案说明 | B3: 方案的用途 | G3: 基础装备 | H3: 武器 | I3: 1 | J3: 新手级 | N3: 大类_特殊C | O3: 小类_B沃玛级B | P3: 等级10-20 | Q3: 绿色
A4: 掉落方式 | B4: 按何种方式掉落 为了满足不同掉落情况，请参见“掉落方式说明”页 | C4: √ | G4: 基础装备 | H4: 戒指 | I4: 1 | J4: 新手级 | N4: 大类_四格 | O4: 小类_B沃玛级A | P4: 等级20-30 | Q4: 紫色
A5: 最小掉落数 | B5: 最小必须掉落的个数，为0时表示可以不掉落 | C5: √ | G5: 基础装备 | H5: 项链 | I5: 1 | J5: 新手级 | N5: 大类_斗盾 | O5: 小类_B沃玛级C | P5: 等级31-35 | Q5: 橙色
A6: 最大掉落数 | B6: 最多掉落的个数 | C6: √ | G6: 基础装备 | H6: 手镯 | I6: 1 | J6: 新手级 | N6: 大类_配饰 | O6: 小类_C祖玛级A | P6: 36-40 | Q6: 红色
A7: 随机装备白色概率 | B7: 掉落方案中的随机装备白色出现几率 | G7: 基础装备 | H7: 头盔 | I7: 1 | J7: 新手级 | N7: 大类_六格 | O7: 小类_C祖玛级B | P7: 41-45
A8: 随机装备绿色概率 | B8: 掉落方案中的随机装备绿色出现几率 | C8: √ | G8: 基础装备 | H8: 衣服 | I8: 1 | J8: 新手级 | O8: 小类_D苍月级 | P8: 46-50
A9: 随机装备蓝色概率 | B9: 掉落方案中的随机装备蓝色出现几率 | C9: √ | G9: 基础装备 | H9: 鞋子 | I9: 10 | J9: B沃玛级 | O9: 小类_E赤月级 | P9: 51-55
A10: 随机装备紫色概率 | B10: 掉落方案中的随机装备紫色出现几率 | C10: √ | G10: 基础装备 | H10: 腰带 | I10: 10 | J10: B沃玛级 | O10: 小类_F魔龙级 | P10: 56-60
A11: 随机装备绑定类型 | B11: 掉落方案中的随机装备的绑定类型 | C11: √ | G11: 斗盾 | H11: 斗笠 | I11: 20 | J11: B沃玛级 | O11: 小类_G雷炎级 | P11: 61-65
A12: 是否按职业掉落 | B12: 掉落方案中的随机装备是否需要根据获得者的职业生成 | C12: √ | G12: 斗盾 | H12: 盾牌 | I12: 20 | J12: B沃玛级 | O12: 小类_H卧龙级 | P12: 66-70
A13: 掉落物数量 | B13: 掉落方案中总共填些了多少个掉落物 | C13: √ | G13: 配饰 | H13: 配饰 | I13: 20 | J13: B沃玛级 | O13: 小类_I魔王级 | P13: 71-75
A14: 掉落物ID1 | B14: 掉落物1的ID，掉落物分两种方式掉落——按ID、按大类子类档次 填写了ID时必然按ID掉落，此时大类子类档次的填写无效 | C14: √ | G14: 特殊C | H14: 翅膀 | I14: 不管 | O14: 小类_J狐月级 | P14: 76-80
A15: 掉落物名称1 | B15: 掉落物1的名称 | G15: 四格 | H15: 勋章 | I15: 25 | J15: B沃玛级 | O15: 小类_K雪域级 | P15: 81-85
A16: 掉落物大类1 | B16: 掉落物1的大类 | C16: √ | G16: 四格 | H16: 血符 | I16: 30 | J16: B沃玛级 | O16: 小类_B沃玛级 | P16: 10-35
A17: 掉落物子类1 | B17: 掉落物1的子类 | C17: √ | G17: 四格 | H17: 晶石 | I17: 30 | J17: B沃玛级 | O17: 小类_C祖玛级 | P17: 36-45
A18: 掉落物档次1 | B18: 掉落物1的档次 | C18: √ | G18: 特殊C | H18: 马匹 | I18: 不管
A19: 掉落物概率1 | B19: 掉落物1的掉落概率，亿分比 | C19: √ | G19: 六格 | H19: 虎符 | I19: 35 | J19: C祖玛级
A20: 系统提示概率1 | B20: 掉落物1掉落后全服广播的概率 | C20: √ | G20: 六格 | H20: 宝珠 | I20: 35 | J20: C祖玛级
G21: 六格 | H21: 军鼓 | I21: 35 | J21: C祖玛级
G22: 六格 | H22: 军旗 | I22: 35 | J22: C祖玛级
G23: 六格 | H23: 印章 | I23: 35 | J23: C祖玛级
A24: 装备 | B24: 大类档次必须指定，子类和职业可以随机 | G24: 六格 | H24: 玉佩 | I24: 35 | J24: C祖玛级
A25: 物品 | B25: 大类必须指定，子类和档次可以随机

Sheet 掉落方式说明
A1: 掉落方式_完全随机可重复
A2: 1、 | B2: 在掉落个数【Min, Max】内随机一个掉落数Select。
A3: 2、 | B3: 如果有衰减，则对Select进行衰减，newSelect=Select*（1-衰减系数）
A4: 3、 | B4: 如果newSelect大于1，则向下取整，newSelect=int（Select）
A5: 4、 | B5: 如果newSelect小于1，则从【0，1】中随机抽一个小数，如果该小数小于newSelect，则掉落1个物品（newSelect = 1），否则 newSelect = 0
A6: 5、 | B6: 从该方案的总物品数目Total中，以完全随机的方式，抽取newSelect次，每次抽取1个进行掉落，方案中的每个物品机会均等。
A7: 6、 | B7: 每个掉落物配置的都是自己的掉落几率，总和不限
A8: 掉落方式_完全随机不可重复
A9: 1、 | B9: 在掉落个数【Min, Max】内随机一个掉落数Select。
A10: 2、 | B10: 如果有衰减，则对Select进行衰减，newSelect=Select*（1-衰减系数） | C10: 5
A11: 3、 | B11: 如果newSelect大于1，则向下取整，newSelect=int（Select）
A12: 4、 | B12: 如果newSelect小于1，则从【0，1】中随机抽一个小数，如果该小数小于newSelect，则掉落1个物品（newSelect = 1），否则 newSelect = 0
A13: 5、 | B13: 从该方案的总物品数目Total中，以完全随机的方式，抽取newSelect个进行掉落，方案中的每个物品机会均等。
A14: 6、 | B14: 如果方案的总物品个数Total小于随机选择的掉落个数newSelect，那么实际掉落数目为Total。
A15: 7、 | B15: 每个掉落物配置的都是自己的掉落几率，总和不限
A16: 掉落方式_按概率
A17: 1、 | B17: 如果有衰减，则各物品的实际掉落概率=原概率*（1-衰减系数）
A18: 2、 | B18: 对方案中的每个物品，按照亿分之的概率进行随机，将所有符合该概率的物品筛选出来。
A19: 3、 | B19: 如果符合概率的物品个数小于Max，那么则筛选出的物品全部掉落
A20: 4、 | B20: 如果符合概率的物品个数大于Max，则从其中随机选择Max个。
A21: 5、 | B21: 允许一个物品都不掉落
A22: 6、 | B22: 每个掉落物配置掉落几率，总和不限
A24: 说明： | B24: 此掉落方式中MinDropNumber无效
A26: 掉落方式_按个数和概率可重复 | B26: （a，掉落个数为[Min, Max] 。 b， 该掉落方式中，策划表中每个物品的配置概率数值之和不可超过1亿）
A27: 1、 | B27: 在掉落个数【Min, Max】内随机一个掉落数Select。
A28: 2、 | B28: 如果有衰减，则对Select进行衰减，newSelect=Select*（1-衰减系数）
A29: 3、 | B29: 如果newSelect大于1，则向下取整，newSelect=int（Select）
A30: 4、 | B30: 如果newSelect小于1，则从【0，1】中随机抽一个小数，如果该小数小于newSelect，则掉落1个物品（newSelect = 1），否则 newSelect = 0
... A36: 10、 | B36: 每个物品配置一个权重，加总需要=100000000（个位数±有点误差可以接受）
A37: 掉落方式_按个数和概率不可重复
A38: 1、 | B38: 在掉落个数【Min, Max】内随机一个掉落数Select。
A39: 2、 | B39: 如果有衰减，则对Select进行衰减，newSelect=Select*（1-衰减系数）
A40: 3、 | B40: 如果newSelect大于1，则向下取整，newSelect=int（Select）
A41: 4、 | B41: 如果newSelect小于1，则从【0，1】中随机抽一个小数，如果该小数小于newSelect，则掉落1个物品（newSelect = 1），否则 newSelect = 0
A42: 5、 | B42: 对掉落方案中的每个物品，按其填写的概率组合成一个【m,n】的掉落区间，每个物品按其填写的概率占有其中一个掉落区间段
A43: 6、 | B43: 其中，m=上一个物品的n+1，n=m+X。如果是第一个物品，则m=1（相当于第0个物品的n=0），n=X。最后一个物品的n=100000000
A44: 7、 | B44: 在【1,100000000】的区间内随机一个掉落数
A45: 8、 | B45: 掉落数落在哪个物品的掉落区间段，则掉落此物品
A46: 9、 | B46: 物品掉落后，在掉落池子里删掉该物品，同时，掉落权重重新进行计算
A47: 10、 | B47: 在剩下的物品中如此反复，直到掉完newSelect个物品
...

Sheet 更新说明
A1: 版本号 | B1: 改动内容
A2: V1.0 | B2: 编号规则，基础配置
A3: V1.01 | B3: 更新基础配置
A4: V1.11 | B4: 红色掉落方案是策划用，计算的。绿色页签掉落表.ts的是给程序用的
A5: V1.12 | B5: 物品表更改编号，掉落表对应更改
A6: V1.13
A7: V1.14 | B7: 更新掉落方式说明中的信息。
A8: V1.15 | B8: 新增任务类的掉落，并对应新增4个掉落物
A9: V1.16
A10: V1.17
A11: V1.18
A12: V1.19
A13: V1.20
A14: V1.21
A15: V1.22
A16: V1.23
A17: V1.24
A18: V1.25
A19: V1.26
A20: V1.27
... A25: V1.32
