Workbook

Sheet region_config
A1: ##var | B1: config_id | C1: rect_name | E1: scene_name | F1: scene_id | K1: is_main_rect | L1: is_born_rect | M1: is_minimap_rect | N1: min_x | O1: max_x | P1: min_y | Q1: max_y | R1: teleport_target | T1: refresh_monster_plans
A2: ##type | B2: int | C2: string | D2: int整数string文本枚举自起名字 | E2: string | F2: int | K2: int | L2: int | M2: int | N2: float? | O2: float? | P2: float? | Q2: float? | R2: int | T2: array,int
A3: ##group | C3: c | D3: c,s,,C客户端S服务器不填都用 | E3: c | R3: c | T3: s
A4: ## | B4: 区域ID | C4: 区域名（传送才外显） | D4: 备注 | E4: 地编名 | F4: 所属场景ID | G4: 类型 | H4: 面积 | I4: 行 | J4: 序号 | K4: 是否场景主区域 | L4: 是否出生区域 | M4: 是否小地图镜头区域 | N4: 区域左边界 | O4: 区域右边界 | P4: 区域下边界 | Q4: 区域上边界 | R4: 传送目标区域 | S4: 刷怪方案说明 | T4: 刷怪方案1 | U4: 刷怪方案2 | V4: 刷怪方案3 | W4: 刷怪方案4 | X4: 刷怪方案5 | Y4: 刷怪方案6 | Z4: 刷怪方案7 | AA4: 刷怪方案8
B5: =70000000+F5*10000+H5*1000+I5*100+J5 -> 70015101 | C5: 天元宗门-怪物1 | E5: =F5&(VLOOKUP(G5,编号表!$E$1:$G$8,2,0))&H5&"_"&I5&"_"&J5 -> 1N5_1_1 | F5: 1 | G5: 怪物 | H5: 5 | I5: 1 | J5: =COUNTIFS($F$5:F5,F5,$I$5:I5,I5) -> 1
B6: =70000000+F6*10000+H6*1000+I6*100+J6 -> 70015102 | C6: 天元宗门-怪物2 | E6: =F6&(VLOOKUP(G6,编号表!$E$1:$G$8,2,0))&H6&"_"&I6&"_"&J6 -> 1N5_1_2 | F6: 1 | G6: 怪物 | H6: 5 | I6: 1 | J6: =COUNTIFS($F$5:F6,F6,$I$5:I6,I6) -> 2
B7: =70000000+F7*10000+H7*1000+I7*100+J7 -> 70015103 | C7: 天元宗门-怪物3 | E7: =F7&(VLOOKUP(G7,编号表!$E$1:$G$8,2,0))&H7&"_"&I7&"_"&J7 -> 1N5_1_3 | F7: 1 | G7: 怪物 | H7: 5 | I7: 1 | J7: =COUNTIFS($F$5:F7,F7,$I$5:I7,I7) -> 3
B8: =70000000+F8*10000+H8*1000+I8*100+J8 -> 70015104 | C8: 天元宗门-怪物4 | E8: =F8&(VLOOKUP(G8,编号表!$E$1:$G$8,2,0))&H8&"_"&I8&"_"&J8 -> 1N5_1_4 | F8: 1 | G8: 怪物 | H8: 5 | I8: 1 | J8: =COUNTIFS($F$5:F8,F8,$I$5:I8,I8) -> 4
B9: =70000000+F9*10000+H9*1000+I9*100+J9 -> 70015105 | C9: 天元宗门-怪物5 | E9: =F9&(VLOOKUP(G9,编号表!$E$1:$G$8,2,0))&H9&"_"&I9&"_"&J9 -> 1N5_1_5 | F9: 1 | G9: 怪物 | H9: 5 | I9: 1 | J9: =COUNTIFS($F$5:F9,F9,$I$5:I9,I9) -> 5
B10: =70000000+F10*10000+H10*1000+I10*100+J10 -> 70015106 | C10: 天元宗门-怪物6 | E10: =F10&(VLOOKUP(G10,编号表!$E$1:$G$8,2,0))&H10&"_"&I10&"_"&J10 -> 1N5_1_6 | F10: 1 | G10: 怪物 | H10: 5 | I10: 1 | J10: =COUNTIFS($F$5:F10,F10,$I$5:I10,I10) -> 6
B11: =70000000+F11*10000+H11*1000+I11*100+J11 -> 70015107 | C11: 天元宗门-怪物7 | E11: =F11&(VLOOKUP(G11,编号表!$E$1:$G$8,2,0))&H11&"_"&I11&"_"&J11 -> 1N5_1_7 | F11: 1 | G11: 怪物 | H11: 5 | I11: 1 | J11: =COUNTIFS($F$5:F11,F11,$I$5:I11,I11) -> 7
B12: =70000000+F12*10000+H12*1000+I12*100+J12 -> 70015108 | C12: 天元宗门-怪物8 | E12: =F12&(VLOOKUP(G12,编号表!$E$1:$G$8,2,0))&H12&"_"&I12&"_"&J12 -> 1N5_1_8 | F12: 1 | G12: 怪物 | H12: 5 | I12: 1 | J12: =COUNTIFS($F$5:F12,F12,$I$5:I12,I12) -> 8
B13: =70000000+F13*10000+H13*1000+I13*100+J13 -> 70015109 | C13: 天元宗门-怪物9 | E13: =F13&(VLOOKUP(G13,编号表!$E$1:$G$8,2,0))&H13&"_"&I13&"_"&J13 -> 1N5_1_9 | F13: 1 | G13: 怪物 | H13: 5 | I13: 1 | J13: =COUNTIFS($F$5:F13,F13,$I$5:I13,I13) -> 9
B14: =70000000+F14*10000+H14*1000+I14*100+J14 -> 70015110 | C14: 天元宗门-怪物10 | E14: =F14&(VLOOKUP(G14,编号表!$E$1:$G$8,2,0))&H14&"_"&I14&"_"&J14 -> 1N5_1_10 | F14: 1 | G14: 怪物 | H14: 5 | I14: 1 | J14: =COUNTIFS($F$5:F14,F14,$I$5:I14,I14) -> 10
B15: =70000000+F15*10000+H15*1000+I15*100+J15 -> 70015111 | C15: 天元宗门-怪物11 | E15: =F15&(VLOOKUP(G15,编号表!$E$1:$G$8,2,0))&H15&"_"&I15&"_"&J15 -> 1N5_1_11 | F15: 1 | G15: 怪物 | H15: 5 | I15: 1 | J15: =COUNTIFS($F$5:F15,F15,$I$5:I15,I15) -> 11
B16: =70000000+F16*10000+H16*1000+I16*100+J16 -> 70015112 | C16: 天元宗门-怪物12 | E16: =F16&(VLOOKUP(G16,编号表!$E$1:$G$8,2,0))&H16&"_"&I16&"_"&J16 -> 1N5_1_12 | F16: 1 | G16: 怪物 | H16: 5 | I16: 1 | J16: =COUNTIFS($F$5:F16,F16,$I$5:I16,I16) -> 12
B17: =70000000+F17*10000+H17*1000+I17*100+J17 -> 70015201 | C17: 天元宗门-怪物13 | E17: =F17&(VLOOKUP(G17,编号表!$E$1:$G$8,2,0))&H17&"_"&I17&"_"&J17 -> 1N5_2_1 | F17: 1 | G17: 怪物 | H17: 5 | I17: 2 | J17: 1
B18: =70000000+F18*10000+H18*1000+I18*100+J18 -> 70015202 | C18: 天元宗门-怪物14 | E18: =F18&(VLOOKUP(G18,编号表!$E$1:$G$8,2,0))&H18&"_"&I18&"_"&J18 -> 1N5_2_2 | F18: 1 | G18: 怪物 | H18: 5 | I18: 2 | J18: 2
B19: =70000000+F19*10000+H19*1000+I19*100+J19 -> 70015203 | C19: 天元宗门-怪物15 | E19: =F19&(VLOOKUP(G19,编号表!$E$1:$G$8,2,0))&H19&"_"&I19&"_"&J19 -> 1N5_2_3 | F19: 1 | G19: 怪物 | H19: 5 | I19: 2 | J19: =COUNTIFS($F$5:F19,F19,$I$5:I19,I19) -> 3
B20: =70000000+F20*10000+H20*1000+I20*100+J20 -> 70015204 | C20: 天元宗门-怪物16 | E20: =F20&(VLOOKUP(G20,编号表!$E$1:$G$8,2,0))&H20&"_"&I20&"_"&J20 -> 1N5_2_4 | F20: 1 | G20: 怪物 | H20: 5 | I20: 2 | J20: =COUNTIFS($F$5:F20,F20,$I$5:I20,I20) -> 4
B21: =70000000+F21*10000+H21*1000+I21*100+J21 -> 70015205 | C21: 天元宗门-怪物17 | E21: =F21&(VLOOKUP(G21,编号表!$E$1:$G$8,2,0))&H21&"_"&I21&"_"&J21 -> 1N5_2_5 | F21: 1 | G21: 怪物 | H21: 5 | I21: 2 | J21: =COUNTIFS($F$5:F21,F21,$I$5:I21,I21) -> 5
B22: =70000000+F22*10000+H22*1000+I22*100+J22 -> 70015206 | C22: 天元宗门-怪物18 | E22: =F22&(VLOOKUP(G22,编号表!$E$1:$G$8,2,0))&H22&"_"&I22&"_"&J22 -> 1N5_2_6 | F22: 1 | G22: 怪物 | H22: 5 | I22: 2 | J22: =COUNTIFS($F$5:F22,F22,$I$5:I22,I22) -> 6
B23: =70000000+F23*10000+H23*1000+I23*100+J23 -> 70015207 | C23: 天元宗门-怪物19 | E23: =F23&(VLOOKUP(G23,编号表!$E$1:$G$8,2,0))&H23&"_"&I23&"_"&J23 -> 1N5_2_7 | F23: 1 | G23: 怪物 | H23: 5 | I23: 2 | J23: =COUNTIFS($F$5:F23,F23,$I$5:I23,I23) -> 7
B24: =70000000+F24*10000+H24*1000+I24*100+J24 -> 70015208 | C24: 天元宗门-怪物20 | E24: =F24&(VLOOKUP(G24,编号表!$E$1:$G$8,2,0))&H24&"_"&I24&"_"&J24 -> 1N5_2_8 | F24: 1 | G24: 怪物 | H24: 5 | I24: 2 | J24: =COUNTIFS($F$5:F24,F24,$I$5:I24,I24) -> 8 | R24: 70031001
B25: =70000000+F25*10000+H25*1000+I25*100+J25 -> 70015209 | C25: 天元宗门-怪物21 | E25: =F25&(VLOOKUP(G25,编号表!$E$1:$G$8,2,0))&H25&"_"&I25&"_"&J25 -> 1N5_2_9 | F25: 1 | G25: 怪物 | H25: 5 | I25: 2 | J25: =COUNTIFS($F$5:F25,F25,$I$5:I25,I25) -> 9 | R25: 70111001
B26: =70000000+F26*10000+H26*1000+I26*100+J26 -> 70015210 | C26: 天元宗门-怪物22 | E26: =F26&(VLOOKUP(G26,编号表!$E$1:$G$8,2,0))&H26&"_"&I26&"_"&J26 -> 1N5_2_10 | F26: 1 | G26: 怪物 | H26: 5 | I26: 2 | J26: =COUNTIFS($F$5:F26,F26,$I$5:I26,I26) -> 10 | R26: 70201001
B27: =70000000+F27*10000+H27*1000+I27*100+J27 -> 70015211 | C27: 天元宗门-怪物23 | E27: =F27&(VLOOKUP(G27,编号表!$E$1:$G$8,2,0))&H27&"_"&I27&"_"&J27 -> 1N5_2_11 | F27: 1 | G27: 怪物 | H27: 5 | I27: 2 | J27: =COUNTIFS($F$5:F27,F27,$I$5:I27,I27) -> 11 | R27: 70291001
B28: =70000000+F28*10000+H28*1000+I28*100+J28 -> 70015212 | C28: 天元宗门-怪物24 | E28: =F28&(VLOOKUP(G28,编号表!$E$1:$G$8,2,0))&H28&"_"&I28&"_"&J28 -> 1N5_2_12 | F28: 1 | G28: 怪物 | H28: 5 | I28: 2 | J28: =COUNTIFS($F$5:F28,F28,$I$5:I28,I28) -> 12 | R28: 70381001
B29: =70000000+F29*10000+H29*1000+I29*100+J29 -> 70015213 | C29: 天元宗门-怪物25 | E29: =F29&(VLOOKUP(G29,编号表!$E$1:$G$8,2,0))&H29&"_"&I29&"_"&J29 -> 1N5_2_13 | F29: 1 | G29: 怪物 | H29: 5 | I29: 2 | J29: =COUNTIFS($F$5:F29,F29,$I$5:I29,I29) -> 13 | R29: 70471001
B30: =70000000+F30*10000+H30*1000+I30*100+J30 -> 70015301 | C30: 天元宗门-怪物26 | E30: =F30&(VLOOKUP(G30,编号表!$E$1:$G$8,2,0))&H30&"_"&I30&"_"&J30 -> 1N5_3_1 | F30: 1 | G30: 怪物 | H30: 5 | I30: 3 | J30: 1
B31: =70000000+F31*10000+H31*1000+I31*100+J31 -> 70015302 | C31: 天元宗门-怪物27 | E31: =F31&(VLOOKUP(G31,编号表!$E$1:$G$8,2,0))&H31&"_"&I31&"_"&J31 -> 1N5_3_2 | F31: 1 | G31: 怪物 | H31: 5 | I31: 3 | J31: 2
B32: =70000000+F32*10000+H32*1000+I32*100+J32 -> 70015303 | C32: 天元宗门-怪物28 | E32: =F32&(VLOOKUP(G32,编号表!$E$1:$G$8,2,0))&H32&"_"&I32&"_"&J32 -> 1N5_3_3 | F32: 1 | G32: 怪物 | H32: 5 | I32: 3 | J32: 3
B33: =70000000+F33*10000+H33*1000+I33*100+J33 -> 70015304 | C33: 天元宗门-怪物29 | E33: =F33&(VLOOKUP(G33,编号表!$E$1:$G$8,2,0))&H33&"_"&I33&"_"&J33 -> 1N5_3_4 | F33: 1 | G33: 怪物 | H33: 5 | I33: 3 | J33: 4
B34: =70000000+F34*10000+H34*1000+I34*100+J34 -> 70015401 | C34: 天元宗门-怪物30 | E34: =F34&(VLOOKUP(G34,编号表!$E$1:$G$8,2,0))&H34&"_"&I34&"_"&J34 -> 1N5_4_1 | F34: 1 | G34: 怪物 | H34: 5 | I34: 4 | J34: 1
B35: =70000000+F35*10000+H35*1000+I35*100+J35 -> 70015402 | C35: 天元宗门-怪物31 | E35: =F35&(VLOOKUP(G35,编号表!$E$1:$G$8,2,0))&H35&"_"&I35&"_"&J35 -> 1N5_4_2 | F35: 1 | G35: 怪物 | H35: 5 | I35: 4 | J35: 2
B36: =70000000+F36*10000+H36*1000+I36*100+J36 -> 70015403 | C36: 天元宗门-怪物32 | E36: =F36&(VLOOKUP(G36,编号表!$E$1:$G$8,2,0))&H36&"_"&I36&"_"&J36 -> 1N5_4_3 | F36: 1 | G36: 怪物 | H36: 5 | I36: 4 | J36: 3
B37: =70000000+F37*10000+H37*1000+I37*100+J37 -> 70015404 | C37: 天元宗门-怪物33 | E37: =F37&(VLOOKUP(G37,编号表!$E$1:$G$8,2,0))&H37&"_"&I37&"_"&J37 -> 1N5_4_4 | F37: 1 | G37: 怪物 | H37: 5 | I37: 4 | J37: 4
B38: =70000000+F38*10000+H38*1000+I38*100+J38 -> 70015405 | C38: 天元宗门-怪物34 | E38: =F38&(VLOOKUP(G38,编号表!$E$1:$G$8,2,0))&H38&"_"&I38&"_"&J38 -> 1N5_4_5 | F38: 1 | G38: 怪物 | H38: 5 | I38: 4 | J38: 5
B39: =70000000+F39*10000+H39*1000+I39*100+J39 -> 70015406 | C39: 天元宗门-怪物35 | E39: =F39&(VLOOKUP(G39,编号表!$E$1:$G$8,2,0))&H39&"_"&I39&"_"&J39 -> 1N5_4_6 | F39: 1 | G39: 怪物 | H39: 5 | I39: 4 | J39: 6
B40: =70000000+F40*10000+H40*1000+I40*100+J40 -> 70015407 | C40: 天元宗门-怪物36 | E40: =F40&(VLOOKUP(G40,编号表!$E$1:$G$8,2,0))&H40&"_"&I40&"_"&J40 -> 1N5_4_7 | F40: 1 | G40: 怪物 | H40: 5 | I40: 4 | J40: 7
...

Sheet ConfigScene
A1: ##var | B1: config_id | C1: scene_name | D1: camera_distance | E1: camera_angle | F1: minimap | G1: bigmap | H1: grade | I1: bgm_sound_id
A2: ##type | B2: int | C2: string | D2: int | E2: int | F2: string | G2: string | H2: int | I2: int
A3: ##group
A4: ## | B4: 场景ID | C4: 场景名 | D4: 镜头距离 | E4: 镜头初始角度 | F4: 小地图 | G4: 大地图 | H4: 场景等级 | I4: 背景音乐
B5: 1 | C5: 天元宗门 | D5: 900 | E5: 315 | F5: mini_zm | G5: big_zm | H5: 0 | I5: 10003
B6: 2 | C6: 蚀苇沼·末流所积 | D6: 900 | E6: 315 | F6: map_xiao_03 | H6: 0 | I6: 10002
B7: 3 | C7: 望岳津 | D7: 900 | E7: 315 | F7: map_xiao_02 | H7: 0 | I7: 10002
B8: 4 | C8: 浮沉洲 | D8: 900 | E8: 315 | F8: map_xiao_04 | H8: 0 | I8: 10002
B9: 5 | C9: 蔽苇汀 | D9: 900 | E9: 315 | F9: map_xiao_05 | H9: 0 | I9: 10002
B10: 6 | C10: 岳骨阶 | D10: 900 | E10: 315 | F10: map_xiao_06 | H10: 0 | I10: 10002
B11: 7 | C11: 异霭浦 | D11: 900 | E11: 315 | F11: map_xiao_07 | H11: 0 | I11: 10002
B12: 8 | C12: 砾台 | D12: 900 | E12: 315 | F12: map_xiao_08 | H12: 0 | I12: 10002
B13: 9 | C13: 垂练岩·覆而偶开 | D13: 900 | E13: 315 | F13: map_xiao_09 | H13: 0 | I13: 10002
B14: 10 | C14: 水镜滩·水退方见 | D14: 900 | E14: 315 | F14: map_xiao_10 | H14: 0 | I14: 10002
B15: 11 | C15: 汇歧渚 | D15: 900 | E15: 315 | F15: map_xiao_11 | H15: 0 | I15: 10006
B16: 12 | C16: 沉浊坡 | D16: 900 | E16: 315 | F16: map_xiao_12 | H16: 0 | I16: 10006
B17: 13 | C17: 豁烟水 | D17: 900 | E17: 315 | F17: map_xiao_13 | H17: 0 | I17: 10006
... B58: 54 | C58: 霁台 | D58: 900 | E58: 315 | F58: map_xiao_54 | H58: 0 | I58: 10005

Sheet 编号表
A1: 场景名 | B1: 序号 | C1: 地编名 | D1: 序号 | E1: 类型 | F1: 缩写 | G1: 序号
A2: 比奇城 | B2: 1 | C2: D1_1_ | D2: 1 | E2: 怪物 | F2: N | G2: 1 | I2: =F4&"-"&E3 -> P-传送 | K2: 刷怪,镜头：蓝色
A3: 兽人古墓一层 | B3: 2 | C3: D1_2_ | D3: 2 | E3: 传送 | F3: T | G3: 2 | I3: =F3&"-"&E4 -> T-NPC | K3: 传送点：绿色
A4: 兽人古墓二层 | B4: 3 | C4: D1_3_ | D4: 3 | E4: NPC | F4: P | G4: 3 | I4: =F2&"-"&E2 -> N-怪物 | K4: npc:黄色
A5: 国王陵墓 | B5: 4 | C5: D1_4_ | D5: 4 | E5: 音效 | F5: M | G5: 4 | I5: =F5&"-"&E5 -> M-音效 | K5: 采集物：紫色
A6: 废矿区东部 | B6: 5 | C6: D1_5_ | D6: 5 | E6: 镜头 | F6: J | G6: 5 | I6: =F6&"-"&E6 -> J-镜头 | K6: D-小地图
A7: 尸王殿 | B7: 6 | C7: D1_6_ | D7: 6 | E7: 采集物 | F7: C | G7: 6 | I7: D-小地图
A8: 地牢 | B8: 7 | C8: D2_1_ | D8: 7 | E8: 小地图 | F8: D | G8: 7
A9: 黑暗地带 | B9: 8 | C9: D2_2_ | D9: 8
A10: 死亡棺材 | B10: 9 | C10: D2_3_ | D10: 9
A11: 未知暗殿 | B11: 10 | C11: D2_4_ | D11: 10
A12: 沃玛寺庙一层 | B12: 11 | C12: D2_5_ | D12: 11
A13: 沃玛寺庙二层 | B13: 12 | C13: D2_6_ | D13: 12
A14: 沃玛教主大殿 | B14: 13 | C14: D3_1_ | D14: 13
A15: 石墓一层 | B15: 14 | C15: D3_2_ | D15: 14
A16: 石墓阵入口 | B16: 15 | C16: D3_3_ | D16: 15
A17: 石墓阵出口 | B17: 16 | C17: D3_4_ | D17: 16
A18: 石墓顶层 | B18: 17 | C18: D3_5_ | D18: 17
A19: 桃源之门 | B19: 18 | C19: D3_6_ | D19: 18
A20: 困惑殿堂 | B20: 19 | C20: D4_1_ | D20: 19
... A25: 封魔矿区 | B25: 24 | C25: D4_6_ | D25: 24
A26: 光芒回廊 | B26: 25 | C26: D5_1_ | D26: 25 | M26: 编号命名 | N26: 1 | O26: 2 | P26: 3 | Q26: 4 | R26: 5 | S26: 6 | T26: 7 | U26: 8
A27: 封魔殿 | B27: 26 | C27: D5_2_ | D27: 26 | N27: 固定“7” | O27: 地图序号 | R27: 格子边长 | S27: 地图从上往下格子所在第x行 | T27: 格子所在行左起第x个
A28: 尸魔洞一层 | B28: 27 | C28: D5_3_ | D28: 27
A29: 尸魔洞二层 | B29: 28 | C29: D5_4_ | D29: 28 | M29: 示例：70015304，解释：序号1的地图边长为5的区域位置在地图从上往下第3行左数第4个
A30: 骨魔洞一层 | B30: 29 | C30: D5_5_ | D30: 29
A31: 骨魔洞二层 | B31: 30 | C31: D5_6_ | D31: 30 | M31: 比奇城按6区域划分行数，传送点-0，左上-1，右上-2，左下-3，右下4，城中-5
A32: 牛魔寺庙入口 | B32: 31 | C32: D6_1_ | D32: 31
A33: 牛魔寺庙一层 | B33: 32 | C33: D6_2_ | D33: 32
A34: 牛魔寺庙大厅 | B34: 33 | C34: D6_3_ | D34: 33 | M34: 地编命名 | N34: 1 | O34: 2 | P34: 3 | Q34: 4 | R34: 5
A35: 丛林迷宫 | B35: 34 | C35: D6_4_ | D35: 34 | N35: 地图序号 | O35: 区域类型 | P35: 格子边长 | Q35: 格子所在第x行 | R35: 格子所在行左起第x个
A36: 赤月峡谷西走廊 | B36: 35 | C36: D6_5_ | D36: 35 | O36: P-传送
A37: 赤月峡谷东二层 | B37: 36 | C37: D6_6_ | D37: 36 | O37: T-NPC
A38: 赤月峡谷广场 | B38: 37 | C38: M1 | D38: 37 | O38: N-怪物
A39: 抉择之地 | B39: 38 | C39: M2 | D39: 38 | O39: M-音效
A40: 恶魔祭坛 | B40: 39 | C40: M3 | D40: 39 | O40: J-镜头
A41: 赤月魔穴 | B41: 40 | C41: M4 | D41: 40 | M41: 示例：1N3_4_5，解释：序号1的地图边长为3的从上往下第4行左数第5个怪物区域
A42: 新手村 | B42: 41 | C42: M5 | D42: 41
D43: 42
D44: 43
...

Sheet 说明
A1: 版本 | B1: 内容
A2: V1.11 | B2: 新增场景区域
A3: V1.12 | B3: 修改兽人古墓、矿区传送、位置
A4: V1.13
A5: V1.14
A6: V1.15 | B6: 更新传送方案，刷怪方案
A7: V1.16 | B7: 增加两个测试木桩，biqi_77,biqi_78
A8: V1.17 | B8: 增加主场景区域-场景镜头区域
A9: V1.18 | B9: 增加场景小地图大地图
A10: V1.19 | B10: 按照新的怪物刷新配置，刷新场景内的怪物配置
A11: V1.20 | B11: 更新场景
A12: V1.21 | B12: 比奇城新增羊，鹿和狼的配置，测试任务用。
A13: V1.22 | B13: 新增新手村场景区域；比奇城22,77,78刷新木桩；
A14: V1.23 | B14: ① 新手村、比奇城各一个出生点 ② 新手村5个备用传送区域，5个落点区域，备用NPC区域10个，普通40，精英10，BOSS 5，音乐10，镜头1
A15: V1.24 | B15: 区域版本重制 1、传送落地点与传送起始点分开 2、区域密度提高，适配更多刷怪密度和位置策略 3、区域命名方式优化，附带区域信息
