Workbook
Name 怪物类型: [1]名称表!$A$3:$A$26
Name 说明: [2]名称表!$A$3:$A$26
Name 阵营: [1]名称表!$H$2:$H$9

Sheet spawn_config
A1: ##var | B1: config_id | G1: position | H1: spawn_monsters | AB1: activity
A2: ##type | B2: int | G2: string | H2: array,SpawnMonster | AB2: int
A3: ##group | G3: s | H3: s | AB3: c
A4: ## | B4: 编号 | C4: 场景名称 | D4: 怪物类型 | E4: 怪物数量 | F4: 说明 | G4: 刷新位置 | H4: 怪物1配置ID | I4: 怪物1数量 | J4: 怪物2配置ID | K4: 怪物2数量 | L4: 怪物3配置ID | M4: 怪物3数量 | N4: 怪物4配置ID | O4: 怪物4数量 | P4: 怪物5配置ID | Q4: 怪物5数量 | R4: 怪物6配置ID | S4: 怪物6数量 | T4: 怪物7配置ID | U4: 怪物7数量 | V4: 怪物8配置ID | W4: 怪物8数量 | X4: 怪物9配置ID | Y4: 怪物9数量 | Z4: 怪物10配置ID | AA4: 怪物10数量 | AB4: 日常活动 activity_config.id；本方案刷出的怪跑什么日常，0/空=驻留
B5: =1000000+INDEX(编号表!$B:$B,MATCH(C5,编号表!$A:$A,0))*1000+INDEX(编号表!$D:$D,MATCH(D5,编号表!$C:$C,0))*100+E5 -> 1001203 | C5: 天元宗门 | D5: 小怪0 | E5: 3 | F5: 鸡 | G5: 区域随机 | H5: 60011001 | I5: 3
B6: =1000000+INDEX(编号表!$B:$B,MATCH(C6,编号表!$A:$A,0))*1000+INDEX(编号表!$D:$D,MATCH(D6,编号表!$C:$C,0))*100+E6 -> 1001303 | C6: 天元宗门 | D6: 小怪1 | E6: 3 | F6: 鹿 | G6: 区域随机 | H6: 60011001 | I6: 3
B7: =1000000+INDEX(编号表!$B:$B,MATCH(C7,编号表!$A:$A,0))*1000+INDEX(编号表!$D:$D,MATCH(D7,编号表!$C:$C,0))*100+E7 -> 1001403 | C7: 天元宗门 | D7: 小怪2 | E7: 3 | F7: 羊 | G7: 区域随机 | H7: 60011002 | I7: 3
B8: =1000000+INDEX(编号表!$B:$B,MATCH(C8,编号表!$A:$A,0))*1000+INDEX(编号表!$D:$D,MATCH(D8,编号表!$C:$C,0))*100+E8 -> 1001503 | C8: 天元宗门 | D8: 小怪3 | E8: 3 | F8: 稻草人 | G8: 区域随机 | H8: 60011003 | I8: 3
B9: =1000000+INDEX(编号表!$B:$B,MATCH(C9,编号表!$A:$A,0))*1000+INDEX(编号表!$D:$D,MATCH(D9,编号表!$C:$C,0))*100+E9 -> 1001603 | C9: 天元宗门 | D9: 小怪4 | E9: 3 | F9: 蛤蟆 | G9: 区域随机 | H9: 60011004 | I9: 3
B10: =1000000+INDEX(编号表!$B:$B,MATCH(C10,编号表!$A:$A,0))*1000+INDEX(编号表!$D:$D,MATCH(D10,编号表!$C:$C,0))*100+E10 -> 1001703 | C10: 天元宗门 | D10: 小怪5 | E10: 3 | F10: 蝙蝠 | G10: 区域随机 | H10: 60011013 | I10: 3
B11: =1000000+INDEX(编号表!$B:$B,MATCH(C11,编号表!$A:$A,0))*1000+INDEX(编号表!$D:$D,MATCH(D11,编号表!$C:$C,0))*100+E11 -> 1001803 | C11: 天元宗门 | D11: 小怪6 | E11: 3 | F11: 虎卫 | G11: 区域随机 | H11: 60011011 | I11: 3
B12: =1000000+INDEX(编号表!$B:$B,MATCH(C12,编号表!$A:$A,0))*1000+INDEX(编号表!$D:$D,MATCH(D12,编号表!$C:$C,0))*100+E12 -> 1001903 | C12: 天元宗门 | D12: 小怪7 | E12: 3 | F12: 鹰卫 | G12: 区域随机 | H12: 60011012 | I12: 3
B13: =1000000+INDEX(编号表!$B:$B,MATCH(C13,编号表!$A:$A,0))*1000+INDEX(编号表!$D:$D,MATCH(D13,编号表!$C:$C,0))*100+E13 -> 1002303 | C13: 蚀苇沼·末流所积 | D13: 小怪1 | E13: 3 | F13: 青魂煞灵 | G13: 区域随机 | H13: 60021014 | I13: 3
B14: =1000000+INDEX(编号表!$B:$B,MATCH(C14,编号表!$A:$A,0))*1000+INDEX(编号表!$D:$D,MATCH(D14,编号表!$C:$C,0))*100+E14 -> 1002403 | C14: 蚀苇沼·末流所积 | D14: 小怪2 | E14: 3 | F14: 深渊水魔 | G14: 区域随机 | H14: 60021015 | I14: 3
B15: =1000000+INDEX(编号表!$B:$B,MATCH(C15,编号表!$A:$A,0))*1000+INDEX(编号表!$D:$D,MATCH(D15,编号表!$C:$C,0))*100+E15 -> 1002503 | C15: 蚀苇沼·末流所积 | D15: 小怪3 | E15: 3 | F15: 冥海幽灵 | G15: 区域随机 | H15: 60021016 | I15: 3
B16: =1000000+INDEX(编号表!$B:$B,MATCH(C16,编号表!$A:$A,0))*1000+INDEX(编号表!$D:$D,MATCH(D16,编号表!$C:$C,0))*100+E16 -> 1002603 | C16: 蚀苇沼·末流所积 | D16: 小怪4 | E16: 3 | F16: 冥河幽魂 | G16: 区域随机 | H16: 60021017 | I16: 3
... B191: =1000000+INDEX(编号表!$B:$B,MATCH(C191,编号表!$A:$A,0))*1000+INDEX(编号表!$D:$D,MATCH(D191,编号表!$C:$C,0))*100+E191 -> 1065604 | C191: 霰砾坡 | D191: 小怪4 | E191: 4 | F191: 链锤野猪 | G191: 区域随机 | H191: 60651193 | I191: 4

Sheet 更新说明
A1: 版本号 | B1: 内容
A2: V1.12 | B2: 减少数量
A3: V1.13 | B3: 增加刷怪场景
A4: V1.14 | B4: 增加两个测试木桩，30和31
A5: V1.15 | B5: 增加蛤蟆刷新场景
A6: V1.16 | B6: 重新整理怪物刷新配置，新增，改ID规则等
A7: V1.17 | B7: 新增新手村刷怪方案；比奇城boss怪物更改为木桩；
A8: V1.18
A9: V1.19
A10: V1.20
A11: V1.21
A12: V1.22
A13: V1.23
A14: V1.24
A15: V1.25
A16: V1.26
A17: V1.27
A18: V1.28
A19: V1.29
... A22: V1.32

Sheet Sheet1
A1: 编号 | B1: 场景名称 | C1: 刷新位置 | D1: 怪物1配置ID | E1: 怪物1数量 | F1: 怪物2配置ID | G1: 怪物2数量 | H1: 怪物3配置ID | I1: 怪物3数量 | J1: 怪物4配置ID | K1: 怪物4数量 | L1: 怪物5配置ID | M1: 怪物5数量 | N1: 怪物6配置ID | O1: 怪物6数量 | P1: 怪物7配置ID | Q1: 怪物7数量 | R1: 怪物8配置ID | S1: 怪物8数量 | T1: 怪物9配置ID | U1: 怪物9数量 | V1: 怪物10配置ID | W1: 怪物10数量
A2: config_id | C2: position | D2: MonsterID1 | E2: MonsterCount1 | F2: MonsterID2 | G2: MonsterCount2 | H2: MonsterID3 | I2: MonsterCount3 | J2: MonsterID4 | K2: MonsterCount4 | L2: MonsterID5 | M2: MonsterCount5 | N2: MonsterID6 | O2: MonsterCount6 | P2: MonsterID7 | Q2: MonsterCount7 | R2: MonsterID8 | S2: MonsterCount8 | T2: MonsterID9 | U2: MonsterCount9 | V2: MonsterID10 | W2: MonsterCount10
A3: 1 | B3: 比奇城 | C3: 区域随机 | D3: 60011037 | E3: 2 | F3: 60011090 | G3: 2 | H3: 60371001 | I3: 2 | J3: 60011033 | K3: 2 | L3: 60011035 | M3: 2 | N3: 60371009 | O3: 2 | P3: 60011016 | Q3: 2 | R3: 60011090 | S3: 2 | T3: 60011081 | U3: 2 | V3: 60371011 | W3: 2
A4: 2 | B4: 祖玛寺庙一层 | C4: 区域随机 | D4: 60011119 | E4: 1 | F4: 60011105 | G4: 1 | H4: 60371107 | I4: 1 | J4: 60011106 | K4: 1 | L4: 60011127 | M4: 1
A5: 3 | B5: 祖玛寺庙一层 | C5: 区域随机 | D5: 60011106 | E5: 1 | F5: 60011127 | G5: 1
A6: 4 | B6: 祖玛寺庙二层 | C6: 区域随机 | D6: 60011105 | E6: 1 | F6: 60371107 | G6: 1 | H6: 60011106 | I6: 1 | J6: 60011127 | K6: 1 | L6: 60011121 | M6: 1
A7: 5 | B7: 祖玛阁 | C7: 区域随机 | D7: 60011105 | E7: 6 | F7: 60371107 | G7: 6 | H7: 60011106 | I7: 6 | J7: 60011127 | K7: 6 | L7: 60011121 | M7: 6 | N7: 60371124 | O7: 6
A8: 6 | B8: 教主大殿 | C8: 区域中心 | D8: 60011132 | E8: 1
A9: 7 | B9: 教主大殿 | C9: 区域随机 | D9: 60011105 | E9: 4 | F9: 60371107 | G9: 4 | H9: 60011106 | I9: 4 | J9: 60011127 | K9: 4 | L9: 60011121 | M9: 4 | N9: 60371124 | O9: 4
A10: 8 | B10: 兽人古墓一层 | C10: 区域随机 | D10: 60011014 | E10: 1 | F10: 60011026 | G10: 1 | H10: 60011032 | I10: 1 | J10: 60371024 | K10: 1 | L10: 60011019 | M10: 1
A11: 9 | B11: 兽人古墓二层 | C11: 区域随机 | D11: 60011014 | E11: 1 | F11: 60011032 | G11: 1 | H11: 60371024 | I11: 1 | J11: 60011019 | K11: 1 | L11: 60011022 | M11: 1
A12: 10 | B12: 国王陵墓 | C12: 区域中心 | D12: 60011028 | E12: 1
A13: 11 | B13: 废矿区东部 | C13: 区域随机 | D13: 60011032 | E13: 1 | F13: 60371059 | G13: 1 | H13: 60371061 | I13: 1 | J13: 60371063 | K13: 1 | L13: 60371065 | M13: 1 | N13: 60371067 | O13: 1 | P13: 60371397 | Q13: 1
A14: 12 | B14: 尸王殿 | C14: 区域随机 | D14: 60371069 | E14: 5
A15: 13 | B15: 地牢 | C15: 区域随机 | D15: 60371091 | E15: 1 | F15: 60371101 | G15: 1 | H15: 60371103 | I15: 2 | J15: 60371094 | K15: 1 | L15: 60371096 | M15: 1
A16: 14 | B16: 黑暗地带 | C16: 区域随机 | D16: 60371091 | E16: 1 | F16: 60371101 | G16: 1 | H16: 60371094 | I16: 1 | J16: 60371096 | K16: 1
A17: 15 | B17: 死亡棺材 | C17: 区域随机 | D17: 60371091 | E17: 1 | F17: 60371101 | G17: 1 | H17: 60371103 | I17: 2 | J17: 60371094 | K17: 1 | L17: 60371096 | M17: 1
A18: 16 | B18: 死亡棺材 | C18: 区域中心 | D18: 60371093 | E18: 1
A19: 17 | B19: 未知暗殿 | C19: 区域随机 | D19: 60011121 | E19: 1 | F19: 60371124 | G19: 1 | H19: 60011127 | I19: 1 | J19: 60371002 | K19: 1
A20: 18 | B20: 未知暗殿 | C20: 区域中心 | D20: 60011132 | E20: 1
A21: 19 | B21: 沃玛寺庙一层 | C21: 区域随机 | D21: 60371057 | E21: 1 | F21: 60371040 | G21: 1 | H21: 60371042 | I21: 1 | J21: 60371044 | K21: 1
A22: 20 | B22: 沃玛寺庙二层 | C22: 区域随机 | D22: 60371042 | E22: 1 | F22: 60371044 | G22: 1 | H22: 60371046 | I22: 1 | J22: 60371055 | K22: 1
A23: 21 | B23: 沃玛教主大殿 | C23: 区域随机 | D23: 60371042 | E23: 1 | F23: 60371044 | G23: 1 | H23: 60371046 | I23: 1 | J23: 60371055 | K23: 1
A24: 22 | B24: 沃玛教主大殿 | C24: 区域中心 | D24: 60371053 | E24: 1
A25: 23 | B25: 石墓一层 | C25: 区域随机 | D25: 60371094 | E25: 1 | F25: 60371107 | G25: 1 | H25: 60371108 | I25: 1 | J25: 60371110 | K25: 1
A26: 24 | B26: 石墓阵入口 | C26: 区域随机 | D26: 60371107 | E26: 1 | F26: 60371108 | G26: 1 | H26: 60371110 | I26: 1 | J26: 60371115 | K26: 1 | L26: 60011105 | M26: 1 | N26: 60011106 | O26: 1
A27: 25 | B27: 石墓阵出口 | C27: 区域随机 | D27: 60371107 | E27: 1 | F27: 60371108 | G27: 1 | H27: 60371110 | I27: 1 | J27: 60371115 | K27: 1 | L27: 60011105 | M27: 1 | N27: 60011106 | O27: 1
A28: 26 | B28: 石墓阵顶层 | C28: 区域随机 | D28: 60371094 | E28: 1 | F28: 60371112 | G28: 2 | H28: 60011105 | I28: 1 | J28: 60011106 | K28: 1
A29: 27 | B29: 石墓阵顶层 | C29: 区域中心 | D29: 60371206 | E29: 1
A30: 28 | B30: 桃源之门 | C30: 区域随机 | D30: 60371207 | E30: 1 | F30: 60371140 | G30: 1 | H30: 60371075 | I30: 1
A31: 29 | B31: 困惑殿堂 | C31: 区域中心 | D31: 60371265 | E31: 1
A32: 30 | B32: 比奇城 | C32: 区域中心 | D32: 60371490 | E32: 1
A33: 31 | B33: 比奇城 | C33: 区域中心 | D33: 60371491 | E33: 1
A38: 1 | B38: 比奇城 | D38: 怪1 | F38: 1000000
A39: 2 | B39: 兽人古墓一层 | D39: 怪2
A40: 3 | B40: 兽人古墓二层 | D40: 怪3
A41: 4 | B41: 国王陵墓 | D41: 怪4
A42: 5 | B42: 废矿区东部 | D42: 怪5
A43: 6 | B43: 尸王殿 | D43: 怪6
A44: 7 | B44: 地牢 | D44: 精英
...

Sheet 编号表
A1: 场景名 | B1: 编号 | C1: 类型 | D1: 编号
A2: 天元宗门 | B2: 1 | C2: BOSS | D2: 0
A3: 蚀苇沼·末流所积 | B3: 2 | C3: 精英 | D3: 1
A4: 望岳津 | B4: 3 | C4: 小怪0 | D4: 2 | G4: 1001205
A5: 浮沉洲 | B5: 4 | C5: 小怪1 | D5: 3 | G5: 怪物刷新配置1开头7位数
A6: 蔽苇汀 | B6: 5 | C6: 小怪2 | D6: 4 | G6: 第1位 | H6: 1开头
A7: 岳骨阶 | B7: 6 | C7: 小怪3 | D7: 5 | G7: 第2位 | H7: 用场景来代表级别。相当于装备的阶级，沃玛级，祖玛级，苍月级，赤月级等，2位应该够，暂时用3位保险。这个级别和场景区域配置严格匹配，相等。和其他一样，表示在哪个地图
A8: 异霭浦 | B8: 7 | C8: 小怪4 | D8: 6 | G8: 第3位
A9: 砾台 | B9: 8 | C9: 小怪5 | D9: 7 | G9: 第4位
A10: 垂练岩·覆而偶开 | B10: 9 | C10: 小怪6 | D10: 8 | G10: 第5位 | H10: 怪物身份，区分普通/精英怪/BOSS
A11: 水镜滩·水退方见 | B11: 10 | C11: 小怪7 | D11: 9 | G11: 第6位 | H11: 具体数字表示这个怪物刷新配置里刷多少个怪100以内可以随便填 也可以用不同数字代表不同的BOSS，比如末位配置1，2，3，4表示都刷新一个，分别代表BOSS1,BOSS2,BOSS3,BOSS4
A12: 沉浊坡 | B12: 11 | G12: 第7位
A13: 豁烟水 | B13: 12
A14: 密荷影 | B14: 13
A15: 末分石 | B15: 14
A16: 粉浪风 | B16: 15
A17: 漫莎台 | B17: 16
A18: 匿汊口 | B18: 17
A19: 砾藏岩 | B19: 18
A20: 砺赭坂 | B20: 19
A21: 铁色横侵 | B21: 20
A22: 伏沟鸣石 | B22: 21
A23: 褐苔含润 | B23: 22
A24: 肩生瘠芽 | B24: 23
... A66: 霰砾坡 | B66: 65
