Workbook
Name 怪物类型: 名称表!$A$3:$A$26
Name 是否: 名称表!$C$3:$C$4
Name 阵营: 名称表!$H$2:$H$9

Sheet monster_config
A1: ##var | B1: config_id | C1: monster_id | D1: monster_name | F1: level | G1: color | J1: scene_id | K1: dignity | N1: hp_color_number | P1: collision | Q1: refresh_time | R1: drop_owner_policy | S1: protect_time | T1: return_hp | U1: drop_methods | X1: skills | AA1: cultivation_tags | AB1: model_id | AC1: model_scale | AD1: shadow_w | AE1: shadow_h | AF1: shadow_x | AG1: shadow_y | AH1: attack_type | AI1: attack_effect | AJ1: effect | AK1: effect_scale | AL1: exp_gift | AM1: attrs | BO1: life_bar_pd | BP1: life_bar_name_pd | BQ1: ambient_sound | BR1: ambient_rate | BS1: hit_sound | BT1: hit_rate | BU1: desc
A2: ##type | B2: int | C2: string | D2: string | F2: int | G2: string | J2: string | K2: MonsterDignity | N2: int | O2: float | P2: int | Q2: int | R2: string | S2: int | T2: bool | U2: array,int | X2: array,int | AA2: string | AB2: int | AC2: float | AD2: int | AE2: int | AF2: int | AG2: int | AH2: string | AI2: int | AJ2: int | AK2: float | AL2: int | AM2: array,Attr | BO2: float | BP2: string | BQ2: int | BR2: int | BS2: int | BT2: int | BU2: string
A3: ##group | D3: c | G3: c | J3: c | K3: c | N3: c | O3: c | P3: c | R3: s | S3: s | T3: c | U3: s | X3: c | AA3: c | AB3: c | AC3: c | AD3: c | AE3: c | AF3: c | AG3: c | AH3: c | AI3: c | AJ3: c | AK3: c | BO3: c | BP3: c | BQ3: c | BR3: c | BS3: c | BT3: c | BU3: c
A4: ## | B4: 配置ID | C4: 0怪物ID | D4: 0名称 | E4: 0内部名 | F4: 0等级 | G4: 0怪物名字颜色 | H4: 区域编号 | I4: 地图内位置 | J4: 0归属场景 | K4: 怪物身份 | L4: 0序号 | M4: 0序号（计算用） | N4: 0血条的条数 | O4: 0是否显示百分比 | P4: 碰撞半径 | Q4: 0复活时间（ms） | R4: 归属策略 | S4: 保护期 | T4: 0脱战回血 | U4: 0掉落方案1 | V4: 0掉落方案2 | W4: 0掉落方案3 | X4: 0技能ID | Y4: 0技能ID | Z4: 0技能ID | AA4: 修炼标签 | AB4: 0怪物模型 | AC4: 0缩放比例 | AD4: 阴影宽度 | AE4: 阴影高度 | AF4: 阴影偏移量X | AG4: 阴影偏移量Y | AH4: 0近战/远程 | AI4: 0特效模型 | AJ4: 0绑定特效 | AK4: 0绑定特效缩放 | AL4: 掉落经验 | AM4: 属性名1 | AN4: 属性值1 | AO4: 属性名2 | AP4: 属性值2 | AQ4: 属性名3 | AR4: 属性值3 | AS4: 属性名4 | AT4: 属性值4 | AU4: 属性名5 | AV4: 属性值5 | AW4: 属性名6 | AX4: 属性值6 | AY4: 属性名7 | AZ4: 属性值7 | BA4: 属性名8 | BB4: 属性值8 | BC4: 属性名9 | BD4: 属性值9 | BE4: 属性名10 | BF4: 属性值10 | BG4: 属性名11 | BH4: 属性值11 | BI4: 属性名12 | BJ4: 属性值12 | BK4: 属性名13 | BL4: 属性值13 | BM4: 属性名14 | BN4: 属性值14 | BO4: 血条偏移量 | BP4: 血条名字偏移量 | BQ4: 氛围音效 | BR4: 氛围音效概率 | BS4: 受击音效 | BT4: 受击音效概率 | BU4: 大地图怪物TIPS
B5: =60000000+INDEX(编号表!$B:$B,MATCH(J5,编号表!$A:$A,0))*10000+INDEX(编号表!$B:$B,MATCH(K5,编号表!$C:$C,0))*1000+L5 -> 60011001 | C5: a001 | D5: 鸡 | E5: 鸡 | F5: 5 | G5: =INDEX(编号表!$E:$E,MATCH(K5,编号表!$C:$C,0)) -> 白色 | H5: 1 | I5: 天元宗门——灵兽园 | J5: 天元宗门 | K5: 普通 | L5: 1 | M5: 1 | P5: 10 | Q5: 100000 | T5: FALSE | U5: 40010001 | X5: 11010001 | Y5: 11020001 | AA5: 体修 | AB5: 20001 | AD5: 10 | AE5: 10 | AF5: 10 | AG5: 20 | AH5: 近战 | AL5: 12 | AM5: 生命值 | AN5: 1 | AO5: 物防下限 | AP5: 0 | AQ5: 物防上限 | AR5: 0 | AS5: 法防下限 | AT5: 0 | AU5: 法防上限 | AV5: 0 | AW5: 攻击下限 | AX5: 1 | AY5: 攻击上限 | AZ5: 2 | BA5: 攻法下限 | BB5: 1 | BC5: 攻法上限 | BD5: 2 | BE5: 攻法下限 | BF5: 1 | BG5: 攻法上限 | BH5: 2 | BI5: 移动速度 | BJ5: 100 | BK5: 攻击范围 | BL5: 10 | BM5: 警戒范围 | BN5: 200 | BQ5: 1 | BR5: 2500 | BS5: 2 | BT5: 2500 | BU5: 怪物说明功能测试： 怪物身份颜色：|cffFF0000BOSS|r，|cff00FF00精英怪|r，普通怪 概率掉落以下物品： |cffFFA500美刀|r、|cffd9d919one刀乐|r、|cffA020F0two刀乐
B6: =60000000+INDEX(编号表!$B:$B,MATCH(J6,编号表!$A:$A,0))*10000+INDEX(编号表!$B:$B,MATCH(K6,编号表!$C:$C,0))*1000+L6 -> 60011002 | C6: a002 | D6: 鹿 | E6: 鹿 | F6: 5 | G6: =INDEX(编号表!$E:$E,MATCH(K6,编号表!$C:$C,0)) -> 白色 | H6: 1 | I6: 天元宗门——灵兽园 | J6: 天元宗门 | K6: 普通 | L6: 2 | M6: 2 | P6: 10 | Q6: 150000 | T6: FALSE | U6: 40010001 | X6: 11010001 | Y6: 11020001 | AA6: 体修 | AB6: 20002 | AD6: 10 | AE6: 10 | AF6: 10 | AG6: 20 | AH6: 近战 | AL6: 33 | AM6: 生命值 | AN6: 1 | AO6: 物防下限 | AP6: 0 | AQ6: 物防上限 | AR6: 0 | AS6: 法防下限 | AT6: 0 | AU6: 法防上限 | AV6: 0 | AW6: 攻击下限 | AX6: 1 | AY6: 攻击上限 | AZ6: 2 | BA6: 攻法下限 | BB6: 1 | BC6: 攻法上限 | BD6: 2 | BE6: 攻法下限 | BF6: 1 | BG6: 攻法上限 | BH6: 2 | BI6: 移动速度 | BJ6: 100 | BK6: 攻击范围 | BL6: 10 | BM6: 警戒范围 | BN6: 200 | BQ6: 1 | BR6: 2500 | BS6: 2 | BT6: 2500 | BU6: 怪物说明功能测试： 怪物身份颜色：|cffFF0000BOSS|r，|cff00FF00精英怪|r，普通怪 概率掉落以下物品： |cffFFA500美刀|r、|cffd9d919one刀乐|r、|cffA020F0two刀乐
B7: =60000000+INDEX(编号表!$B:$B,MATCH(J7,编号表!$A:$A,0))*10000+INDEX(编号表!$B:$B,MATCH(K7,编号表!$C:$C,0))*1000+L7 -> 60011003 | C7: a003 | D7: 羊 | E7: 羊 | F7: 5 | G7: =INDEX(编号表!$E:$E,MATCH(K7,编号表!$C:$C,0)) -> 白色 | H7: 1 | I7: 天元宗门——灵兽园 | J7: 天元宗门 | K7: 普通 | L7: 3 | M7: 3 | P7: 10 | Q7: 300000 | T7: FALSE | U7: 40010001 | X7: 11010001 | Y7: 11020001 | AA7: 体修 | AB7: 20003 | AD7: 30 | AE7: 30 | AF7: 10 | AG7: 20 | AH7: 近战 | AL7: 36 | AM7: 生命值 | AN7: 1 | AO7: 物防下限 | AP7: 0 | AQ7: 物防上限 | AR7: 0 | AS7: 法防下限 | AT7: 0 | AU7: 法防上限 | AV7: 0 | AW7: 攻击下限 | AX7: 1 | AY7: 攻击上限 | AZ7: 2 | BA7: 攻法下限 | BB7: 1 | BC7: 攻法上限 | BD7: 2 | BE7: 攻法下限 | BF7: 1 | BG7: 攻法上限 | BH7: 2 | BI7: 移动速度 | BJ7: 100 | BK7: 攻击范围 | BL7: 10 | BM7: 警戒范围 | BN7: 200 | BQ7: 1 | BR7: 2500 | BS7: 2 | BT7: 2500 | BU7: 怪物说明功能测试： 怪物身份颜色：|cffFF0000BOSS|r，|cff00FF00精英怪|r，普通怪 概率掉落以下物品： |cffFFA500美刀|r、|cffd9d919one刀乐|r、|cffA020F0two刀乐
B8: =60000000+INDEX(编号表!$B:$B,MATCH(J8,编号表!$A:$A,0))*10000+INDEX(编号表!$B:$B,MATCH(K8,编号表!$C:$C,0))*1000+L8 -> 60011004 | C8: a004 | D8: 稻草人 | E8: 稻草人 | F8: 5 | G8: =INDEX(编号表!$E:$E,MATCH(K8,编号表!$C:$C,0)) -> 白色 | H8: 1 | I8: 天元宗门——灵兽园 | J8: 天元宗门 | K8: 普通 | L8: 4 | M8: 4 | P8: 10 | Q8: 150000 | T8: FALSE | U8: 40010001 | X8: 11010001 | Y8: 11020001 | AA8: 体修 | AB8: 20004 | AD8: 10 | AE8: 10 | AF8: 10 | AG8: 20 | AH8: 近战 | AL8: 26 | AM8: 生命值 | AN8: 1 | AO8: 物防下限 | AP8: 2 | AQ8: 物防上限 | AR8: 3 | AS8: 法防下限 | AT8: 2 | AU8: 法防上限 | AV8: 3 | AW8: 攻击下限 | AX8: 5 | AY8: 攻击上限 | AZ8: 7 | BA8: 攻法下限 | BB8: 5 | BC8: 攻法上限 | BD8: 7 | BE8: 攻法下限 | BF8: 0 | BG8: 攻法上限 | BH8: 0 | BI8: 移动速度 | BJ8: 100 | BK8: 攻击范围 | BL8: 10 | BM8: 警戒范围 | BN8: 200 | BQ8: 1 | BR8: 2500 | BS8: 2 | BT8: 2500 | BU8: 怪物说明功能测试： 怪物身份颜色：|cffFF0000BOSS|r，|cff00FF00精英怪|r，普通怪 概率掉落以下物品： |cffFFA500美刀|r、|cffd9d919one刀乐|r、|cffA020F0two刀乐
B9: =60000000+INDEX(编号表!$B:$B,MATCH(J9,编号表!$A:$A,0))*10000+INDEX(编号表!$B:$B,MATCH(K9,编号表!$C:$C,0))*1000+L9 -> 60011005 | C9: a005 | D9: 蛤蟆 | E9: 蛤蟆 | F9: 5 | G9: =INDEX(编号表!$E:$E,MATCH(K9,编号表!$C:$C,0)) -> 白色 | H9: 1 | I9: 天元宗门——灵兽园 | J9: 天元宗门 | K9: 普通 | L9: 5 | M9: 5 | P9: 10 | Q9: 150000 | T9: FALSE | U9: 40010001 | X9: 11010001 | Y9: 11020001 | AA9: 体修 | AB9: 20005 | AD9: 10 | AE9: 10 | AF9: 10 | AG9: 20 | AH9: 近战 | AL9: 33 | AM9: 生命值 | AN9: 1 | AO9: 物防下限 | AP9: 3 | AQ9: 物防上限 | AR9: 4 | AS9: 法防下限 | AT9: 3 | AU9: 法防上限 | AV9: 4 | AW9: 攻击下限 | AX9: 7 | AY9: 攻击上限 | AZ9: 9 | BA9: 攻法下限 | BB9: 7 | BC9: 攻法上限 | BD9: 9 | BE9: 攻法下限 | BF9: 0 | BG9: 攻法上限 | BH9: 0 | BI9: 移动速度 | BJ9: 100 | BK9: 攻击范围 | BL9: 10 | BM9: 警戒范围 | BN9: 200 | BQ9: 1 | BR9: 2500 | BS9: 2 | BT9: 2500 | BU9: 怪物说明功能测试： 怪物身份颜色：|cffFF0000BOSS|r，|cff00FF00精英怪|r，普通怪 概率掉落以下物品： |cffFFA500美刀|r、|cffd9d919one刀乐|r、|cffA020F0two刀乐
B10: =60000000+INDEX(编号表!$B:$B,MATCH(J10,编号表!$A:$A,0))*10000+INDEX(编号表!$B:$B,MATCH(K10,编号表!$C:$C,0))*1000+L10 -> 60011006 | C10: a006 | D10: 毒蜘蛛 | E10: 毒蜘蛛 | F10: 5 | G10: =INDEX(编号表!$E:$E,MATCH(K10,编号表!$C:$C,0)) -> 白色 | H10: 1 | I10: 天元宗门——灵兽园 | J10: 天元宗门 | K10: 普通 | L10: 6 | M10: 6 | P10: 10 | Q10: 150000 | T10: FALSE | U10: 40010001 | X10: 11010001 | Y10: 11020001 | AA10: 体修 | AD10: 30 | AE10: 30 | AF10: 10 | AG10: 20 | AH10: 近战 | AL10: 49 | AM10: 生命值 | AN10: 1 | AO10: 物防下限 | AP10: 4 | AQ10: 物防上限 | AR10: 6 | AS10: 法防下限 | AT10: 4 | AU10: 法防上限 | AV10: 5 | AW10: 攻击下限 | AX10: 10 | AY10: 攻击上限 | AZ10: 13 | BA10: 攻法下限 | BB10: 10 | BC10: 攻法上限 | BD10: 13 | BE10: 攻法下限 | BF10: 0 | BG10: 攻法上限 | BH10: 0 | BI10: 移动速度 | BJ10: 100 | BK10: 攻击范围 | BL10: 10 | BM10: 警戒范围 | BN10: 200 | BQ10: 1 | BR10: 2500 | BS10: 2 | BT10: 2500 | BU10: 怪物说明功能测试： 怪物身份颜色：|cffFF0000BOSS|r，|cff00FF00精英怪|r，普通怪 概率掉落以下物品： |cffFFA500美刀|r、|cffd9d919one刀乐|r、|cffA020F0two刀乐
B11: =60000000+INDEX(编号表!$B:$B,MATCH(J11,编号表!$A:$A,0))*10000+INDEX(编号表!$B:$B,MATCH(K11,编号表!$C:$C,0))*1000+L11 -> 60011007 | C11: a007 | D11: 食人花 | E11: 食人花 | F11: 5 | G11: =INDEX(编号表!$E:$E,MATCH(K11,编号表!$C:$C,0)) -> 白色 | H11: 1 | I11: 天元宗门——灵兽园 | J11: 天元宗门 | K11: 普通 | L11: 7 | M11: 7 | P11: 10 | Q11: 300000 | T11: FALSE | U11: 40010001 | X11: 11010001 | Y11: 11020001 | AA11: 体修 | AD11: 30 | AE11: 30 | AF11: 10 | AG11: 20 | AH11: 近战 | AL11: 58 | AM11: 生命值 | AN11: 1 | AO11: 物防下限 | AP11: 5 | AQ11: 物防上限 | AR11: 7 | AS11: 法防下限 | AT11: 4 | AU11: 法防上限 | AV11: 6 | AW11: 攻击下限 | AX11: 11 | AY11: 攻击上限 | AZ11: 14 | BA11: 攻法下限 | BB11: 11 | BC11: 攻法上限 | BD11: 14 | BE11: 攻法下限 | BF11: 1 | BG11: 攻法上限 | BH11: 2 | BI11: 移动速度 | BJ11: 100 | BK11: 攻击范围 | BL11: 10 | BM11: 警戒范围 | BN11: 200 | BQ11: 1 | BR11: 2500 | BS11: 2 | BT11: 2500 | BU11: 怪物说明功能测试： 怪物身份颜色：|cffFF0000BOSS|r，|cff00FF00精英怪|r，普通怪 概率掉落以下物品： |cffFFA500美刀|r、|cffd9d919one刀乐|r、|cffA020F0two刀乐
B12: =60000000+INDEX(编号表!$B:$B,MATCH(J12,编号表!$A:$A,0))*10000+INDEX(编号表!$B:$B,MATCH(K12,编号表!$C:$C,0))*1000+L12 -> 60011008 | C12: a008 | D12: 红蛇 | E12: 红蛇 | F12: 5 | G12: =INDEX(编号表!$E:$E,MATCH(K12,编号表!$C:$C,0)) -> 白色 | H12: 1 | I12: 天元宗门——灵兽园 | J12: 天元宗门 | K12: 普通 | L12: 8 | M12: 8 | P12: 10 | Q12: 300000 | T12: FALSE | U12: 40010001 | X12: 11010001 | Y12: 11020001 | AA12: 体修 | AB12: 20009 | AD12: 30 | AE12: 30 | AF12: 10 | AG12: 20 | AH12: 近战 | AL12: 53 | AM12: 生命值 | AN12: 1 | AO12: 物防下限 | AP12: 4 | AQ12: 物防上限 | AR12: 6 | AS12: 法防下限 | AT12: 4 | AU12: 法防上限 | AV12: 6 | AW12: 攻击下限 | AX12: 11 | AY12: 攻击上限 | AZ12: 15 | BA12: 攻法下限 | BB12: 11 | BC12: 攻法上限 | BD12: 15 | BE12: 攻法下限 | BF12: 1 | BG12: 攻法上限 | BH12: 2 | BI12: 移动速度 | BJ12: 100 | BK12: 攻击范围 | BL12: 10 | BM12: 警戒范围 | BN12: 200 | BQ12: 1 | BR12: 2500 | BS12: 2 | BT12: 2500 | BU12: 怪物说明功能测试： 怪物身份颜色：|cffFF0000BOSS|r，|cff00FF00精英怪|r，普通怪 概率掉落以下物品： |cffFFA500美刀|r、|cffd9d919one刀乐|r、|cffA020F0two刀乐
B13: =60000000+INDEX(编号表!$B:$B,MATCH(J13,编号表!$A:$A,0))*10000+INDEX(编号表!$B:$B,MATCH(K13,编号表!$C:$C,0))*1000+L13 -> 60011009 | C13: a009 | D13: 虎蛇 | E13: 虎蛇 | F13: 5 | G13: =INDEX(编号表!$E:$E,MATCH(K13,编号表!$C:$C,0)) -> 白色 | H13: 1 | I13: 天元宗门——灵兽园 | J13: 天元宗门 | K13: 普通 | L13: 9 | M13: 9 | P13: 10 | Q13: 300000 | T13: FALSE | U13: 40010001 | X13: 11010001 | Y13: 11020001 | AA13: 体修 | AD13: 30 | AE13: 30 | AF13: 10 | AG13: 20 | AH13: 近战 | AL13: 58 | AM13: 生命值 | AN13: 1 | AO13: 物防下限 | AP13: 5 | AQ13: 物防上限 | AR13: 7 | AS13: 法防下限 | AT13: 4 | AU13: 法防上限 | AV13: 6 | AW13: 攻击下限 | AX13: 12 | AY13: 攻击上限 | AZ13: 16 | BA13: 攻法下限 | BB13: 12 | BC13: 攻法上限 | BD13: 16 | BE13: 攻法下限 | BF13: 1 | BG13: 攻法上限 | BH13: 2 | BI13: 移动速度 | BJ13: 100 | BK13: 攻击范围 | BL13: 10 | BM13: 警戒范围 | BN13: 200 | BQ13: 1 | BR13: 2500 | BS13: 2 | BT13: 2500 | BU13: 怪物说明功能测试： 怪物身份颜色：|cffFF0000BOSS|r，|cff00FF00精英怪|r，普通怪 概率掉落以下物品： |cffFFA500美刀|r、|cffd9d919one刀乐|r、|cffA020F0two刀乐
B14: =60000000+INDEX(编号表!$B:$B,MATCH(J14,编号表!$A:$A,0))*10000+INDEX(编号表!$B:$B,MATCH(K14,编号表!$C:$C,0))*1000+L14 -> 60011010 | C14: a010 | D14: 狼 | E14: 狼 | F14: 5 | G14: =INDEX(编号表!$E:$E,MATCH(K14,编号表!$C:$C,0)) -> 白色 | H14: 1 | I14: 天元宗门——灵兽园 | J14: 天元宗门 | K14: 普通 | L14: 10 | M14: 10 | P14: 10 | Q14: 150000 | T14: FALSE | U14: 40010001 | X14: 11010001 | Y14: 11020001 | AA14: 体修 | AB14: 20008 | AD14: 30 | AE14: 30 | AF14: 10 | AG14: 20 | AH14: 近战 | AL14: 49 | AM14: 生命值 | AN14: 1 | AO14: 物防下限 | AP14: 4 | AQ14: 物防上限 | AR14: 6 | AS14: 法防下限 | AT14: 4 | AU14: 法防上限 | AV14: 5 | AW14: 攻击下限 | AX14: 9 | AY14: 攻击上限 | AZ14: 12 | BA14: 攻法下限 | BB14: 9 | BC14: 攻法上限 | BD14: 12 | BE14: 攻法下限 | BF14: 0 | BG14: 攻法上限 | BH14: 0 | BI14: 移动速度 | BJ14: 100 | BK14: 攻击范围 | BL14: 10 | BM14: 警戒范围 | BN14: 200 | BQ14: 1 | BR14: 2500 | BS14: 2 | BT14: 2500 | BU14: 怪物说明功能测试： 怪物身份颜色：|cffFF0000BOSS|r，|cff00FF00精英怪|r，普通怪 概率掉落以下物品： |cffFFA500美刀|r、|cffd9d919one刀乐|r、|cffA020F0two刀乐
B15: =60000000+INDEX(编号表!$B:$B,MATCH(J15,编号表!$A:$A,0))*10000+INDEX(编号表!$B:$B,MATCH(K15,编号表!$C:$C,0))*1000+L15 -> 60011011 | C15: a011 | D15: 虎卫 | E15: 虎卫 | F15: 5 | G15: =INDEX(编号表!$E:$E,MATCH(K15,编号表!$C:$C,0)) -> 白色 | H15: 1 | I15: 天元宗门——灵兽园 | J15: 天元宗门 | K15: 普通 | L15: 11 | M15: 11 | P15: 10 | Q15: 300000 | T15: FALSE | U15: 40010001 | X15: 11010001 | Y15: 11020001 | AA15: 体修 | AB15: 20006 | AD15: 10 | AE15: 10 | AF15: 10 | AG15: 20 | AH15: 近战 | AL15: 58 | AM15: 生命值 | AN15: 1 | AO15: 物防下限 | AP15: 5 | AQ15: 物防上限 | AR15: 7 | AS15: 法防下限 | AT15: 4 | AU15: 法防上限 | AV15: 6 | AW15: 攻击下限 | AX15: 11 | AY15: 攻击上限 | AZ15: 14 | BA15: 攻法下限 | BB15: 11 | BC15: 攻法上限 | BD15: 14 | BE15: 攻法下限 | BF15: 1 | BG15: 攻法上限 | BH15: 2 | BI15: 移动速度 | BJ15: 100 | BK15: 攻击范围 | BL15: 10 | BM15: 警戒范围 | BN15: 200 | BQ15: 1 | BR15: 2500 | BS15: 2 | BT15: 2500 | BU15: 怪物说明功能测试： 怪物身份颜色：|cffFF0000BOSS|r，|cff00FF00精英怪|r，普通怪 概率掉落以下物品： |cffFFA500美刀|r、|cffd9d919one刀乐|r、|cffA020F0two刀乐
B16: =60000000+INDEX(编号表!$B:$B,MATCH(J16,编号表!$A:$A,0))*10000+INDEX(编号表!$B:$B,MATCH(K16,编号表!$C:$C,0))*1000+L16 -> 60011012 | C16: a012 | D16: 鹰卫 | E16: 鹰卫 | F16: 5 | G16: =INDEX(编号表!$E:$E,MATCH(K16,编号表!$C:$C,0)) -> 白色 | H16: 1 | I16: 天元宗门——灵兽园 | J16: 天元宗门 | K16: 普通 | L16: 12 | M16: 12 | P16: 10 | Q16: 300000 | T16: FALSE | U16: 40010001 | X16: 11010001 | Y16: 11020001 | AA16: 体修 | AB16: 20007 | AD16: 10 | AE16: 10 | AF16: 10 | AG16: 20 | AH16: 远程 | AL16: 58 | AM16: 生命值 | AN16: 1 | AO16: 物防下限 | AP16: 5 | AQ16: 物防上限 | AR16: 7 | AS16: 法防下限 | AT16: 4 | AU16: 法防上限 | AV16: 6 | AW16: 攻击下限 | AX16: 11 | AY16: 攻击上限 | AZ16: 14 | BA16: 攻法下限 | BB16: 11 | BC16: 攻法上限 | BD16: 14 | BE16: 攻法下限 | BF16: 1 | BG16: 攻法上限 | BH16: 2 | BI16: 移动速度 | BJ16: 100 | BK16: 攻击范围 | BL16: 300 | BM16: 警戒范围 | BN16: 200 | BQ16: 1 | BR16: 2500 | BS16: 2 | BT16: 2500 | BU16: 怪物说明功能测试： 怪物身份颜色：|cffFF0000BOSS|r，|cff00FF00精英怪|r，普通怪 概率掉落以下物品： |cffFFA500美刀|r、|cffd9d919one刀乐|r、|cffA020F0two刀乐
B17: =60000000+INDEX(编号表!$B:$B,MATCH(J17,编号表!$A:$A,0))*10000+INDEX(编号表!$B:$B,MATCH(K17,编号表!$C:$C,0))*1000+L17 -> 60011013 | C17: a013 | D17: 山洞蝙蝠 | E17: 山洞蝙蝠 | F17: 5 | G17: =INDEX(编号表!$E:$E,MATCH(K17,编号表!$C:$C,0)) -> 白色 | H17: 1 | I17: 天元宗门——灵兽园 | J17: 天元宗门 | K17: 普通 | L17: 13 | M17: 13 | P17: 10 | Q17: 150000 | T17: FALSE | U17: 40010001 | X17: 11010001 | Y17: 11020001 | AA17: 体修 | AB17: 20008 | AD17: 10 | AE17: 20 | AF17: 20 | AG17: 30 | AH17: 近战 | AL17: 59 | AM17: 生命值 | AN17: 190 | AO17: 物防下限 | AP17: 4 | AQ17: 物防上限 | AR17: 5 | AS17: 法防下限 | AT17: 3 | AU17: 法防上限 | AV17: 5 | AW17: 攻击下限 | AX17: 12 | AY17: 攻击上限 | AZ17: 16 | BA17: 攻法下限 | BB17: 12 | BC17: 攻法上限 | BD17: 16 | BE17: 攻法下限 | BF17: 0 | BG17: 攻法上限 | BH17: 0 | BI17: 移动速度 | BJ17: 100 | BK17: 攻击范围 | BL17: 10 | BM17: 警戒范围 | BN17: 250 | BO17: 0.03 | BQ17: 1 | BR17: 2500 | BS17: 2 | BT17: 2500 | BU17: 怪物说明功能测试： 怪物身份颜色：|cffFF0000BOSS|r，|cff00FF00精英怪|r，普通怪 概率掉落以下物品： |cffFFA500美刀|r、|cffd9d919one刀乐|r、|cffA020F0two刀乐
B18: =60000000+INDEX(编号表!$B:$B,MATCH(J18,编号表!$A:$A,0))*10000+INDEX(编号表!$B:$B,MATCH(K18,编号表!$C:$C,0))*1000+L18 -> 60021014 | C18: a014 | D18: 青魂煞灵 | E18: 青魂煞灵 | F18: 5 | G18: =INDEX(编号表!$E:$E,MATCH(K18,编号表!$C:$C,0)) -> 白色 | H18: 2 | I18: 蚀苇沼·末流所积 | J18: 蚀苇沼·末流所积 | K18: 普通 | L18: 14 | M18: 14 | P18: 10 | Q18: 150000 | T18: FALSE | U18: 40010001 | X18: 11010001 | Y18: 11020001 | AA18: 体修 | AB18: 20030 | AD18: 80 | AE18: 80 | AF18: 20 | AG18: 30 | AH18: 近战 | AL18: 255 | AM18: 生命值 | AN18: 1500 | AO18: 物防下限 | AP18: 8 | AQ18: 物防上限 | AR18: 12 | AS18: 法防下限 | AT18: 8 | AU18: 法防上限 | AV18: 11 | AW18: 攻击下限 | AX18: 21 | AY18: 攻击上限 | AZ18: 29 | BA18: 攻法下限 | BB18: 21 | BC18: 攻法上限 | BD18: 29 | BE18: 攻法下限 | BF18: 0 | BG18: 攻法上限 | BH18: 0 | BI18: 移动速度 | BJ18: 100 | BK18: 攻击范围 | BL18: 10 | BM18: 警戒范围 | BN18: 250 | BQ18: 1 | BR18: 2500 | BS18: 2 | BT18: 2500 | BU18: 怪物说明功能测试： 怪物身份颜色：|cffFF0000BOSS|r，|cff00FF00精英怪|r，普通怪 概率掉落以下物品： |cffFFA500美刀|r、|cffd9d919one刀乐|r、|cffA020F0two刀乐
B19: =60000000+INDEX(编号表!$B:$B,MATCH(J19,编号表!$A:$A,0))*10000+INDEX(编号表!$B:$B,MATCH(K19,编号表!$C:$C,0))*1000+L19 -> 60021015 | C19: a015 | D19: 深渊水魔 | E19: 深渊水魔 | F19: 5 | G19: =INDEX(编号表!$E:$E,MATCH(K19,编号表!$C:$C,0)) -> 白色 | H19: 2 | I19: 蚀苇沼·末流所积 | J19: 蚀苇沼·末流所积 | K19: 普通 | L19: 15 | M19: 15 | P19: 10 | Q19: 150000 | T19: FALSE | U19: 40010001 | X19: 11010001 | Y19: 11020001 | AA19: 体修 | AB19: 20031 | AD19: 80 | AE19: 80 | AF19: 20 | AG19: 30 | AH19: 近战 | AL19: 255 | AM19: 生命值 | AN19: 1500 | AO19: 物防下限 | AP19: 8 | AQ19: 物防上限 | AR19: 12 | AS19: 法防下限 | AT19: 8 | AU19: 法防上限 | AV19: 11 | AW19: 攻击下限 | AX19: 21 | AY19: 攻击上限 | AZ19: 29 | BA19: 攻法下限 | BB19: 21 | BC19: 攻法上限 | BD19: 29 | BE19: 攻法下限 | BF19: 0 | BG19: 攻法上限 | BH19: 0 | BI19: 移动速度 | BJ19: 100 | BK19: 攻击范围 | BL19: 10 | BM19: 警戒范围 | BN19: 250 | BQ19: 1 | BR19: 2500 | BS19: 2 | BT19: 2500 | BU19: 怪物说明功能测试： 怪物身份颜色：|cffFF0000BOSS|r，|cff00FF00精英怪|r，普通怪 概率掉落以下物品： |cffFFA500美刀|r、|cffd9d919one刀乐|r、|cffA020F0two刀乐
B20: =60000000+INDEX(编号表!$B:$B,MATCH(J20,编号表!$A:$A,0))*10000+INDEX(编号表!$B:$B,MATCH(K20,编号表!$C:$C,0))*1000+L20 -> 60021016 | C20: a016 | D20: 冥海幽灵 | E20: 冥海幽灵 | F20: 5 | G20: =INDEX(编号表!$E:$E,MATCH(K20,编号表!$C:$C,0)) -> 白色 | H20: 2 | I20: 蚀苇沼·末流所积 | J20: 蚀苇沼·末流所积 | K20: 普通 | L20: 16 | M20: 16 | P20: 10 | Q20: 150000 | T20: FALSE | U20: 40010001 | X20: 11010001 | Y20: 11020001 | AA20: 体修 | AB20: 20032 | AD20: 80 | AE20: 80 | AF20: 20 | AG20: 30 | AH20: 近战 | AL20: 255 | AM20: 生命值 | AN20: 1500 | AO20: 物防下限 | AP20: 8 | AQ20: 物防上限 | AR20: 12 | AS20: 法防下限 | AT20: 8 | AU20: 法防上限 | AV20: 11 | AW20: 攻击下限 | AX20: 21 | AY20: 攻击上限 | AZ20: 29 | BA20: 攻法下限 | BB20: 21 | BC20: 攻法上限 | BD20: 29 | BE20: 攻法下限 | BF20: 0 | BG20: 攻法上限 | BH20: 0 | BI20: 移动速度 | BJ20: 100 | BK20: 攻击范围 | BL20: 10 | BM20: 警戒范围 | BN20: 250 | BQ20: 1 | BR20: 2500 | BS20: 2 | BT20: 2500 | BU20: 怪物说明功能测试： 怪物身份颜色：|cffFF0000BOSS|r，|cff00FF00精英怪|r，普通怪 概率掉落以下物品： |cffFFA500美刀|r、|cffd9d919one刀乐|r、|cffA020F0two刀乐
B21: =60000000+INDEX(编号表!$B:$B,MATCH(J21,编号表!$A:$A,0))*10000+INDEX(编号表!$B:$B,MATCH(K21,编号表!$C:$C,0))*1000+L21 -> 60021017 | C21: a017 | D21: 冥河幽魂 | E21: 冥河幽魂 | F21: 5 | G21: =INDEX(编号表!$E:$E,MATCH(K21,编号表!$C:$C,0)) -> 白色 | H21: 2 | I21: 蚀苇沼·末流所积 | J21: 蚀苇沼·末流所积 | K21: 普通 | L21: 17 | M21: 17 | P21: 10 | Q21: 150000 | T21: FALSE | U21: 40010001 | X21: 11010001 | Y21: 11020001 | AA21: 体修 | AB21: 20033 | AD21: 80 | AE21: 80 | AF21: 20 | AG21: 30 | AH21: 近战 | AL21: 255 | AM21: 生命值 | AN21: 1500 | AO21: 物防下限 | AP21: 8 | AQ21: 物防上限 | AR21: 12 | AS21: 法防下限 | AT21: 8 | AU21: 法防上限 | AV21: 11 | AW21: 攻击下限 | AX21: 21 | AY21: 攻击上限 | AZ21: 29 | BA21: 攻法下限 | BB21: 21 | BC21: 攻法上限 | BD21: 29 | BE21: 攻法下限 | BF21: 0 | BG21: 攻法上限 | BH21: 0 | BI21: 移动速度 | BJ21: 100 | BK21: 攻击范围 | BL21: 10 | BM21: 警戒范围 | BN21: 250 | BQ21: 1 | BR21: 2500 | BS21: 2 | BT21: 2500 | BU21: 怪物说明功能测试： 怪物身份颜色：|cffFF0000BOSS|r，|cff00FF00精英怪|r，普通怪 概率掉落以下物品： |cffFFA500美刀|r、|cffd9d919one刀乐|r、|cffA020F0two刀乐
B22: =60000000+INDEX(编号表!$B:$B,MATCH(J22,编号表!$A:$A,0))*10000+INDEX(编号表!$B:$B,MATCH(K22,编号表!$C:$C,0))*1000+L22 -> 60022018 | C22: a018 | D22: 冥河幽魂 | E22: 冥河幽魂 | F22: 5 | G22: =INDEX(编号表!$E:$E,MATCH(K22,编号表!$C:$C,0)) -> 绿色 | H22: 2 | I22: 蚀苇沼·末流所积 | J22: 蚀苇沼·末流所积 | K22: 精英 | L22: 18 | M22: 18 | P22: 10 | Q22: 150000 | T22: FALSE | U22: 40010001 | X22: 11010001 | Y22: 11020001 | AA22: 体修 | AB22: 20033 | AC22: 1.5 | AD22: 80 | AE22: 80 | AF22: 20 | AG22: 30 | AH22: 近战 | AJ22: 30010 | AL22: 255 | AM22: 生命值 | AN22: 1500 | AO22: 物防下限 | AP22: 8 | AQ22: 物防上限 | AR22: 12 | AS22: 法防下限 | AT22: 8 | AU22: 法防上限 | AV22: 11 | AW22: 攻击下限 | AX22: 21 | AY22: 攻击上限 | AZ22: 29 | BA22: 攻法下限 | BB22: 21 | BC22: 攻法上限 | BD22: 29 | BE22: 攻法下限 | BF22: 0 | BG22: 攻法上限 | BH22: 0 | BI22: 移动速度 | BJ22: 100 | BK22: 攻击范围 | BL22: 10 | BM22: 警戒范围 | BN22: 250 | BQ22: 1 | BR22: 2500 | BS22: 2 | BT22: 2500 | BU22: 怪物说明功能测试： 怪物身份颜色：|cffFF0000BOSS|r，|cff00FF00精英怪|r，普通怪 概率掉落以下物品： |cffFFA500美刀|r、|cffd9d919one刀乐|r、|cffA020F0two刀乐
B23: =60000000+INDEX(编号表!$B:$B,MATCH(J23,编号表!$A:$A,0))*10000+INDEX(编号表!$B:$B,MATCH(K23,编号表!$C:$C,0))*1000+L23 -> 60031019 | C23: a019 | D23: 骷髅长枪兵 | E23: 骷髅长枪兵 | F23: 5 | G23: =INDEX(编号表!$E:$E,MATCH(K23,编号表!$C:$C,0)) -> 白色 | H23: 3 | I23: 浮沉洲 | J23: 浮沉洲 | K23: 普通 | L23: 19 | M23: 19 | P23: 10 | Q23: 150000 | T23: FALSE | U23: 40010001 | X23: 11010001 | Y23: 11020001 | AA23: 体修 | AB23: 20013 | AD23: 80 | AE23: 80 | AF23: 20 | AG23: 30 | AH23: 近战 | AL23: 255 | AM23: 生命值 | AN23: 1500 | AO23: 物防下限 | AP23: 8 | AQ23: 物防上限 | AR23: 12 | AS23: 法防下限 | AT23: 8 | AU23: 法防上限 | AV23: 11 | AW23: 攻击下限 | AX23: 21 | AY23: 攻击上限 | AZ23: 29 | BA23: 攻法下限 | BB23: 21 | BC23: 攻法上限 | BD23: 29 | BE23: 攻法下限 | BF23: 0 | BG23: 攻法上限 | BH23: 0 | BI23: 移动速度 | BJ23: 100 | BK23: 攻击范围 | BL23: 10 | BM23: 警戒范围 | BN23: 250 | BQ23: 1 | BR23: 2500 | BS23: 2 | BT23: 2500 | BU23: 怪物说明功能测试： 怪物身份颜色：|cffFF0000BOSS|r，|cff00FF00精英怪|r，普通怪 概率掉落以下物品： |cffFFA500美刀|r、|cffd9d919one刀乐|r、|cffA020F0two刀乐
B24: =60000000+INDEX(编号表!$B:$B,MATCH(J24,编号表!$A:$A,0))*10000+INDEX(编号表!$B:$B,MATCH(K24,编号表!$C:$C,0))*1000+L24 -> 60031020 | C24: a020 | D24: 骷髅弓箭手 | E24: 骷髅弓箭手 | F24: 5 | G24: =INDEX(编号表!$E:$E,MATCH(K24,编号表!$C:$C,0)) -> 白色 | H24: 3 | I24: 浮沉洲 | J24: 浮沉洲 | K24: 普通 | L24: 20 | M24: 20 | P24: 10 | Q24: 150000 | T24: FALSE | U24: 40010001 | X24: 11010001 | Y24: 11020001 | AA24: 体修 | AB24: 20014 | AD24: 80 | AE24: 80 | AF24: 20 | AG24: 30 | AH24: 近战 | AL24: 255 | AM24: 生命值 | AN24: 1500 | AO24: 物防下限 | AP24: 8 | AQ24: 物防上限 | AR24: 12 | AS24: 法防下限 | AT24: 8 | AU24: 法防上限 | AV24: 11 | AW24: 攻击下限 | AX24: 21 | AY24: 攻击上限 | AZ24: 29 | BA24: 攻法下限 | BB24: 21 | BC24: 攻法上限 | BD24: 29 | BE24: 攻法下限 | BF24: 0 | BG24: 攻法上限 | BH24: 0 | BI24: 移动速度 | BJ24: 100 | BK24: 攻击范围 | BL24: 10 | BM24: 警戒范围 | BN24: 250 | BQ24: 1 | BR24: 2500 | BS24: 2 | BT24: 2500 | BU24: 怪物说明功能测试： 怪物身份颜色：|cffFF0000BOSS|r，|cff00FF00精英怪|r，普通怪 概率掉落以下物品： |cffFFA500美刀|r、|cffd9d919one刀乐|r、|cffA020F0two刀乐
B25: =60000000+INDEX(编号表!$B:$B,MATCH(J25,编号表!$A:$A,0))*10000+INDEX(编号表!$B:$B,MATCH(K25,编号表!$C:$C,0))*1000+L25 -> 60031021 | C25: a021 | D25: 骷髅锤兵 | E25: 骷髅锤兵 | F25: 5 | G25: =INDEX(编号表!$E:$E,MATCH(K25,编号表!$C:$C,0)) -> 白色 | H25: 3 | I25: 浮沉洲 | J25: 浮沉洲 | K25: 普通 | L25: 21 | M25: 21 | P25: 10 | Q25: 150000 | T25: FALSE | U25: 40010001 | X25: 11010001 | Y25: 11020001 | AA25: 体修 | AB25: 20016 | AD25: 80 | AE25: 80 | AF25: 20 | AG25: 30 | AH25: 近战 | AL25: 255 | AM25: 生命值 | AN25: 1500 | AO25: 物防下限 | AP25: 8 | AQ25: 物防上限 | AR25: 12 | AS25: 法防下限 | AT25: 8 | AU25: 法防上限 | AV25: 11 | AW25: 攻击下限 | AX25: 21 | AY25: 攻击上限 | AZ25: 29 | BA25: 攻法下限 | BB25: 21 | BC25: 攻法上限 | BD25: 29 | BE25: 攻法下限 | BF25: 0 | BG25: 攻法上限 | BH25: 0 | BI25: 移动速度 | BJ25: 100 | BK25: 攻击范围 | BL25: 10 | BM25: 警戒范围 | BN25: 250 | BQ25: 1 | BR25: 2500 | BS25: 2 | BT25: 2500 | BU25: 怪物说明功能测试： 怪物身份颜色：|cffFF0000BOSS|r，|cff00FF00精英怪|r，普通怪 概率掉落以下物品： |cffFFA500美刀|r、|cffd9d919one刀乐|r、|cffA020F0two刀乐
B26: =60000000+INDEX(编号表!$B:$B,MATCH(J26,编号表!$A:$A,0))*10000+INDEX(编号表!$B:$B,MATCH(K26,编号表!$C:$C,0))*1000+L26 -> 60031022 | C26: a022 | D26: 骷髅刀斧手 | E26: 骷髅刀斧手 | F26: 5 | G26: =INDEX(编号表!$E:$E,MATCH(K26,编号表!$C:$C,0)) -> 白色 | H26: 3 | I26: 浮沉洲 | J26: 浮沉洲 | K26: 普通 | L26: 22 | M26: 22 | P26: 10 | Q26: 150000 | T26: FALSE | U26: 40010001 | X26: 11010001 | Y26: 11020001 | AA26: 体修 | AB26: 20017 | AD26: 80 | AE26: 80 | AF26: 20 | AG26: 30 | AH26: 近战 | AL26: 255 | AM26: 生命值 | AN26: 1500 | AO26: 物防下限 | AP26: 8 | AQ26: 物防上限 | AR26: 12 | AS26: 法防下限 | AT26: 8 | AU26: 法防上限 | AV26: 11 | AW26: 攻击下限 | AX26: 21 | AY26: 攻击上限 | AZ26: 29 | BA26: 攻法下限 | BB26: 21 | BC26: 攻法上限 | BD26: 29 | BE26: 攻法下限 | BF26: 0 | BG26: 攻法上限 | BH26: 0 | BI26: 移动速度 | BJ26: 100 | BK26: 攻击范围 | BL26: 10 | BM26: 警戒范围 | BN26: 250 | BQ26: 1 | BR26: 2500 | BS26: 2 | BT26: 2500 | BU26: 怪物说明功能测试： 怪物身份颜色：|cffFF0000BOSS|r，|cff00FF00精英怪|r，普通怪 概率掉落以下物品： |cffFFA500美刀|r、|cffd9d919one刀乐|r、|cffA020F0two刀乐
B27: =60000000+INDEX(编号表!$B:$B,MATCH(J27,编号表!$A:$A,0))*10000+INDEX(编号表!$B:$B,MATCH(K27,编号表!$C:$C,0))*1000+L27 -> 60031023 | C27: a023 | D27: 骷髅盾卫 | E27: 骷髅盾卫 | F27: 5 | G27: =INDEX(编号表!$E:$E,MATCH(K27,编号表!$C:$C,0)) -> 白色 | H27: 3 | I27: 浮沉洲 | J27: 浮沉洲 | K27: 普通 | L27: 23 | M27: 23 | P27: 10 | Q27: 150000 | T27: FALSE | U27: 40010001 | X27: 11010001 | Y27: 11020001 | AA27: 体修 | AB27: 20036 | AD27: 80 | AE27: 80 | AF27: 20 | AG27: 30 | AH27: 近战 | AL27: 255 | AM27: 生命值 | AN27: 1500 | AO27: 物防下限 | AP27: 8 | AQ27: 物防上限 | AR27: 12 | AS27: 法防下限 | AT27: 8 | AU27: 法防上限 | AV27: 11 | AW27: 攻击下限 | AX27: 21 | AY27: 攻击上限 | AZ27: 29 | BA27: 攻法下限 | BB27: 21 | BC27: 攻法上限 | BD27: 29 | BE27: 攻法下限 | BF27: 0 | BG27: 攻法上限 | BH27: 0 | BI27: 移动速度 | BJ27: 100 | BK27: 攻击范围 | BL27: 10 | BM27: 警戒范围 | BN27: 250 | BQ27: 1 | BR27: 2500 | BS27: 2 | BT27: 2500 | BU27: 怪物说明功能测试： 怪物身份颜色：|cffFF0000BOSS|r，|cff00FF00精英怪|r，普通怪 概率掉落以下物品： |cffFFA500美刀|r、|cffd9d919one刀乐|r、|cffA020F0two刀乐
B28: =60000000+INDEX(编号表!$B:$B,MATCH(J28,编号表!$A:$A,0))*10000+INDEX(编号表!$B:$B,MATCH(K28,编号表!$C:$C,0))*1000+L28 -> 60032024 | C28: a024 | D28: 骷髅盾卫 | E28: 骷髅盾卫 | F28: 5 | G28: =INDEX(编号表!$E:$E,MATCH(K28,编号表!$C:$C,0)) -> 绿色 | H28: 3 | I28: 浮沉洲 | J28: 浮沉洲 | K28: 精英 | L28: 24 | M28: 24 | P28: 10 | Q28: 150000 | T28: FALSE | U28: 40010001 | X28: 11010001 | Y28: 11020001 | AA28: 体修 | AB28: 20036 | AC28: 1.5 | AD28: 80 | AE28: 80 | AF28: 20 | AG28: 30 | AH28: 近战 | AJ28: 30010 | AL28: 255 | AM28: 生命值 | AN28: 1500 | AO28: 物防下限 | AP28: 8 | AQ28: 物防上限 | AR28: 12 | AS28: 法防下限 | AT28: 8 | AU28: 法防上限 | AV28: 11 | AW28: 攻击下限 | AX28: 21 | AY28: 攻击上限 | AZ28: 29 | BA28: 攻法下限 | BB28: 21 | BC28: 攻法上限 | BD28: 29 | BE28: 攻法下限 | BF28: 0 | BG28: 攻法上限 | BH28: 0 | BI28: 移动速度 | BJ28: 100 | BK28: 攻击范围 | BL28: 10 | BM28: 警戒范围 | BN28: 250 | BQ28: 1 | BR28: 2500 | BS28: 2 | BT28: 2500 | BU28: 怪物说明功能测试： 怪物身份颜色：|cffFF0000BOSS|r，|cff00FF00精英怪|r，普通怪 概率掉落以下物品： |cffFFA500美刀|r、|cffd9d919one刀乐|r、|cffA020F0two刀乐
B29: =60000000+INDEX(编号表!$B:$B,MATCH(J29,编号表!$A:$A,0))*10000+INDEX(编号表!$B:$B,MATCH(K29,编号表!$C:$C,0))*1000+L29 -> 60041025 | C29: a025 | D29: 跳跳蜂 | E29: 跳跳蜂 | F29: 5 | G29: =INDEX(编号表!$E:$E,MATCH(K29,编号表!$C:$C,0)) -> 白色 | H29: 4 | I29: 蔽苇汀 | J29: 蔽苇汀 | K29: 普通 | L29: 25 | M29: 25 | P29: 10 | Q29: 150000 | T29: FALSE | U29: 40010001 | X29: 11010001 | Y29: 11020001 | AA29: 体修 | AB29: 20011 | AD29: 80 | AE29: 80 | AF29: 20 | AG29: 30 | AH29: 近战 | AL29: 255 | AM29: 生命值 | AN29: 1500 | AO29: 物防下限 | AP29: 8 | AQ29: 物防上限 | AR29: 12 | AS29: 法防下限 | AT29: 8 | AU29: 法防上限 | AV29: 11 | AW29: 攻击下限 | AX29: 21 | AY29: 攻击上限 | AZ29: 29 | BA29: 攻法下限 | BB29: 21 | BC29: 攻法上限 | BD29: 29 | BE29: 攻法下限 | BF29: 0 | BG29: 攻法上限 | BH29: 0 | BI29: 移动速度 | BJ29: 100 | BK29: 攻击范围 | BL29: 10 | BM29: 警戒范围 | BN29: 250 | BQ29: 1 | BR29: 2500 | BS29: 2 | BT29: 2500 | BU29: 怪物说明功能测试： 怪物身份颜色：|cffFF0000BOSS|r，|cff00FF00精英怪|r，普通怪 概率掉落以下物品： |cffFFA500美刀|r、|cffd9d919one刀乐|r、|cffA020F0two刀乐
B30: =60000000+INDEX(编号表!$B:$B,MATCH(J30,编号表!$A:$A,0))*10000+INDEX(编号表!$B:$B,MATCH(K30,编号表!$C:$C,0))*1000+L30 -> 60041026 | C30: a026 | D30: 飞蛾 | E30: 飞蛾 | F30: 5 | G30: =INDEX(编号表!$E:$E,MATCH(K30,编号表!$C:$C,0)) -> 白色 | H30: 4 | I30: 蔽苇汀 | J30: 蔽苇汀 | K30: 普通 | L30: 26 | M30: 26 | P30: 10 | Q30: 150000 | T30: FALSE | U30: 40010001 | X30: 11010001 | Y30: 11020001 | AA30: 体修 | AB30: 20012 | AD30: 80 | AE30: 80 | AF30: 20 | AG30: 30 | AH30: 近战 | AL30: 255 | AM30: 生命值 | AN30: 1500 | AO30: 物防下限 | AP30: 8 | AQ30: 物防上限 | AR30: 12 | AS30: 法防下限 | AT30: 8 | AU30: 法防上限 | AV30: 11 | AW30: 攻击下限 | AX30: 21 | AY30: 攻击上限 | AZ30: 29 | BA30: 攻法下限 | BB30: 21 | BC30: 攻法上限 | BD30: 29 | BE30: 攻法下限 | BF30: 0 | BG30: 攻法上限 | BH30: 0 | BI30: 移动速度 | BJ30: 100 | BK30: 攻击范围 | BL30: 10 | BM30: 警戒范围 | BN30: 250 | BQ30: 1 | BR30: 2500 | BS30: 2 | BT30: 2500 | BU30: 怪物说明功能测试： 怪物身份颜色：|cffFF0000BOSS|r，|cff00FF00精英怪|r，普通怪 概率掉落以下物品： |cffFFA500美刀|r、|cffd9d919one刀乐|r、|cffA020F0two刀乐
B31: =60000000+INDEX(编号表!$B:$B,MATCH(J31,编号表!$A:$A,0))*10000+INDEX(编号表!$B:$B,MATCH(K31,编号表!$C:$C,0))*1000+L31 -> 60041027 | C31: a027 | D31: 蝎蛇 | E31: 蝎蛇 | F31: 5 | G31: =INDEX(编号表!$E:$E,MATCH(K31,编号表!$C:$C,0)) -> 白色 | H31: 4 | I31: 蔽苇汀 | J31: 蔽苇汀 | K31: 普通 | L31: 27 | M31: 27 | P31: 10 | Q31: 150000 | T31: FALSE | U31: 40010001 | X31: 11010001 | Y31: 11020001 | AA31: 体修 | AB31: 20015 | AD31: 80 | AE31: 80 | AF31: 20 | AG31: 30 | AH31: 近战 | AL31: 255 | AM31: 生命值 | AN31: 1500 | AO31: 物防下限 | AP31: 8 | AQ31: 物防上限 | AR31: 12 | AS31: 法防下限 | AT31: 8 | AU31: 法防上限 | AV31: 11 | AW31: 攻击下限 | AX31: 21 | AY31: 攻击上限 | AZ31: 29 | BA31: 攻法下限 | BB31: 21 | BC31: 攻法上限 | BD31: 29 | BE31: 攻法下限 | BF31: 0 | BG31: 攻法上限 | BH31: 0 | BI31: 移动速度 | BJ31: 100 | BK31: 攻击范围 | BL31: 10 | BM31: 警戒范围 | BN31: 250 | BQ31: 1 | BR31: 2500 | BS31: 2 | BT31: 2500 | BU31: 怪物说明功能测试： 怪物身份颜色：|cffFF0000BOSS|r，|cff00FF00精英怪|r，普通怪 概率掉落以下物品： |cffFFA500美刀|r、|cffd9d919one刀乐|r、|cffA020F0two刀乐
B32: =60000000+INDEX(编号表!$B:$B,MATCH(J32,编号表!$A:$A,0))*10000+INDEX(编号表!$B:$B,MATCH(K32,编号表!$C:$C,0))*1000+L32 -> 60041028 | C32: a028 | D32: 腐毒蛙 | E32: 腐毒蛙 | F32: 5 | G32: =INDEX(编号表!$E:$E,MATCH(K32,编号表!$C:$C,0)) -> 白色 | H32: 4 | I32: 蔽苇汀 | J32: 蔽苇汀 | K32: 普通 | L32: 28 | M32: 28 | P32: 10 | Q32: 150000 | T32: FALSE | U32: 40010001 | X32: 11010001 | Y32: 11020001 | AA32: 体修 | AB32: 20022 | AD32: 80 | AE32: 80 | AF32: 20 | AG32: 30 | AH32: 近战 | AL32: 255 | AM32: 生命值 | AN32: 1500 | AO32: 物防下限 | AP32: 8 | AQ32: 物防上限 | AR32: 12 | AS32: 法防下限 | AT32: 8 | AU32: 法防上限 | AV32: 11 | AW32: 攻击下限 | AX32: 21 | AY32: 攻击上限 | AZ32: 29 | BA32: 攻法下限 | BB32: 21 | BC32: 攻法上限 | BD32: 29 | BE32: 攻法下限 | BF32: 0 | BG32: 攻法上限 | BH32: 0 | BI32: 移动速度 | BJ32: 100 | BK32: 攻击范围 | BL32: 10 | BM32: 警戒范围 | BN32: 250 | BQ32: 1 | BR32: 2500 | BS32: 2 | BT32: 2500 | BU32: 怪物说明功能测试： 怪物身份颜色：|cffFF0000BOSS|r，|cff00FF00精英怪|r，普通怪 概率掉落以下物品： |cffFFA500美刀|r、|cffd9d919one刀乐|r、|cffA020F0two刀乐
B33: =60000000+INDEX(编号表!$B:$B,MATCH(J33,编号表!$A:$A,0))*10000+INDEX(编号表!$B:$B,MATCH(K33,编号表!$C:$C,0))*1000+L33 -> 60041029 | C33: a029 | D33: 赤发魔童 | E33: 赤发魔童 | F33: 5 | G33: =INDEX(编号表!$E:$E,MATCH(K33,编号表!$C:$C,0)) -> 白色 | H33: 4 | I33: 蔽苇汀 | J33: 蔽苇汀 | K33: 普通 | L33: 29 | M33: 29 | P33: 10 | Q33: 150000 | T33: FALSE | U33: 40010001 | X33: 11010001 | Y33: 11020001 | AA33: 体修 | AB33: 20024 | AD33: 80 | AE33: 80 | AF33: 20 | AG33: 30 | AH33: 近战 | AL33: 255 | AM33: 生命值 | AN33: 1500 | AO33: 物防下限 | AP33: 8 | AQ33: 物防上限 | AR33: 12 | AS33: 法防下限 | AT33: 8 | AU33: 法防上限 | AV33: 11 | AW33: 攻击下限 | AX33: 21 | AY33: 攻击上限 | AZ33: 29 | BA33: 攻法下限 | BB33: 21 | BC33: 攻法上限 | BD33: 29 | BE33: 攻法下限 | BF33: 0 | BG33: 攻法上限 | BH33: 0 | BI33: 移动速度 | BJ33: 100 | BK33: 攻击范围 | BL33: 10 | BM33: 警戒范围 | BN33: 250 | BQ33: 1 | BR33: 2500 | BS33: 2 | BT33: 2500 | BU33: 怪物说明功能测试： 怪物身份颜色：|cffFF0000BOSS|r，|cff00FF00精英怪|r，普通怪 概率掉落以下物品： |cffFFA500美刀|r、|cffd9d919one刀乐|r、|cffA020F0two刀乐
B34: =60000000+INDEX(编号表!$B:$B,MATCH(J34,编号表!$A:$A,0))*10000+INDEX(编号表!$B:$B,MATCH(K34,编号表!$C:$C,0))*1000+L34 -> 60042030 | C34: a030 | D34: 赤发魔童 | E34: 赤发魔童 | F34: 5 | G34: =INDEX(编号表!$E:$E,MATCH(K34,编号表!$C:$C,0)) -> 绿色 | H34: 4 | I34: 蔽苇汀 | J34: 蔽苇汀 | K34: 精英 | L34: 30 | M34: 30 | P34: 10 | Q34: 150000 | T34: FALSE | U34: 40010001 | X34: 11010001 | Y34: 11020001 | AA34: 体修 | AB34: 20024 | AD34: 80 | AE34: 80 | AF34: 20 | AG34: 30 | AH34: 近战 | AJ34: 30010 | AL34: 255 | AM34: 生命值 | AN34: 1500 | AO34: 物防下限 | AP34: 8 | AQ34: 物防上限 | AR34: 12 | AS34: 法防下限 | AT34: 8 | AU34: 法防上限 | AV34: 11 | AW34: 攻击下限 | AX34: 21 | AY34: 攻击上限 | AZ34: 29 | BA34: 攻法下限 | BB34: 21 | BC34: 攻法上限 | BD34: 29 | BE34: 攻法下限 | BF34: 0 | BG34: 攻法上限 | BH34: 0 | BI34: 移动速度 | BJ34: 100 | BK34: 攻击范围 | BL34: 10 | BM34: 警戒范围 | BN34: 250 | BQ34: 1 | BR34: 2500 | BS34: 2 | BT34: 2500 | BU34: 怪物说明功能测试： 怪物身份颜色：|cffFF0000BOSS|r，|cff00FF00精英怪|r，普通怪 概率掉落以下物品： |cffFFA500美刀|r、|cffd9d919one刀乐|r、|cffA020F0two刀乐
B35: =60000000+INDEX(编号表!$B:$B,MATCH(J35,编号表!$A:$A,0))*10000+INDEX(编号表!$B:$B,MATCH(K35,编号表!$C:$C,0))*1000+L35 -> 60051031 | C35: a031 | D35: 蜈蚣 | E35: 蜈蚣 | F35: 5 | G35: =INDEX(编号表!$E:$E,MATCH(K35,编号表!$C:$C,0)) -> 白色 | H35: 5 | I35: 岳骨阶 | J35: 岳骨阶 | K35: 普通 | L35: 31 | M35: 31 | P35: 10 | Q35: 150000 | T35: FALSE | U35: 40010001 | X35: 11010001 | Y35: 11020001 | AA35: 体修 | AB35: 20010 | AD35: 80 | AE35: 80 | AF35: 20 | AG35: 30 | AH35: 近战 | AL35: 255 | AM35: 生命值 | AN35: 1500 | AO35: 物防下限 | AP35: 8 | AQ35: 物防上限 | AR35: 12 | AS35: 法防下限 | AT35: 8 | AU35: 法防上限 | AV35: 11 | AW35: 攻击下限 | AX35: 21 | AY35: 攻击上限 | AZ35: 29 | BA35: 攻法下限 | BB35: 21 | BC35: 攻法上限 | BD35: 29 | BE35: 攻法下限 | BF35: 0 | BG35: 攻法上限 | BH35: 0 | BI35: 移动速度 | BJ35: 100 | BK35: 攻击范围 | BL35: 10 | BM35: 警戒范围 | BN35: 250 | BQ35: 1 | BR35: 2500 | BS35: 2 | BT35: 2500 | BU35: 怪物说明功能测试： 怪物身份颜色：|cffFF0000BOSS|r，|cff00FF00精英怪|r，普通怪 概率掉落以下物品： |cffFFA500美刀|r、|cffd9d919one刀乐|r、|cffA020F0two刀乐
B36: =60000000+INDEX(编号表!$B:$B,MATCH(J36,编号表!$A:$A,0))*10000+INDEX(编号表!$B:$B,MATCH(K36,编号表!$C:$C,0))*1000+L36 -> 60051032 | C36: a032 | D36: 血炼尸妖 | E36: 血炼尸妖 | F36: 5 | G36: =INDEX(编号表!$E:$E,MATCH(K36,编号表!$C:$C,0)) -> 白色 | H36: 5 | I36: 岳骨阶 | J36: 岳骨阶 | K36: 普通 | L36: 32 | M36: 32 | P36: 10 | Q36: 150000 | T36: FALSE | U36: 40010001 | X36: 11010001 | Y36: 11020001 | AA36: 体修 | AB36: 20023 | AD36: 80 | AE36: 80 | AF36: 20 | AG36: 30 | AH36: 近战 | AL36: 255 | AM36: 生命值 | AN36: 1500 | AO36: 物防下限 | AP36: 8 | AQ36: 物防上限 | AR36: 12 | AS36: 法防下限 | AT36: 8 | AU36: 法防上限 | AV36: 11 | AW36: 攻击下限 | AX36: 21 | AY36: 攻击上限 | AZ36: 29 | BA36: 攻法下限 | BB36: 21 | BC36: 攻法上限 | BD36: 29 | BE36: 攻法下限 | BF36: 0 | BG36: 攻法上限 | BH36: 0 | BI36: 移动速度 | BJ36: 100 | BK36: 攻击范围 | BL36: 10 | BM36: 警戒范围 | BN36: 250 | BQ36: 1 | BR36: 2500 | BS36: 2 | BT36: 2500 | BU36: 怪物说明功能测试： 怪物身份颜色：|cffFF0000BOSS|r，|cff00FF00精英怪|r，普通怪 概率掉落以下物品： |cffFFA500美刀|r、|cffd9d919one刀乐|r、|cffA020F0two刀乐
B37: =60000000+INDEX(编号表!$B:$B,MATCH(J37,编号表!$A:$A,0))*10000+INDEX(编号表!$B:$B,MATCH(K37,编号表!$C:$C,0))*1000+L37 -> 60051033 | C37: a033 | D37: 碎骨妖兵 | E37: 碎骨妖兵 | F37: 5 | G37: =INDEX(编号表!$E:$E,MATCH(K37,编号表!$C:$C,0)) -> 白色 | H37: 5 | I37: 岳骨阶 | J37: 岳骨阶 | K37: 普通 | L37: 33 | M37: 33 | P37: 10 | Q37: 150000 | T37: FALSE | U37: 40010001 | X37: 11010001 | Y37: 11020001 | AA37: 体修 | AB37: 20037 | AD37: 80 | AE37: 80 | AF37: 20 | AG37: 30 | AH37: 近战 | AL37: 255 | AM37: 生命值 | AN37: 1500 | AO37: 物防下限 | AP37: 8 | AQ37: 物防上限 | AR37: 12 | AS37: 法防下限 | AT37: 8 | AU37: 法防上限 | AV37: 11 | AW37: 攻击下限 | AX37: 21 | AY37: 攻击上限 | AZ37: 29 | BA37: 攻法下限 | BB37: 21 | BC37: 攻法上限 | BD37: 29 | BE37: 攻法下限 | BF37: 0 | BG37: 攻法上限 | BH37: 0 | BI37: 移动速度 | BJ37: 100 | BK37: 攻击范围 | BL37: 10 | BM37: 警戒范围 | BN37: 250 | BQ37: 1 | BR37: 2500 | BS37: 2 | BT37: 2500 | BU37: 怪物说明功能测试： 怪物身份颜色：|cffFF0000BOSS|r，|cff00FF00精英怪|r，普通怪 概率掉落以下物品： |cffFFA500美刀|r、|cffd9d919one刀乐|r、|cffA020F0two刀乐
B38: =60000000+INDEX(编号表!$B:$B,MATCH(J38,编号表!$A:$A,0))*10000+INDEX(编号表!$B:$B,MATCH(K38,编号表!$C:$C,0))*1000+L38 -> 60051034 | C38: a034 | D38: 骨棺祭司 | E38: 骨棺祭司 | F38: 5 | G38: =INDEX(编号表!$E:$E,MATCH(K38,编号表!$C:$C,0)) -> 白色 | H38: 5 | I38: 岳骨阶 | J38: 岳骨阶 | K38: 普通 | L38: 34 | M38: 34 | P38: 10 | Q38: 150000 | T38: FALSE | U38: 40010001 | X38: 11010001 | Y38: 11020001 | AA38: 体修 | AB38: 20025 | AD38: 80 | AE38: 80 | AF38: 20 | AG38: 30 | AH38: 近战 | AL38: 255 | AM38: 生命值 | AN38: 1500 | AO38: 物防下限 | AP38: 8 | AQ38: 物防上限 | AR38: 12 | AS38: 法防下限 | AT38: 8 | AU38: 法防上限 | AV38: 11 | AW38: 攻击下限 | AX38: 21 | AY38: 攻击上限 | AZ38: 29 | BA38: 攻法下限 | BB38: 21 | BC38: 攻法上限 | BD38: 29 | BE38: 攻法下限 | BF38: 0 | BG38: 攻法上限 | BH38: 0 | BI38: 移动速度 | BJ38: 100 | BK38: 攻击范围 | BL38: 10 | BM38: 警戒范围 | BN38: 250 | BQ38: 1 | BR38: 2500 | BS38: 2 | BT38: 2500 | BU38: 怪物说明功能测试： 怪物身份颜色：|cffFF0000BOSS|r，|cff00FF00精英怪|r，普通怪 概率掉落以下物品： |cffFFA500美刀|r、|cffd9d919one刀乐|r、|cffA020F0two刀乐
B39: =60000000+INDEX(编号表!$B:$B,MATCH(J39,编号表!$A:$A,0))*10000+INDEX(编号表!$B:$B,MATCH(K39,编号表!$C:$C,0))*1000+L39 -> 60052035 | C39: a035 | D39: 骨棺祭司 | E39: 骨棺祭司 | F39: 5 | G39: =INDEX(编号表!$E:$E,MATCH(K39,编号表!$C:$C,0)) -> 绿色 | H39: 5 | I39: 岳骨阶 | J39: 岳骨阶 | K39: 精英 | L39: 35 | M39: 35 | P39: 10 | Q39: 150000 | T39: FALSE | U39: 40010001 | X39: 11010001 | Y39: 11020001 | AA39: 体修 | AB39: 20026 | AC39: 1.5 | AD39: 80 | AE39: 80 | AF39: 20 | AG39: 30 | AH39: 近战 | AJ39: 30010 | AL39: 255 | AM39: 生命值 | AN39: 1500 | AO39: 物防下限 | AP39: 8 | AQ39: 物防上限 | AR39: 12 | AS39: 法防下限 | AT39: 8 | AU39: 法防上限 | AV39: 11 | AW39: 攻击下限 | AX39: 21 | AY39: 攻击上限 | AZ39: 29 | BA39: 攻法下限 | BB39: 21 | BC39: 攻法上限 | BD39: 29 | BE39: 攻法下限 | BF39: 0 | BG39: 攻法上限 | BH39: 0 | BI39: 移动速度 | BJ39: 100 | BK39: 攻击范围 | BL39: 10 | BM39: 警戒范围 | BN39: 250 | BQ39: 1 | BR39: 2500 | BS39: 2 | BT39: 2500 | BU39: 怪物说明功能测试： 怪物身份颜色：|cffFF0000BOSS|r，|cff00FF00精英怪|r，普通怪 概率掉落以下物品： |cffFFA500美刀|r、|cffd9d919one刀乐|r、|cffA020F0two刀乐
B40: =60000000+INDEX(编号表!$B:$B,MATCH(J40,编号表!$A:$A,0))*10000+INDEX(编号表!$B:$B,MATCH(K40,编号表!$C:$C,0))*1000+L40 -> 60054036 | C40: a036 | D40: 狂骨妖刀将 | E40: 狂骨妖刀将 | F40: 5 | G40: =INDEX(编号表!$E:$E,MATCH(K40,编号表!$C:$C,0)) -> 橙色 | H40: 5 | I40: 岳骨阶 | J40: 岳骨阶 | K40: BOSS | L40: 36 | M40: 36 | P40: 10 | Q40: 150000 | T40: FALSE | U40: 40010001 | X40: 11010001 | Y40: 11020001 | AA40: 体修 | AB40: 20021 | AC40: 2 | AD40: 80 | AE40: 80 | AF40: 20 | AG40: 30 | AH40: 近战 | AJ40: 30011 | AL40: 255 | AM40: 生命值 | AN40: 1500 | AO40: 物防下限 | AP40: 8 | AQ40: 物防上限 | AR40: 12 | AS40: 法防下限 | AT40: 8 | AU40: 法防上限 | AV40: 11 | AW40: 攻击下限 | AX40: 21 | AY40: 攻击上限 | AZ40: 29 | BA40: 攻法下限 | BB40: 21 | BC40: 攻法上限 | BD40: 29 | BE40: 攻法下限 | BF40: 0 | BG40: 攻法上限 | BH40: 0 | BI40: 移动速度 | BJ40: 100 | BK40: 攻击范围 | BL40: 10 | BM40: 警戒范围 | BN40: 250 | BQ40: 1 | BR40: 2500 | BS40: 2 | BT40: 2500 | BU40: 怪物说明功能测试： 怪物身份颜色：|cffFF0000BOSS|r，|cff00FF00精英怪|r，普通怪 概率掉落以下物品： |cffFFA500美刀|r、|cffd9d919one刀乐|r、|cffA020F0two刀乐
...

Sheet 编号表
A1: 场景归属 | B1: 内部编号 | C1: 怪物身份 | D1: 内部编号 | E1: 颜色 | J1: 新手
A2: 天元宗门 | B2: 1 | C2: 普通 | D2: 1 | E2: 白色 | J2: 沃玛级
A3: 蚀苇沼·末流所积 | B3: 2 | C3: 精英 | D3: 2 | E3: 绿色 | G3: 装备是5开头8位数 | J3: 祖玛级
A4: 浮沉洲 | B4: 3 | C4: 大精英 | D4: 3 | E4: 紫色 | G4: 第1位 | H4: 6开头代表怪物 | J4: 苍月级
A5: 蔽苇汀 | B5: 4 | C5: BOSS | D5: 4 | E5: 橙色 | G5: 第2位 | H5: 用场景来代表级别。相当于装备的阶级，沃玛级，祖玛级，苍月级，赤月级等，2位应该够，暂时用3位保险。这个级别和场景区域配置严格匹配，相等。 | J5: 赤月级
A6: 岳骨阶 | B6: 5 | C6: 大BOSS | D6: 5 | E6: 红色 | G6: 第3位 | J6: 雷霆级
A7: 异霭浦 | B7: 6 | C7: 任务 | D7: 6 | E7: 橙色 | G7: 第4位 | J7: 战神级
A8: 砾台 | B8: 7 | C8: 活动 | D8: 7 | E8: 橙色 | G8: 第5位 | H8: 怪物身份，区分普通/精英怪/BOSS | J8: 星王级
A9: 垂练岩·覆而偶开 | B9: 8 | D9: 8 | G9: 第6位 | H9: 具体数字，填在正表E列，3位数总共1000个，代表本类别的具体序号。每个场景的每一类怪物分别计。比如比奇城的普通怪，从0开始计算1，2，3……比奇城的精英怪的序号，BOSS的序号也都是从0开始重新计算 | J9: 天龙级
A10: 水镜滩·水退方见 | B10: 9 | D10: 9 | G10: 第7位 | J10: 王者级
A11: 未知暗殿 | B11: 10 | D11: 10 | G11: 第8位 | J11: 皓天级
A12: 沃玛寺庙一层 | B12: 11 | D12: 11 | J12: 传奇级
A13: 沃玛寺庙二层 | B13: 12
A14: 沃玛教主大殿 | B14: 13
A15: 石墓一层 | B15: 14
A16: 石墓阵入口 | B16: 15
A17: 石墓阵出口 | B17: 16 | F17: 怪物的区分 | G17: 区域，代表等级范围或者说级别，决定掉落，经验，数值
A18: 石墓顶层 | B18: 17 | G18: 身份，决定掉落，经验，数值
A19: 桃源之门 | B19: 18
A20: 困惑殿堂 | B20: 19 | F20: ID使用公式的主要原因
A21: 祖玛寺庙一层 | B21: 20 | F21: 在配置内容频繁的变化，新增，尤其是插入新内容的改动时，确保对应ID的内在逻辑顺畅，方便在调用该ID的地方方便配置，减少出错也方便查错。同时保证在频繁变动的情况下，更好的保证ID的唯一性。
A22: 祖玛寺庙二层 | B22: 21 | F22: 比如，技能分战士，法师，道士，坐骑，翅膀等等N个大类，在后续新增了某翅膀和对应的技能，并在道具表，活动配置，装备表，掉落表等多地都要用到该ID时，使用公式算出来的ID填写，查错都会便捷非常多。
A23: 祖玛阁 | B23: 22 | F23: 按照变动频率来预估，变动最频繁的是掉落方案和技能表，状态表和物品表其次，装备表和怪物表的变动频率最低。
A24: 祖玛教主之家 | B24: 23
A25: 封魔矿区 | B25: 24 | F25: BOSS物编使用B开头，BNNN
A26: 光芒回廊 | B26: 25
A27: 封魔殿 | B27: 26
A28: 尸魔洞一层 | B28: 27
A29: 尸魔洞二层 | B29: 28
A30: 骨魔洞一层 | B30: 29
A31: 骨魔洞二层 | B31: 30
A32: 牛魔寺庙入口 | B32: 31
A33: 牛魔寺庙一层 | B33: 32
A34: 牛魔寺庙大厅 | B34: 33
A35: 丛林迷宫 | B35: 34
A36: 赤月峡谷西走廊 | B36: 35
A37: 赤月峡谷东二层 | B37: 36
... A41: 赤月魔穴 | B41: 40
B42: 41
B43: 42
...

Sheet 名称表
A1: Dignity | E1: OwnerMode | F1: 掉落类型 | H1: 阵营 | K1: 显示名字类型 | N1: 等级 | O1: 名字颜色 | Q1: 职业 | R1: 种族
A2: 怪物身份 | E2: 属主模型 | F2: 掉落_均可见属主拾取 | H2: 阵营_普通玩家 | K2: 名字_显示 | N2: 1 | O2: 绿色 | Q2: 职业_战士 | R2: 种族_风
A3: 怪物类型_普通 | C3: 是 | E3: 属主_首刀 | F3: 掉落_属主可见可拾取 | H3: 阵营_普通怪物 | K3: 名字_不显示 | N3: 2 | O3: 绿色 | Q3: 职业_法师 | R3: 种族_火
A4: 怪物类型_世界BOSS | C4: 否 | E4: 属主_组队伤害 | F4: 掉落_均可见均可拾取 | H4: 阵营_中立怪物 | K4: 名字_永久显示 | N4: 3 | O4: 绿色 | Q4: 职业_牧师 | R4: 种族_雷
A5: 怪物类型_人数值 | E5: 属主_组队伤害唯一 | F5: 掉落_均可见队伍拾取 | H5: 阵营_友好怪物 | N5: 4 | O5: 绿色 | Q5: 职业_萨满 | R5: 种族_水
A6: 怪物类型_宠数值 | E6: 属主_仇恨 | F6: 掉落_均可见区服拾取 | H6: 阵营_动画怪物 | N6: 5 | O6: 绿色
A7: 怪物类型_精英 | E7: 属主_普通 | H7: 阵营_动画怪物2 | N7: 6 | O7: 绿色
E8: 属主_末刀 | H8: 阵营_动画怪物3 | N8: 7 | O8: 绿色
E9: 属主_个人伤害 | H9: 阵营_动画怪物4 | N9: 8 | O9: 绿色
E10: 属主_个人伤害唯一 | N10: 9 | O10: 绿色
N11: 10 | O11: 绿色
N12: 11 | O12: 绿色
N13: 12 | O13: 绿色
N14: 13 | O14: 绿色
N15: 14 | O15: 绿色
N16: 15 | O16: 蓝色
N17: 16 | O17: 蓝色
N18: 17 | O18: 蓝色
N19: 18 | O19: 蓝色
N20: 19 | O20: 蓝色
A21: 怪物类型_首领 | N21: 20 | O21: 蓝色
A22: 怪物类型_世界PVPBOSS | N22: 21 | O22: 蓝色
A23: 怪物类型_散仙陷阱 | N23: 22 | O23: 蓝色
A24: 怪物类型_采集物 | N24: 23 | O24: 蓝色
A25: 怪物类型_琅琊福地NPC | N25: 24 | O25: 蓝色
A26: 怪物类型_阵营战炮台 | N26: 25 | O26: 蓝色
A27: 怪物类型_技能召唤 | N27: 26 | O27: 蓝色
A28: 怪物类型_前台怪 | N28: 27 | O28: 蓝色
A29: 怪物类型_受击掉落 | N29: 28 | O29: 紫色
N30: 29 | O30: 紫色
N31: 30 | O31: 紫色
N32: 31 | O32: 紫色
N33: 32 | O33: 紫色
N34: 33 | O34: 紫色
N35: 34 | O35: 紫色
N36: 35 | O36: 紫色
N37: 36 | O37: 紫色
N38: 37 | O38: 紫色
N39: 38 | O39: 紫色
N40: 39 | O40: 紫色
...

Sheet 版本变更
A1: 版本号 | B1: 改动内容
A2: V1.12 | B2: 1、删除金币掉落字段 2、更新怪物模型
A3: V1.13 | B3: 1、新增怪物缩放比例 2、更改盔甲虫模型
A4: V1.14 | B4: 1、更改了比奇城怪物攻击数值 2、更改的归属场景数据
A5: V1.15 | B5: 更新掉落方案
A6: V1.16 | B6: 更新怪物普攻和技能ID
A7: V1.17 | B7: 更改怪物的编号计算规则和对应的编号
A8: V1.18 | B8: 更新“蛤蟆”模型
A9: V1.19 | B9: 更新移动速度巡逻半径等数据
A10: V1.20 | B10: 所有蛤蟆模型放大到原5倍
A11: V1.21 | B11: 祖玛弓箭手模型更新
A12: V1.22 | B12: 怪物距离和速度属性更改
... A18: V1.28 | B18: 60371394 60371395，黑狐赤狐改为测试数值
A19: V1.29
A20: V1.30
A21: V1.31
A22: V1.32
A23: V1.33
A24: V1.34
A25: V1.35 | B25: 删掉视野半径和巡逻范围，新增属性警戒范围。
A26: V1.36 | B26: 调整掉落方案，对应调整怪物表
A27: V1.37 | B27: 怪物数据使用李鑫配置版本，同时所有的ID规则进行调整。困惑殿堂新增2普通2精英怪，封魔殿新增3精英物编ID用aa开头
A28: V1.38 | B28: 调整模型大小，1.36版本模型大小应该是对的，这个版本是之前复制李鑫的数据，模型大小可能比较原始，对所有＞0.5的基本都改成0.5了，持续修改 复制过来遗留的0全都删了，模型缩放不要配置0！！！ 所有模型改前缀，很多模型名字乱填的都改了，还有2个模型缺失，先用别的代替了。
A29: V1.39 | B29: 修改模型大小，沃玛战将模型用沃玛勇士暂替，碰撞体积20改为10
A30: V1.40 | B30: 新增任务掉落
A31: V1.41 | B31: 掉落方案出现BUG，把错误的掉落方案ID改正。增加一个木桩。所有怪物复活时间×10
A32: V1.42 | B32: 新增3个配置项，2个绑定特效+缩放，新增一个技能配置，改技能ID。修改警戒范围，
A33: V1.43 | B33: 增加NPC鸡
A34: V1.44
A35: V1.45
A36: V1.46
A37: V1.47
A38: V1.48
A39: V1.49
A40: V1.50

Sheet Sheet1
F1: a001 | G1: 比奇城 | R1: A107 | S1: 比奇城
F2: a002 | G2: 待定 | R2: A038 | S2: 比奇城
F3: a003 | G3: 待定 | R3: A120 | S3: 比奇城
F4: a004 | G4: 待定 | R4: A036 | S4: 比奇城
F5: a005 | G5: 待定 | R5: A033 | S5: 比奇城
F6: a006 | G6: 待定 | R6: A034 | S6: 比奇城
F7: a007 | G7: 待定 | R7: A013 | S7: 比奇城
F8: a008 | G8: 待定 | R8: A001 | S8: 比奇城
F9: a009 | G9: 待定 | R9: A106 | S9: 比奇城
F10: a010 | G10: 待定 | R10: A020 | S10: 比奇城
F11: a011 | G11: 待定 | R11: A029 | S11: 比奇城
F12: a012 | G12: 待定 | R12: A027 | S12: 比奇城
... F20: a020 | G20: 比奇城 | R20: A082 | S20: 比奇城
F21: a021 | G21: 待定
F22: a022 | G22: 待定
F23: a023 | G23: 比奇城
F24: a024 | G24: 待定
F25: a025 | G25: 待定
F26: a026 | G26: 待定
F27: a027 | G27: 比奇城
F28: a028 | G28: 待定
F29: a029 | G29: 比奇城
F30: a030 | G30: 待定
F31: a031 | G31: 待定
F32: a032 | G32: 待定
... F540: a540 | G540: 待定
