Workbook

Sheet skill_config
A1: ##var | B1: id | C1: name | D1: internal_name | E1: skill_type | F1: skill_class | G1: is_passive_skill | H1: is_invoked | I1: skill_level | J1: identify_id | K1: color | L1: required_skill_id | M1: next_level_id | N1: description | O1: icon_id | P1: consumable_id | Q1: lingli_cost | R1: required_level | S1: required_wupin | T1: exp_to_next | U1: exp_trigger | V1: cast_distance | W1: acquire_range | X1: aim_kind | Y1: skill_selector | AL1: sub_selector | AY1: damage_type | AZ1: base_power | BA1: skill_effects | GR1: cast_time | GS1: recovery_time | GT1: cast_action | GU1: cast_effect | GV1: cast_point_effect | GW1: hurt_effect | GX1: stop_move | GY1: cooldown | GZ1: cooldown_reduction_disabled | HA1: max_charges | HB1: charge_recover_time | HC1: channel_time | HD1: channel_interval | HE1: channel_move_cancel | HF1: hit_stun | HG1: cast_sound_id | HH1: hit_sound_id | HI1: passive_trigger | HJ1: passive_skill_id | HK1: passive_icd | HL1: base_realm | HM1: passive_hp_threshold | HN1: is_basic_attack
A2: ##var | BA2: 0 | CX2: 1 | EU2: 2
A3: ##var | Y3: $type | Z3: target_faction | AA3: max_target_ally | AB3: max_target_enemy | AC3: include_caster | AD3: priority | AE3: circle_radius | AF3: sector_radius | AG3: angle | AH3: length | AI3: width | AJ3: inner_radius | AK3: outer_radius | AL3: $type | AM3: target_faction | AN3: max_target_ally | AO3: max_target_enemy | AP3: include_caster | AQ3: priority | AR3: circle_radius | AS3: sector_radius | AT3: angle | AU3: length | AV3: width | AW3: inner_radius | AX3: outer_radius | BA3: $type | BB3: target_faction | BC3: rate | BD3: delay | BE3: effect_range | BF3: require_target_hp_below | BG3: dmg_type | BH3: dmg_coefficient | BI3: dmg_flat | BJ3: dmg_can_crit | BK3: dmg_crit | BL3: falloff_edge_ratio | BM3: buff_id | BN3: heal_type | BO3: heal_coefficient | BP3: heal_flat | BQ3: heal_can_crit | BR3: heal_crit | BS3: summon_id | BT3: position | BU3: duration | BV3: summon_count | BW3: max_count | BX3: init_lv | BY3: max_lv | BZ3: subject | CA3: distance | CB3: mode | CC3: direction | CD3: pass_through | CE3: move_speed | CF3: effect | CG3: sound | CH3: proj_speed | CI3: height | CJ3: path | CK3: proj_count | CL3: interval | CM3: portion | CN3: range | CO3: hit_radius | CP3: spread_angle | CQ3: pierce | CR3: proj_sub_skill_id | CS3: seek_distance | CT3: seek_radius | CU3: turn_rate | CV3: seek_mode | CW3: call_skill_id | CX3: $type | CY3: target_faction | CZ3: rate | DA3: delay | DB3: effect_range | DC3: require_target_hp_below | DD3: dmg_type | DE3: dmg_coefficient | DF3: dmg_flat | DG3: dmg_can_crit | DH3: dmg_crit | DI3: falloff_edge_ratio | DJ3: buff_id | DK3: heal_type | DL3: heal_coefficient | DM3: heal_flat | DN3: heal_can_crit | DO3: heal_crit | DP3: summon_id | DQ3: position | DR3: duration | DS3: summon_count | DT3: max_count | DU3: init_lv | DV3: max_lv | DW3: subject | DX3: distance | DY3: mode | DZ3: direction | EA3: pass_through | EB3: move_speed | EC3: effect | ED3: sound | EE3: proj_speed | EF3: height | EG3: path | EH3: proj_count | EI3: interval | EJ3: portion | EK3: range | EL3: hit_radius | EM3: spread_angle | EN3: pierce | EO3: proj_sub_skill_id | EP3: seek_distance | EQ3: seek_radius | ER3: turn_rate | ES3: seek_mode | ET3: call_skill_id | EU3: $type | EV3: target_faction | EW3: rate | EX3: delay | EY3: effect_range | EZ3: require_target_hp_below | FA3: dmg_type | FB3: dmg_coefficient | FC3: dmg_flat | FD3: dmg_can_crit | FE3: dmg_crit | FF3: falloff_edge_ratio | FG3: buff_id | FH3: heal_type | FI3: heal_coefficient | FJ3: heal_flat | FK3: heal_can_crit | FL3: heal_crit | FM3: summon_id | FN3: position | FO3: duration | FP3: summon_count | FQ3: max_count | FR3: init_lv | FS3: max_lv | FT3: subject | FU3: distance | FV3: mode | FW3: direction | FX3: pass_through | FY3: move_speed | FZ3: effect | GA3: sound | GB3: proj_speed | GC3: height | GD3: path | GE3: proj_count | GF3: interval | GG3: portion | GH3: range | GI3: hit_radius | GJ3: spread_angle | GK3: pierce | GL3: proj_sub_skill_id | GM3: seek_distance | GN3: seek_radius | GO3: turn_rate | GP3: seek_mode | GQ3: call_skill_id
A4: ##type | B4: int | C4: string | D4: string | E4: SkillType | F4: ClassType | G4: bool | H4: bool | I4: int | J4: int | K4: ItemQuality | L4: int | M4: int | N4: string | O4: int | P4: int | Q4: int | R4: int | S4: int | T4: int | U4: (list#sep=|),ExpTriggerType | V4: int | W4: int | X4: AimKind | Y4: SkillSelector? | AL4: SkillSelector? | AY4: string | AZ4: int | BA4: array,SkillEffect | GR4: int | GS4: int | GT4: string | GU4: int | GV4: string | GW4: string | GX4: bool | GY4: int | GZ4: bool | HA4: int | HB4: int | HC4: int | HD4: int | HE4: bool | HF4: int | HG4: int | HH4: string | HI4: PassiveSkillTriggerType | HJ4: int | HK4: int | HL4: MajorRealm | HM4: int | HN4: bool
A5: ##group | C5: c | D5: c | G5: c,s | H5: c,s | N5: c | O5: c | Q5: c | U5: c,s | V5: c | W5: c | X5: c | Y5: c | AL5: c | AY5: c | AZ5: c | BA5: c,s | GR5: c | GS5: c | GT5: c | GU5: c | GV5: c | GW5: c | GX5: c | GY5: c | GZ5: c | HA5: c | HB5: c | HC5: c | HD5: c | HE5: c | HF5: c | HG5: c | HH5: c | HI5: c,s | HJ5: c | HK5: c | HM5: c | HN5: c,s
A6: ## | B6: 技能ID | C6: 技能显示名称 | D6: 内部名称 | E6: 技能分类 | F6: 技能系别 | G6: 是否被动类型技能 | H6: 是否为被调用技能 | I6: 技能等级 | J6: 技能识别ID | K6: 颜色标签 | L6: 前置技能ID | M6: 下一级技能ID | N6: 技能描述文本 | O6: 技能图标ID | P6: 施法消耗道具ID | Q6: 灵力消耗 | R6: 学习技能所需等级 | S6: 升级消耗道具 | T6: 熟练度上限 | U6: 熟练度触发行为 | V6: 施法距离 | W6: 智能施法查询半径 | X6: 施法瞄准类型 | Y6: 形状：单体 / 圆形 / 扇形 / 线形 / 环形 选一个；单体没有专属列，其余只填该形状那一段列 | Z6: 【公共】目标阵营 | AA6: 【公共】友方最大目标数，0=不限 | AB6: 【公共】敌对最大目标数，0=不限 | AC6: 【公共】是否包含施法者自身 | AD6: 【公共】目标选取优先级 | AE6: 【圆形】半径 | AF6: 【扇形】半径 | AG6: 【扇形】角度（上限180） | AH6: 【线形】长度 | AI6: 【线形】宽度 | AJ6: 【环形】内圈半径 | AK6: 【环形】外圈半径 | AL6: 形状：单体 / 圆形 / 扇形 / 线形 / 环形 选一个；单体没有专属列，其余只填该形状那一段列 | AM6: 【公共】目标阵营 | AN6: 【公共】友方最大目标数，0=不限 | AO6: 【公共】敌对最大目标数，0=不限 | AP6: 【公共】是否包含施法者自身 | AQ6: 【公共】目标选取优先级 | AR6: 【圆形】半径 | AS6: 【扇形】半径 | AT6: 【扇形】角度（上限180） | AU6: 【线形】长度 | AV6: 【线形】宽度 | AW6: 【环形】内圈半径 | AX6: 【环形】外圈半径 | AY6: 伤害类型（仅用于展示，实际伤害类型由效果自身决定） | AZ6: 技能威力基础值 | BA6: 效果1·效果类型：选定后只填带同名前缀【…】的那一段列，其余留空 | BB6: 效果1·【公共】应用目标阵营 | BC6: 效果1·【公共】触发概率（万分比） | BD6: 效果1·【公共】延迟触发(毫秒) | BE6: 效果1·【公共】作用范围：全部候选 / 仅子范围内 / 子范围外，需配子选择器 | BF6: 效果1·【公共】生效血量阈值（万分比）：目标生命低于此值才生效，0=无条件 | BG6: 效果1·【伤害】伤害类型 | BH6: 效果1·【伤害】万分比伤害系数 | BI6: 效果1·【伤害】固定伤害数值 | BJ6: 效果1·【伤害】是否允许暴击：FALSE=按普通伤害结算，不判暴击 | BK6: 效果1·【伤害】暴击率加成（万分比）：最终暴击率=施法者暴击率+本值−目标免暴击率，限 0～100%；0=不加成 | BL6: 效果1·【伤害】边缘伤害系数（万分比）：10000=不衰减，5000=边缘半伤 | BM6: 效果1·【调用状态】状态ID（buff_config.id） | BN6: 效果1·【治疗】治疗类型 | BO6: 效果1·【治疗】治疗万分比系数 | BP6: 效果1·【治疗】固定治疗值 | BQ6: 效果1·【治疗】是否允许暴击：治疗不暴击，填 FALSE | BR6: 效果1·【治疗】暴击参数：填 0 | BS6: 效果1·【召唤】从属实体ID（owned_entity_config.config_id） | BT6: 效果1·【召唤】出生点 | BU6: 效果1·【召唤】持续时间(毫秒)，0=不限 | BV6: 效果1·【召唤】召唤数量 | BW6: 效果1·【召唤】同类召唤物上限 | BX6: 效果1·【召唤】初始等级 | BY6: 效果1·【召唤】等级上限，0=不限 | BZ6: 效果1·【位移】位移目标单位 | CA6: 效果1·【位移】位移距离 | CB6: 效果1·【位移】位移模式 | CC6: 效果1·【位移】位移方向 | CD6: 效果1·【位移】能否穿越地形 | CE6: 效果1·【位移】位移速度 | CF6: 效果1·【弹道】投射物特效 | CG6: 效果1·【弹道】投射物释放音效 | CH6: 效果1·【弹道】投射物速度 | CI6: 效果1·【弹道】投射物高度 | CJ6: 效果1·【弹道】运行轨迹 | CK6: 效果1·【弹道】投射物总数量 | CL6: 效果1·【弹道】发射波次间隔(毫秒) | CM6: 效果1·【弹道】每次发射数量 | CN6: 效果1·【弹道】射程 | CO6: 效果1·【弹道】命中半径 | CP6: 效果1·【弹道】散布角 | CQ6: 效果1·【弹道】穿透目标数量 | CR6: 效果1·【弹道】命中调用的子技能ID（弹道自身不带伤害） | CS6: 效果1·【弹道】追踪·外飞距离（码）：先直飞多远才开始索敌，0=出膛即索敌 | CT6: 效果1·【弹道】追踪·索敌半径（码）：追踪轨迹必须 >0 | CU6: 效果1·【弹道】追踪·最大转向速度（度/秒）：0=不限 | CV6: 效果1·【弹道】追踪·目标分配：最近 / 分散 / 集火，留空=最近 | CW6: 效果1·【调用技能】被调用神通等级行ID | CX6: 效果2·效果类型：选定后只填带同名前缀【…】的那一段列，其余留空 | CY6: 效果2·【公共】应用目标阵营 | CZ6: 效果2·【公共】触发概率（万分比） | DA6: 效果2·【公共】延迟触发(毫秒) | DB6: 效果2·【公共】作用范围：全部候选 / 仅子范围内 / 子范围外，需配子选择器 | DC6: 效果2·【公共】生效血量阈值（万分比）：目标生命低于此值才生效，0=无条件 | DD6: 效果2·【伤害】伤害类型 | DE6: 效果2·【伤害】万分比伤害系数 | DF6: 效果2·【伤害】固定伤害数值 | DG6: 效果2·【伤害】是否允许暴击：FALSE=按普通伤害结算，不判暴击 | DH6: 效果2·【伤害】暴击率加成（万分比）：最终暴击率=施法者暴击率+本值−目标免暴击率，限 0～100%；0=不加成 | DI6: 效果2·【伤害】边缘伤害系数（万分比）：10000=不衰减，5000=边缘半伤 | DJ6: 效果2·【调用状态】状态ID（buff_config.id） | DK6: 效果2·【治疗】治疗类型 | DL6: 效果2·【治疗】治疗万分比系数 | DM6: 效果2·【治疗】固定治疗值 | DN6: 效果2·【治疗】是否允许暴击：治疗不暴击，填 FALSE | DO6: 效果2·【治疗】暴击参数：填 0 | DP6: 效果2·【召唤】从属实体ID（owned_entity_config.config_id） | DQ6: 效果2·【召唤】出生点 | DR6: 效果2·【召唤】持续时间(毫秒)，0=不限 | DS6: 效果2·【召唤】召唤数量 | DT6: 效果2·【召唤】同类召唤物上限 | DU6: 效果2·【召唤】初始等级 | DV6: 效果2·【召唤】等级上限，0=不限 | DW6: 效果2·【位移】位移目标单位 | DX6: 效果2·【位移】位移距离 | DY6: 效果2·【位移】位移模式 | DZ6: 效果2·【位移】位移方向 | EA6: 效果2·【位移】能否穿越地形 | EB6: 效果2·【位移】位移速度 | EC6: 效果2·【弹道】投射物特效 | ED6: 效果2·【弹道】投射物释放音效 | EE6: 效果2·【弹道】投射物速度 | EF6: 效果2·【弹道】投射物高度 | EG6: 效果2·【弹道】运行轨迹 | EH6: 效果2·【弹道】投射物总数量 | EI6: 效果2·【弹道】发射波次间隔(毫秒) | EJ6: 效果2·【弹道】每次发射数量 | EK6: 效果2·【弹道】射程 | EL6: 效果2·【弹道】命中半径 | EM6: 效果2·【弹道】散布角 | EN6: 效果2·【弹道】穿透目标数量 | EO6: 效果2·【弹道】命中调用的子技能ID（弹道自身不带伤害） | EP6: 效果2·【弹道】追踪·外飞距离（码）：先直飞多远才开始索敌，0=出膛即索敌 | EQ6: 效果2·【弹道】追踪·索敌半径（码）：追踪轨迹必须 >0 | ER6: 效果2·【弹道】追踪·最大转向速度（度/秒）：0=不限 | ES6: 效果2·【弹道】追踪·目标分配：最近 / 分散 / 集火，留空=最近 | ET6: 效果2·【调用技能】被调用神通等级行ID | EU6: 效果3·效果类型：选定后只填带同名前缀【…】的那一段列，其余留空 | EV6: 效果3·【公共】应用目标阵营 | EW6: 效果3·【公共】触发概率（万分比） | EX6: 效果3·【公共】延迟触发(毫秒) | EY6: 效果3·【公共】作用范围：全部候选 / 仅子范围内 / 子范围外，需配子选择器 | EZ6: 效果3·【公共】生效血量阈值（万分比）：目标生命低于此值才生效，0=无条件 | FA6: 效果3·【伤害】伤害类型 | FB6: 效果3·【伤害】万分比伤害系数 | FC6: 效果3·【伤害】固定伤害数值 | FD6: 效果3·【伤害】是否允许暴击：FALSE=按普通伤害结算，不判暴击 | FE6: 效果3·【伤害】暴击率加成（万分比）：最终暴击率=施法者暴击率+本值−目标免暴击率，限 0～100%；0=不加成 | FF6: 效果3·【伤害】边缘伤害系数（万分比）：10000=不衰减，5000=边缘半伤 | FG6: 效果3·【调用状态】状态ID（buff_config.id） | FH6: 效果3·【治疗】治疗类型 | FI6: 效果3·【治疗】治疗万分比系数 | FJ6: 效果3·【治疗】固定治疗值 | FK6: 效果3·【治疗】是否允许暴击：治疗不暴击，填 FALSE | FL6: 效果3·【治疗】暴击参数：填 0 | FM6: 效果3·【召唤】从属实体ID（owned_entity_config.config_id） | FN6: 效果3·【召唤】出生点 | FO6: 效果3·【召唤】持续时间(毫秒)，0=不限 | FP6: 效果3·【召唤】召唤数量 | FQ6: 效果3·【召唤】同类召唤物上限 | FR6: 效果3·【召唤】初始等级 | FS6: 效果3·【召唤】等级上限，0=不限 | FT6: 效果3·【位移】位移目标单位 | FU6: 效果3·【位移】位移距离 | FV6: 效果3·【位移】位移模式 | FW6: 效果3·【位移】位移方向 | FX6: 效果3·【位移】能否穿越地形 | FY6: 效果3·【位移】位移速度 | FZ6: 效果3·【弹道】投射物特效 | GA6: 效果3·【弹道】投射物释放音效 | GB6: 效果3·【弹道】投射物速度 | GC6: 效果3·【弹道】投射物高度 | GD6: 效果3·【弹道】运行轨迹 | GE6: 效果3·【弹道】投射物总数量 | GF6: 效果3·【弹道】发射波次间隔(毫秒) | GG6: 效果3·【弹道】每次发射数量 | GH6: 效果3·【弹道】射程 | GI6: 效果3·【弹道】命中半径 | GJ6: 效果3·【弹道】散布角 | GK6: 效果3·【弹道】穿透目标数量 | GL6: 效果3·【弹道】命中调用的子技能ID（弹道自身不带伤害） | GM6: 效果3·【弹道】追踪·外飞距离（码）：先直飞多远才开始索敌，0=出膛即索敌 | GN6: 效果3·【弹道】追踪·索敌半径（码）：追踪轨迹必须 >0 | GO6: 效果3·【弹道】追踪·最大转向速度（度/秒）：0=不限 | GP6: 效果3·【弹道】追踪·目标分配：最近 / 分散 / 集火，留空=最近 | GQ6: 效果3·【调用技能】被调用神通等级行ID | GR6: 前摇时长(毫秒) | GS6: 后摇时长(毫秒) | GT6: 施法动作名称 | GU6: 施法特效ID（effect_config.id，0=不播） | GV6: 施法点特效路径 | GW6: 怪物受击特效路径 | GX6: 是否停止移动 | GY6: 冷却时间(毫秒) | GZ6: 禁止冷却缩减 | HA6: 最大充能层数 | HB6: 单层充能恢复时间(毫秒) | HC6: 引导时长(毫秒) | HD6: 引导结算间隔(毫秒) | HE6: 引导时移动是否中断 | HF6: 受击硬直时间(毫秒) | HG6: 施法音效ID（sound_config.id，0=不播） | HH6: 命中音效路径（命中帧在施法者身上播放） | HI6: 被动触发事件类型 | HJ6: 被动触发条件技能ID | HK6: 被动内置冷却(毫秒) | HL6: 基准境界 | HM6: 被动血量阈值(万分比) | HN6: 是否普攻
B7: {=10000000+INDEX(编号表!$B$1:$B$112,MATCH(D7,编号表!$A$1:$A$112,0))*10000+I7} -> 10010001 | C7: 青萍剑诀 | D7: 青萍剑诀 | E7: 人道 | F7: 剑道 | G7: FALSE | H7: FALSE | I7: 1 | J7: =LEFT(B7,6) -> 100100 | K7: 凡品 | M7: =B8 -> 10010002 | N7: 剑出青萍，疾刺目标，造成物理伤害。剑道诸式皆由此起。 | O7: 10202000 | P7: 0 | Q7: 0 | R7: 1 | T7: 100 | V7: 500 | W7: 500 | X7: 单位 | Y7: 单体 | Z7: 敌对 | AA7: 0 | AB7: 1 | AC7: 0 | AD7: 最近 | AY7: 物理 | AZ7: 10000 | BA7: 技能效果_伤害 | BB7: 敌对 | BC7: 10000 | BD7: 0 | BE7: 全部 | BF7: 0 | BG7: 0 | BH7: 10000 | BI7: 3 | BJ7: TRUE | BK7: 0 | BL7: 10000 | GR7: 200 | GS7: 400 | GT7: Attack One | GU7: 30046 | GX7: 1 | GZ7: 0 | HA7: 0 | HB7: 0 | HC7: 0 | HD7: 0 | HE7: FALSE | HG7: 10001 | HI7: 无 | HJ7: 0 | HK7: 0 | HL7: 0
B8: {=10000000+INDEX(编号表!$B$1:$B$112,MATCH(D8,编号表!$A$1:$A$112,0))*10000+I8} -> 10010002 | C8: 青萍剑诀 | D8: 青萍剑诀 | E8: 人道 | F8: 剑道 | G8: FALSE | H8: FALSE | I8: 2 | J8: =LEFT(B8,6) -> 100100 | K8: 凡品 | L8: =B7 -> 10010001 | M8: =B9 -> 10010003 | N8: 剑出青萍，疾刺目标，造成物理伤害。剑道诸式皆由此起。 | O8: 10202000 | P8: 0 | Q8: 1 | R8: 7 | T8: 100 | V8: 500 | W8: 500 | X8: 单位 | Y8: 单体 | Z8: 敌对 | AA8: 0 | AB8: 1 | AC8: 0 | AD8: 最近 | AY8: 物理 | AZ8: 10400 | BA8: 技能效果_伤害 | BB8: 敌对 | BC8: 10000 | BD8: 0 | BE8: 全部 | BF8: 0 | BG8: 0 | BH8: 10000 | BI8: 4 | BJ8: TRUE | BK8: 0 | BL8: 10000 | GR8: 200 | GS8: 400 | GT8: Attack One | GU8: 30046 | GX8: 1 | GZ8: 0 | HA8: 0 | HB8: 0 | HC8: 0 | HD8: 0 | HE8: FALSE | HG8: 10001 | HI8: 无 | HJ8: 0 | HK8: 0 | HL8: 0
B9: {=10000000+INDEX(编号表!$B$1:$B$112,MATCH(D9,编号表!$A$1:$A$112,0))*10000+I9} -> 10010003 | C9: 青萍剑诀 | D9: 青萍剑诀 | E9: 人道 | F9: 剑道 | G9: FALSE | H9: FALSE | I9: 3 | J9: =LEFT(B9,6) -> 100100 | K9: 凡品 | L9: =B8 -> 10010002 | M9: =B10 -> 10010004 | N9: 剑出青萍，疾刺目标，造成物理伤害。剑道诸式皆由此起。 | O9: 10202000 | P9: 0 | Q9: 2 | R9: 11 | T9: 100 | V9: 500 | W9: 500 | X9: 单位 | Y9: 单体 | Z9: 敌对 | AA9: 0 | AB9: 1 | AC9: 0 | AD9: 最近 | AY9: 物理 | AZ9: 10800 | BA9: 技能效果_伤害 | BB9: 敌对 | BC9: 10000 | BD9: 0 | BE9: 全部 | BF9: 0 | BG9: 0 | BH9: 10000 | BI9: 5 | BJ9: TRUE | BK9: 0 | BL9: 10000 | GR9: 200 | GS9: 400 | GT9: Attack One | GU9: 30046 | GX9: 1 | GZ9: 0 | HA9: 0 | HB9: 0 | HC9: 0 | HD9: 0 | HE9: FALSE | HG9: 10001 | HI9: 无 | HJ9: 0 | HK9: 0 | HL9: 0
B10: {=10000000+INDEX(编号表!$B$1:$B$112,MATCH(D10,编号表!$A$1:$A$112,0))*10000+I10} -> 10010004 | C10: 青萍剑诀 | D10: 青萍剑诀 | E10: 人道 | F10: 剑道 | G10: FALSE | H10: FALSE | I10: 4 | J10: =LEFT(B10,6) -> 100100 | K10: 凡品 | L10: =B9 -> 10010003 | M10: =B11 -> 10010005 | N10: 剑出青萍，疾刺目标，造成物理伤害。剑道诸式皆由此起。 | O10: 10202000 | P10: 0 | Q10: 3 | R10: 16 | T10: 100 | V10: 500 | W10: 500 | X10: 单位 | Y10: 单体 | Z10: 敌对 | AA10: 0 | AB10: 1 | AC10: 0 | AD10: 最近 | AY10: 物理 | AZ10: 11200 | BA10: 技能效果_伤害 | BB10: 敌对 | BC10: 10000 | BD10: 0 | BE10: 全部 | BF10: 0 | BG10: 0 | BH10: 10000 | BI10: 6 | BJ10: TRUE | BK10: 0 | BL10: 10000 | GR10: 200 | GS10: 400 | GT10: Attack One | GU10: 30046 | GX10: 1 | GZ10: 0 | HA10: 0 | HB10: 0 | HC10: 0 | HD10: 0 | HE10: FALSE | HG10: 10001 | HI10: 无 | HJ10: 0 | HK10: 0 | HL10: 0
B11: {=10000000+INDEX(编号表!$B$1:$B$112,MATCH(D11,编号表!$A$1:$A$112,0))*10000+I11} -> 10010005 | C11: 青萍剑诀 | D11: 青萍剑诀 | E11: 人道 | F11: 剑道 | G11: FALSE | H11: FALSE | I11: 5 | J11: =LEFT(B11,6) -> 100100 | K11: 凡品 | L11: =B10 -> 10010004 | M11: =B12 -> 10010006 | N11: 剑出青萍，疾刺目标，造成物理伤害。剑道诸式皆由此起。 | O11: 10202000 | P11: 0 | Q11: 3 | R11: 25 | T11: 100 | V11: 500 | W11: 500 | X11: 单位 | Y11: 单体 | Z11: 敌对 | AA11: 0 | AB11: 1 | AC11: 0 | AD11: 最近 | AY11: 物理 | AZ11: 11300 | BA11: 技能效果_伤害 | BB11: 敌对 | BC11: 10000 | BD11: 0 | BE11: 全部 | BF11: 0 | BG11: 0 | BH11: 10000 | BI11: 6 | BJ11: TRUE | BK11: 0 | BL11: 10000 | GR11: 200 | GS11: 400 | GT11: Attack One | GU11: 30046 | GX11: 1 | GZ11: 0 | HA11: 0 | HB11: 0 | HC11: 0 | HD11: 0 | HE11: FALSE | HG11: 10001 | HI11: 无 | HJ11: 0 | HK11: 0 | HL11: 0
B12: {=10000000+INDEX(编号表!$B$1:$B$112,MATCH(D12,编号表!$A$1:$A$112,0))*10000+I12} -> 10010006 | C12: 青萍剑诀 | D12: 青萍剑诀 | E12: 人道 | F12: 剑道 | G12: FALSE | H12: FALSE | I12: 6 | J12: =LEFT(B12,6) -> 100100 | K12: 凡品 | L12: =B11 -> 10010005 | M12: =B13 -> 10010007 | N12: 剑出青萍，疾刺目标，造成物理伤害。剑道诸式皆由此起。 | O12: 10202000 | P12: 0 | Q12: 3 | R12: 30 | T12: 100 | V12: 500 | W12: 500 | X12: 单位 | Y12: 单体 | Z12: 敌对 | AA12: 0 | AB12: 1 | AC12: 0 | AD12: 最近 | AY12: 物理 | AZ12: 11600 | BA12: 技能效果_伤害 | BB12: 敌对 | BC12: 10000 | BD12: 0 | BE12: 全部 | BF12: 0 | BG12: 0 | BH12: 10000 | BI12: 7 | BJ12: TRUE | BK12: 0 | BL12: 10000 | GR12: 200 | GS12: 400 | GT12: Attack One | GU12: 30046 | GX12: 1 | GZ12: 0 | HA12: 0 | HB12: 0 | HC12: 0 | HD12: 0 | HE12: FALSE | HG12: 10001 | HI12: 无 | HJ12: 0 | HK12: 0 | HL12: 0
B13: {=10000000+INDEX(编号表!$B$1:$B$112,MATCH(D13,编号表!$A$1:$A$112,0))*10000+I13} -> 10010007 | C13: 青萍剑诀 | D13: 青萍剑诀 | E13: 人道 | F13: 剑道 | G13: FALSE | H13: FALSE | I13: 7 | J13: =LEFT(B13,6) -> 100100 | K13: 凡品 | L13: =B12 -> 10010006 | M13: =B14 -> 10010008 | N13: 剑出青萍，疾刺目标，造成物理伤害。剑道诸式皆由此起。 | O13: 10202000 | P13: 0 | Q13: 3 | R13: 35 | T13: 100 | V13: 500 | W13: 500 | X13: 单位 | Y13: 单体 | Z13: 敌对 | AA13: 0 | AB13: 1 | AC13: 0 | AD13: 最近 | AY13: 物理 | AZ13: 11700 | BA13: 技能效果_伤害 | BB13: 敌对 | BC13: 10000 | BD13: 0 | BE13: 全部 | BF13: 0 | BG13: 0 | BH13: 10000 | BI13: 9 | BJ13: TRUE | BK13: 0 | BL13: 10000 | GR13: 200 | GS13: 400 | GT13: Attack One | GU13: 30046 | GX13: 1 | GZ13: 0 | HA13: 0 | HB13: 0 | HC13: 0 | HD13: 0 | HE13: FALSE | HG13: 10001 | HI13: 无 | HJ13: 0 | HK13: 0 | HL13: 0
B14: {=10000000+INDEX(编号表!$B$1:$B$112,MATCH(D14,编号表!$A$1:$A$112,0))*10000+I14} -> 10010008 | C14: 青萍剑诀 | D14: 青萍剑诀 | E14: 人道 | F14: 剑道 | G14: FALSE | H14: FALSE | I14: 8 | J14: =LEFT(B14,6) -> 100100 | K14: 凡品 | L14: =B13 -> 10010007 | M14: =B15 -> 10010009 | N14: 剑出青萍，疾刺目标，造成物理伤害。剑道诸式皆由此起。 | O14: 10202000 | P14: 0 | Q14: 3 | R14: 35 | T14: 100 | V14: 500 | W14: 500 | X14: 单位 | Y14: 单体 | Z14: 敌对 | AA14: 0 | AB14: 1 | AC14: 0 | AD14: 最近 | AY14: 物理 | AZ14: 11800 | BA14: 技能效果_伤害 | BB14: 敌对 | BC14: 10000 | BD14: 0 | BE14: 全部 | BF14: 0 | BG14: 0 | BH14: 10000 | BI14: 10 | BJ14: TRUE | BK14: 0 | BL14: 10000 | GR14: 200 | GS14: 400 | GT14: Attack One | GU14: 30046 | GX14: 1 | GZ14: 0 | HA14: 0 | HB14: 0 | HC14: 0 | HD14: 0 | HE14: FALSE | HG14: 10001 | HI14: 无 | HJ14: 0 | HK14: 0 | HL14: 0
B15: {=10000000+INDEX(编号表!$B$1:$B$112,MATCH(D15,编号表!$A$1:$A$112,0))*10000+I15} -> 10010009 | C15: 青萍剑诀 | D15: 青萍剑诀 | E15: 人道 | F15: 剑道 | G15: FALSE | H15: FALSE | I15: 9 | J15: =LEFT(B15,6) -> 100100 | K15: 凡品 | L15: =B14 -> 10010008 | M15: =B16 -> 10010010 | N15: 剑出青萍，疾刺目标，造成物理伤害。剑道诸式皆由此起。 | O15: 10202000 | P15: 0 | Q15: 3 | R15: 40 | T15: 100 | V15: 500 | W15: 500 | X15: 单位 | Y15: 单体 | Z15: 敌对 | AA15: 0 | AB15: 1 | AC15: 0 | AD15: 最近 | AY15: 物理 | AZ15: 11900 | BA15: 技能效果_伤害 | BB15: 敌对 | BC15: 10000 | BD15: 0 | BE15: 全部 | BF15: 0 | BG15: 0 | BH15: 10000 | BI15: 12 | BJ15: TRUE | BK15: 0 | BL15: 10000 | GR15: 200 | GS15: 400 | GT15: Attack One | GU15: 30046 | GX15: 1 | GZ15: 0 | HA15: 0 | HB15: 0 | HC15: 0 | HD15: 0 | HE15: FALSE | HG15: 10001 | HI15: 无 | HJ15: 0 | HK15: 0 | HL15: 0
B16: {=10000000+INDEX(编号表!$B$1:$B$112,MATCH(D16,编号表!$A$1:$A$112,0))*10000+I16} -> 10010010 | C16: 青萍剑诀 | D16: 青萍剑诀 | E16: 人道 | F16: 剑道 | G16: FALSE | H16: FALSE | I16: 10 | J16: =LEFT(B16,6) -> 100100 | K16: 凡品 | L16: =B15 -> 10010009 | N16: 剑出青萍，疾刺目标，造成物理伤害。剑道诸式皆由此起。 | O16: 10202000 | P16: 0 | Q16: 3 | R16: 40 | T16: 100 | V16: 500 | W16: 500 | X16: 单位 | Y16: 单体 | Z16: 敌对 | AA16: 0 | AB16: 1 | AC16: 0 | AD16: 最近 | AY16: 物理 | AZ16: 12000 | BA16: 技能效果_伤害 | BB16: 敌对 | BC16: 10000 | BD16: 0 | BE16: 全部 | BF16: 0 | BG16: 0 | BH16: 10000 | BI16: 15 | BJ16: TRUE | BK16: 0 | BL16: 10000 | GR16: 200 | GS16: 400 | GT16: Attack One | GU16: 30046 | GX16: 1 | GZ16: 0 | HA16: 0 | HB16: 0 | HC16: 0 | HD16: 0 | HE16: FALSE | HG16: 10001 | HI16: 无 | HJ16: 0 | HK16: 0 | HL16: 0
B17: {=10000000+INDEX(编号表!$B$1:$B$112,MATCH(D17,编号表!$A$1:$A$112,0))*10000+I17} -> 10020001 | C17: 玄门伏虎击 | D17: 玄门伏虎击 | E17: 人道 | F17: 炼体 | G17: FALSE | H17: FALSE | I17: 1 | J17: =LEFT(B17,6) -> 100200 | K17: 凡品 | L17: 0 | M17: 10020002 | N17: 凝聚近身劲力向目标发动一击，造成物理伤害。 | O17: 10202001 | P17: 0 | Q17: 0 | R17: 1 | S17: 0 | T17: 100 | U17: 施放本神通 | V17: 200 | W17: 500 | X17: 单位 | Y17: 单体 | Z17: 敌对 | AA17: 0 | AB17: 1 | AC17: FALSE | AD17: 最近 | AY17: 物理 | AZ17: 10000 | BA17: 技能效果_伤害 | BB17: 敌对 | BC17: 10000 | BD17: 0 | BE17: 全部 | BF17: 0 | BG17: 物理 | BH17: 10000 | BI17: 3 | BJ17: TRUE | BK17: 0 | BL17: 10000 | GR17: 200 | GS17: 400 | GT17: Attack One | GU17: 30043 | GV17: 340 | GW17: 340 | GX17: TRUE | GY17: 1200 | GZ17: FALSE | HA17: 0 | HB17: 0 | HC17: 0 | HD17: 0 | HE17: FALSE | HF17: 0 | HG17: 10001 | HH17: 340 | HI17: 无 | HJ17: 0 | HK17: 0 | HL17: 0 | HM17: 0 | HN17: FALSE
B18: {=10000000+INDEX(编号表!$B$1:$B$112,MATCH(D18,编号表!$A$1:$A$112,0))*10000+I18} -> 10020002 | C18: 玄门伏虎击 | D18: 玄门伏虎击 | E18: 人道 | F18: 炼体 | G18: FALSE | H18: FALSE | I18: 2 | J18: =LEFT(B18,6) -> 100200 | K18: 凡品 | L18: =B17 -> 10020001 | M18: =B19 -> 10020003 | N18: 凝聚近身劲力向目标发动一击，造成物理伤害。 | O18: 10202001 | P18: 0 | Q18: 1 | R18: 7 | S18: 0 | T18: 100 | U18: 施放本神通 | V18: 200 | W18: 500 | X18: 单位 | Y18: 单体 | Z18: 敌对 | AA18: 0 | AB18: 1 | AC18: FALSE | AD18: 最近 | AY18: 物理 | AZ18: 10400 | BA18: 技能效果_伤害 | BB18: 敌对 | BC18: 10000 | BD18: 0 | BE18: 全部 | BF18: 0 | BG18: 物理 | BH18: 10000 | BI18: 4 | BJ18: TRUE | BK18: 0 | BL18: 10000 | GR18: 200 | GS18: 400 | GT18: Attack One | GU18: 30043 | GV18: 340 | GW18: 340 | GX18: TRUE | GY18: 1200 | GZ18: FALSE | HA18: 0 | HB18: 0 | HC18: 0 | HD18: 0 | HE18: FALSE | HF18: 0 | HG18: 10001 | HH18: 340 | HI18: 无 | HJ18: 0 | HK18: 0 | HL18: 0 | HM18: 0 | HN18: FALSE
B19: {=10000000+INDEX(编号表!$B$1:$B$112,MATCH(D19,编号表!$A$1:$A$112,0))*10000+I19} -> 10020003 | C19: 玄门伏虎击 | D19: 玄门伏虎击 | E19: 人道 | F19: 炼体 | G19: FALSE | H19: FALSE | I19: 3 | J19: =LEFT(B19,6) -> 100200 | K19: 凡品 | L19: =B18 -> 10020002 | M19: =B20 -> 10020004 | N19: 凝聚近身劲力向目标发动一击，造成物理伤害。 | O19: 10202001 | P19: 0 | Q19: 2 | R19: 11 | S19: 0 | T19: 100 | U19: 施放本神通 | V19: 200 | W19: 500 | X19: 单位 | Y19: 单体 | Z19: 敌对 | AA19: 0 | AB19: 1 | AC19: FALSE | AD19: 最近 | AY19: 物理 | AZ19: 10800 | BA19: 技能效果_伤害 | BB19: 敌对 | BC19: 10000 | BD19: 0 | BE19: 全部 | BF19: 0 | BG19: 物理 | BH19: 10000 | BI19: 5 | BJ19: TRUE | BK19: 0 | BL19: 10000 | GR19: 200 | GS19: 400 | GT19: Attack One | GU19: 30043 | GV19: 340 | GW19: 340 | GX19: TRUE | GY19: 1200 | GZ19: FALSE | HA19: 0 | HB19: 0 | HC19: 0 | HD19: 0 | HE19: FALSE | HF19: 0 | HG19: 10001 | HH19: 340 | HI19: 无 | HJ19: 0 | HK19: 0 | HL19: 0 | HM19: 0 | HN19: FALSE
B20: {=10000000+INDEX(编号表!$B$1:$B$112,MATCH(D20,编号表!$A$1:$A$112,0))*10000+I20} -> 10020004 | C20: 玄门伏虎击 | D20: 玄门伏虎击 | E20: 人道 | F20: 炼体 | G20: FALSE | H20: FALSE | I20: 4 | J20: =LEFT(B20,6) -> 100200 | K20: 凡品 | L20: =B19 -> 10020003 | M20: =B21 -> 10020005 | N20: 凝聚近身劲力向目标发动一击，造成物理伤害。 | O20: 10202001 | P20: 0 | Q20: 3 | R20: 16 | S20: 0 | T20: 100 | U20: 施放本神通 | V20: 200 | W20: 500 | X20: 单位 | Y20: 单体 | Z20: 敌对 | AA20: 0 | AB20: 1 | AC20: FALSE | AD20: 最近 | AY20: 物理 | AZ20: 11200 | BA20: 技能效果_伤害 | BB20: 敌对 | BC20: 10000 | BD20: 0 | BE20: 全部 | BF20: 0 | BG20: 物理 | BH20: 10000 | BI20: 6 | BJ20: TRUE | BK20: 0 | BL20: 10000 | GR20: 200 | GS20: 400 | GT20: Attack One | GU20: 30043 | GV20: 340 | GW20: 340 | GX20: TRUE | GY20: 1200 | GZ20: FALSE | HA20: 0 | HB20: 0 | HC20: 0 | HD20: 0 | HE20: FALSE | HF20: 0 | HG20: 10001 | HH20: 340 | HI20: 无 | HJ20: 0 | HK20: 0 | HL20: 0 | HM20: 0 | HN20: FALSE
B21: {=10000000+INDEX(编号表!$B$1:$B$112,MATCH(D21,编号表!$A$1:$A$112,0))*10000+I21} -> 10020005 | C21: 玄门伏虎击 | D21: 玄门伏虎击 | E21: 人道 | F21: 炼体 | G21: FALSE | H21: FALSE | I21: 5 | J21: =LEFT(B21,6) -> 100200 | K21: 凡品 | L21: =B20 -> 10020004 | M21: =B22 -> 10020006 | N21: 凝聚近身劲力向目标发动一击，造成物理伤害。 | O21: 10202001 | P21: 0 | Q21: 3 | R21: 25 | S21: 0 | T21: 100 | U21: 施放本神通 | V21: 200 | W21: 500 | X21: 单位 | Y21: 单体 | Z21: 敌对 | AA21: 0 | AB21: 1 | AC21: FALSE | AD21: 最近 | AY21: 物理 | AZ21: 11300 | BA21: 技能效果_伤害 | BB21: 敌对 | BC21: 10000 | BD21: 0 | BE21: 全部 | BF21: 0 | BG21: 物理 | BH21: 10000 | BI21: 6 | BJ21: TRUE | BK21: 0 | BL21: 10000 | GR21: 200 | GS21: 400 | GT21: Attack One | GU21: 30043 | GV21: 340 | GW21: 340 | GX21: TRUE | GY21: 1200 | GZ21: FALSE | HA21: 0 | HB21: 0 | HC21: 0 | HD21: 0 | HE21: FALSE | HF21: 0 | HG21: 10001 | HH21: 340 | HI21: 无 | HJ21: 0 | HK21: 0 | HL21: 0 | HM21: 0 | HN21: FALSE
B22: {=10000000+INDEX(编号表!$B$1:$B$112,MATCH(D22,编号表!$A$1:$A$112,0))*10000+I22} -> 10020006 | C22: 玄门伏虎击 | D22: 玄门伏虎击 | E22: 人道 | F22: 炼体 | G22: FALSE | H22: FALSE | I22: 6 | J22: =LEFT(B22,6) -> 100200 | K22: 凡品 | L22: =B21 -> 10020005 | M22: =B23 -> 10020007 | N22: 凝聚近身劲力向目标发动一击，造成物理伤害。 | O22: 10202001 | P22: 0 | Q22: 3 | R22: 30 | S22: 0 | T22: 100 | U22: 施放本神通 | V22: 200 | W22: 500 | X22: 单位 | Y22: 单体 | Z22: 敌对 | AA22: 0 | AB22: 1 | AC22: FALSE | AD22: 最近 | AY22: 物理 | AZ22: 11600 | BA22: 技能效果_伤害 | BB22: 敌对 | BC22: 10000 | BD22: 0 | BE22: 全部 | BF22: 0 | BG22: 物理 | BH22: 10000 | BI22: 7 | BJ22: TRUE | BK22: 0 | BL22: 10000 | GR22: 200 | GS22: 400 | GT22: Attack One | GU22: 30043 | GV22: 340 | GW22: 340 | GX22: TRUE | GY22: 1200 | GZ22: FALSE | HA22: 0 | HB22: 0 | HC22: 0 | HD22: 0 | HE22: FALSE | HF22: 0 | HG22: 10001 | HH22: 340 | HI22: 无 | HJ22: 0 | HK22: 0 | HL22: 0 | HM22: 0 | HN22: FALSE
B23: {=10000000+INDEX(编号表!$B$1:$B$112,MATCH(D23,编号表!$A$1:$A$112,0))*10000+I23} -> 10020007 | C23: 玄门伏虎击 | D23: 玄门伏虎击 | E23: 人道 | F23: 炼体 | G23: FALSE | H23: FALSE | I23: 7 | J23: =LEFT(B23,6) -> 100200 | K23: 凡品 | L23: =B22 -> 10020006 | M23: =B24 -> 10020008 | N23: 凝聚近身劲力向目标发动一击，造成物理伤害。 | O23: 10202001 | P23: 0 | Q23: 3 | R23: 35 | S23: 0 | T23: 100 | U23: 施放本神通 | V23: 200 | W23: 500 | X23: 单位 | Y23: 单体 | Z23: 敌对 | AA23: 0 | AB23: 1 | AC23: FALSE | AD23: 最近 | AY23: 物理 | AZ23: 11700 | BA23: 技能效果_伤害 | BB23: 敌对 | BC23: 10000 | BD23: 0 | BE23: 全部 | BF23: 0 | BG23: 物理 | BH23: 10000 | BI23: 9 | BJ23: TRUE | BK23: 0 | BL23: 10000 | GR23: 200 | GS23: 400 | GT23: Attack One | GU23: 30043 | GV23: 340 | GW23: 340 | GX23: TRUE | GY23: 1200 | GZ23: FALSE | HA23: 0 | HB23: 0 | HC23: 0 | HD23: 0 | HE23: FALSE | HF23: 0 | HG23: 10001 | HH23: 340 | HI23: 无 | HJ23: 0 | HK23: 0 | HL23: 0 | HM23: 0 | HN23: FALSE
B24: {=10000000+INDEX(编号表!$B$1:$B$112,MATCH(D24,编号表!$A$1:$A$112,0))*10000+I24} -> 10020008 | C24: 玄门伏虎击 | D24: 玄门伏虎击 | E24: 人道 | F24: 炼体 | G24: FALSE | H24: FALSE | I24: 8 | J24: =LEFT(B24,6) -> 100200 | K24: 凡品 | L24: =B23 -> 10020007 | M24: =B25 -> 10020009 | N24: 凝聚近身劲力向目标发动一击，造成物理伤害。 | O24: 10202001 | P24: 0 | Q24: 3 | R24: 35 | S24: 0 | T24: 100 | U24: 施放本神通 | V24: 200 | W24: 500 | X24: 单位 | Y24: 单体 | Z24: 敌对 | AA24: 0 | AB24: 1 | AC24: FALSE | AD24: 最近 | AY24: 物理 | AZ24: 11800 | BA24: 技能效果_伤害 | BB24: 敌对 | BC24: 10000 | BD24: 0 | BE24: 全部 | BF24: 0 | BG24: 物理 | BH24: 10000 | BI24: 10 | BJ24: TRUE | BK24: 0 | BL24: 10000 | GR24: 200 | GS24: 400 | GT24: Attack One | GU24: 30043 | GV24: 340 | GW24: 340 | GX24: TRUE | GY24: 1200 | GZ24: FALSE | HA24: 0 | HB24: 0 | HC24: 0 | HD24: 0 | HE24: FALSE | HF24: 0 | HG24: 10001 | HH24: 340 | HI24: 无 | HJ24: 0 | HK24: 0 | HL24: 0 | HM24: 0 | HN24: FALSE
B25: {=10000000+INDEX(编号表!$B$1:$B$112,MATCH(D25,编号表!$A$1:$A$112,0))*10000+I25} -> 10020009 | C25: 玄门伏虎击 | D25: 玄门伏虎击 | E25: 人道 | F25: 炼体 | G25: FALSE | H25: FALSE | I25: 9 | J25: =LEFT(B25,6) -> 100200 | K25: 凡品 | L25: =B24 -> 10020008 | M25: =B26 -> 10020010 | N25: 凝聚近身劲力向目标发动一击，造成物理伤害。 | O25: 10202001 | P25: 0 | Q25: 3 | R25: 40 | S25: 0 | T25: 100 | U25: 施放本神通 | V25: 200 | W25: 500 | X25: 单位 | Y25: 单体 | Z25: 敌对 | AA25: 0 | AB25: 1 | AC25: FALSE | AD25: 最近 | AY25: 物理 | AZ25: 11900 | BA25: 技能效果_伤害 | BB25: 敌对 | BC25: 10000 | BD25: 0 | BE25: 全部 | BF25: 0 | BG25: 物理 | BH25: 10000 | BI25: 12 | BJ25: TRUE | BK25: 0 | BL25: 10000 | GR25: 200 | GS25: 400 | GT25: Attack One | GU25: 30043 | GV25: 340 | GW25: 340 | GX25: TRUE | GY25: 1200 | GZ25: FALSE | HA25: 0 | HB25: 0 | HC25: 0 | HD25: 0 | HE25: FALSE | HF25: 0 | HG25: 10001 | HH25: 340 | HI25: 无 | HJ25: 0 | HK25: 0 | HL25: 0 | HM25: 0 | HN25: FALSE
B26: {=10000000+INDEX(编号表!$B$1:$B$112,MATCH(D26,编号表!$A$1:$A$112,0))*10000+I26} -> 10020010 | C26: 玄门伏虎击 | D26: 玄门伏虎击 | E26: 人道 | F26: 炼体 | G26: FALSE | H26: FALSE | I26: 10 | J26: =LEFT(B26,6) -> 100200 | K26: 凡品 | L26: =B25 -> 10020009 | M26: 0 | N26: 凝聚近身劲力向目标发动一击，造成物理伤害。 | O26: 10202001 | P26: 0 | Q26: 3 | R26: 40 | S26: 0 | T26: 0 | U26: 施放本神通 | V26: 200 | W26: 500 | X26: 单位 | Y26: 单体 | Z26: 敌对 | AA26: 0 | AB26: 1 | AC26: FALSE | AD26: 最近 | AY26: 物理 | AZ26: 12000 | BA26: 技能效果_伤害 | BB26: 敌对 | BC26: 10000 | BD26: 0 | BE26: 全部 | BF26: 0 | BG26: 物理 | BH26: 10000 | BI26: 15 | BJ26: TRUE | BK26: 0 | BL26: 10000 | GR26: 200 | GS26: 400 | GT26: Attack One | GU26: 30043 | GV26: 340 | GW26: 340 | GX26: TRUE | GY26: 1200 | GZ26: FALSE | HA26: 0 | HB26: 0 | HC26: 0 | HD26: 0 | HE26: FALSE | HF26: 0 | HG26: 10001 | HH26: 340 | HI26: 无 | HJ26: 0 | HK26: 0 | HL26: 0 | HM26: 0 | HN26: FALSE
B27: {=10000000+INDEX(编号表!$B$1:$B$112,MATCH(D27,编号表!$A$1:$A$112,0))*10000+I27} -> 10030001 | C27: 太白藏锋斩 | D27: 太白藏锋斩 | E27: 人道 | F27: 炼体 | G27: FALSE | H27: FALSE | I27: 1 | J27: =LEFT(B27,6) -> 100300 | K27: 凡品 | L27: 0 | M27: =B28 -> 10030002 | N27: 藏锋蓄势，拔刃横扫前方扇形范围，对敌人造成物理伤害。 | O27: 10202002 | P27: 0 | Q27: 0 | R27: 1 | S27: 0 | T27: 100 | U27: 施放本神通 | V27: 0 | W27: 0 | X27: 目标方向 | Y27: 扇形 | Z27: 敌对 | AA27: 0 | AB27: 8 | AC27: FALSE | AD27: 最近 | AF27: 320 | AG27: 80 | AY27: 物理 | AZ27: 10000 | BA27: 技能效果_伤害 | BB27: 敌对 | BC27: 10000 | BD27: 0 | BE27: 全部 | BF27: 0 | BG27: 物理 | BH27: 9000 | BI27: 3 | BJ27: TRUE | BK27: 0 | BL27: 8000 | GR27: 200 | GS27: 400 | GT27: Attack One | GU27: 30057 | GV27: 340 | GW27: 340 | GX27: TRUE | GY27: 2500 | GZ27: FALSE | HA27: 0 | HB27: 0 | HC27: 0 | HD27: 0 | HE27: FALSE | HF27: 0 | HG27: 10001 | HH27: 340 | HI27: 无 | HJ27: 0 | HK27: 0 | HL27: 0 | HM27: 0 | HN27: FALSE
B28: {=10000000+INDEX(编号表!$B$1:$B$112,MATCH(D28,编号表!$A$1:$A$112,0))*10000+I28} -> 10030002 | C28: 太白藏锋斩 | D28: 太白藏锋斩 | E28: 人道 | F28: 炼体 | G28: FALSE | H28: FALSE | I28: 2 | J28: =LEFT(B28,6) -> 100300 | K28: 凡品 | L28: =B27 -> 10030001 | M28: =B29 -> 10030003 | N28: 藏锋蓄势，拔刃横扫前方扇形范围，对敌人造成物理伤害。 | O28: 10202002 | P28: 0 | Q28: 1 | R28: 7 | S28: 0 | T28: 100 | U28: 施放本神通 | V28: 0 | W28: 0 | X28: 目标方向 | Y28: 扇形 | Z28: 敌对 | AA28: 0 | AB28: 8 | AC28: FALSE | AD28: 最近 | AF28: 320 | AG28: 80 | AY28: 物理 | AZ28: 10400 | BA28: 技能效果_伤害 | BB28: 敌对 | BC28: 10000 | BD28: 0 | BE28: 全部 | BF28: 0 | BG28: 物理 | BH28: 9000 | BI28: 4 | BJ28: TRUE | BK28: 0 | BL28: 8000 | GR28: 200 | GS28: 400 | GT28: Attack One | GU28: 30057 | GV28: 340 | GW28: 340 | GX28: TRUE | GY28: 2500 | GZ28: FALSE | HA28: 0 | HB28: 0 | HC28: 0 | HD28: 0 | HE28: FALSE | HF28: 0 | HG28: 10001 | HH28: 340 | HI28: 无 | HJ28: 0 | HK28: 0 | HL28: 0 | HM28: 0 | HN28: FALSE
B29: {=10000000+INDEX(编号表!$B$1:$B$112,MATCH(D29,编号表!$A$1:$A$112,0))*10000+I29} -> 10030003 | C29: 太白藏锋斩 | D29: 太白藏锋斩 | E29: 人道 | F29: 炼体 | G29: FALSE | H29: FALSE | I29: 3 | J29: =LEFT(B29,6) -> 100300 | K29: 凡品 | L29: =B28 -> 10030002 | M29: =B30 -> 10030004 | N29: 藏锋蓄势，拔刃横扫前方扇形范围，对敌人造成物理伤害。 | O29: 10202002 | P29: 0 | Q29: 2 | R29: 11 | S29: 0 | T29: 100 | U29: 施放本神通 | V29: 0 | W29: 0 | X29: 目标方向 | Y29: 扇形 | Z29: 敌对 | AA29: 0 | AB29: 8 | AC29: FALSE | AD29: 最近 | AF29: 320 | AG29: 80 | AY29: 物理 | AZ29: 10800 | BA29: 技能效果_伤害 | BB29: 敌对 | BC29: 10000 | BD29: 0 | BE29: 全部 | BF29: 0 | BG29: 物理 | BH29: 9000 | BI29: 5 | BJ29: TRUE | BK29: 0 | BL29: 8000 | GR29: 200 | GS29: 400 | GT29: Attack One | GU29: 30057 | GV29: 340 | GW29: 340 | GX29: TRUE | GY29: 2500 | GZ29: FALSE | HA29: 0 | HB29: 0 | HC29: 0 | HD29: 0 | HE29: FALSE | HF29: 0 | HG29: 10001 | HH29: 340 | HI29: 无 | HJ29: 0 | HK29: 0 | HL29: 0 | HM29: 0 | HN29: FALSE
B30: {=10000000+INDEX(编号表!$B$1:$B$112,MATCH(D30,编号表!$A$1:$A$112,0))*10000+I30} -> 10030004 | C30: 太白藏锋斩 | D30: 太白藏锋斩 | E30: 人道 | F30: 炼体 | G30: FALSE | H30: FALSE | I30: 4 | J30: =LEFT(B30,6) -> 100300 | K30: 凡品 | L30: =B29 -> 10030003 | M30: =B31 -> 10030005 | N30: 藏锋蓄势，拔刃横扫前方扇形范围，对敌人造成物理伤害。 | O30: 10202002 | P30: 0 | Q30: 3 | R30: 16 | S30: 0 | T30: 100 | U30: 施放本神通 | V30: 0 | W30: 0 | X30: 目标方向 | Y30: 扇形 | Z30: 敌对 | AA30: 0 | AB30: 8 | AC30: FALSE | AD30: 最近 | AF30: 320 | AG30: 80 | AY30: 物理 | AZ30: 11200 | BA30: 技能效果_伤害 | BB30: 敌对 | BC30: 10000 | BD30: 0 | BE30: 全部 | BF30: 0 | BG30: 物理 | BH30: 9000 | BI30: 6 | BJ30: TRUE | BK30: 0 | BL30: 8000 | GR30: 200 | GS30: 400 | GT30: Attack One | GU30: 30057 | GV30: 340 | GW30: 340 | GX30: TRUE | GY30: 2500 | GZ30: FALSE | HA30: 0 | HB30: 0 | HC30: 0 | HD30: 0 | HE30: FALSE | HF30: 0 | HG30: 10001 | HH30: 340 | HI30: 无 | HJ30: 0 | HK30: 0 | HL30: 0 | HM30: 0 | HN30: FALSE
B31: {=10000000+INDEX(编号表!$B$1:$B$112,MATCH(D31,编号表!$A$1:$A$112,0))*10000+I31} -> 10030005 | C31: 太白藏锋斩 | D31: 太白藏锋斩 | E31: 人道 | F31: 炼体 | G31: FALSE | H31: FALSE | I31: 5 | J31: =LEFT(B31,6) -> 100300 | K31: 凡品 | L31: =B30 -> 10030004 | M31: =B32 -> 10030006 | N31: 藏锋蓄势，拔刃横扫前方扇形范围，对敌人造成物理伤害。 | O31: 10202002 | P31: 0 | Q31: 3 | R31: 25 | S31: 0 | T31: 100 | U31: 施放本神通 | V31: 0 | W31: 0 | X31: 目标方向 | Y31: 扇形 | Z31: 敌对 | AA31: 0 | AB31: 8 | AC31: FALSE | AD31: 最近 | AF31: 320 | AG31: 80 | AY31: 物理 | AZ31: 11300 | BA31: 技能效果_伤害 | BB31: 敌对 | BC31: 10000 | BD31: 0 | BE31: 全部 | BF31: 0 | BG31: 物理 | BH31: 9000 | BI31: 6 | BJ31: TRUE | BK31: 0 | BL31: 8000 | GR31: 200 | GS31: 400 | GT31: Attack One | GU31: 30057 | GV31: 340 | GW31: 340 | GX31: TRUE | GY31: 2500 | GZ31: FALSE | HA31: 0 | HB31: 0 | HC31: 0 | HD31: 0 | HE31: FALSE | HF31: 0 | HG31: 10001 | HH31: 340 | HI31: 无 | HJ31: 0 | HK31: 0 | HL31: 0 | HM31: 0 | HN31: FALSE
B32: {=10000000+INDEX(编号表!$B$1:$B$112,MATCH(D32,编号表!$A$1:$A$112,0))*10000+I32} -> 10030006 | C32: 太白藏锋斩 | D32: 太白藏锋斩 | E32: 人道 | F32: 炼体 | G32: FALSE | H32: FALSE | I32: 6 | J32: =LEFT(B32,6) -> 100300 | K32: 凡品 | L32: =B31 -> 10030005 | M32: =B33 -> 10030007 | N32: 藏锋蓄势，拔刃横扫前方扇形范围，对敌人造成物理伤害。 | O32: 10202002 | P32: 0 | Q32: 3 | R32: 30 | S32: 0 | T32: 100 | U32: 施放本神通 | V32: 0 | W32: 0 | X32: 目标方向 | Y32: 扇形 | Z32: 敌对 | AA32: 0 | AB32: 8 | AC32: FALSE | AD32: 最近 | AF32: 320 | AG32: 80 | AY32: 物理 | AZ32: 11600 | BA32: 技能效果_伤害 | BB32: 敌对 | BC32: 10000 | BD32: 0 | BE32: 全部 | BF32: 0 | BG32: 物理 | BH32: 9000 | BI32: 7 | BJ32: TRUE | BK32: 0 | BL32: 8000 | GR32: 200 | GS32: 400 | GT32: Attack One | GU32: 30057 | GV32: 340 | GW32: 340 | GX32: TRUE | GY32: 2500 | GZ32: FALSE | HA32: 0 | HB32: 0 | HC32: 0 | HD32: 0 | HE32: FALSE | HF32: 0 | HG32: 10001 | HH32: 340 | HI32: 无 | HJ32: 0 | HK32: 0 | HL32: 0 | HM32: 0 | HN32: FALSE
B33: {=10000000+INDEX(编号表!$B$1:$B$112,MATCH(D33,编号表!$A$1:$A$112,0))*10000+I33} -> 10030007 | C33: 太白藏锋斩 | D33: 太白藏锋斩 | E33: 人道 | F33: 炼体 | G33: FALSE | H33: FALSE | I33: 7 | J33: =LEFT(B33,6) -> 100300 | K33: 凡品 | L33: =B32 -> 10030006 | M33: =B34 -> 10030008 | N33: 藏锋蓄势，拔刃横扫前方扇形范围，对敌人造成物理伤害。 | O33: 10202002 | P33: 0 | Q33: 3 | R33: 35 | S33: 0 | T33: 100 | U33: 施放本神通 | V33: 0 | W33: 0 | X33: 目标方向 | Y33: 扇形 | Z33: 敌对 | AA33: 0 | AB33: 8 | AC33: FALSE | AD33: 最近 | AF33: 320 | AG33: 80 | AY33: 物理 | AZ33: 11700 | BA33: 技能效果_伤害 | BB33: 敌对 | BC33: 10000 | BD33: 0 | BE33: 全部 | BF33: 0 | BG33: 物理 | BH33: 9000 | BI33: 9 | BJ33: TRUE | BK33: 0 | BL33: 8000 | GR33: 200 | GS33: 400 | GT33: Attack One | GU33: 30057 | GV33: 340 | GW33: 340 | GX33: TRUE | GY33: 2500 | GZ33: FALSE | HA33: 0 | HB33: 0 | HC33: 0 | HD33: 0 | HE33: FALSE | HF33: 0 | HG33: 10001 | HH33: 340 | HI33: 无 | HJ33: 0 | HK33: 0 | HL33: 0 | HM33: 0 | HN33: FALSE
B34: {=10000000+INDEX(编号表!$B$1:$B$112,MATCH(D34,编号表!$A$1:$A$112,0))*10000+I34} -> 10030008 | C34: 太白藏锋斩 | D34: 太白藏锋斩 | E34: 人道 | F34: 炼体 | G34: FALSE | H34: FALSE | I34: 8 | J34: =LEFT(B34,6) -> 100300 | K34: 凡品 | L34: =B33 -> 10030007 | M34: =B35 -> 10030009 | N34: 藏锋蓄势，拔刃横扫前方扇形范围，对敌人造成物理伤害。 | O34: 10202002 | P34: 0 | Q34: 3 | R34: 35 | S34: 0 | T34: 100 | U34: 施放本神通 | V34: 0 | W34: 0 | X34: 目标方向 | Y34: 扇形 | Z34: 敌对 | AA34: 0 | AB34: 8 | AC34: FALSE | AD34: 最近 | AF34: 320 | AG34: 80 | AY34: 物理 | AZ34: 11800 | BA34: 技能效果_伤害 | BB34: 敌对 | BC34: 10000 | BD34: 0 | BE34: 全部 | BF34: 0 | BG34: 物理 | BH34: 9000 | BI34: 10 | BJ34: TRUE | BK34: 0 | BL34: 8000 | GR34: 200 | GS34: 400 | GT34: Attack One | GU34: 30057 | GV34: 340 | GW34: 340 | GX34: TRUE | GY34: 2500 | GZ34: FALSE | HA34: 0 | HB34: 0 | HC34: 0 | HD34: 0 | HE34: FALSE | HF34: 0 | HG34: 10001 | HH34: 340 | HI34: 无 | HJ34: 0 | HK34: 0 | HL34: 0 | HM34: 0 | HN34: FALSE
B35: {=10000000+INDEX(编号表!$B$1:$B$112,MATCH(D35,编号表!$A$1:$A$112,0))*10000+I35} -> 10030009 | C35: 太白藏锋斩 | D35: 太白藏锋斩 | E35: 人道 | F35: 炼体 | G35: FALSE | H35: FALSE | I35: 9 | J35: =LEFT(B35,6) -> 100300 | K35: 凡品 | L35: =B34 -> 10030008 | M35: =B36 -> 10030010 | N35: 藏锋蓄势，拔刃横扫前方扇形范围，对敌人造成物理伤害。 | O35: 10202002 | P35: 0 | Q35: 3 | R35: 40 | S35: 0 | T35: 100 | U35: 施放本神通 | V35: 0 | W35: 0 | X35: 目标方向 | Y35: 扇形 | Z35: 敌对 | AA35: 0 | AB35: 8 | AC35: FALSE | AD35: 最近 | AF35: 320 | AG35: 80 | AY35: 物理 | AZ35: 11900 | BA35: 技能效果_伤害 | BB35: 敌对 | BC35: 10000 | BD35: 0 | BE35: 全部 | BF35: 0 | BG35: 物理 | BH35: 9000 | BI35: 12 | BJ35: TRUE | BK35: 0 | BL35: 8000 | GR35: 200 | GS35: 400 | GT35: Attack One | GU35: 30057 | GV35: 340 | GW35: 340 | GX35: TRUE | GY35: 2500 | GZ35: FALSE | HA35: 0 | HB35: 0 | HC35: 0 | HD35: 0 | HE35: FALSE | HF35: 0 | HG35: 10001 | HH35: 340 | HI35: 无 | HJ35: 0 | HK35: 0 | HL35: 0 | HM35: 0 | HN35: FALSE
B36: {=10000000+INDEX(编号表!$B$1:$B$112,MATCH(D36,编号表!$A$1:$A$112,0))*10000+I36} -> 10030010 | C36: 太白藏锋斩 | D36: 太白藏锋斩 | E36: 人道 | F36: 炼体 | G36: FALSE | H36: FALSE | I36: 10 | J36: =LEFT(B36,6) -> 100300 | K36: 凡品 | L36: =B35 -> 10030009 | M36: 0 | N36: 藏锋蓄势，拔刃横扫前方扇形范围，对敌人造成物理伤害。 | O36: 10202002 | P36: 0 | Q36: 3 | R36: 40 | S36: 0 | T36: 0 | U36: 施放本神通 | V36: 0 | W36: 0 | X36: 目标方向 | Y36: 扇形 | Z36: 敌对 | AA36: 0 | AB36: 8 | AC36: FALSE | AD36: 最近 | AF36: 320 | AG36: 80 | AY36: 物理 | AZ36: 12000 | BA36: 技能效果_伤害 | BB36: 敌对 | BC36: 10000 | BD36: 0 | BE36: 全部 | BF36: 0 | BG36: 物理 | BH36: 9000 | BI36: 15 | BJ36: TRUE | BK36: 0 | BL36: 8000 | GR36: 200 | GS36: 400 | GT36: Attack One | GU36: 30057 | GV36: 340 | GW36: 340 | GX36: TRUE | GY36: 2500 | GZ36: FALSE | HA36: 0 | HB36: 0 | HC36: 0 | HD36: 0 | HE36: FALSE | HF36: 0 | HG36: 10001 | HH36: 340 | HI36: 无 | HJ36: 0 | HK36: 0 | HL36: 0 | HM36: 0 | HN36: FALSE
B37: {=10000000+INDEX(编号表!$B$1:$B$112,MATCH(D37,编号表!$A$1:$A$112,0))*10000+I37} -> 10040001 | C37: 玄罡撼岳劲 | D37: 玄罡撼岳劲 | E37: 人道 | F37: 炼体 | G37: FALSE | H37: FALSE | I37: 1 | J37: 100400 | K37: 凡品 | L37: 0 | M37: 10040002 | N37: 以玄罡重击目标，造成物理伤害并将其击退。 | O37: 10202003 | P37: 0 | Q37: 0 | R37: 1 | S37: 0 | T37: 100 | U37: 施放本神通 | V37: 220 | W37: 500 | X37: 单位 | Y37: 单体 | Z37: 敌对 | AA37: 0 | AB37: 1 | AC37: FALSE | AD37: 最近 | AY37: 物理 | AZ37: 10000 | BA37: 技能效果_伤害 | BB37: 敌对 | BC37: 10000 | BD37: 0 | BE37: 全部 | BF37: 0 | BG37: 物理 | BH37: 10500 | BI37: 3 | BJ37: TRUE | BK37: 0 | BL37: 10000 | CX37: 技能效果_位移 | CY37: 敌对 | CZ37: 10000 | DA37: 0 | DB37: 全部 | DC37: 0 | DW37: 命中者 | DX37: 160 | DY37: 直线 | DZ37: 远离施法者 | EA37: FALSE | EB37: 900 | GR37: 200 | GS37: 400 | GT37: Attack One | GU37: 30047 | GV37: 340 | GW37: 340 | GX37: TRUE | GY37: 3500 | GZ37: FALSE | HA37: 0 | HB37: 0 | HC37: 0 | HD37: 0 | HE37: FALSE | HF37: 0 | HG37: 10001 | HH37: 340 | HI37: 无 | HJ37: 0 | HK37: 0 | HL37: 0 | HM37: 0 | HN37: FALSE
B38: {=10000000+INDEX(编号表!$B$1:$B$112,MATCH(D38,编号表!$A$1:$A$112,0))*10000+I38} -> 10040002 | C38: 玄罡撼岳劲 | D38: 玄罡撼岳劲 | E38: 人道 | F38: 炼体 | G38: FALSE | H38: FALSE | I38: 2 | J38: 100400 | K38: 凡品 | L38: 10040001 | M38: 10040003 | N38: 以玄罡重击目标，造成物理伤害并将其击退。 | O38: 10202003 | P38: 0 | Q38: 1 | R38: 7 | S38: 0 | T38: 100 | U38: 施放本神通 | V38: 220 | W38: 500 | X38: 单位 | Y38: 单体 | Z38: 敌对 | AA38: 0 | AB38: 1 | AC38: FALSE | AD38: 最近 | AY38: 物理 | AZ38: 10400 | BA38: 技能效果_伤害 | BB38: 敌对 | BC38: 10000 | BD38: 0 | BE38: 全部 | BF38: 0 | BG38: 物理 | BH38: 10500 | BI38: 4 | BJ38: TRUE | BK38: 0 | BL38: 10000 | CX38: 技能效果_位移 | CY38: 敌对 | CZ38: 10000 | DA38: 0 | DB38: 全部 | DC38: 0 | DW38: 命中者 | DX38: 160 | DY38: 直线 | DZ38: 远离施法者 | EA38: FALSE | EB38: 900 | GR38: 200 | GS38: 400 | GT38: Attack One | GU38: 30047 | GV38: 340 | GW38: 340 | GX38: TRUE | GY38: 3500 | GZ38: FALSE | HA38: 0 | HB38: 0 | HC38: 0 | HD38: 0 | HE38: FALSE | HF38: 0 | HG38: 10001 | HH38: 340 | HI38: 无 | HJ38: 0 | HK38: 0 | HL38: 0 | HM38: 0 | HN38: FALSE
B39: {=10000000+INDEX(编号表!$B$1:$B$112,MATCH(D39,编号表!$A$1:$A$112,0))*10000+I39} -> 10040003 | C39: 玄罡撼岳劲 | D39: 玄罡撼岳劲 | E39: 人道 | F39: 炼体 | G39: FALSE | H39: FALSE | I39: 3 | J39: 100400 | K39: 凡品 | L39: 10040002 | M39: 10040004 | N39: 以玄罡重击目标，造成物理伤害并将其击退。 | O39: 10202003 | P39: 0 | Q39: 2 | R39: 11 | S39: 0 | T39: 100 | U39: 施放本神通 | V39: 220 | W39: 500 | X39: 单位 | Y39: 单体 | Z39: 敌对 | AA39: 0 | AB39: 1 | AC39: FALSE | AD39: 最近 | AY39: 物理 | AZ39: 10800 | BA39: 技能效果_伤害 | BB39: 敌对 | BC39: 10000 | BD39: 0 | BE39: 全部 | BF39: 0 | BG39: 物理 | BH39: 10500 | BI39: 5 | BJ39: TRUE | BK39: 0 | BL39: 10000 | CX39: 技能效果_位移 | CY39: 敌对 | CZ39: 10000 | DA39: 0 | DB39: 全部 | DC39: 0 | DW39: 命中者 | DX39: 160 | DY39: 直线 | DZ39: 远离施法者 | EA39: FALSE | EB39: 900 | GR39: 200 | GS39: 400 | GT39: Attack One | GU39: 30047 | GV39: 340 | GW39: 340 | GX39: TRUE | GY39: 3500 | GZ39: FALSE | HA39: 0 | HB39: 0 | HC39: 0 | HD39: 0 | HE39: FALSE | HF39: 0 | HG39: 10001 | HH39: 340 | HI39: 无 | HJ39: 0 | HK39: 0 | HL39: 0 | HM39: 0 | HN39: FALSE
B40: {=10000000+INDEX(编号表!$B$1:$B$112,MATCH(D40,编号表!$A$1:$A$112,0))*10000+I40} -> 10040004 | C40: 玄罡撼岳劲 | D40: 玄罡撼岳劲 | E40: 人道 | F40: 炼体 | G40: FALSE | H40: FALSE | I40: 4 | J40: 100400 | K40: 凡品 | L40: 10040003 | M40: 10040005 | N40: 以玄罡重击目标，造成物理伤害并将其击退。 | O40: 10202003 | P40: 0 | Q40: 3 | R40: 16 | S40: 0 | T40: 100 | U40: 施放本神通 | V40: 220 | W40: 500 | X40: 单位 | Y40: 单体 | Z40: 敌对 | AA40: 0 | AB40: 1 | AC40: FALSE | AD40: 最近 | AY40: 物理 | AZ40: 11200 | BA40: 技能效果_伤害 | BB40: 敌对 | BC40: 10000 | BD40: 0 | BE40: 全部 | BF40: 0 | BG40: 物理 | BH40: 10500 | BI40: 6 | BJ40: TRUE | BK40: 0 | BL40: 10000 | CX40: 技能效果_位移 | CY40: 敌对 | CZ40: 10000 | DA40: 0 | DB40: 全部 | DC40: 0 | DW40: 命中者 | DX40: 160 | DY40: 直线 | DZ40: 远离施法者 | EA40: FALSE | EB40: 900 | GR40: 200 | GS40: 400 | GT40: Attack One | GU40: 30047 | GV40: 340 | GW40: 340 | GX40: TRUE | GY40: 3500 | GZ40: FALSE | HA40: 0 | HB40: 0 | HC40: 0 | HD40: 0 | HE40: FALSE | HF40: 0 | HG40: 10001 | HH40: 340 | HI40: 无 | HJ40: 0 | HK40: 0 | HL40: 0 | HM40: 0 | HN40: FALSE
...

Sheet buff_config
A1: ##var | B1: id | C1: icon_name | D1: name | F1: level | G1: description | H1: identify_id | I1: show_time | J1: time_override | K1: pile_type | L1: pile_max | M1: duration | N1: interval | O1: display_position | P1: icon_id | Q1: effect_path | R1: binding_position | S1: category | T1: dispel_level | U1: effects
A2: ##var | U2: 0 | AL2: 1 | BC2: 2
A3: ##var | U3: $type | V3: rate | W3: tag | X3: damage_type | Y3: dot_coefficient | Z3: dot_flat | AA3: dot_can_crit | AB3: dot_crit | AC3: heal_type | AD3: hot_coefficient | AE3: hot_flat | AF3: hot_can_crit | AG3: hot_crit | AH3: attr_key | AI3: attr_value | AJ3: sub_skill_id | AK3: per_target_interval_ms | AL3: $type | AM3: rate | AN3: tag | AO3: damage_type | AP3: dot_coefficient | AQ3: dot_flat | AR3: dot_can_crit | AS3: dot_crit | AT3: heal_type | AU3: hot_coefficient | AV3: hot_flat | AW3: hot_can_crit | AX3: hot_crit | AY3: attr_key | AZ3: attr_value | BA3: sub_skill_id | BB3: per_target_interval_ms | BC3: $type | BD3: rate | BE3: tag | BF3: damage_type | BG3: dot_coefficient | BH3: dot_flat | BI3: dot_can_crit | BJ3: dot_crit | BK3: heal_type | BL3: hot_coefficient | BM3: hot_flat | BN3: hot_can_crit | BO3: hot_crit | BP3: attr_key | BQ3: attr_value | BR3: sub_skill_id | BS3: per_target_interval_ms
A4: ##type | B4: int | C4: string | D4: string | E4: BuffTarget | F4: int | G4: string | H4: string | I4: bool | J4: BuffTimeOverrideType | K4: BuffOverrideType | L4: int | M4: int | N4: int | O4: string | P4: int | Q4: string | R4: BuffBindPosition | S4: BuffCategory | T4: int | U4: array,BuffEffect
A5: ##group
A6: ## | B6: 状态ID | C6: 状态图标资源名称 | D6: 状态显示名称 | E6: 状态适用目标类型（不导出：程序不读，只供策划分类） 记录所属对象类别：角色身上填 角色状态，怪物、宠物等填 怪物状态；不限制施加对象 | F6: 状态等级 | G6: 状态描述文本 | H6: 识别ID | I6: 显示剩余时间 | J6: 时间覆盖类型 | K6: 层数叠加类型 | L6: 最大叠加层数 | M6: 持续时间(毫秒) | N6: 作用间隔(毫秒) | O6: 图标显示位置 | P6: 状态图标ID | Q6: 状态特效路径 | R6: 特效绑定位置 | S6: Buff分类 | T6: 驱散级别 0=不可驱散（剧情、BOSS 机制状态），1=普通驱散可驱，2=需强驱散；驱散强度≥本值才驱得掉 | U6: 效果1·效果类型：选定后只填带同名前缀【…】的那一段列，其余留空 | V6: 效果1·【公共】触发概率（万分比） | W6: 效果1·【控制】控制类型 | X6: 效果1·【持续伤害】伤害类型 | Y6: 效果1·【持续伤害】万分比伤害系数 | Z6: 效果1·【持续伤害】固定伤害数值 | AA6: 效果1·【持续伤害】是否允许暴击：持续伤害不暴击，填 FALSE | AB6: 效果1·【持续伤害】暴击参数：填 0 | AC6: 效果1·【持续治疗】治疗类型 | AD6: 效果1·【持续治疗】治疗万分比系数 | AE6: 效果1·【持续治疗】固定治疗值 | AF6: 效果1·【持续治疗】是否允许暴击：持续治疗不暴击，填 FALSE | AG6: 效果1·【持续治疗】暴击参数：填 0 | AH6: 效果1·【属性修正】修正属性类型 | AI6: 效果1·【属性修正】修正属性值 | AJ6: 效果1·【光环】光环释放的技能ID（按状态作用间隔释放） | AK6: 效果1·【光环】同一目标再触发间隔(毫秒)：0=每跳都打；正数=同一目标至少隔这么久再打；-1=同一目标只生效一次（火蛇/火墙/地刺填 -1） | AL6: 效果2·效果类型：选定后只填带同名前缀【…】的那一段列，其余留空 | AM6: 效果2·【公共】触发概率（万分比） | AN6: 效果2·【控制】控制类型 | AO6: 效果2·【持续伤害】伤害类型 | AP6: 效果2·【持续伤害】万分比伤害系数 | AQ6: 效果2·【持续伤害】固定伤害数值 | AR6: 效果2·【持续伤害】是否允许暴击：持续伤害不暴击，填 FALSE | AS6: 效果2·【持续伤害】暴击参数：填 0 | AT6: 效果2·【持续治疗】治疗类型 | AU6: 效果2·【持续治疗】治疗万分比系数 | AV6: 效果2·【持续治疗】固定治疗值 | AW6: 效果2·【持续治疗】是否允许暴击：持续治疗不暴击，填 FALSE | AX6: 效果2·【持续治疗】暴击参数：填 0 | AY6: 效果2·【属性修正】修正属性类型 | AZ6: 效果2·【属性修正】修正属性值 | BA6: 效果2·【光环】光环释放的技能ID（按状态作用间隔释放） | BB6: 效果2·【光环】同一目标再触发间隔(毫秒)：0=每跳都打；正数=同一目标至少隔这么久再打；-1=同一目标只生效一次（火蛇/火墙/地刺填 -1） | BC6: 效果3·效果类型：选定后只填带同名前缀【…】的那一段列，其余留空 | BD6: 效果3·【公共】触发概率（万分比） | BE6: 效果3·【控制】控制类型 | BF6: 效果3·【持续伤害】伤害类型 | BG6: 效果3·【持续伤害】万分比伤害系数 | BH6: 效果3·【持续伤害】固定伤害数值 | BI6: 效果3·【持续伤害】是否允许暴击：持续伤害不暴击，填 FALSE | BJ6: 效果3·【持续伤害】暴击参数：填 0 | BK6: 效果3·【持续治疗】治疗类型 | BL6: 效果3·【持续治疗】治疗万分比系数 | BM6: 效果3·【持续治疗】固定治疗值 | BN6: 效果3·【持续治疗】是否允许暴击：持续治疗不暴击，填 FALSE | BO6: 效果3·【持续治疗】暴击参数：填 0 | BP6: 效果3·【属性修正】修正属性类型 | BQ6: 效果3·【属性修正】修正属性值 | BR6: 效果3·【光环】光环释放的技能ID（按状态作用间隔释放） | BS6: 效果3·【光环】同一目标再触发间隔(毫秒)：0=每跳都打；正数=同一目标至少隔这么久再打；-1=同一目标只生效一次（火蛇/火墙/地刺填 -1）
B7: 21000301 | C7: 眩晕 | D7: 眩晕 | E7: 角色状态 | F7: 1 | G7: 眩晕(无法行动)2秒 | H7: 210003 | I7: 1 | J7: 覆盖 | L7: 1 | M7: 2000 | N7: 0 | Q7: 30058 | S7: 减益 | U7: 状态效果_控制 | V7: 10000 | W7: 眩晕
B8: 21000401 | C8: 石化 | D8: 石化 | E8: 角色状态 | F8: 1 | G8: 石化(无法行动)2秒 | H8: 210004 | I8: 1 | J8: 覆盖 | L8: 1 | M8: 2000 | N8: 0 | Q8: 30058 | S8: 减益 | U8: 状态效果_控制 | V8: 10000 | W8: 石化
B9: 21000601 | C9: 冰冻 | D9: 冰冻 | E9: 角色状态 | F9: 1 | G9: 目标被冰冻定身 | H9: 210006 | I9: 1 | J9: 覆盖 | L9: 1 | M9: 2000 | Q9: 30060 | S9: 减益 | U9: 状态效果_控制 | V9: 10000 | W9: 冰冻
B10: 21001001 | C10: 虚弱 | D10: 虚弱 | E10: 角色状态 | F10: 1 | G10: 敌方伤害减免减20%，持续10秒 | H10: 210010 | I10: 1 | J10: 覆盖 | L10: 1 | M10: 10000 | N10: 0 | S10: 减益 | U10: 状态效果_属性修正 | V10: 10000 | AH10: 伤害减免增幅 | AI10: -2000
B11: 21000201 | C11: 中毒 | D11: 中毒 | E11: 角色状态 | F11: 1 | G11: 中毒状态，持续减少血量 | H11: 210002 | I11: 1 | J11: 覆盖 | L11: 1 | M11: 12000 | N11: 3000 | Q11: 30059 | R11: 原点 | S11: 减益 | U11: 状态效果_持续伤害 | V11: 10000 | X11: 魔法 | Y11: 2200 | Z11: 2 | AA11: 0 | AB11: 0
B12: 21000202 | C12: 中毒 | D12: 中毒 | E12: 角色状态 | F12: 2 | G12: 中毒状态，持续减少血量 | H12: 210002 | I12: 1 | J12: 覆盖 | L12: 1 | M12: 12000 | N12: 3000 | Q12: 30059 | R12: 原点 | S12: 减益 | U12: 状态效果_持续伤害 | V12: 10000 | X12: 魔法 | Y12: 2600 | Z12: 3 | AA12: 0 | AB12: 0
B13: 21000203 | C13: 中毒 | D13: 中毒 | E13: 角色状态 | F13: 3 | G13: 中毒状态，持续减少血量 | H13: 210002 | I13: 1 | J13: 覆盖 | L13: 1 | M13: 12000 | N13: 3000 | Q13: 30059 | R13: 原点 | S13: 减益 | U13: 状态效果_持续伤害 | V13: 10000 | X13: 魔法 | Y13: 3000 | Z13: 4 | AA13: 0 | AB13: 0
B14: 21000204 | C14: 中毒 | D14: 中毒 | E14: 角色状态 | F14: 4 | G14: 中毒状态，持续减少血量 | H14: 210002 | I14: 1 | J14: 覆盖 | L14: 1 | M14: 12000 | N14: 3000 | Q14: 30059 | R14: 原点 | S14: 减益 | U14: 状态效果_持续伤害 | V14: 10000 | X14: 魔法 | Y14: 3600 | Z14: 6 | AA14: 0 | AB14: 0
B15: 21001101 | C15: 春脉绵生 | D15: 春脉绵生 | E15: 角色状态 | F15: 1 | G15: 周期性恢复生命。 | H15: 210011 | I15: TRUE | J15: 覆盖 | K15: 无 | L15: 1 | M15: 9000 | N15: 3000 | O15: 340 | P15: 0 | Q15: 30044 | R15: 无 | S15: 增益 | T15: 1 | U15: 状态效果_持续治疗 | V15: 10000 | AC15: 魔法 | AD15: 1600 | AE15: 1 | AF15: FALSE | AG15: 0
B16: 21001102 | C16: 春脉绵生 | D16: 春脉绵生 | E16: 角色状态 | F16: 2 | G16: 周期性恢复生命。 | H16: 210011 | I16: TRUE | J16: 覆盖 | K16: 无 | L16: 1 | M16: 9000 | N16: 3000 | O16: 340 | P16: 0 | Q16: 30044 | R16: 无 | S16: 增益 | T16: 1 | U16: 状态效果_持续治疗 | V16: 10000 | AC16: 魔法 | AD16: 1800 | AE16: 1 | AF16: FALSE | AG16: 0
B17: 21001103 | C17: 春脉绵生 | D17: 春脉绵生 | E17: 角色状态 | F17: 3 | G17: 周期性恢复生命。 | H17: 210011 | I17: TRUE | J17: 覆盖 | K17: 无 | L17: 1 | M17: 9000 | N17: 3000 | O17: 340 | P17: 0 | Q17: 30044 | R17: 无 | S17: 增益 | T17: 1 | U17: 状态效果_持续治疗 | V17: 10000 | AC17: 魔法 | AD17: 2000 | AE17: 1 | AF17: FALSE | AG17: 0
B18: 21001104 | C18: 春脉绵生 | D18: 春脉绵生 | E18: 角色状态 | F18: 4 | G18: 周期性恢复生命。 | H18: 210011 | I18: TRUE | J18: 覆盖 | K18: 无 | L18: 1 | M18: 9000 | N18: 3000 | O18: 340 | P18: 0 | Q18: 30044 | R18: 无 | S18: 增益 | T18: 1 | U18: 状态效果_持续治疗 | V18: 10000 | AC18: 魔法 | AD18: 2200 | AE18: 2 | AF18: FALSE | AG18: 0
B19: 21001105 | C19: 春脉绵生 | D19: 春脉绵生 | E19: 角色状态 | F19: 5 | G19: 周期性恢复生命。 | H19: 210011 | I19: TRUE | J19: 覆盖 | K19: 无 | L19: 1 | M19: 9000 | N19: 3000 | O19: 340 | P19: 0 | Q19: 30044 | R19: 无 | S19: 增益 | T19: 1 | U19: 状态效果_持续治疗 | V19: 10000 | AC19: 魔法 | AD19: 2400 | AE19: 2 | AF19: FALSE | AG19: 0
B20: 21001106 | C20: 春脉绵生 | D20: 春脉绵生 | E20: 角色状态 | F20: 6 | G20: 周期性恢复生命。 | H20: 210011 | I20: TRUE | J20: 覆盖 | K20: 无 | L20: 1 | M20: 9000 | N20: 3000 | O20: 340 | P20: 0 | Q20: 30044 | R20: 无 | S20: 增益 | T20: 1 | U20: 状态效果_持续治疗 | V20: 10000 | AC20: 魔法 | AD20: 2600 | AE20: 2 | AF20: FALSE | AG20: 0
B21: 21001107 | C21: 春脉绵生 | D21: 春脉绵生 | E21: 角色状态 | F21: 7 | G21: 周期性恢复生命。 | H21: 210011 | I21: TRUE | J21: 覆盖 | K21: 无 | L21: 1 | M21: 9000 | N21: 3000 | O21: 340 | P21: 0 | Q21: 30044 | R21: 无 | S21: 增益 | T21: 1 | U21: 状态效果_持续治疗 | V21: 10000 | AC21: 魔法 | AD21: 2800 | AE21: 2 | AF21: FALSE | AG21: 0
B22: 21001108 | C22: 春脉绵生 | D22: 春脉绵生 | E22: 角色状态 | F22: 8 | G22: 周期性恢复生命。 | H22: 210011 | I22: TRUE | J22: 覆盖 | K22: 无 | L22: 1 | M22: 9000 | N22: 3000 | O22: 340 | P22: 0 | Q22: 30044 | R22: 无 | S22: 增益 | T22: 1 | U22: 状态效果_持续治疗 | V22: 10000 | AC22: 魔法 | AD22: 3000 | AE22: 3 | AF22: FALSE | AG22: 0
B23: 21001109 | C23: 春脉绵生 | D23: 春脉绵生 | E23: 角色状态 | F23: 9 | G23: 周期性恢复生命。 | H23: 210011 | I23: TRUE | J23: 覆盖 | K23: 无 | L23: 1 | M23: 9000 | N23: 3000 | O23: 340 | P23: 0 | Q23: 30044 | R23: 无 | S23: 增益 | T23: 1 | U23: 状态效果_持续治疗 | V23: 10000 | AC23: 魔法 | AD23: 3200 | AE23: 3 | AF23: FALSE | AG23: 0
B24: 21001110 | C24: 春脉绵生 | D24: 春脉绵生 | E24: 角色状态 | F24: 10 | G24: 周期性恢复生命。 | H24: 210011 | I24: TRUE | J24: 覆盖 | K24: 无 | L24: 1 | M24: 9000 | N24: 3000 | O24: 340 | P24: 0 | Q24: 30044 | R24: 无 | S24: 增益 | T24: 1 | U24: 状态效果_持续治疗 | V24: 10000 | AC24: 魔法 | AD24: 3500 | AE24: 3 | AF24: FALSE | AG24: 0
B25: 21001201 | C25: 定魄符 | D25: 定魄符 | E25: 角色状态 | F25: 1 | G25: 受到定魄符约束，暂时无法行动。 | H25: 210012 | I25: TRUE | J25: 覆盖 | K25: 无 | L25: 1 | M25: 1200 | N25: 0 | O25: 340 | P25: 0 | Q25: 30058 | R25: 无 | S25: 减益 | T25: 1 | U25: 状态效果_控制 | V25: 10000 | W25: 眩晕
B26: 21001202 | C26: 定魄符 | D26: 定魄符 | E26: 角色状态 | F26: 2 | G26: 受到定魄符约束，暂时无法行动。 | H26: 210012 | I26: TRUE | J26: 覆盖 | K26: 无 | L26: 1 | M26: 1300 | N26: 0 | O26: 340 | P26: 0 | Q26: 30058 | R26: 无 | S26: 减益 | T26: 1 | U26: 状态效果_控制 | V26: 10000 | W26: 眩晕
B27: 21001203 | C27: 定魄符 | D27: 定魄符 | E27: 角色状态 | F27: 3 | G27: 受到定魄符约束，暂时无法行动。 | H27: 210012 | I27: TRUE | J27: 覆盖 | K27: 无 | L27: 1 | M27: 1400 | N27: 0 | O27: 340 | P27: 0 | Q27: 30058 | R27: 无 | S27: 减益 | T27: 1 | U27: 状态效果_控制 | V27: 10000 | W27: 眩晕
B28: 21001204 | C28: 定魄符 | D28: 定魄符 | E28: 角色状态 | F28: 4 | G28: 受到定魄符约束，暂时无法行动。 | H28: 210012 | I28: TRUE | J28: 覆盖 | K28: 无 | L28: 1 | M28: 1500 | N28: 0 | O28: 340 | P28: 0 | Q28: 30058 | R28: 无 | S28: 减益 | T28: 1 | U28: 状态效果_控制 | V28: 10000 | W28: 眩晕
B29: 21001205 | C29: 定魄符 | D29: 定魄符 | E29: 角色状态 | F29: 5 | G29: 受到定魄符约束，暂时无法行动。 | H29: 210012 | I29: TRUE | J29: 覆盖 | K29: 无 | L29: 1 | M29: 1600 | N29: 0 | O29: 340 | P29: 0 | Q29: 30058 | R29: 无 | S29: 减益 | T29: 1 | U29: 状态效果_控制 | V29: 10000 | W29: 眩晕
B30: 21001206 | C30: 定魄符 | D30: 定魄符 | E30: 角色状态 | F30: 6 | G30: 受到定魄符约束，暂时无法行动。 | H30: 210012 | I30: TRUE | J30: 覆盖 | K30: 无 | L30: 1 | M30: 1700 | N30: 0 | O30: 340 | P30: 0 | Q30: 30058 | R30: 无 | S30: 减益 | T30: 1 | U30: 状态效果_控制 | V30: 10000 | W30: 眩晕
B31: 21001207 | C31: 定魄符 | D31: 定魄符 | E31: 角色状态 | F31: 7 | G31: 受到定魄符约束，暂时无法行动。 | H31: 210012 | I31: TRUE | J31: 覆盖 | K31: 无 | L31: 1 | M31: 1800 | N31: 0 | O31: 340 | P31: 0 | Q31: 30058 | R31: 无 | S31: 减益 | T31: 1 | U31: 状态效果_控制 | V31: 10000 | W31: 眩晕
B32: 21001208 | C32: 定魄符 | D32: 定魄符 | E32: 角色状态 | F32: 8 | G32: 受到定魄符约束，暂时无法行动。 | H32: 210012 | I32: TRUE | J32: 覆盖 | K32: 无 | L32: 1 | M32: 1900 | N32: 0 | O32: 340 | P32: 0 | Q32: 30058 | R32: 无 | S32: 减益 | T32: 1 | U32: 状态效果_控制 | V32: 10000 | W32: 眩晕
B33: 21001209 | C33: 定魄符 | D33: 定魄符 | E33: 角色状态 | F33: 9 | G33: 受到定魄符约束，暂时无法行动。 | H33: 210012 | I33: TRUE | J33: 覆盖 | K33: 无 | L33: 1 | M33: 2000 | N33: 0 | O33: 340 | P33: 0 | Q33: 30058 | R33: 无 | S33: 减益 | T33: 1 | U33: 状态效果_控制 | V33: 10000 | W33: 眩晕
B34: 21001210 | C34: 定魄符 | D34: 定魄符 | E34: 角色状态 | F34: 10 | G34: 受到定魄符约束，暂时无法行动。 | H34: 210012 | I34: TRUE | J34: 覆盖 | K34: 无 | L34: 1 | M34: 2200 | N34: 0 | O34: 340 | P34: 0 | Q34: 30058 | R34: 无 | S34: 减益 | T34: 1 | U34: 状态效果_控制 | V34: 10000 | W34: 眩晕
B35: 21001301 | C35: 霜锁九脉 | D35: 霜锁九脉 | E35: 角色状态 | F35: 1 | G35: 经脉被寒霜封锁，暂时陷入冰冻。 | H35: 210013 | I35: TRUE | J35: 覆盖 | K35: 无 | L35: 1 | M35: 1500 | N35: 0 | O35: 340 | P35: 0 | Q35: 30060 | R35: 无 | S35: 减益 | T35: 1 | U35: 状态效果_控制 | V35: 10000 | W35: 冰冻
B36: 21001302 | C36: 霜锁九脉 | D36: 霜锁九脉 | E36: 角色状态 | F36: 2 | G36: 经脉被寒霜封锁，暂时陷入冰冻。 | H36: 210013 | I36: TRUE | J36: 覆盖 | K36: 无 | L36: 1 | M36: 1600 | N36: 0 | O36: 340 | P36: 0 | Q36: 30060 | R36: 无 | S36: 减益 | T36: 1 | U36: 状态效果_控制 | V36: 10000 | W36: 冰冻
... B44: 21001310 | C44: 霜锁九脉 | D44: 霜锁九脉 | E44: 角色状态 | F44: 10 | G44: 经脉被寒霜封锁，暂时陷入冰冻。 | H44: 210013 | I44: TRUE | J44: 覆盖 | K44: 无 | L44: 1 | M44: 2500 | N44: 0 | O44: 340 | P44: 0 | Q44: 30060 | R44: 无 | S44: 减益 | T44: 1 | U44: 状态效果_控制 | V44: 10000 | W44: 冰冻
B45: 21001401 | C45: 砺锋诀 | D45: 砺锋诀 | E45: 角色状态 | F45: 1 | G45: 物理攻击上下限提高。 | H45: 210014 | I45: TRUE | J45: 覆盖 | K45: 无 | L45: 1 | M45: 12000 | N45: 0 | O45: 340 | P45: 0 | Q45: 30009 | R45: 无 | S45: 增益 | T45: 1 | U45: 状态效果_属性修正 | V45: 10000 | AH45: 攻击下限增幅 | AI45: 800 | AL45: 状态效果_属性修正 | AM45: 10000 | AY45: 攻击上限增幅 | AZ45: 800
B46: 21001402 | C46: 砺锋诀 | D46: 砺锋诀 | E46: 角色状态 | F46: 2 | G46: 物理攻击上下限提高。 | H46: 210014 | I46: TRUE | J46: 覆盖 | K46: 无 | L46: 1 | M46: 12000 | N46: 0 | O46: 340 | P46: 0 | Q46: 30009 | R46: 无 | S46: 增益 | T46: 1 | U46: 状态效果_属性修正 | V46: 10000 | AH46: 攻击下限增幅 | AI46: 1000 | AL46: 状态效果_属性修正 | AM46: 10000 | AY46: 攻击上限增幅 | AZ46: 1000
B47: 21001403 | C47: 砺锋诀 | D47: 砺锋诀 | E47: 角色状态 | F47: 3 | G47: 物理攻击上下限提高。 | H47: 210014 | I47: TRUE | J47: 覆盖 | K47: 无 | L47: 1 | M47: 12000 | N47: 0 | O47: 340 | P47: 0 | Q47: 30009 | R47: 无 | S47: 增益 | T47: 1 | U47: 状态效果_属性修正 | V47: 10000 | AH47: 攻击下限增幅 | AI47: 1200 | AL47: 状态效果_属性修正 | AM47: 10000 | AY47: 攻击上限增幅 | AZ47: 1200
...

Sheet 编号表
A1: 技能内部名 | B1: 内部名编号 | E1: 状态内部名 | F1: 编号
A2: 青萍剑诀 | B2: 1 | E2: 眩晕 | F2: 1
A3: 玄门伏虎击 | B3: 2 | E3: 石化 | F3: 2
A4: 太白藏锋斩 | B4: 3 | E4: 冰冻 | F4: 3
A5: 玄罡撼岳劲 | B5: 4 | E5: 虚弱 | F5: 4
A6: 庚芒诀 | B6: 5 | E6: 中毒 | F6: 5
A7: 青萝引 | B7: 6 | E7: 春脉绵生 | F7: 6
A8: 听潮印 | B8: 7 | E8: 定魄符 | F8: 7
A9: 离火星 | B9: 8 | E9: 霜锁九脉 | F9: 8
A10: 凝岳印 | B10: 9 | E10: 砺锋诀 | F10: 9
A11: 惊蛰落霆 | B11: 10 | E11: 玄炁贯灵 | F11: 10
A12: 赤霄焚野 | B12: 11 | E12: 破甲印 | F12: 11
A13: 御锋诀 | B13: 12 | E13: 蚀法咒 | F13: 12
... A18: 春脉绵生 | B18: 17 | E18: 坤岳辟界阵 | F18: 17
A19: 定魄符 | B19: 18 | F19: 18
A20: 霜锁九脉 | B20: 19 | F20: 19
A21: 砺锋诀 | B21: 20 | F21: 20
A22: 玄炁贯灵 | B22: 21 | F22: 21
A23: 破甲印 | B23: 22 | F23: 22
A24: 蚀法咒 | B24: 23 | F24: 23
A25: 余烬侵脉 | B25: 24 | F25: 24
A26: 离焰周身 | B26: 25 | F26: 25
A27: 玄霜蚀法 | B27: 26 | F27: 26
A28: 坤岳辟界阵 | B28: 27 | F28: 27
A29: 游身九转 | B29: 28 | F29: 28
A30: 离火星·命中 | B30: 29 | F30: 29
... A37: 坤岳辟界阵·光环结算 | B37: 36 | F37: 36
B38: 37 | F38: 37
B39: 38 | F39: 38
B40: 39
B41: 40
B42: 41
B43: 42
B44: 43
B45: 44
B46: 45
B47: 46
B48: 47
B49: 48
B50: 49
...

Sheet 名称表
A1: 施法目标 | C1: 范围类型 | F1: 效果目标 | H1: 特效绑定位置 | J1: 技能效果 | K1: 数据类型 | L1: 介绍 | M1: 状态效果 | N1: 数据类型 | O1: 介绍
A2: 施法目标_自身 | C2: 范围类型_所选目标 | D2: 单体 | F2: 效果目标_所选 | G2: 筛选的所有目标 | H2: BindingPosition | J2: 技能效果_技能增伤 | M2: 状态效果_眩晕 | N2: 不配数据 | O2: 引擎内置（BuffModuleswitch-case，War3未使用（持续时间走配置）
A3: 施法目标_敌对 | C3: 范围类型_目标圆形范围 | D3: 圆形范围 | F3: 效果目标_自身 | G3: 无视筛选，对自身施放 | H3: 脚底 | I3: origin | J3: 技能效果_忽视防御 | K3: 万分比 | M3: 状态效果_石化 | N3: 不配数据 | O3: 引擎内置（同上）未使用
A4: 施法目标_友方 | C4: 范围类型_目标矩形范围 | F4: 效果目标_范围内的敌对 | G4: 筛选的所有敌方目标 | H4: 胸部 | I4: chest | J4: 技能效果_调用技能 | M4: 状态效果_封印 | N4: 不配数据 | O4: 引擎内置（同上）未使用
A5: 施法目标_目标点 | C5: 范围类型_目标扇形范围 | F5: 效果目标_范围内的友方 | G5: 筛选的所有友方目标 | H5: 背部 | I5: rear | J5: 技能效果_调用状态 | M5: 状态效果_中毒 | O5: game层PoisonHandler每DOT
A6: 施法目标_主人 | C6: 范围类型_自身为中心矩形 | F6: 效果目标_目标点 | H6: 头顶上方 | I6: overhead | J6: 技能效果_召唤单位 | M6: 状态效果_火墙 | O6: game层PoisonHandler同上
C7: 范围类型_自身为圆心 | F7: 效果目标_主人 | H7: 头部 | I7: head | J7: 技能效果_弹道 | M7: 状态效果_火墙整数 | O7: game层PoisonHandler同上
F8: 效果目标_范围内的全部 | H8: 手 | I8: hand | J8: 技能效果_冲撞位移 | M8: 状态效果_虚弱 | N8: 万分比 | O8: game层AttrModHandler伤害减少的万分比
F9: 效果目标_范围内的队友 | H9: 左手 | I9: hand left | J9: 技能效果_火环位移 | M9: 状态效果_易伤 | N9: 万分比 | O9: game层AttrModHandler受伤增幅值
F10: 效果目标_范围内的中立 | H10: 右手 | I10: hand right | J10: 技能效果_隔位刺杀 | M10: 状态效果_物防上限整数增加 | N10: 整数 | O10: game层AttrModHandler平坦物防变化量（乘层数）
F11: 效果目标_范围内的敌对怪 | H11: 脚 | I11: foot | J11: 技能效果_被触发 | M11: 状态效果_魔防上限整数增加 | N11: 整数 | O11: game层AttrModHandler平坦魔防变化量（乘层数）
F12: 效果目标_友方生命值最低 | H12: 左脚 | I12: foot left | J12: 技能效果_被动增加准确 | L12: 未实现 | M12: 状态效果_物防上限万分比增加 | N12: 万分比 | O12: game层AttrModHandler基于施法者法术强度的万分比
H13: 右脚 | I13: foot right | J13: 技能效果_无 | L13: 枚举占位，无逻辑— | M13: 状态效果_魔防上限万分比增加 | N13: 万分比 | O13: game层AttrModHandler同上
A14: 施法逻辑 | H14: 武器 | I14: weapon | J14: 技能效果_刺杀近身 | M14: 状态效果_回血 | N14: 整数 | O14: game层HealHandler（瞬时）回复HP量（整数）
A15: 1、通过【施法目标】确定施法目标点(单位) | H15: 精灵绑定点 | I15: sprite | J15: 技能效果_刺杀隔位 | M15: 状态效果_回蓝 | N15: 整数 | O15: game层HealHandler（瞬时）回复MP量（整数）
A16: 2、在目标点以【范围类型】再次进行筛选 | H16: 模型中部 | I16: medium | J16: 技能效果_传送 | L16: 1，2，3分别是回城，随机，指定传送 | M16: 状态效果_治愈术 | N16: 万分比 | O16: game层HealHandler（DOT）施法者法术强度的万分比（每跳）
A17: 3、筛选的所有目标里，对符合【效果目标】的单位确定具体对谁施加（包括数量） | H17: 坐骑 | I17: mount | M17: 状态效果_治愈术整数 | N17: 万分比 | O17: game层HealHandler（DOT）每跳回血量（整数，乘层数）
A18: 3、对符合【效果目标】的单位施加技能效果 | I18: 只配置中文部分，英文是引擎使用，我们只要上面5个挂点，下面黄底色先不管，需要动作全部做一下挂点，这一点上我们具体跟动作同学聊。 | M18: 状态效果_魔法盾系数 | N18: 整数 | O18: game层MagicShieldHandler盾值系数（万分比，基于法力值）
A19: 4、如果【技能效果】是【调用技能B】，则技能B以【每个效果目标】作为【施法目标】(多个效果目标时，技能B会执行多次) | M19: 状态效果_魔法盾吸收伤害 | N19: 不配数据 | O19: game层MagicShieldHandler伤害吸收百分比（万分比）
A20: 5、技能B【跳过逻辑1】【执行逻辑2】 | M20: 状态效果_隐身 | N20: 整数 | O20: game层InvisibleHandler未使用
A21: 6.效果目标选择 效果目标_自身 时，无视前面说的，只对自己施放 | M21: 状态效果_隐身术 | N21: 整数 | O21: game层InvisibleHandler（别名）未使用
A22: 7.被调用的技能一般不需要配置施法目标。 | M22: 状态效果_盾破CD | N22: 整数 | O22: game层ShieldBreakCDHandler未使用（持续时间走配置）
M23: 状态效果_缓慢回血 | N23: 整数 | O23: game层HealHandler（BUFF按配置缓慢回）回复HP量（整数）
M24: 状态效果_缓慢回蓝 | N24: 整数 | O24: game层HealHandler（BUFF按配置缓慢回）回复MP量（整数）
M25: 状态效果_中毒 | N25: 计算自己道术属性，效果值相当于取值以后X万分比，是一个系数。算出来是整数DOT掉血（上面已有）
M26: 状态效果_战士DOT | N26: 计算自己攻击属性，效果值相当于取值以后X万分比，是一个系数。算出来是整数DOT掉血
M27: 状态效果_法师DOT | N27: 计算自己魔法属性，效果值相当于取值以后X万分比，是一个系数。算出来是整数DOT掉血（相当于火墙技能）
M28: 状态效果_攻击万分比
M29: 状态效果_魔法万分比
M30: 状态效果_道术万分比
M31: 状态效果_攻击速度 | O31: ？？
M32: 状态效果_施法速度 | O32: ？？
M33: 状态效果_施法速度 | O33: ？？
M34: 状态效果_物防上限整数降低
M35: 状态效果_魔防上限整数降低
M36: 状态效果_物防上限万分比降低
M37: 状态效果_魔防上限万分比降低
M38: 状态效果_暴击增加
M39: 状态效果_流血战 | N39: 每秒损失攻击力*X%的生命，每秒这个事情通过间隔配置，伤害计算上和前面不一样，攻击力单独算一次，考虑幸运值的情况，从上下限取值
M40: 状态效果_流血法 | N40: 每秒损失魔法*X%的生命，每秒这个事情通过间隔配置，伤害计算上和前面不一样，攻击力单独算一次，考虑幸运值的情况，从上下限取值
...

Sheet Sheet1
M1: skill_class
M3: ClassType
M4: 技能系别
L5: 参数_系别 | M5: 剑道 | N5: =L5&M5 -> 参数_系别剑道 | O5: 1.png = 剑道 | S5: 1.png = 剑道
L6: 参数_系别 | M6: 炼体 | N6: =L6&M6 -> 参数_系别炼体 | O6: 14.png = 炼体 | S6: 2.png = 灵植
L7: 参数_系别 | M7: 金行 | N7: =L7&M7 -> 参数_系别金行 | O7: 8.png = 五行 | S7: 3.png = 灵材
L8: 参数_系别 | M8: 木行 | N8: =L8&M8 -> 参数_系别木行 | O8: 8.png = 五行 | S8: 4.png = 炼丹
L9: 参数_系别 | M9: 水行 | N9: =L9&M9 -> 参数_系别水行 | O9: 8.png = 五行 | S9: 5.png = 炼器
L10: 参数_系别 | M10: 火行 | N10: =L10&M10 -> 参数_系别火行 | O10: 8.png = 五行 | S10: 6.png = 符箓
L11: 参数_系别 | M11: 土行 | N11: =L11&M11 -> 参数_系别土行 | O11: 8.png = 五行 | S11: 7.png = 阵法
L12: 参数_系别 | M12: 术法 | N12: =L12&M12 -> 参数_系别术法 | O12: 13.png = 术法 | S12: 8.png = 五行
L13: 参数_系别 | M13: 灵植 | N13: =L13&M13 -> 参数_系别灵植 | O13: 2.png = 灵植 | S13: 9.png = 御兽
L14: 参数_系别 | M14: 灵材 | N14: =L14&M14 -> 参数_系别灵材 | O14: 3.png = 灵材 | S14: 10.png = 修炼
L15: 参数_系别 | M15: 炼丹 | N15: =L15&M15 -> 参数_系别炼丹 | O15: 4.png = 炼丹 | S15: 11.png = 破境
L16: 参数_系别 | M16: 炼器 | N16: =L16&M16 -> 参数_系别炼器 | O16: 5.png = 炼器 | S16: 12.png = 神识
... L18: 参数_系别 | M18: 阵法 | N18: =L18&M18 -> 参数_系别阵法 | O18: 7.png = 阵法 | S18: 14.png = 炼体
L19: 参数_系别 | M19: 御兽 | N19: =L19&M19 -> 参数_系别御兽 | O19: 9.png = 御兽
L20: 参数_系别 | M20: 修炼 | N20: =L20&M20 -> 参数_系别修炼 | O20: 10.png = 修炼
L21: 参数_系别 | M21: 破境 | N21: =L21&M21 -> 参数_系别破境 | O21: 11.png = 破境
L22: 参数_系别 | M22: 神识 | N22: =L22&M22 -> 参数_系别神识 | O22: 12.png = 神识
L23: 参数_系别 | M23: 五行 | N23: =L23&M23 -> 参数_系别五行 | O23: 8.png = 五行
L24: 参数_系别 | M24: 神通 | N24: =L24&M24 -> 参数_系别神通 | O24: 19
