Workbook

Sheet 灵植表
A1: ##var | B1: seq | C1: id | D1: name | F1: realm | G1: role | H1: quality | I1: element | J1: taste | L1: max_material_count | M1: nval | O1: power | P1: dross | Q1: target_power | R1: price
A2: ##type | B2: int | C2: int | D2: string | F2: MajorRealm | G2: string | H2: string | I2: string | J2: string | L2: int | M2: int | O2: int | P2: int | Q2: int | R2: long
A3: ##group | C3: c,s | D3: c,s | F3: c,s | G3: c,s | H3: c,s | I3: c,s | J3: c,s | K3: 前后台不读策划用 | L3: c,s | M3: c,s | O3: c,s | P3: c,s | Q3: c,s | R3: c,s
A4: ## | B4: 序号 | C4: 灵植ID | D4: 名称[权威在物品表] | E4: 编号ID | F4: 境界 | G4: 分类 | H4: 品质 | I4: 五行[仅臣] | J4: 五味[仅使] | K4: 药势 | L4: 最大承药份数[仅丹头] | M4: 性值 | N4: ID编号用 | O4: 单份药力 | P4: 杂质 | Q4: 目标药力[仅君] | R4: 价格
B5: 1 | C5: =30000000+INDEX(编号表!$B:$B,MATCH(G5,编号表!$A:$A,0))*100000+INDEX(编号表!$F:$F,MATCH(H5,编号表!$E:$E,0))*1000+INDEX(编号表!$D:$D,MATCH(F5,编号表!$C:$C,0))*10000+E5 -> 31221000 | D5: 足年定元参·凡株 | E5: 0 | F5: 筑基 | G5: 君 | H5: 凡品 | L5: 0 | M5: 0 | O5: 2000 | P5: 1100 | Q5: 10000 | R5: 180
B6: 2 | C6: =30000000+INDEX(编号表!$B:$B,MATCH(G6,编号表!$A:$A,0))*100000+INDEX(编号表!$F:$F,MATCH(H6,编号表!$E:$E,0))*1000+INDEX(编号表!$D:$D,MATCH(F6,编号表!$C:$C,0))*10000+E6 -> 31321000 | D6: 足年铁骨藤·凡株 | E6: 0 | F6: 筑基 | G6: 臣 | H6: 凡品 | I6: 金 | L6: 0 | M6: -2 | O6: 1195 | P6: 658 | Q6: 0 | R6: 140
B7: 3 | C7: =30000000+INDEX(编号表!$B:$B,MATCH(G7,编号表!$A:$A,0))*100000+INDEX(编号表!$F:$F,MATCH(H7,编号表!$E:$E,0))*1000+INDEX(编号表!$D:$D,MATCH(F7,编号表!$C:$C,0))*10000+E7 -> 31321001 | D7: 足年金英花·凡株 | E7: 1 | F7: 筑基 | G7: 臣 | H7: 凡品 | I7: 金 | L7: 0 | M7: 3 | O7: 1277 | P7: 869 | Q7: 0 | R7: 180
B8: 4 | C8: =30000000+INDEX(编号表!$B:$B,MATCH(G8,编号表!$A:$A,0))*100000+INDEX(编号表!$F:$F,MATCH(H8,编号表!$E:$E,0))*1000+INDEX(编号表!$D:$D,MATCH(F8,编号表!$C:$C,0))*10000+E8 -> 31321002 | D8: 足年青玉藤·凡株 | E8: 2 | F8: 筑基 | G8: 臣 | H8: 凡品 | I8: 木 | L8: 0 | M8: -1 | O8: 1133 | P8: 408 | Q8: 0 | R8: 195
B9: 5 | C9: =30000000+INDEX(编号表!$B:$B,MATCH(G9,编号表!$A:$A,0))*100000+INDEX(编号表!$F:$F,MATCH(H9,编号表!$E:$E,0))*1000+INDEX(编号表!$D:$D,MATCH(F9,编号表!$C:$C,0))*10000+E9 -> 31321003 | D9: 足年翠叶藤·凡株 | E9: 3 | F9: 筑基 | G9: 臣 | H9: 凡品 | I9: 木 | L9: 0 | M9: 2 | O9: 1195 | P9: 980 | Q9: 0 | R9: 60
B10: 6 | C10: =30000000+INDEX(编号表!$B:$B,MATCH(G10,编号表!$A:$A,0))*100000+INDEX(编号表!$F:$F,MATCH(H10,编号表!$E:$E,0))*1000+INDEX(编号表!$D:$D,MATCH(F10,编号表!$C:$C,0))*10000+E10 -> 31321004 | D10: 足年寒潭藻·凡株 | E10: 4 | F10: 筑基 | G10: 臣 | H10: 凡品 | I10: 水 | L10: 0 | M10: -1 | O10: 1195 | P10: 813 | Q10: 0 | R10: 145
B11: 7 | C11: =30000000+INDEX(编号表!$B:$B,MATCH(G11,编号表!$A:$A,0))*100000+INDEX(编号表!$F:$F,MATCH(H11,编号表!$E:$E,0))*1000+INDEX(编号表!$D:$D,MATCH(F11,编号表!$C:$C,0))*10000+E11 -> 31321005 | D11: 足年沸泉苔·凡株 | E11: 5 | F11: 筑基 | G11: 臣 | H11: 凡品 | I11: 水 | L11: 0 | M11: 4 | O11: 1236 | P11: 1014 | Q11: 0 | R11: 260
B12: 8 | C12: =30000000+INDEX(编号表!$B:$B,MATCH(G12,编号表!$A:$A,0))*100000+INDEX(编号表!$F:$F,MATCH(H12,编号表!$E:$E,0))*1000+INDEX(编号表!$D:$D,MATCH(F12,编号表!$C:$C,0))*10000+E12 -> 31321006 | D12: 足年丹露花·凡株 | E12: 6 | F12: 筑基 | G12: 臣 | H12: 凡品 | I12: 火 | L12: 0 | M12: -1 | O12: 1236 | P12: 347 | Q12: 0 | R12: 420
B13: 9 | C13: =30000000+INDEX(编号表!$B:$B,MATCH(G13,编号表!$A:$A,0))*100000+INDEX(编号表!$F:$F,MATCH(H13,编号表!$E:$E,0))*1000+INDEX(编号表!$D:$D,MATCH(F13,编号表!$C:$C,0))*10000+E13 -> 31321007 | D13: 足年丹炎苔·凡株 | E13: 7 | F13: 筑基 | G13: 臣 | H13: 凡品 | I13: 火 | L13: 0 | M13: 2 | O13: 1195 | P13: 980 | Q13: 0 | R13: 60
B14: 10 | C14: =30000000+INDEX(编号表!$B:$B,MATCH(G14,编号表!$A:$A,0))*100000+INDEX(编号表!$F:$F,MATCH(H14,编号表!$E:$E,0))*1000+INDEX(编号表!$D:$D,MATCH(F14,编号表!$C:$C,0))*10000+E14 -> 31321008 | D14: 足年白岩参·凡株 | E14: 8 | F14: 筑基 | G14: 臣 | H14: 凡品 | I14: 土 | L14: 0 | M14: -2 | O14: 1195 | P14: 658 | Q14: 0 | R14: 140
B15: 11 | C15: =30000000+INDEX(编号表!$B:$B,MATCH(G15,编号表!$A:$A,0))*100000+INDEX(编号表!$F:$F,MATCH(H15,编号表!$E:$E,0))*1000+INDEX(编号表!$D:$D,MATCH(F15,编号表!$C:$C,0))*10000+E15 -> 31321009 | D15: 足年厚元苔·凡株 | E15: 9 | F15: 筑基 | G15: 臣 | H15: 凡品 | I15: 土 | L15: 0 | M15: 1 | O15: 1133 | P15: 408 | Q15: 0 | R15: 195
B16: 12 | C16: =30000000+INDEX(编号表!$B:$B,MATCH(G16,编号表!$A:$A,0))*100000+INDEX(编号表!$F:$F,MATCH(H16,编号表!$E:$E,0))*1000+INDEX(编号表!$D:$D,MATCH(F16,编号表!$C:$C,0))*10000+E16 -> 31521000 | D16: 足年霜辛草·凡株 | E16: 0 | F16: 筑基 | G16: 使 | H16: 凡品 | J16: 辛 | L16: 0 | M16: -2 | O16: 1195 | P16: 658 | Q16: 0 | R16: 140
B17: 13 | C17: =30000000+INDEX(编号表!$B:$B,MATCH(G17,编号表!$A:$A,0))*100000+INDEX(编号表!$F:$F,MATCH(H17,编号表!$E:$E,0))*1000+INDEX(编号表!$D:$D,MATCH(F17,编号表!$C:$C,0))*10000+E17 -> 31521001 | D17: 足年烈香花·凡株 | E17: 1 | F17: 筑基 | G17: 使 | H17: 凡品 | J17: 辛 | L17: 0 | M17: 3 | O17: 1277 | P17: 869 | Q17: 0 | R17: 180
B18: 14 | C18: =30000000+INDEX(编号表!$B:$B,MATCH(G18,编号表!$A:$A,0))*100000+INDEX(编号表!$F:$F,MATCH(H18,编号表!$E:$E,0))*1000+INDEX(编号表!$D:$D,MATCH(F18,编号表!$C:$C,0))*10000+E18 -> 31521002 | D18: 足年甘露草·凡株 | E18: 2 | F18: 筑基 | G18: 使 | H18: 凡品 | J18: 甘 | L18: 0 | M18: -1 | O18: 1133 | P18: 408 | Q18: 0 | R18: 195
B19: 15 | C19: =30000000+INDEX(编号表!$B:$B,MATCH(G19,编号表!$A:$A,0))*100000+INDEX(编号表!$F:$F,MATCH(H19,编号表!$E:$E,0))*1000+INDEX(编号表!$D:$D,MATCH(F19,编号表!$C:$C,0))*10000+E19 -> 31521003 | D19: 足年蜜香果·凡株 | E19: 3 | F19: 筑基 | G19: 使 | H19: 凡品 | J19: 甘 | L19: 0 | M19: 2 | O19: 1195 | P19: 980 | Q19: 0 | R19: 60
B20: 16 | C20: =30000000+INDEX(编号表!$B:$B,MATCH(G20,编号表!$A:$A,0))*100000+INDEX(编号表!$F:$F,MATCH(H20,编号表!$E:$E,0))*1000+INDEX(编号表!$D:$D,MATCH(F20,编号表!$C:$C,0))*10000+E20 -> 31521004 | D20: 足年青梅草·凡株 | E20: 4 | F20: 筑基 | G20: 使 | H20: 凡品 | J20: 酸 | L20: 0 | M20: -1 | O20: 1195 | P20: 813 | Q20: 0 | R20: 145
B21: 17 | C21: =30000000+INDEX(编号表!$B:$B,MATCH(G21,编号表!$A:$A,0))*100000+INDEX(编号表!$F:$F,MATCH(H21,编号表!$E:$E,0))*1000+INDEX(编号表!$D:$D,MATCH(F21,编号表!$C:$C,0))*10000+E21 -> 31521005 | D21: 足年火梅藤·凡株 | E21: 5 | F21: 筑基 | G21: 使 | H21: 凡品 | J21: 酸 | L21: 0 | M21: 4 | O21: 1236 | P21: 1014 | Q21: 0 | R21: 260
B22: 18 | C22: =30000000+INDEX(编号表!$B:$B,MATCH(G22,编号表!$A:$A,0))*100000+INDEX(编号表!$F:$F,MATCH(H22,编号表!$E:$E,0))*1000+INDEX(编号表!$D:$D,MATCH(F22,编号表!$C:$C,0))*10000+E22 -> 31521006 | D22: 足年黄连芽·凡株 | E22: 6 | F22: 筑基 | G22: 使 | H22: 凡品 | J22: 苦 | L22: 0 | M22: -1 | O22: 1236 | P22: 347 | Q22: 0 | R22: 420
B23: 19 | C23: =30000000+INDEX(编号表!$B:$B,MATCH(G23,编号表!$A:$A,0))*100000+INDEX(编号表!$F:$F,MATCH(H23,编号表!$E:$E,0))*1000+INDEX(编号表!$D:$D,MATCH(F23,编号表!$C:$C,0))*10000+E23 -> 31521007 | D23: 足年苦参根·凡株 | E23: 7 | F23: 筑基 | G23: 使 | H23: 凡品 | J23: 苦 | L23: 0 | M23: 2 | O23: 1195 | P23: 980 | Q23: 0 | R23: 60
B24: 20 | C24: =30000000+INDEX(编号表!$B:$B,MATCH(G24,编号表!$A:$A,0))*100000+INDEX(编号表!$F:$F,MATCH(H24,编号表!$E:$E,0))*1000+INDEX(编号表!$D:$D,MATCH(F24,编号表!$C:$C,0))*10000+E24 -> 31521008 | D24: 足年海潮苔·凡株 | E24: 8 | F24: 筑基 | G24: 使 | H24: 凡品 | J24: 咸 | L24: 0 | M24: -2 | O24: 1195 | P24: 658 | Q24: 0 | R24: 140
B25: 21 | C25: =30000000+INDEX(编号表!$B:$B,MATCH(G25,编号表!$A:$A,0))*100000+INDEX(编号表!$F:$F,MATCH(H25,编号表!$E:$E,0))*1000+INDEX(编号表!$D:$D,MATCH(F25,编号表!$C:$C,0))*10000+E25 -> 31521009 | D25: 足年海砂苔·凡株 | E25: 9 | F25: 筑基 | G25: 使 | H25: 凡品 | J25: 咸 | L25: 0 | M25: 1 | O25: 1133 | P25: 408 | Q25: 0 | R25: 195
B26: 22 | C26: =30000000+INDEX(编号表!$B:$B,MATCH(G26,编号表!$A:$A,0))*100000+INDEX(编号表!$F:$F,MATCH(H26,编号表!$E:$E,0))*1000+INDEX(编号表!$D:$D,MATCH(F26,编号表!$C:$C,0))*10000+E26 -> 31421000 | D26: 足年净元草·凡株 | E26: 0 | F26: 筑基 | G26: 佐 | H26: 凡品 | L26: 0 | M26: 0 | O26: 1133 | P26: 318 | Q26: 0 | R26: 230
B27: 23 | C27: =30000000+INDEX(编号表!$B:$B,MATCH(G27,编号表!$A:$A,0))*100000+INDEX(编号表!$F:$F,MATCH(H27,编号表!$E:$E,0))*1000+INDEX(编号表!$D:$D,MATCH(F27,编号表!$C:$C,0))*10000+E27 -> 31421001 | D27: 足年太和草·凡株 | E27: 1 | F27: 筑基 | G27: 佐 | H27: 凡品 | L27: 0 | M27: 0 | O27: 1277 | P27: 1048 | Q27: 0 | R27: 80
B28: 24 | C28: =30000000+INDEX(编号表!$B:$B,MATCH(G28,编号表!$A:$A,0))*100000+INDEX(编号表!$F:$F,MATCH(H28,编号表!$E:$E,0))*1000+INDEX(编号表!$D:$D,MATCH(F28,编号表!$C:$C,0))*10000+E28 -> 31421002 | D28: 足年温脉花·凡株 | E28: 2 | F28: 筑基 | G28: 佐 | H28: 凡品 | L28: 0 | M28: 1 | O28: 1236 | P28: 347 | Q28: 0 | R28: 420
B29: 25 | C29: =30000000+INDEX(编号表!$B:$B,MATCH(G29,编号表!$A:$A,0))*100000+INDEX(编号表!$F:$F,MATCH(H29,编号表!$E:$E,0))*1000+INDEX(编号表!$D:$D,MATCH(F29,编号表!$C:$C,0))*10000+E29 -> 31421003 | D29: 足年烈阳藤·凡株 | E29: 3 | F29: 筑基 | G29: 佐 | H29: 凡品 | L29: 0 | M29: 4 | O29: 1236 | P29: 1014 | Q29: 0 | R29: 260
B30: 26 | C30: =30000000+INDEX(编号表!$B:$B,MATCH(G30,编号表!$A:$A,0))*100000+INDEX(编号表!$F:$F,MATCH(H30,编号表!$E:$E,0))*1000+INDEX(编号表!$D:$D,MATCH(F30,编号表!$C:$C,0))*10000+E30 -> 31621000 | D30: 足年七叶丹莲·凡株 | E30: 0 | F30: 筑基 | G30: 丹头 | H30: 凡品 | L30: 7 | M30: 0 | O30: 0 | P30: 0 | Q30: 0 | R30: 120
B31: 27 | C31: =30000000+INDEX(编号表!$B:$B,MATCH(G31,编号表!$A:$A,0))*100000+INDEX(编号表!$F:$F,MATCH(H31,编号表!$E:$E,0))*1000+INDEX(编号表!$D:$D,MATCH(F31,编号表!$C:$C,0))*10000+E31 -> 31621001 | D31: 足年八脉丹藤·凡株 | E31: 1 | F31: 筑基 | G31: 丹头 | H31: 凡品 | L31: 8 | M31: 0 | O31: 0 | P31: 0 | Q31: 0 | R31: 220
B32: 28 | C32: =30000000+INDEX(编号表!$B:$B,MATCH(G32,编号表!$A:$A,0))*100000+INDEX(编号表!$F:$F,MATCH(H32,编号表!$E:$E,0))*1000+INDEX(编号表!$D:$D,MATCH(F32,编号表!$C:$C,0))*10000+E32 -> 31621002 | D32: 足年九环丹芝·凡株 | E32: 2 | F32: 筑基 | G32: 丹头 | H32: 凡品 | L32: 9 | M32: 0 | O32: 0 | P32: 0 | Q32: 0 | R32: 340
B33: 29 | C33: =30000000+INDEX(编号表!$B:$B,MATCH(G33,编号表!$A:$A,0))*100000+INDEX(编号表!$F:$F,MATCH(H33,编号表!$E:$E,0))*1000+INDEX(编号表!$D:$D,MATCH(F33,编号表!$C:$C,0))*10000+E33 -> 31222000 | D33: 足年定元参·灵株 | E33: 0 | F33: 筑基 | G33: 君 | H33: 灵品 | L33: 0 | M33: 0 | O33: 3600 | P33: 1921 | Q33: 18000 | R33: 324
B34: 30 | C34: =30000000+INDEX(编号表!$B:$B,MATCH(G34,编号表!$A:$A,0))*100000+INDEX(编号表!$F:$F,MATCH(H34,编号表!$E:$E,0))*1000+INDEX(编号表!$D:$D,MATCH(F34,编号表!$C:$C,0))*10000+E34 -> 31322000 | D34: 足年铁骨藤·灵株 | E34: 0 | F34: 筑基 | G34: 臣 | H34: 灵品 | I34: 金 | L34: 0 | M34: -2 | O34: 2151 | P34: 1148 | Q34: 0 | R34: 252
B35: 31 | C35: =30000000+INDEX(编号表!$B:$B,MATCH(G35,编号表!$A:$A,0))*100000+INDEX(编号表!$F:$F,MATCH(H35,编号表!$E:$E,0))*1000+INDEX(编号表!$D:$D,MATCH(F35,编号表!$C:$C,0))*10000+E35 -> 31322001 | D35: 足年金英花·灵株 | E35: 1 | F35: 筑基 | G35: 臣 | H35: 灵品 | I35: 金 | L35: 0 | M35: 3 | O35: 2298 | P35: 1516 | Q35: 0 | R35: 324
B36: 32 | C36: =30000000+INDEX(编号表!$B:$B,MATCH(G36,编号表!$A:$A,0))*100000+INDEX(编号表!$F:$F,MATCH(H36,编号表!$E:$E,0))*1000+INDEX(编号表!$D:$D,MATCH(F36,编号表!$C:$C,0))*10000+E36 -> 31322002 | D36: 足年青玉藤·灵株 | E36: 2 | F36: 筑基 | G36: 臣 | H36: 灵品 | I36: 木 | L36: 0 | M36: -1 | O36: 2039 | P36: 714 | Q36: 0 | R36: 351
B37: 33 | C37: =30000000+INDEX(编号表!$B:$B,MATCH(G37,编号表!$A:$A,0))*100000+INDEX(编号表!$F:$F,MATCH(H37,编号表!$E:$E,0))*1000+INDEX(编号表!$D:$D,MATCH(F37,编号表!$C:$C,0))*10000+E37 -> 31322003 | D37: 足年翠叶藤·灵株 | E37: 3 | F37: 筑基 | G37: 臣 | H37: 灵品 | I37: 木 | L37: 0 | M37: 2 | O37: 2151 | P37: 1712 | Q37: 0 | R37: 108
B38: 34 | C38: =30000000+INDEX(编号表!$B:$B,MATCH(G38,编号表!$A:$A,0))*100000+INDEX(编号表!$F:$F,MATCH(H38,编号表!$E:$E,0))*1000+INDEX(编号表!$D:$D,MATCH(F38,编号表!$C:$C,0))*10000+E38 -> 31322004 | D38: 足年寒潭藻·灵株 | E38: 4 | F38: 筑基 | G38: 臣 | H38: 灵品 | I38: 水 | L38: 0 | M38: -1 | O38: 2151 | P38: 1420 | Q38: 0 | R38: 261
B39: 35 | C39: =30000000+INDEX(编号表!$B:$B,MATCH(G39,编号表!$A:$A,0))*100000+INDEX(编号表!$F:$F,MATCH(H39,编号表!$E:$E,0))*1000+INDEX(编号表!$D:$D,MATCH(F39,编号表!$C:$C,0))*10000+E39 -> 31322005 | D39: 足年沸泉苔·灵株 | E39: 5 | F39: 筑基 | G39: 臣 | H39: 灵品 | I39: 水 | L39: 0 | M39: 4 | O39: 2224 | P39: 1770 | Q39: 0 | R39: 468
B40: 36 | C40: =30000000+INDEX(编号表!$B:$B,MATCH(G40,编号表!$A:$A,0))*100000+INDEX(编号表!$F:$F,MATCH(H40,编号表!$E:$E,0))*1000+INDEX(编号表!$D:$D,MATCH(F40,编号表!$C:$C,0))*10000+E40 -> 31322006 | D40: 足年丹露花·灵株 | E40: 6 | F40: 筑基 | G40: 臣 | H40: 灵品 | I40: 火 | L40: 0 | M40: -1 | O40: 2224 | P40: 605 | Q40: 0 | R40: 756
...

Sheet 计算用
A1: L灵植表 · 炼丹数值生成依据
A2: 项目 | B2: 候选值/公式 | C2: 说明
A3: U基准 | B3: 筑基凡品10000 | C3: 逐境×3，逐品×1.8后向下取整
A4: 君材 | B4: 药力=floor(20%U)；杂质见第14行 | C4: 每境每品一行
A5: 低药力 | B5: 1133bp | C5: 低药力低杂质型
A6: 基准药力 | B6: 1195bp | C6: 基准、易配药性、低药力高杂质型
A7: 高药力 | B7: 1236～1277bp | C7: 极性药性、高药力低杂质、高药力高杂质型
A8: 精品净 | B8: 2200～2999bp；当前点2800bp | C8: 与洁净档不重叠
A9: 洁净 | B9: 3000～4200bp；当前点3600bp | C9: 基础密度；另乘品质纯化系数
A10: 普通 | B10: 4800～6000bp；当前点5500bp | C10: 基础密度；另乘品质纯化系数
A11: 偏脏 | B11: 6200～7400bp；当前点6800bp | C11: 基础密度；另乘品质纯化系数
A12: 高杂 | B12: 7600～9000bp；当前点8200bp | C12: 基础密度；另乘品质纯化系数
A13: 材料药力 | B13: floor(U×药力bp/10000) | C13: 整数
... A20: 顶尖炼制条件 | B20: 最低纯度≥7800采用满技能五档炉口径 | C20: 高品质丹同时提高纯度要求

Sheet 说明
A1: L灵植表 · 第十四步正式价格
A2: 价格 | B2: price由候选价格指数转为正式货币值，数值保持不变。 | C2: 已纳入五类路线期望成本与收益核算。
A3: 数值类型 | B3: price使用long。 | C3: 成本结算使用64位整数。
A4: 状态 | B4: 1176条炼丹相关配置正式。 | C4: 后续仅按联合压测结果回调。
A5: 第六步 | B5: 君材42、丹头126，共168行。 | C5: 丹头容量为7/8/9。
A6: 字段 | B6: ID已使用int；君臣佐使与丹头共用同一表。 | C6: 药势、ID编号用不进入运行时。
A7: 数值配置 | B7: 药力、杂质已按联算结果配置。 | C7: 自由配药可达7份；8/9份丹头提供余量。
A8: 名称 | B8: 沿用原灵植命名素材并按新结构重排。 | C8: 正式显示名仍以物品表为准。
A9: 旧页签 | B9: “灵植数值表”旧机制数据已清除。 | C9: 避免与运行页签形成第二套数值。
A10: 日期 | B10: 2026-09-12 | C10: 炼丹数值配置

Sheet 编号表
A1: 内部名 | B1: 编号 | C1: 境界 | D1: 编号 | E1: 品质 | F1: 编号 | G1: 颜色 | I1: 灵植 | L1: 材位 | M1: 编号 | N1: 主轴 | O1: 编号 | P1: 药性 | Q1: 编号 | R1: 叫法
B2: 1 | C2: 通用 | D2: 0 | E2: 凡品 | F2: 1 | G2: 白色 | L2: 君 | M2: 0 | N2: 甘 | O2: 0 | P2: 4 | Q2: 0 | R2: 极热
B3: 2 | C3: 炼气 | D3: 1 | E3: 灵品 | F3: 2 | G3: 绿色 | L3: 臣 | M3: 1 | N3: 辛 | O3: 1 | P3: 3 | Q3: 1 | R3: 大热
B4: 3 | C4: 筑基 | D4: 2 | E4: 玄品 | F4: 3 | G4: 蓝色 | L4: 佐 | M4: 2 | N4: 咸 | O4: 2 | P4: 2 | Q4: 2 | R4: 热
B5: 4 | C5: 金丹 | D5: 3 | E5: 仙品 | F5: 4 | G5: 紫色 | L5: 使 | M5: 3 | N5: 苦 | O5: 3 | P5: 1 | Q5: 3 | R5: 温
B6: 5 | C6: 元婴 | D6: 4 | E6: 神品 | F6: 5 | G6: 橙色 | L6: 丹头 | M6: 4 | N6: 酸 | O6: 4 | P6: 0 | Q6: 4 | R6: 平
B7: 6 | C7: 化神 | D7: 5 | E7: 道品 | F7: 6 | G7: 红色 | N7: 金 | O7: 0 | P7: -1 | Q7: 5 | R7: 凉
B8: 7 | C8: 炼虚 | D8: 6 | F8: 7 | N8: 木 | O8: 1 | P8: -2 | Q8: 6 | R8: 寒
B9: 8 | C9: 合体 | D9: 7 | F9: 8 | N9: 水 | O9: 2 | P9: -3 | Q9: 7 | R9: 大寒
B10: 9 | C10: 大乘 | D10: 8 | F10: 9 | N10: 火 | O10: 3 | P10: -4 | Q10: 8 | R10: 极寒
B11: 10 | D11: 9 | N11: 土 | O11: 4
B12: 11 | N12: 升 | O12: 0
A13: 君 | B13: 12 | N13: 降 | O13: 1
A14: 臣 | B14: 13 | N14: 浮 | O14: 2
A15: 佐 | B15: 14 | N15: 沉 | O15: 3
A16: 使 | B16: 15 | N16: 守 | O16: 4
A17: 丹头 | B17: 16
B18: 17
B19: 18
B20: 19
E22: 道具ID必须下拉，使用公式自动生成ID！！！
E23: 新物品ID编号计算规则=30000000+@INDEX(编号表!$B:$B,MATCH(C3,编号表!$A:$A,0))*10000+E3
E24: 改动原因：因为现在的道具配置之后，品质有改动的可能，因此暂时把品质对ID的影响取消掉。

Sheet 灵植数值表
A1: 已停用：灵植数值表
A3: 状态 | B3: 旧机制数据已清除 | C3: 不进入运行时
A4: 唯一现行数据 | B4: 灵植表 | C4: 君臣佐使与丹头统一保存
A5: 恢复方式 | B5: 本轮修改前完整工作簿已备份 | C5: 不得从本页复制旧数值回正式表
