Workbook

Sheet item_config
A1: ##var | B1: id | C1: name | D1: quality | H1: dur_t | I1: main_class | J1: sub_class | K1: drop_level | L1: display_type | M1: attrLimit | N1: keep_dur_t | O1: is_drop | P1: is_quick_slot | Q1: is_auto_use | R1: required_level | S1: cultivation_tag | T1: pile_max | U1: function_type | V1: function_id | W1: function_value | X1: desc | Y1: desc1 | Z1: spec_desc | AA1: icon_id | AB1: mdx_id | AC1: light_eff_id | AD1: border1 | AE1: border2 | AF1: decompose_drop_id | AG1: sell_price | AH1: tags | AL1: use_panel_id
A2: ##type | B2: int | C2: string | D2: ItemQuality | H2: int | I2: string | J2: string | K2: int | L2: ItemDisplayType | M2: int | N2: int | O2: bool | P2: bool | Q2: bool | R2: int | S2: string | T2: int | U2: ItemFunctionType | V2: int | W2: int | X2: string | Y2: string | Z2: string | AA2: int | AB2: string | AC2: int | AD2: int | AE2: int | AF2: int | AG2: long | AH2: array,string | AL2: int
A3: ##group | C3: c | Q3: c | X3: c | Y3: c | Z3: c | AA3: c | AB3: c | AC3: c | AD3: c | AE3: c | AF3: c,s | AG3: c,s | AL3: c
A4: ## | B4: 道具ID | C4: 0名称 | D4: 0道具品质 | E4: 境界代码不用 | F4: 0大类 | G4: ID编号 | H4: 存在时间 | I4: 0大类 | J4: 0子类 | K4: 0档次 | L4: 显示分类 | M4: 属性限制 | N4: 有效时间 | O4: 0TRUEFALSE可丢弃 | P4: 是否可进快捷物品栏 | Q4: 是否可以自动使用 | R4: 0使用级别下限 | S4: 修炼标签 | T4: 0堆叠上限 | U4: 0功能类型 | V4: 0功能ID | W4: 0功能数值 | X4: 0说明 | Y4: 说明 | Z4: 0获得说明 | AA4: 0背包图标 | AB4: 0地表模型 | AC4: 掉落光柱模型 | AD4: 静态边框 | AE4: 动态边框 | AF4: 分解掉落方案 | AG4: 售价 | AH4: 标签1 | AI4: 标签2 | AJ4: 标签3 | AK4: 标签4 | AL4: 使用时打开面板编号；0不打开；突破准备面板=1
B5: =10000000+INDEX(编号表!$B:$B,MATCH(F5,编号表!$A:$A,0))*100000+INDEX(编号表!$F:$F,MATCH(D5,编号表!$E:$E,0))*1000+INDEX(编号表!$D:$D,MATCH(E5,编号表!$C:$C,0))*10000+G5 -> 10101000 | C5: 一小袋灵石 | D5: 凡品 | E5: 通用 | F5: 货币 | G5: 0 | H5: 60 | I5: 大类_基础 | J5: 子类_货币 | K5: 1 | L5: 货币 | N5: 0 | O5: FALSE | Q5: FALSE | R5: 1 | S5: 无 | T5: 999 | U5: 功能_加货币 | V5: 1000001 | W5: 50 | X5: ="|cff00FF00"&C5&"，启封后可以获得"&W5&"灵石。" -> |cff00FF00一小袋灵石，启封后可以获得50灵石。 | Y5: |cff00FF00灵石是天地灵气在地脉中经年凝结而成的晶石，也是修士之间通行的货币。玉石般的一枚，内里却藏着可供调用的灵气。修士以之交易，也以之修行；阵禁、炼制与诸般法物，皆可借其中灵气运转。 | Z5: 击杀所有怪物，出售道具装备可获得 | AA5: 10101000 | AB5: 90014 | AC5: 40001 | AE5: 70001 | AH5: 货币 | AI5: 灵石 | AJ5: 通用
B6: =10000000+INDEX(编号表!$B:$B,MATCH(F6,编号表!$A:$A,0))*100000+INDEX(编号表!$F:$F,MATCH(D6,编号表!$E:$E,0))*1000+INDEX(编号表!$D:$D,MATCH(E6,编号表!$C:$C,0))*10000+G6 -> 10101001 | C6: 一小袋仙玉 | D6: 凡品 | E6: 通用 | F6: 货币 | G6: 1 | H6: 60 | I6: 大类_基础 | J6: 子类_货币 | K6: 2 | L6: 货币 | N6: 0 | O6: FALSE | Q6: FALSE | R6: 1 | S6: 无 | T6: 999 | U6: 功能_加货币 | V6: 1000002 | W6: 5 | X6: ="|cff00FF00"&C6&"，启封后可以获得"&W6&"仙玉。" -> |cff00FF00一小袋仙玉，启封后可以获得5仙玉。 | Y6: |cff00FF00仙玉灵华深敛，握之温润，神识探入却似望见深潭，灵气层层蕴于玉中。其力雄厚而绵长，可供宏大阵禁与珍奇法物运转。世间重宝易主时，仙玉亦是修士郑重取出的交易之物。 | Z6: 击杀所有怪物，出售道具装备可获得 | AA6: 10101001 | AB6: 90015 | AC6: 40001 | AE6: 70001 | AH6: 货币 | AI6: 仙玉 | AJ6: 通用
B7: =10000000+INDEX(编号表!$B:$B,MATCH(F7,编号表!$A:$A,0))*100000+INDEX(编号表!$F:$F,MATCH(D7,编号表!$E:$E,0))*1000+INDEX(编号表!$D:$D,MATCH(E7,编号表!$C:$C,0))*10000+G7 -> 10102000 | C7: 一袋灵石 | D7: 灵品 | E7: 通用 | F7: 货币 | G7: 0 | H7: 60 | I7: 大类_基础 | J7: 子类_货币 | K7: 3 | L7: 货币 | N7: 0 | O7: FALSE | Q7: FALSE | R7: 1 | S7: 无 | T7: 999 | U7: 功能_加货币 | V7: 1000001 | W7: 100 | X7: ="|cff00FF00"&C7&"，启封后可以获得"&W7&"灵石。" -> |cff00FF00一袋灵石，启封后可以获得100灵石。 | Y7: |cff00FF00灵石是天地灵气在地脉中经年凝结而成的晶石，也是修士之间通行的货币。玉石般的一枚，内里却藏着可供调用的灵气。修士以之交易，也以之修行；阵禁、炼制与诸般法物，皆可借其中灵气运转。 | Z7: 击杀所有怪物，出售道具装备可获得 | AA7: 10102000 | AB7: 90014 | AC7: 40001 | AE7: 70001 | AH7: 货币 | AI7: 灵石 | AJ7: 通用
B8: =10000000+INDEX(编号表!$B:$B,MATCH(F8,编号表!$A:$A,0))*100000+INDEX(编号表!$F:$F,MATCH(D8,编号表!$E:$E,0))*1000+INDEX(编号表!$D:$D,MATCH(E8,编号表!$C:$C,0))*10000+G8 -> 10102001 | C8: 一袋仙玉 | D8: 灵品 | E8: 通用 | F8: 货币 | G8: 1 | H8: 60 | I8: 大类_基础 | J8: 子类_货币 | K8: 4 | L8: 货币 | N8: 0 | O8: FALSE | Q8: FALSE | R8: 1 | S8: 无 | T8: 999 | U8: 功能_加货币 | V8: 1000002 | W8: 10 | X8: ="|cff00FF00"&C8&"，启封后可以获得"&W8&"仙玉。" -> |cff00FF00一袋仙玉，启封后可以获得10仙玉。 | Y8: |cff00FF00仙玉灵华深敛，握之温润，神识探入却似望见深潭，灵气层层蕴于玉中。其力雄厚而绵长，可供宏大阵禁与珍奇法物运转。世间重宝易主时，仙玉亦是修士郑重取出的交易之物。 | Z8: 击杀所有怪物，出售道具装备可获得 | AA8: 10102001 | AB8: 90015 | AC8: 40001 | AE8: 70001 | AH8: 货币 | AI8: 仙玉 | AJ8: 通用
B9: =10000000+INDEX(编号表!$B:$B,MATCH(F9,编号表!$A:$A,0))*100000+INDEX(编号表!$F:$F,MATCH(D9,编号表!$E:$E,0))*1000+INDEX(编号表!$D:$D,MATCH(E9,编号表!$C:$C,0))*10000+G9 -> 10103000 | C9: 一大袋灵石 | D9: 玄品 | E9: 通用 | F9: 货币 | G9: 0 | H9: 60 | I9: 大类_基础 | J9: 子类_货币 | K9: 5 | L9: 货币 | N9: 0 | O9: FALSE | Q9: FALSE | R9: 1 | S9: 无 | T9: 999 | U9: 功能_加货币 | V9: 1000001 | W9: 500 | X9: ="|cff00FF00"&C9&"，启封后可以获得"&W9&"灵石。" -> |cff00FF00一大袋灵石，启封后可以获得500灵石。 | Y9: |cff00FF00灵石是天地灵气在地脉中经年凝结而成的晶石，也是修士之间通行的货币。玉石般的一枚，内里却藏着可供调用的灵气。修士以之交易，也以之修行；阵禁、炼制与诸般法物，皆可借其中灵气运转。 | Z9: 击杀所有怪物，出售道具装备可获得 | AA9: 10103000 | AB9: 90014 | AC9: 40001 | AE9: 70001 | AH9: 货币 | AI9: 灵石 | AJ9: 通用
B10: =10000000+INDEX(编号表!$B:$B,MATCH(F10,编号表!$A:$A,0))*100000+INDEX(编号表!$F:$F,MATCH(D10,编号表!$E:$E,0))*1000+INDEX(编号表!$D:$D,MATCH(E10,编号表!$C:$C,0))*10000+G10 -> 10103001 | C10: 一大袋仙玉 | D10: 玄品 | E10: 通用 | F10: 货币 | G10: 1 | H10: 60 | I10: 大类_基础 | J10: 子类_货币 | K10: 6 | L10: 货币 | N10: 0 | O10: FALSE | Q10: FALSE | R10: 1 | S10: 无 | T10: 999 | U10: 功能_加货币 | V10: 1000002 | W10: 50 | X10: ="|cff00FF00"&C10&"，启封后可以获得"&W10&"仙玉。" -> |cff00FF00一大袋仙玉，启封后可以获得50仙玉。 | Y10: |cff00FF00仙玉灵华深敛，握之温润，神识探入却似望见深潭，灵气层层蕴于玉中。其力雄厚而绵长，可供宏大阵禁与珍奇法物运转。世间重宝易主时，仙玉亦是修士郑重取出的交易之物。 | Z10: 击杀所有怪物，出售道具装备可获得 | AA10: 10103001 | AB10: 90015 | AC10: 40001 | AE10: 70001 | AH10: 货币 | AI10: 仙玉 | AJ10: 通用
B11: =10000000+INDEX(编号表!$B:$B,MATCH(F11,编号表!$A:$A,0))*100000+INDEX(编号表!$F:$F,MATCH(D11,编号表!$E:$E,0))*1000+INDEX(编号表!$D:$D,MATCH(E11,编号表!$C:$C,0))*10000+G11 -> 10104000 | C11: 一匣灵石 | D11: 仙品 | E11: 通用 | F11: 货币 | G11: 0 | H11: 60 | I11: 大类_基础 | J11: 子类_货币 | K11: 7 | L11: 货币 | N11: 0 | O11: FALSE | Q11: FALSE | R11: 1 | S11: 无 | T11: 999 | U11: 功能_加货币 | V11: 1000001 | W11: 1000 | X11: ="|cff00FF00"&C11&"，启封后可以获得"&W11&"灵石。" -> |cff00FF00一匣灵石，启封后可以获得1000灵石。 | Y11: |cff00FF00灵石是天地灵气在地脉中经年凝结而成的晶石，也是修士之间通行的货币。玉石般的一枚，内里却藏着可供调用的灵气。修士以之交易，也以之修行；阵禁、炼制与诸般法物，皆可借其中灵气运转。 | Z11: 击杀所有怪物，出售道具装备可获得 | AA11: 10104000 | AB11: 90014 | AC11: 40001 | AE11: 70001 | AH11: 货币 | AI11: 灵石 | AJ11: 通用
B12: =10000000+INDEX(编号表!$B:$B,MATCH(F12,编号表!$A:$A,0))*100000+INDEX(编号表!$F:$F,MATCH(D12,编号表!$E:$E,0))*1000+INDEX(编号表!$D:$D,MATCH(E12,编号表!$C:$C,0))*10000+G12 -> 10104001 | C12: 一匣仙玉 | D12: 仙品 | E12: 通用 | F12: 货币 | G12: 1 | H12: 60 | I12: 大类_基础 | J12: 子类_货币 | K12: 8 | L12: 货币 | N12: 0 | O12: FALSE | Q12: FALSE | R12: 1 | S12: 无 | T12: 999 | U12: 功能_加货币 | V12: 1000002 | W12: 100 | X12: ="|cff00FF00"&C12&"，启封后可以获得"&W12&"仙玉。" -> |cff00FF00一匣仙玉，启封后可以获得100仙玉。 | Y12: |cff00FF00仙玉灵华深敛，握之温润，神识探入却似望见深潭，灵气层层蕴于玉中。其力雄厚而绵长，可供宏大阵禁与珍奇法物运转。世间重宝易主时，仙玉亦是修士郑重取出的交易之物。 | Z12: 击杀所有怪物，出售道具装备可获得 | AA12: 10104001 | AB12: 90015 | AC12: 40001 | AE12: 70001 | AH12: 货币 | AI12: 仙玉 | AJ12: 通用
B13: =10000000+INDEX(编号表!$B:$B,MATCH(F13,编号表!$A:$A,0))*100000+INDEX(编号表!$F:$F,MATCH(D13,编号表!$E:$E,0))*1000+INDEX(编号表!$D:$D,MATCH(E13,编号表!$C:$C,0))*10000+G13 -> 10105000 | C13: 一箱灵石 | D13: 神品 | E13: 通用 | F13: 货币 | G13: 0 | H13: 60 | I13: 大类_基础 | J13: 子类_货币 | K13: 9 | L13: 货币 | N13: 0 | O13: FALSE | Q13: FALSE | R13: 1 | S13: 无 | T13: 999 | U13: 功能_加货币 | V13: 1000001 | W13: 5000 | X13: ="|cff00FF00"&C13&"，启封后可以获得"&W13&"灵石。" -> |cff00FF00一箱灵石，启封后可以获得5000灵石。 | Y13: |cff00FF00灵石是天地灵气在地脉中经年凝结而成的晶石，也是修士之间通行的货币。玉石般的一枚，内里却藏着可供调用的灵气。修士以之交易，也以之修行；阵禁、炼制与诸般法物，皆可借其中灵气运转。 | Z13: 击杀所有怪物，出售道具装备可获得 | AA13: 10105000 | AB13: 90014 | AC13: 40001 | AE13: 70001 | AH13: 货币 | AI13: 灵石 | AJ13: 通用
B14: =10000000+INDEX(编号表!$B:$B,MATCH(F14,编号表!$A:$A,0))*100000+INDEX(编号表!$F:$F,MATCH(D14,编号表!$E:$E,0))*1000+INDEX(编号表!$D:$D,MATCH(E14,编号表!$C:$C,0))*10000+G14 -> 10105001 | C14: 一箱仙玉 | D14: 神品 | E14: 通用 | F14: 货币 | G14: 1 | H14: 60 | I14: 大类_基础 | J14: 子类_货币 | K14: 10 | L14: 货币 | N14: 0 | O14: FALSE | Q14: FALSE | R14: 1 | S14: 无 | T14: 999 | U14: 功能_加货币 | V14: 1000002 | W14: 500 | X14: ="|cff00FF00"&C14&"，启封后可以获得"&W14&"仙玉。" -> |cff00FF00一箱仙玉，启封后可以获得500仙玉。 | Y14: |cff00FF00仙玉灵华深敛，握之温润，神识探入却似望见深潭，灵气层层蕴于玉中。其力雄厚而绵长，可供宏大阵禁与珍奇法物运转。世间重宝易主时，仙玉亦是修士郑重取出的交易之物。 | Z14: 击杀所有怪物，出售道具装备可获得 | AA14: 10105001 | AB14: 90015 | AC14: 40001 | AE14: 70001 | AH14: 货币 | AI14: 仙玉 | AJ14: 通用
B15: =10000000+INDEX(编号表!$B:$B,MATCH(F15,编号表!$A:$A,0))*100000+INDEX(编号表!$F:$F,MATCH(D15,编号表!$E:$E,0))*1000+INDEX(编号表!$D:$D,MATCH(E15,编号表!$C:$C,0))*10000+G15 -> 10106000 | C15: 一大箱灵石 | D15: 道品 | E15: 通用 | F15: 货币 | G15: 0 | H15: 60 | I15: 大类_基础 | J15: 子类_货币 | K15: 11 | L15: 货币 | N15: 0 | O15: FALSE | Q15: FALSE | R15: 1 | S15: 无 | T15: 999 | U15: 功能_加货币 | V15: 1000001 | W15: 10000 | X15: ="|cff00FF00"&C15&"，启封后可以获得"&W15&"灵石。" -> |cff00FF00一大箱灵石，启封后可以获得10000灵石。 | Y15: |cff00FF00灵石是天地灵气在地脉中经年凝结而成的晶石，也是修士之间通行的货币。玉石般的一枚，内里却藏着可供调用的灵气。修士以之交易，也以之修行；阵禁、炼制与诸般法物，皆可借其中灵气运转。 | Z15: 击杀所有怪物，出售道具装备可获得 | AA15: 10106000 | AB15: 90014 | AC15: 40001 | AE15: 70001 | AH15: 货币 | AI15: 灵石 | AJ15: 通用
B16: =10000000+INDEX(编号表!$B:$B,MATCH(F16,编号表!$A:$A,0))*100000+INDEX(编号表!$F:$F,MATCH(D16,编号表!$E:$E,0))*1000+INDEX(编号表!$D:$D,MATCH(E16,编号表!$C:$C,0))*10000+G16 -> 10106001 | C16: 一大箱仙玉 | D16: 道品 | E16: 通用 | F16: 货币 | G16: 1 | H16: 60 | I16: 大类_基础 | J16: 子类_货币 | K16: 12 | L16: 货币 | N16: 0 | O16: FALSE | Q16: FALSE | R16: 1 | S16: 无 | T16: 999 | U16: 功能_加货币 | V16: 1000002 | W16: 1000 | X16: ="|cff00FF00"&C16&"，启封后可以获得"&W16&"仙玉。" -> |cff00FF00一大箱仙玉，启封后可以获得1000仙玉。 | Y16: |cff00FF00仙玉灵华深敛，握之温润，神识探入却似望见深潭，灵气层层蕴于玉中。其力雄厚而绵长，可供宏大阵禁与珍奇法物运转。世间重宝易主时，仙玉亦是修士郑重取出的交易之物。 | Z16: 击杀所有怪物，出售道具装备可获得 | AA16: 10106001 | AB16: 90015 | AC16: 40001 | AE16: 70001 | AH16: 货币 | AI16: 仙玉 | AJ16: 通用
B17: =10000000+INDEX(编号表!$B:$B,MATCH(F17,编号表!$A:$A,0))*100000+INDEX(编号表!$F:$F,MATCH(D17,编号表!$E:$E,0))*1000+INDEX(编号表!$D:$D,MATCH(E17,编号表!$C:$C,0))*10000+G17 -> 10106002 | C17: 一储物袋灵石 | D17: 道品 | E17: 通用 | F17: 货币 | G17: 2 | H17: 60 | I17: 大类_基础 | J17: 子类_货币 | K17: 13 | L17: 货币 | N17: 0 | O17: FALSE | Q17: FALSE | R17: 1 | S17: 无 | T17: 999 | U17: 功能_加货币 | V17: 1000001 | W17: 50000 | X17: ="|cff00FF00"&C17&"，启封后可以获得"&W17&"灵石。" -> |cff00FF00一储物袋灵石，启封后可以获得50000灵石。 | Y17: |cff00FF00灵石是天地灵气在地脉中经年凝结而成的晶石，也是修士之间通行的货币。玉石般的一枚，内里却藏着可供调用的灵气。修士以之交易，也以之修行；阵禁、炼制与诸般法物，皆可借其中灵气运转。 | Z17: 击杀所有怪物，出售道具装备可获得 | AA17: 10106002 | AB17: 90014 | AC17: 40001 | AE17: 70001 | AH17: 货币 | AI17: 灵石 | AJ17: 通用
B18: =10000000+INDEX(编号表!$B:$B,MATCH(F18,编号表!$A:$A,0))*100000+INDEX(编号表!$F:$F,MATCH(D18,编号表!$E:$E,0))*1000+INDEX(编号表!$D:$D,MATCH(E18,编号表!$C:$C,0))*10000+G18 -> 10106003 | C18: 一储物袋仙玉 | D18: 道品 | E18: 通用 | F18: 货币 | G18: 3 | H18: 60 | I18: 大类_基础 | J18: 子类_货币 | K18: 14 | L18: 货币 | N18: 0 | O18: FALSE | Q18: FALSE | R18: 1 | S18: 无 | T18: 999 | U18: 功能_加货币 | V18: 1000002 | W18: 5000 | X18: ="|cff00FF00"&C18&"，启封后可以获得"&W18&"仙玉。" -> |cff00FF00一储物袋仙玉，启封后可以获得5000仙玉。 | Y18: |cff00FF00仙玉灵华深敛，握之温润，神识探入却似望见深潭，灵气层层蕴于玉中。其力雄厚而绵长，可供宏大阵禁与珍奇法物运转。世间重宝易主时，仙玉亦是修士郑重取出的交易之物。 | Z18: 击杀所有怪物，出售道具装备可获得 | AA18: 10106003 | AB18: 90015 | AC18: 40001 | AE18: 70001 | AH18: 货币 | AI18: 仙玉 | AJ18: 通用
B19: =10000000+INDEX(编号表!$B:$B,MATCH(F19,编号表!$A:$A,0))*100000+INDEX(编号表!$F:$F,MATCH(D19,编号表!$E:$E,0))*1000+INDEX(编号表!$D:$D,MATCH(E19,编号表!$C:$C,0))*10000+G19 -> 10104090 | C19: 活跃丹 | D19: 仙品 | E19: 通用 | F19: 货币 | G19: 90 | H19: 60 | I19: 大类_基础 | J19: 子类_货币 | K19: 15 | L19: 货币 | N19: 0 | O19: FALSE | Q19: FALSE | R19: 1 | S19: 无 | T19: 999 | U19: 功能_多效果组 | V19: 50001 | W19: 0 | X19: ="|cff00FF00"&C19&"，打开后可以获得"&W19&"活跃点。" -> |cff00FF00活跃丹，打开后可以获得0活跃点。 | Z19: 系统赠送获得 | AA19: 12421007 | AB19: 0 | AC19: 40004 | AE19: 70004 | AH19: 货币 | AI19: 活跃点 | AJ19: 通用
B20: =10000000+INDEX(编号表!$B:$B,MATCH(F20,编号表!$A:$A,0))*100000+INDEX(编号表!$F:$F,MATCH(D20,编号表!$E:$E,0))*1000+INDEX(编号表!$D:$D,MATCH(E20,编号表!$C:$C,0))*10000+G20 -> 10104091 | C20: 声望丹 | D20: 仙品 | E20: 通用 | F20: 货币 | G20: 91 | H20: 60 | I20: 大类_基础 | J20: 子类_货币 | K20: 16 | L20: 货币 | N20: 0 | O20: FALSE | Q20: FALSE | R20: 1 | S20: 无 | T20: 999 | U20: 功能_多效果组 | V20: 50002 | W20: 0 | X20: ="|cff00FF00"&C20&"，打开后可以获得"&W20&"声望点。" -> |cff00FF00声望丹，打开后可以获得0声望点。 | Z20: 系统赠送获得 | AA20: 12421007 | AB20: 0 | AC20: 40004 | AE20: 70004 | AH20: 货币 | AI20: 声望点 | AJ20: 通用
B21: =10000000+INDEX(编号表!$B:$B,MATCH(F21,编号表!$A:$A,0))*100000+INDEX(编号表!$F:$F,MATCH(D21,编号表!$E:$E,0))*1000+INDEX(编号表!$D:$D,MATCH(E21,编号表!$C:$C,0))*10000+G21 -> 10104092 | C21: 声望丹 | D21: 仙品 | E21: 通用 | F21: 货币 | G21: 92 | H21: 60 | I21: 大类_基础 | J21: 子类_货币 | K21: 17 | L21: 货币 | N21: 0 | O21: FALSE | Q21: FALSE | R21: 1 | S21: 无 | T21: 999 | U21: 功能_多效果组 | V21: 50002 | W21: 0 | X21: ="|cff00FF00"&C21&"，打开后可以获得"&W21&"声望点。" -> |cff00FF00声望丹，打开后可以获得0声望点。 | Z21: 系统赠送获得 | AA21: 12421007 | AB21: 0 | AC21: 40004 | AE21: 70004 | AH21: 货币 | AI21: 声望点 | AJ21: 通用
B22: =10000000+INDEX(编号表!$B:$B,MATCH(F22,编号表!$A:$A,0))*100000+INDEX(编号表!$F:$F,MATCH(D22,编号表!$E:$E,0))*1000+INDEX(编号表!$D:$D,MATCH(E22,编号表!$C:$C,0))*10000+G22 -> 10202000 | C22: 青萍剑诀 | D22: 灵品 | E22: 通用 | F22: 人道神通 | G22: 0 | H22: 60 | I22: ="大类_"&D22&E22&F22 -> 大类_灵品通用人道神通 | J22: 子类_技能书 | K22: 1 | L22: 功法 | N22: 0 | O22: TRUE | Q22: FALSE | R22: 1 | S22: 炼体 | T22: 999 | U22: 功能_技能书 | V22: 100100 | X22: 剑出青萍，疾刺目标，造成物理伤害。剑道诸式皆由此起。 | Y22: |cff00FF00“剑起于青萍之末，一刺一收皆是根基；根基既稳，万般剑式方可由此生发。”——《青萍剑谱》|r | Z22: 宗门兑换，购买，秘境或遗迹可得 | AA22: =B22 -> 10202000 | AB22: 0 | AC22: 0 | AE22: 70002 | AH22: 功法 | AI22: 人道神通 | AJ22: 通用
B23: =10000000+INDEX(编号表!$B:$B,MATCH(F23,编号表!$A:$A,0))*100000+INDEX(编号表!$F:$F,MATCH(D23,编号表!$E:$E,0))*1000+INDEX(编号表!$D:$D,MATCH(E23,编号表!$C:$C,0))*10000+G23 -> 10202001 | C23: 玄门伏虎击 | D23: 灵品 | E23: 通用 | F23: 人道神通 | G23: 1 | H23: 60 | I23: ="大类_"&D23&E23&F23 -> 大类_灵品通用人道神通 | J23: 子类_技能书 | K23: 1 | L23: 功法 | N23: 0 | O23: TRUE | Q23: FALSE | R23: 1 | S23: 炼体 | T23: 999 | U23: 功能_技能书 | V23: 100200 | X23: 凝聚近身劲力猛击目标，造成物理伤害。 | Y23: |cff00FF00“气沉丹田，劲贯双臂；一击伏虎，不恃蛮力而恃整劲。”——《玄门伏虎篇》|r | Z23: 宗门兑换，购买，秘境或遗迹可得 | AA23: =B23 -> 10202001 | AB23: 0 | AC23: 0 | AE23: 70002 | AH23: 功法 | AI23: 人道神通 | AJ23: 通用
B24: =10000000+INDEX(编号表!$B:$B,MATCH(F24,编号表!$A:$A,0))*100000+INDEX(编号表!$F:$F,MATCH(D24,编号表!$E:$E,0))*1000+INDEX(编号表!$D:$D,MATCH(E24,编号表!$C:$C,0))*10000+G24 -> 10202002 | C24: 太白藏锋斩 | D24: 灵品 | E24: 通用 | F24: 人道神通 | G24: 2 | H24: 60 | I24: ="大类_"&D24&E24&F24 -> 大类_灵品通用人道神通 | J24: 子类_技能书 | K24: 1 | L24: 功法 | N24: 0 | O24: TRUE | Q24: FALSE | R24: 1 | S24: 炼体 | T24: 999 | U24: 功能_技能书 | V24: 100300 | X24: 藏锋蓄势，拔刃横扫前方扇形范围，对敌人造成物理伤害。 | Y24: |cff00FF00“剑未出鞘，锋意先藏；一线既明，寒光已过群敌。”——《太白剑藏》|r | Z24: 宗门兑换，购买，秘境或遗迹可得 | AA24: =B24 -> 10202002 | AB24: 0 | AC24: 0 | AE24: 70002 | AH24: 功法 | AI24: 人道神通 | AJ24: 通用
B25: =10000000+INDEX(编号表!$B:$B,MATCH(F25,编号表!$A:$A,0))*100000+INDEX(编号表!$F:$F,MATCH(D25,编号表!$E:$E,0))*1000+INDEX(编号表!$D:$D,MATCH(E25,编号表!$C:$C,0))*10000+G25 -> 10202003 | C25: 玄罡撼岳劲 | D25: 灵品 | E25: 通用 | F25: 人道神通 | G25: 3 | H25: 60 | I25: ="大类_"&D25&E25&F25 -> 大类_灵品通用人道神通 | J25: 子类_技能书 | K25: 1 | L25: 功法 | N25: 0 | O25: TRUE | Q25: FALSE | R25: 1 | S25: 炼体 | T25: 999 | U25: 功能_技能书 | V25: 100400 | X25: 以玄罡重击目标，造成物理伤害并将其击退。 | Y25: |cff00FF00“玄罡聚于一臂，发则如岳移；受劲者退，立地者倾。”——《撼岳玄罡录》|r | Z25: 宗门兑换，购买，秘境或遗迹可得 | AA25: =B25 -> 10202003 | AB25: 0 | AC25: 0 | AE25: 70002 | AH25: 功法 | AI25: 人道神通 | AJ25: 通用
B26: =10000000+INDEX(编号表!$B:$B,MATCH(F26,编号表!$A:$A,0))*100000+INDEX(编号表!$F:$F,MATCH(D26,编号表!$E:$E,0))*1000+INDEX(编号表!$D:$D,MATCH(E26,编号表!$C:$C,0))*10000+G26 -> 10202004 | C26: 庚芒诀 | D26: 灵品 | E26: 通用 | F26: 人道神通 | G26: 4 | H26: 60 | I26: ="大类_"&D26&E26&F26 -> 大类_灵品通用人道神通 | J26: 子类_技能书 | K26: 1 | L26: 功法 | N26: 0 | O26: TRUE | Q26: FALSE | R26: 1 | S26: 金行 | T26: 999 | U26: 功能_技能书 | V26: 100500 | X26: 向前方贯出一道金芒，对路径上的敌人造成法术伤害。 | Y26: |cff00FF00“庚金主肃，炼芒成线；所过之处，邪秽皆分。”——《庚金锐芒诀》|r | Z26: 宗门兑换，购买，秘境或遗迹可得 | AA26: =B26 -> 10202004 | AB26: 0 | AC26: 0 | AE26: 70002 | AH26: 功法 | AI26: 人道神通 | AJ26: 通用
B27: =10000000+INDEX(编号表!$B:$B,MATCH(F27,编号表!$A:$A,0))*100000+INDEX(编号表!$F:$F,MATCH(D27,编号表!$E:$E,0))*1000+INDEX(编号表!$D:$D,MATCH(E27,编号表!$C:$C,0))*10000+G27 -> 10202005 | C27: 青萝引 | D27: 灵品 | E27: 通用 | F27: 人道神通 | G27: 5 | H27: 60 | I27: ="大类_"&D27&E27&F27 -> 大类_灵品通用人道神通 | J27: 子类_技能书 | K27: 1 | L27: 功法 | N27: 0 | O27: TRUE | Q27: FALSE | R27: 1 | S27: 木行 | T27: 999 | U27: 功能_技能书 | V27: 100600 | X27: 引动青萝藤刺穿击目标，造成法术伤害。 | Y27: |cff00FF00“青萝借木气而生，柔可缠枝，锐亦穿石。”——《青萝木引篇》|r | Z27: 宗门兑换，购买，秘境或遗迹可得 | AA27: =B27 -> 10202005 | AB27: 0 | AC27: 0 | AE27: 70002 | AH27: 功法 | AI27: 人道神通 | AJ27: 通用
B28: =10000000+INDEX(编号表!$B:$B,MATCH(F28,编号表!$A:$A,0))*100000+INDEX(编号表!$F:$F,MATCH(D28,编号表!$E:$E,0))*1000+INDEX(编号表!$D:$D,MATCH(E28,编号表!$C:$C,0))*10000+G28 -> 10202006 | C28: 听潮印 | D28: 灵品 | E28: 通用 | F28: 人道神通 | G28: 6 | H28: 60 | I28: ="大类_"&D28&E28&F28 -> 大类_灵品通用人道神通 | J28: 子类_技能书 | K28: 1 | L28: 功法 | N28: 0 | O28: TRUE | Q28: FALSE | R28: 1 | S28: 水行 | T28: 999 | U28: 功能_技能书 | V28: 100700 | X28: 在目标身侧合拢潮纹，造成水行法术伤害。 | Y28: |cff00FF00“潮声未至，水势先合；双纹一闭，万钧同压。”——《沧澜听潮印》|r | Z28: 宗门兑换，购买，秘境或遗迹可得 | AA28: =B28 -> 10202006 | AB28: 0 | AC28: 0 | AE28: 70002 | AH28: 功法 | AI28: 人道神通 | AJ28: 通用
B29: =10000000+INDEX(编号表!$B:$B,MATCH(F29,编号表!$A:$A,0))*100000+INDEX(编号表!$F:$F,MATCH(D29,编号表!$E:$E,0))*1000+INDEX(编号表!$D:$D,MATCH(E29,编号表!$C:$C,0))*10000+G29 -> 10202007 | C29: 离火星 | D29: 灵品 | E29: 通用 | F29: 人道神通 | G29: 7 | H29: 60 | I29: ="大类_"&D29&E29&F29 -> 大类_灵品通用人道神通 | J29: 子类_技能书 | K29: 1 | L29: 功法 | N29: 0 | O29: TRUE | Q29: FALSE | R29: 1 | S29: 火行 | T29: 999 | U29: 功能_技能书 | V29: 100800 | X29: 凝成火球飞向目标，命中后造成法术伤害。 | Y29: |cff00FF00“离火聚则为星，疾行如矢；一星落处，炎意自生。”——《离火星经》|r | Z29: 宗门兑换，购买，秘境或遗迹可得 | AA29: =B29 -> 10202007 | AB29: 0 | AC29: 0 | AE29: 70002 | AH29: 功法 | AI29: 人道神通 | AJ29: 通用
B30: =10000000+INDEX(编号表!$B:$B,MATCH(F30,编号表!$A:$A,0))*100000+INDEX(编号表!$F:$F,MATCH(D30,编号表!$E:$E,0))*1000+INDEX(编号表!$D:$D,MATCH(E30,编号表!$C:$C,0))*10000+G30 -> 10202008 | C30: 凝岳印 | D30: 灵品 | E30: 通用 | F30: 人道神通 | G30: 8 | H30: 60 | I30: ="大类_"&D30&E30&F30 -> 大类_灵品通用人道神通 | J30: 子类_技能书 | K30: 1 | L30: 功法 | N30: 0 | O30: TRUE | Q30: FALSE | R30: 1 | S30: 土行 | T30: 999 | U30: 功能_技能书 | V30: 100900 | X30: 在目标上方凝成土印砸落，造成法术伤害。 | Y30: |cff00FF00“撮土成印，引岳为势；印虽方寸，落若峰倾。”——《坤元凝岳篇》|r | Z30: 宗门兑换，购买，秘境或遗迹可得 | AA30: =B30 -> 10202008 | AB30: 0 | AC30: 0 | AE30: 70002 | AH30: 功法 | AI30: 人道神通 | AJ30: 通用
B31: =10000000+INDEX(编号表!$B:$B,MATCH(F31,编号表!$A:$A,0))*100000+INDEX(编号表!$F:$F,MATCH(D31,编号表!$E:$E,0))*1000+INDEX(编号表!$D:$D,MATCH(E31,编号表!$C:$C,0))*10000+G31 -> 10202009 | C31: 惊蛰落霆 | D31: 灵品 | E31: 通用 | F31: 人道神通 | G31: 9 | H31: 60 | I31: ="大类_"&D31&E31&F31 -> 大类_灵品通用人道神通 | J31: 子类_技能书 | K31: 1 | L31: 功法 | N31: 0 | O31: TRUE | Q31: FALSE | R31: 1 | S31: 通用术法 | T31: 999 | U31: 功能_技能书 | V31: 101000 | X31: 召下一道雷光轰击目标，造成法术伤害。 | Y31: |cff00FF00“惊蛰一响，蛰气尽动；雷从九霄落，邪妄无所藏。”——《震雷惊蛰录》|r | Z31: 宗门兑换，购买，秘境或遗迹可得 | AA31: =B31 -> 10202009 | AB31: 0 | AC31: 0 | AE31: 70002 | AH31: 功法 | AI31: 人道神通 | AJ31: 通用
B32: =10000000+INDEX(编号表!$B:$B,MATCH(F32,编号表!$A:$A,0))*100000+INDEX(编号表!$F:$F,MATCH(D32,编号表!$E:$E,0))*1000+INDEX(编号表!$D:$D,MATCH(E32,编号表!$C:$C,0))*10000+G32 -> 10202010 | C32: 赤霄焚野 | D32: 灵品 | E32: 通用 | F32: 人道神通 | G32: 10 | H32: 60 | I32: ="大类_"&D32&E32&F32 -> 大类_灵品通用人道神通 | J32: 子类_技能书 | K32: 1 | L32: 功法 | N32: 0 | O32: TRUE | Q32: FALSE | R32: 1 | S32: 火行 | T32: 999 | U32: 功能_技能书 | V32: 101100 | X32: 在目标区域铺开火纹，对范围内敌人造成法术伤害。 | Y32: |cff00FF00“赤霄垂焰，火纹布野；一步成阵，八方同燃。”——《赤霄焚野章》|r | Z32: 宗门兑换，购买，秘境或遗迹可得 | AA32: =B32 -> 10202010 | AB32: 0 | AC32: 0 | AE32: 70002 | AH32: 功法 | AI32: 人道神通 | AJ32: 通用
B33: =10000000+INDEX(编号表!$B:$B,MATCH(F33,编号表!$A:$A,0))*100000+INDEX(编号表!$F:$F,MATCH(D33,编号表!$E:$E,0))*1000+INDEX(编号表!$D:$D,MATCH(E33,编号表!$C:$C,0))*10000+G33 -> 10202011 | C33: 御锋诀 | D33: 灵品 | E33: 通用 | F33: 人道神通 | G33: 11 | H33: 60 | I33: ="大类_"&D33&E33&F33 -> 大类_灵品通用人道神通 | J33: 子类_技能书 | K33: 1 | L33: 功法 | N33: 0 | O33: TRUE | Q33: FALSE | R33: 1 | S33: 剑道 | T33: 999 | U33: 功能_技能书 | V33: 101200 | X33: 御使飞剑射向目标，命中后造成物理伤害。 | Y33: |cff00FF00“以神御锋，不劳手引；念至则剑至，锋回而意不散。”——《御锋剑诀》|r | Z33: 宗门兑换，购买，秘境或遗迹可得 | AA33: =B33 -> 10202011 | AB33: 0 | AC33: 0 | AE33: 70002 | AH33: 功法 | AI33: 人道神通 | AJ33: 通用
... B85: =10000000+INDEX(编号表!$B:$B,MATCH(F85,编号表!$A:$A,0))*100000+INDEX(编号表!$F:$F,MATCH(D85,编号表!$E:$E,0))*1000+INDEX(编号表!$D:$D,MATCH(E85,编号表!$C:$C,0))*10000+G85 -> 10902028 | C85: 万灵御心诀 | D85: 灵品 | E85: 通用 | F85: 天道神通 | G85: 28 | H85: 60 | I85: ="大类_"&D85&E85&F85 -> 大类_灵品通用天道神通 | J85: 子类_技能书 | K85: 1 | L85: 功法 | N85: 0 | O85: TRUE | Q85: FALSE | R85: 7 | S85: 法修 | T85: 999 | U85: 功能_技能书 | V85: 108500 | X85: 提高所有御兽类技能的效果。 | Y85: |cff00FF00“御兽先通其心，后御其力；强压得用一时，感应方可同行久远。”——《万灵感应录》|r | Z85: 宗门兑换，购买，秘境或遗迹可得 | AA85: =B85 -> 10902028 | AB85: 0 | AC85: 0 | AE85: 70002 | AH85: 功法 | AI85: 天道神通 | AJ85: 通用
B86: =10000000+INDEX(编号表!$B:$B,MATCH(F86,编号表!$A:$A,0))*100000+INDEX(编号表!$F:$F,MATCH(D86,编号表!$E:$E,0))*1000+INDEX(编号表!$D:$D,MATCH(E86,编号表!$C:$C,0))*10000+G86 -> 11721000 | C86: 青烟炉 | D86: 凡品 | E86: 筑基 | F86: 丹炉 | G86: 0 | H86: 60 | I86: ="大类_"&D86&E86&F86 -> 大类_凡品筑基丹炉 | J86: 子类_贵重品 | K86: 1 | L86: 炼丹 | N86: 0 | O86: TRUE | Q86: FALSE | R86: 1 | S86: 无 | T86: 999 | U86: 功能_丹炉 | V86: 1721000 | X86: 青烟袅袅，炉火徐徐。炼丹所用之炉，可承载药材与丹液，供修士掌火炼药。 | Z86: 宗门兑换，购买，秘境或遗迹可得 | AA86: 12421007 | AB86: 0 | AC86: 0 | AE86: 70001 | AH86: 丹炉 | AI86: 丹炉 | AJ86: 筑基
B87: =10000000+INDEX(编号表!$B:$B,MATCH(F87,编号表!$A:$A,0))*100000+INDEX(编号表!$F:$F,MATCH(D87,编号表!$E:$E,0))*1000+INDEX(编号表!$D:$D,MATCH(E87,编号表!$C:$C,0))*10000+G87 -> 11722000 | C87: 青烟炉 | D87: 灵品 | E87: 筑基 | F87: 丹炉 | G87: 0 | H87: 60 | I87: ="大类_"&D87&E87&F87 -> 大类_灵品筑基丹炉 | J87: 子类_贵重品 | K87: 1 | L87: 炼丹 | N87: 0 | O87: TRUE | Q87: FALSE | R87: 1 | S87: 无 | T87: 999 | U87: 功能_丹炉 | V87: 1722000 | X87: 青烟袅袅，炉火徐徐。炼丹所用之炉，可承载药材与丹液，供修士掌火炼药。 | Z87: 宗门兑换，购买，秘境或遗迹可得 | AA87: 12421007 | AB87: 0 | AC87: 0 | AE87: 70002 | AH87: 丹炉 | AI87: 丹炉 | AJ87: 筑基
B88: =10000000+INDEX(编号表!$B:$B,MATCH(F88,编号表!$A:$A,0))*100000+INDEX(编号表!$F:$F,MATCH(D88,编号表!$E:$E,0))*1000+INDEX(编号表!$D:$D,MATCH(E88,编号表!$C:$C,0))*10000+G88 -> 11723000 | C88: 青烟炉 | D88: 玄品 | E88: 筑基 | F88: 丹炉 | G88: 0 | H88: 60 | I88: ="大类_"&D88&E88&F88 -> 大类_玄品筑基丹炉 | J88: 子类_贵重品 | K88: 1 | L88: 炼丹 | N88: 0 | O88: TRUE | Q88: FALSE | R88: 1 | S88: 无 | T88: 999 | U88: 功能_丹炉 | V88: 1723000 | X88: 青烟袅袅，炉火徐徐。炼丹所用之炉，可承载药材与丹液，供修士掌火炼药。 | Z88: 宗门兑换，购买，秘境或遗迹可得 | AA88: 12421007 | AB88: 0 | AC88: 0 | AE88: 70003 | AH88: 丹炉 | AI88: 丹炉 | AJ88: 筑基
B89: =10000000+INDEX(编号表!$B:$B,MATCH(F89,编号表!$A:$A,0))*100000+INDEX(编号表!$F:$F,MATCH(D89,编号表!$E:$E,0))*1000+INDEX(编号表!$D:$D,MATCH(E89,编号表!$C:$C,0))*10000+G89 -> 11731000 | C89: 赤霞炉 | D89: 凡品 | E89: 金丹 | F89: 丹炉 | G89: 0 | H89: 60 | I89: ="大类_"&D89&E89&F89 -> 大类_凡品金丹丹炉 | J89: 子类_贵重品 | K89: 1 | L89: 炼丹 | N89: 0 | O89: TRUE | Q89: FALSE | R89: 1 | S89: 无 | T89: 999 | U89: 功能_丹炉 | V89: 1731000 | X89: 炉色如霞，火映铜光。炼丹所用之炉，可承载药材与丹液，供修士掌火炼药。 | Z89: 宗门兑换，购买，秘境或遗迹可得 | AA89: 12421007 | AB89: 0 | AC89: 0 | AE89: 70001 | AH89: 丹炉 | AI89: 丹炉 | AJ89: 金丹
B90: =10000000+INDEX(编号表!$B:$B,MATCH(F90,编号表!$A:$A,0))*100000+INDEX(编号表!$F:$F,MATCH(D90,编号表!$E:$E,0))*1000+INDEX(编号表!$D:$D,MATCH(E90,编号表!$C:$C,0))*10000+G90 -> 11732000 | C90: 赤霞炉 | D90: 灵品 | E90: 金丹 | F90: 丹炉 | G90: 0 | H90: 60 | I90: ="大类_"&D90&E90&F90 -> 大类_灵品金丹丹炉 | J90: 子类_贵重品 | K90: 1 | L90: 炼丹 | N90: 0 | O90: TRUE | Q90: FALSE | R90: 1 | S90: 无 | T90: 999 | U90: 功能_丹炉 | V90: 1732000 | X90: 炉色如霞，火映铜光。炼丹所用之炉，可承载药材与丹液，供修士掌火炼药。 | Z90: 宗门兑换，购买，秘境或遗迹可得 | AA90: 12421007 | AB90: 0 | AC90: 0 | AE90: 70002 | AH90: 丹炉 | AI90: 丹炉 | AJ90: 金丹
B91: =10000000+INDEX(编号表!$B:$B,MATCH(F91,编号表!$A:$A,0))*100000+INDEX(编号表!$F:$F,MATCH(D91,编号表!$E:$E,0))*1000+INDEX(编号表!$D:$D,MATCH(E91,编号表!$C:$C,0))*10000+G91 -> 11733000 | C91: 赤霞炉 | D91: 玄品 | E91: 金丹 | F91: 丹炉 | G91: 0 | H91: 60 | I91: ="大类_"&D91&E91&F91 -> 大类_玄品金丹丹炉 | J91: 子类_贵重品 | K91: 1 | L91: 炼丹 | N91: 0 | O91: TRUE | Q91: FALSE | R91: 1 | S91: 无 | T91: 999 | U91: 功能_丹炉 | V91: 1733000 | X91: 炉色如霞，火映铜光。炼丹所用之炉，可承载药材与丹液，供修士掌火炼药。 | Z91: 宗门兑换，购买，秘境或遗迹可得 | AA91: 12421007 | AB91: 0 | AC91: 0 | AE91: 70003 | AH91: 丹炉 | AI91: 丹炉 | AJ91: 金丹
...

Sheet item_effect_config
A1: ##var | B1: group_id | D1: seq | E1: op | F1: target_id | G1: amount | H1: duration
A2: ##type | B2: int | D2: int | E2: ItemFunctionType | F2: int | G2: int | H2: int
A3: ##group
A4: ## | B4: 0效果组ID | C4: 0组名称 | D4: 0组内序号 | E4: 效果算子 | F4: 0目标ID | G4: 0数量/强度 | H4: 0持续秒数 | I4: 0策划备注
B5: 50001 | C5: 新手礼包 | D5: 1 | E5: 功能_客户端效果 | F5: 0 | G5: 0 | H5: 0 | I5: 播放开箱动画（服务端跳过，客户端自己表现）
B6: 50001 | D6: 2 | E6: 功能_加修为 | F6: 0 | G6: 5000 | H6: 0 | I6: 送 50 点修为（单位 1/100 点）
B7: 50001 | D7: 3 | E7: 功能_技能书 | F7: 10010001 | G7: 0 | H7: 0 | I7: 直接学会「青萍剑诀」
B8: 50002 | C8: 木质宝箱 | D8: 1 | E8: 功能_随机产出 | F8: 40010001 | G8: 3 | H8: 0 | I8: 按 D掉落方案 里的方案抽 3 次，概率在那张表配
B9: 50003 | C9: 回春丹 | D9: 1 | E9: 功能_客户端效果 | F9: 1 | G9: 800 | H9: 10 | I9: 10 秒内共回 800 血；两个参数列服务端不读，客户端自解释
B10: 50003 | D10: 2 | E10: 功能_加修为 | F10: 0 | G10: 2000 | H10: 0 | I10: 附送 20 点修为（这一行才是服务端结算的）

Sheet 编号表
A1: 内部名 | B1: 编号 | C1: 境界 | D1: 编号 | E1: 品质 | F1: 编号 | G1: 颜色 | I1: 从左数起 | M1: 从左数起
A2: 货币 | B2: 1 | C2: 通用 | D2: 0 | E2: 凡品 | F2: 1 | G2: 白色 | I2: 第1位 | J2: 固定为3表示物品 | M2: 第1位 | N2: 固定为3表示物品
A3: 人道神通 | B3: 2 | C3: 炼气 | D3: 1 | E3: 灵品 | F3: 2 | G3: 绿色 | I3: 第2位 | J3: 分大类 | M3: 第2位 | N3: 分大类
A4: 修为 | B4: 3 | C4: 筑基 | D4: 2 | E4: 玄品 | F4: 3 | G4: 蓝色 | I4: 第3位 | M4: 第3位
A5: 强化 | B5: 4 | C5: 金丹 | D5: 3 | E5: 仙品 | F5: 4 | G5: 紫色 | I5: 第4位 | M5: 第4位 | N5: 境界
A6: 药品 | B6: 5 | C6: 元婴 | D6: 4 | E6: 神品 | F6: 5 | G6: 橙色 | I6: 第5位 | J6: 本分类下的序号 | M6: 第5位 | N6: 品质
A7: 任务 | B7: 6 | C7: 化神 | D7: 5 | E7: 道品 | F7: 6 | G7: 红色 | I7: 第6位 | M7: 第6位 | N7: 本分类下的序号
A8: 真意 | B8: 7 | C8: 炼虚 | D8: 6 | F8: 7 | I8: 第7位 | M8: 第7位
A9: 外观 | B9: 8 | C9: 合体 | D9: 7 | F9: 8 | I9: 第8位 | M9: 第8位
A10: 天道神通 | B10: 9 | C10: 大乘 | D10: 8 | F10: 9
A11: 地道神通 | B11: 10 | D11: 9
A12: 人道神通 | B12: 11
A13: 灵植君 | B13: 12
A14: 灵植臣 | B14: 13 | I14: 新物品ID编号计算规则=30000000+@INDEX(编号表!$B:$B,MATCH(C3,编号表!$A:$A,0))*10000+E3
A15: 灵植佐 | B15: 14 | I15: 改动原因：因为现在的道具配置之后，品质有改动的可能，因此暂时把品质对ID的影响取消掉。
A16: 灵植使 | B16: 15
A17: 灵植丹头 | B17: 16
A18: 丹炉 | B18: 17
A19: 丹方 | B19: 18
A20: 丹药 | B20: 19
A21: 道痕 | B21: 20
A22: 阵法 | B22: 21 | G22: 道具ID必须下拉，使用公式自动生成ID！！！
A23: 符箓 | B23: 22
A24: 灵材主材 | B24: 23
A25: 法宝 | B25: 24
A26: 灵材辅材 | B26: 25
A27: 灵材特性 | B27: 26
A28: 成宝核心 | B28: 27
A29: 灵材两用 | B29: 28
B30: 29
B31: 30
B32: 31

Sheet 更新说明
A1: 版本 | B1: 说明
A2: 1.12 | B2: 物品编号从2开头七位改为3开头8位 增加光柱配置
A3: 1.13 | B3: 掉落模型
A4: 1.14 | B4: 新增0显示分类DisplayType纯TIPS上显示用
A5: 1.15 | B5: 更新编号规则，增加颜色对应的品质，对应改物品ID
A6: 1.16 | B6: 更新图标
A7: 1.17 | B7: 新增血药蓝药对应功能ID配置
A8: 1.18 | B8: 新增小极品打造相关道具
A9: 1.19 | B9: 给小极品打造道具配置图标，临时使用
A10: 1.2 | B10: 新增双加药
A11: 1.21 | B11: 新增多种金币和灵符道具，打开获得的数量不同。同时更新道具描述
A12: 1.22 | B12: 更新掉落物，物品ID增加格式，重复显示红色
A13: 1.23 | B13: 新增静态边框和动态边框的配置项
A14: 1.24 | B14: 新增铭文ICON编号和对应掉落物模型，修改34040043为道神纹
A15: 1.25
A16: 1.26 | B16: 编号里新增了一类任务，对应新增的任务物品的大类颜色和序号都改了，对应物品的ID也变了
A17: 1.27 | B17: 对ID规则进行改动，在ID编号的计算中删掉了品质的影响。铭文使用新的ID计算规则计算，其他的老物品ID不变，删掉ID编号规则，直接粘贴老的ID | E17: 新物品ID编号计算规则=30000000+@INDEX(编号表!$B:$B,MATCH(C3,编号表!$A:$A,0))*10000+E3
A18: 1.28 | B18: 新增一类外观道具
A19: 1.29
A20: 1.3
A21: 1.31
A22: 1.32
A23: 1.33
A24: 1.34

Sheet 字段说明
A1: item_effect_config 字段说明
A2: 一行一个效果，同一个 group_id 的多行构成一组。只有 W物品表 里 function_type=功能_多效果组 的物品才需要在这里建组。
A4: 字段 | B4: 类型 | C4: 必填 | D4: 说明
A5: group_id | B5: int | C5: 是 | D5: 效果组 ID。W物品表 的 function_id 指向它。同组多行共用同一个值。建议用 5xxxx 独立号段，避免和物品 ID 混淆。
A6: 组名称 | B6: — | C6: 否 | D6: 辅助列，不导出。写给人看的组名，方便在表里定位。只需在每组第一行填。
A7: seq | B7: int | C7: 是 | D7: 组内序号，从 1 开始、同组内唯一且连续，决定结算顺序。 注意：本项目所有序号/槽位一律从 1 起，0 是「漏填」的哨兵值，填 0 会被判为非法。
A8: op | B8: ItemFunctionType | C8: 是 | D8: 效果算子，填中文别名（见「效果算子对照」）。 与 W物品表 的 function_type 共用同一个枚举——同一个别名在两处含义完全相同，区别只是「写在物品表里」还是「写在效果组里」。 组里不能填「功能_无」和「功能_多效果组」，那两个只在物品表用。
A9: target_id | B9: int | C9: 否 | D9: 目标 ID，含义由 op 决定（技能 ID / 币种 / 物品 ID / 掉落方案 ID）。该算子不需要时填 0。
A10: amount | B10: int | C10: 否 | D10: 数量或强度，含义由 op 决定。不需要时填 0。
A11: duration | B11: int | C11: 否 | D11: 持续秒数，0 = 瞬时。 这是物品表那三列给不了的东西，也是很多物品必须转成效果组的唯一原因。 目前只有「功能_客户端效果」会用到；其余算子填 0。
A12: 策划备注 | B12: — | C12: 否 | D12: 辅助列，不导出。写清楚这一行是干什么的，方便日后 review。
A14: 为什么参数列是 target_id / amount / duration 这种固定三列
A15: 通用做法有两种：一种是「算子 + 变长参数数组」（表达力无限，但完全丢语义，只能运行时校验）；一种是固定宽表（语义清楚，但列名对某些算子不完全贴切）。本表取后者——考虑到你们已经在用中文别名填表，可读性权重更高。 代价是极少数算子会觉得列名不贴切（比如「功能_随机产出」的 amount 其实是「抽几次」），用备注列补充即可。
A17: 随机产出不在这张表里配概率
A18: 宝箱、随机礼包一律用「功能_随机产出」指向 D掉落方案.xlsx 里的方案 ID。那张表已经有「按概率 / 按个数和概率可重复 / 按个数和概率不可重复」三种方式和逐项概率。 所以本表每一行都是必定生效，没有概率列。两套概率语义并存会出严重问题：逐行独立概率表达不了「80% 出 A、20% 出 B」这种互斥，策划照着填会得到「有时两个都出、有时一个都不出」。
A20: 🔴 硬约束：账号共享货币不能和别的效果同组
A21: 账号共享货币写的是账号数据，其余效果写的是角色数据，分属不同的存储聚合，没有共同事务，无法保证一起成功或一起失败。所以一个组里出现「加账号共享货币」时，该组不得再有任何其它行。 直接后果：同时发角色级货币与账号共享货币的双币礼包现在做不了，服务端启动校验会拦。等跨聚合方案落地再放开。
B25: 物品类别 | C25: 品质配置情况 | D25: 说明
B26: 灵植（君、臣、佐、使、丹头） | C26: 六品质齐全 | D26: 28 种灵植，每个境界都有六品质版本
B27: 灵材（主材、辅材、两用、特性） | C27: 六品质齐全 | D27: 在各材料已有的境界内，均有六品质；部分材料只在特定境界出现
B28: 法宝（常规、稀有） | C28: 六品质齐全 | D28: 在各法宝已有的境界内，均有六品质
B29: 丹药 | C29: 每个境界 3 个品质 | D29: 具体是哪三个，随境界变化，见下表
B30: 丹方物品 | C30: 每个境界 1 个品质 | D30: 对应该境界丹药的最低品质，见下表
B31: 符箓 | C31: 每个境界 3 个品质 | D31: 凡品，灵品，玄品
B32: 道痕 | C32: 每种固定一个品质：仙品或神品 | D32: 不同道痕品质不同，不是每种都有两品质版本
B33: 阵法 | C33: 每种固定一个品质：仙品或神品 | D33: 不同阵法品质不同，不是每种都有两品质版本
B34: 人道神通 | C34: 固定灵品 | D34: 当前 1 条
B35: 地道神通 | C35: 固定灵品 | D35: 当前 7 条
B36: 天道神通 | C36: 固定灵品 | D36: 当前 29 条
... B41: 货币类：活跃丹、声望丹 | C41: 固定仙品 | D41: 虽然名称带“丹”，表内归在货币类
B43: 丹药、丹方的具体对应关系：
B45: 境界 | C45: 丹药品质（每种 3 个） | D45: 丹方物品品质（每种 1 个）
B46: 筑基、金丹、元婴 | C46: 凡品、灵品、玄品 | D46: 凡品
B47: 化神、炼虚、合体 | C47: 灵品、玄品、仙品 | D47: 灵品
B48: 大乘 | C48: 玄品、仙品、神品 | D48: 玄品

Sheet 效果算子对照
A1: ItemFunctionType 枚举对照表
A2: 同一个枚举同时用在两处：W物品表.function_type（单效果内联）和 本表.op（多效果组里的一行）。绿底 = 服务端已实现，可以填；灰底 = 已规划但未实现，填了服务端启动会失败。
A4: 填写值（中文别名） | B4: 程序内部名 | C4: 数值 | D4: 含义 | E4: target_id / function_id | F4: amount / function_value | G4: duration | H4: 状态 | I4: 说明
A5: 功能_无 | B5: None | C5: 0 | D5: 不可使用 | E5: 0 | F5: 0 | G5: 0 | H5: ✅ 已实现 | I5: 只用在物品表，效果组里不能填。装备、材料、系统凭证、外观等一切不能通过背包使用的物品都填它。程序对它一律拒绝使用请求——这条兜底是防止装备被误当消耗品删掉，所以拿不准就填它。
A6: 功能_客户端效果 | B6: ClientEffect | C6: 900 | D6: 可使用，效果由客户端表现 | E6: 客户端自定 | F6: 客户端自定 | G6: 客户端自定 | H6: ✅ 已实现 | I6: 回血、回蓝、加 buff、特效、动画……一切服务端不需要参与的效果，全部填这一个。 服务端行为：扣掉数量 → 写物品流水 → 返回成功。客户端收到成功后自己表现。 三个参数列服务端完全不读取、不校验、不解释，客户端按自己的规则用（现有药品 function_id 里的 21xxxxxx 号段保持原样即可，不用迁）。 为什么不给回血/回蓝/加 buff 各配一个值：本作战斗数值是客户端自己算的，服务端连玩家血量都不知道，对这些效果的行为永远是同一个。分开配只会让策划每加一种客户端效果，服务端就得跟着改代码。
A7: 功能_技能书 | B7: SkillBook | C7: 1 | D7: 学技能 | E7: 技能配置行 ID | F7: 0 | G7: 0 | H7: ✅ 已实现 | I7: 服务端会校验技能是否存在、是否已学会、栏位是否已满。已学会的重复使用会被拒绝，道具不扣。
A8: 功能_加货币 | B8: AddCurrency | C8: 2 | D8: 加货币 | E8: 币种：填货币表（系统参数表 ConfigAssets 页签）的 config_id | F8: 数量（正整数） | G8: 0 | H8: ⏳ 未实现 | I8: 等钱包模块做完再开放。注意：货币道具拾取时不直接进钱包，先作为道具占背包格，使用时才入钱包。
A9: 功能_加修为 | B9: AddCult | C9: 3 | D9: 加修为 | E9: 0 | F9: 修为量，单位 1/100 点（填 2000 = 20 点） | G9: 0 | H9: ⏳ 未实现 | I9: 只加修为，不加等级。等级只能由玩家点击突破获得，配置里不开加等级的口子。
A10: 功能_加物品 | B10: AddItem | C10: 4 | D10: 加物品 | E10: 物品 ID | F10: 数量（正整数） | G10: 0 | H10: ⏳ 未实现 | I10: 固定发放某件物品。要随机发放用「功能_随机产出」。背包放不下时整个使用失败、道具不扣，不做部分发放。
A11: 功能_随机产出 | B11: DropRoll | C11: 5 | D11: 随机产出 | E11: D掉落方案 的方案 ID | F11: 抽取次数（0 或 1 都按 1 次） | G11: 0 | H11: ⏳ 未实现 | I11: 宝箱、随机礼包。概率、可否重复、产出条数全在掉落方案里配，这里只填指向哪个方案。
A12: 功能_多效果组 | B12: EffectGroup | C12: 100 | D12: 转到效果组 | E12: 本表的 group_id | F12: 0 | G12: 0 | H12: ⏳ 未实现 | I12: 只用在物品表，效果组里不能填。一个物品要触发多个效果、或某个效果需要持续时间时用。
A14: 填表决策就三步：不能用 → 功能_无；能用但服务端不用管 → 功能_客户端效果；服务端要发东西 / 要改存档 → 查上表找对应值。
A16: 🔴 枚举纪律：任何值一经确定，禁止重排、禁止改含义、禁止复用废弃的值，新增一律追加。配置表和服务端代码是两边独立发布的，重排数值会造成静默串号（比如「学技能」变成「加货币」），而且不报任何错。要废弃某个值，标停用即可，数值永久保留。

Sheet 枚举与注册
A1: 接入步骤：要往三个元表里加什么
A2: 本表建好后还不能导出，需要在 __enums__.xlsx 注册枚举、在 __tables__.xlsx 注册表。以下是要加的确切内容，照抄即可。
A4: 第 1 步 · __enums__.xlsx 追加枚举 ItemFunctionType
A5: 首行填 full_name=ItemFunctionType、flags=False、unique=True、group 留空、comment=物品功能类型；后续行只填右侧的 name / alias / value / comment 四列（与现有 DropType、ItemQuality 的写法一致）。
A7: full_name | B7: flags | C7: unique | D7: group | E7: comment | F7: *items name | G7: alias | H7: value | I7: comment
A8: ItemFunctionType | B8: False | C8: True | D8: 12610 | E8: 物品功能类型 | F8: None | G8: 功能_无 | H8: 0 | I8: 不可使用
A9: 12610 | B9: 12610 | C9: 12610 | D9: 12610 | E9: 12610 | F9: SkillBook | G9: 功能_技能书 | H9: 1 | I9: 学技能
A10: 12610 | B10: 12610 | C10: 12610 | D10: 12610 | E10: 12610 | F10: AddCurrency | G10: 功能_加货币 | H10: 2 | I10: 加货币（未实现）
A11: 12610 | B11: 12610 | C11: 12610 | D11: 12610 | E11: 12610 | F11: AddCult | G11: 功能_加修为 | H11: 3 | I11: 加修为（未实现）
A12: 12610 | B12: 12610 | C12: 12610 | D12: 12610 | E12: 12610 | F12: AddItem | G12: 功能_加物品 | H12: 4 | I12: 加物品（未实现）
A13: 12610 | B13: 12610 | C13: 12610 | D13: 12610 | E13: 12610 | F13: DropRoll | G13: 功能_随机产出 | H13: 5 | I13: 按掉落方案随机产出（未实现）
A14: 12610 | B14: 12610 | C14: 12610 | D14: 12610 | E14: 12610 | F14: EffectGroup | G14: 功能_多效果组 | H14: 100 | I14: 转到 item_effect_config（未实现）
A15: 12610 | B15: 12610 | C15: 12610 | D15: 12610 | E15: 12610 | F15: ClientEffect | G15: 功能_客户端效果 | H15: 900 | I15: 服务端只扣数量返回成功，效果由客户端表现
A17: 第 2 步 · __tables__.xlsx 追加一行
A18: index 留空 + mode=list：本表没有单一主键，服务端加载后自行按 group_id 分组建索引。 group 留空 = 客户端和服务端都导出（客户端要读「功能_客户端效果」那些行，服务端要读其余行）。
A20: full_name | B20: value_type | C20: read_schema_from_file | D20: input | E20: index | F20: mode | G20: group | H20: comment | I20: output
A21: TbItemEffectConfig | B21: ItemEffectConfig | C21: True | D21: item_effect_config@W物品效果表.xlsx | E21: （留空） | F21: list | G21: （留空） | H21: 物品使用效果组 | I21: item_effect_config
A23: 第 3 步 · W物品表.xlsx 把 function_type 列的类型改掉
A24: ##type 行：把 function_type 那一列从 string 改成 ItemFunctionType。function_id / function_value 两列不动。 ⚠ 改完那一刻，现有 167 行里所有 function_type 的值都必须是上面注册过的中文别名，否则导表直接失败。 现存的「货币_某币种」「药品_加血」「系统_铭文」等 21 个自由中文串全都不是合法别名。 最快的过渡办法：整列先批量填「功能_无」，再把确实要能用的几十个物品逐个改成对应别名。
A26: 第 4 步 · 通知服务端
A27: 服务端要同步改判定逻辑：现在是靠「以『药品_』开头就算可使用」这种前缀匹配猜出来的，改成读枚举。这一步之前，新的中文别名服务端认不出来。

Sheet 物品效果更新说明
A1: 更新说明
A3: 日期 | B3: 版本 | C3: 内容
A4: 2026-08-08 | B4: 初版 | C4: 新建 item_effect_config 表，用于「一个物品触发多个效果」的场景。 同时把 W物品表.function_type 从自由中文串改成枚举 ItemFunctionType，两处共用同一个枚举。 改动理由：服务端需要知道「这个物品能不能被使用」，而这个事实现在是靠中文串前缀猜的——策划把某个丹药写成「丹药_解毒」，它就静默变成不可使用，不报错、不告警，玩家点了没反应。
