Workbook

Sheet 装备
A1: ##var | B1: id | C1: name | D1: dur_t | F1: required_level | G1: show_level | H1: equip_part | I1: quality | L1: suit_id | M1: cultivation_tag | N1: illustrated_id | O1: durability | P1: model_id | Q1: textures_id | R1: ground_mx | S1: icon_id | T1: model_icon | U1: model_icon_num | V1: model_icon_x | W1: model_icon_y | X1: model_icon_z | Y1: light_eff | Z1: bag_class | AA1: main_class | AB1: sub_class | AC1: drop_level | AD1: level | AF1: bind_type | AG1: is_store | AH1: is_destroy | AI1: random_type | AJ1: attrs | BN1: skills | BP1: hidden_attribute | BQ1: refine_id | BR1: reinforcement_id | BS1: hidden_affix | BT1: luck_value | BU1: sell_price | BV1: sell_price_id | BW1: rec_price | BX1: rec_price_id | BY1: rec_materials | CC1: des_price | CD1: des_price_id | CE1: des_materials | CI1: border | CJ1: border1 | CK1: tags | CO1: desc | CP1: desc1
A2: ##type | B2: int | C2: string | D2: int | F2: int | G2: MajorRealm | H2: EquipPart | I2: ItemQuality | L2: int | M2: string | N2: int | O2: int | P2: int | Q2: string | R2: int | S2: int | T2: string | U2: int | V2: string | W2: string | X2: string | Y2: int | Z2: string | AA2: string | AB2: string | AC2: string | AD2: int | AF2: string | AG2: bool | AH2: bool | AI2: string | AJ2: array,Attr | BN2: array,int | BP2: int | BQ2: int | BR2: int | BS2: int | BT2: int | BU2: int | BV2: int | BW2: int | BX2: int | BY2: array,RecMaterial | CC2: int | CD2: int | CE2: array,RecMaterial | CI2: int | CJ2: string | CK2: array,string | CO2: string | CP2: string
A3: ##group | C3: c | P3: c | Q3: c | R3: c | S3: c | T3: c | U3: c | V3: c | W3: c | X3: c | Y3: c | CI3: c | CJ3: c | CO3: c | CP3: c
A4: ## | B4: 装备ID | C4: 名称 | D4: 存活时间 | E4: 装备等级区间 | F4: 限制使用等级下限 | G4: 装备阶级 | H4: 装备位 | I4: 颜色 | J4: 序号 | K4: 序号（算） | L4: 套装ID | M4: 修炼标签 | N4: 图鉴暂时没用 | O4: 暂时没用 | P4: 装备模型 | Q4: 贴图 | R4: 地面模型 | S4: 图标 | T4: 模型图标 | U4: 图标序列帧数 | V4: 模型图标X | W4: 模型图标Y | X4: 模型图标Z | Y4: 光柱模型 | Z4: 背包类型 | AA4: 大类 | AB4: 小类 | AC4: 掉落档次 | AD4: 档次 | AE4: 性别限制 | AF4: 绑定类型 | AG4: TRUE否可存入仓库 | AH4: 是FALSE可丢弃 | AI4: 随机类型 | AJ4: 属性名1 | AK4: 属性值 | AL4: 属性名2 | AM4: 属性值 | AN4: 属性名3 | AO4: 属性值 | AP4: 属性名4 | AQ4: 属性值 | AR4: 属性名5 | AS4: 属性值 | AT4: 属性名6 | AU4: 属性值 | AV4: 属性名7 | AW4: 属性值 | AX4: 属性名8 | AY4: 属性值 | AZ4: 属性名9 | BA4: 属性值 | BB4: 属性名10 | BC4: 属性值 | BD4: 属性名11 | BE4: 属性值 | BF4: 属性名12 | BG4: 属性值 | BH4: 属性名13 | BI4: 属性值 | BJ4: 属性名14 | BK4: 属性值 | BL4: 属性名15 | BM4: 属性值 | BN4: 器法1技能行ID | BO4: 器法2技能行ID | BP4: 灵蕴方案ID | BQ4: 炼化方案ID | BR4: 强化方案ID | BS4: 道纹方案ID | BT4: 初始天运值 | BU4: 商店出售价格 | BV4: 卖出货币ID | BW4: 回收出售价格 | BX4: 卖出货币ID | BY4: 卖出1材料ID | BZ4: 材料1数量 | CA4: 卖出2材料ID | CB4: 材料2数量 | CC4: 分解出售价格 | CD4: 卖出货币ID | CE4: 卖出1材料ID | CF4: 卖出1材料数量 | CG4: 卖出2材料ID | CH4: 卖出2材料数量 | CI4: 基础边框 | CJ4: 高级边框 | CK4: 标签1 | CL4: 标签2 | CM4: 标签3 | CN4: 标签4 | CO4: 道具说明正文 | CP4: 道具风味文字 | CQ4: 策划备注（不导出）
B5: =50000000+INDEX(编号表!$D$2:$D$37,MATCH(G5,编号表!$C$2:$C$37,0))*100000+INDEX(编号表!$F$2:$F$24,MATCH(H5,编号表!$E$2:$E$24,0))*1000+INDEX(编号表!$B$2:$B$7,MATCH(I5,编号表!$A$2:$A$7,0))*100+K5 -> 50000100 | C5: 粗铁剑 | D5: 180 | E5: 1-10 | F5: 1 | G5: 炼气 | H5: 武器 | I5: 凡品 | J5: =COUNTIFS($G$5:G5,G5,$H$5:H5,H5,$I$5:I5,I5)-1 -> 0 | K5: 0 | L5: 0 | M5: 剑道 | O5: 5 | R5: 90010 | S5: 15001001 | Y5: 40001 | Z5: 装备 | AA5: 大类_基础装备 | AB5: 小类_A炼气 | AC5: 凡品 | AD5: 1 | AE5: 无 | AF5: 默认 | AG5: TRUE | AH5: FALSE | AI5: 无 | AJ5: 攻击上限 | AK5: 3 | BN5: 0 | BO5: 0 | BP5: 50000100 | BQ5: 50000100 | BR5: 50000100 | BS5: 50000100 | BT5: 0 | BU5: 8 | BV5: 1000001 | CI5: 70001 | CK5: 装备 | CL5: 炼气级 | CM5: 过渡 | CN5: 散件 | CO5: 粗铁剑，剑身经反复锻炼，以锋刃承载攻伐之力。 | CP5: 锋芒初露，先问前路。 | CQ5: 【开发试配】过渡；过渡装备无固定器法。数值、被动与词条均待正式平衡；美术沿用占位。
B6: =50000000+INDEX(编号表!$D$2:$D$37,MATCH(G6,编号表!$C$2:$C$37,0))*100000+INDEX(编号表!$F$2:$F$24,MATCH(H6,编号表!$E$2:$E$24,0))*1000+INDEX(编号表!$B$2:$B$7,MATCH(I6,编号表!$A$2:$A$7,0))*100+K6 -> 50000200 | C6: 精铁剑 | D6: 180 | E6: 1-10 | F6: 1 | G6: 炼气 | H6: 武器 | I6: 灵品 | J6: =COUNTIFS($G$5:G6,G6,$H$5:H6,H6,$I$5:I6,I6)-1 -> 0 | K6: 0 | L6: 0 | M6: 剑道 | O6: 5 | R6: 90010 | S6: 15001001 | Y6: 40002 | Z6: 装备 | AA6: 大类_基础装备 | AB6: 小类_A炼气 | AC6: 灵品 | AD6: 2 | AE6: 无 | AF6: 默认 | AG6: TRUE | AH6: FALSE | AI6: 无 | AJ6: 攻击上限 | AK6: 4 | BN6: 0 | BO6: 0 | BP6: 50000200 | BQ6: 50000200 | BR6: 50000200 | BS6: 50000200 | BT6: 0 | BU6: 24 | BV6: 1000001 | CI6: 70002 | CK6: 装备 | CL6: 炼气级 | CM6: 过渡 | CN6: 散件 | CO6: 精铁剑，剑身经反复锻炼，以锋刃承载攻伐之力。 | CP6: 锋芒初露，先问前路。 | CQ6: 【开发试配】过渡；过渡装备无固定器法。数值、被动与词条均待正式平衡；美术沿用占位。
B7: =50000000+INDEX(编号表!$D$2:$D$37,MATCH(G7,编号表!$C$2:$C$37,0))*100000+INDEX(编号表!$F$2:$F$24,MATCH(H7,编号表!$E$2:$E$24,0))*1000+INDEX(编号表!$B$2:$B$7,MATCH(I7,编号表!$A$2:$A$7,0))*100+K7 -> 50000300 | C7: 清风剑 | D7: 180 | E7: 1-10 | F7: 1 | G7: 炼气 | H7: 武器 | I7: 玄品 | J7: =COUNTIFS($G$5:G7,G7,$H$5:H7,H7,$I$5:I7,I7)-1 -> 0 | K7: 0 | L7: 0 | M7: 剑道 | O7: 5 | R7: 90010 | S7: 15001001 | Y7: 40003 | Z7: 装备 | AA7: 大类_基础装备 | AB7: 小类_A炼气 | AC7: 玄品 | AD7: 3 | AE7: 无 | AF7: 默认 | AG7: TRUE | AH7: FALSE | AI7: 无 | AJ7: 攻击上限 | AK7: 5 | BN7: 11900101 | BO7: 0 | BP7: 50000300 | BQ7: 50000300 | BR7: 50000300 | BS7: 50000300 | BT7: 0 | BU7: 96 | BV7: 1000001 | CI7: 70003 | CK7: 装备 | CL7: 炼气级 | CM7: 主力 | CN7: 散件 | CO7: 清风剑，剑身经反复锻炼，以锋刃承载攻伐之力。 | CP7: 剑意藏锋，出鞘见真。 | CQ7: 【开发试配】主力；器法：养锋·1。数值、被动与词条均待正式平衡；美术沿用占位。
B8: =50000000+INDEX(编号表!$D$2:$D$37,MATCH(G8,编号表!$C$2:$C$37,0))*100000+INDEX(编号表!$F$2:$F$24,MATCH(H8,编号表!$E$2:$E$24,0))*1000+INDEX(编号表!$B$2:$B$7,MATCH(I8,编号表!$A$2:$A$7,0))*100+K8 -> 50000301 | C8: 五气拂尘 | D8: 180 | E8: 1-10 | F8: 1 | G8: 炼气 | H8: 武器 | I8: 玄品 | J8: =COUNTIFS($G$5:G8,G8,$H$5:H8,H8,$I$5:I8,I8)-1 -> 1 | K8: 1 | L8: 0 | M8: 五行 | O8: 5 | R8: 90010 | S8: 15001001 | Y8: 40003 | Z8: 装备 | AA8: 大类_基础装备 | AB8: 小类_A炼气 | AC8: 玄品 | AD8: 3 | AE8: 无 | AF8: 默认 | AG8: TRUE | AH8: FALSE | AI8: 无 | AJ8: 攻击上限 | AK8: 5 | BN8: 11900201 | BO8: 0 | BP8: 50000301 | BQ8: 50000301 | BR8: 50000301 | BS8: 50000301 | BT8: 0 | BU8: 96 | BV8: 1000001 | CI8: 70003 | CK8: 装备 | CL8: 炼气级 | CM8: 主力 | CN8: 散件 | CO8: 五气拂尘，丝缕聚散随心，以器身引导攻伐之力。 | CP8: 尘丝拂尽，灵机自明。 | CQ8: 【开发试配】主力；器法：引灵·1。数值、被动与词条均待正式平衡；美术沿用占位。
B9: =50000000+INDEX(编号表!$D$2:$D$37,MATCH(G9,编号表!$C$2:$C$37,0))*100000+INDEX(编号表!$F$2:$F$24,MATCH(H9,编号表!$E$2:$E$24,0))*1000+INDEX(编号表!$B$2:$B$7,MATCH(I9,编号表!$A$2:$A$7,0))*100+K9 -> 50000400 | C9: 寒星剑 | D9: 180 | E9: 1-10 | F9: 1 | G9: 炼气 | H9: 武器 | I9: 仙品 | J9: =COUNTIFS($G$5:G9,G9,$H$5:H9,H9,$I$5:I9,I9)-1 -> 0 | K9: 0 | L9: 0 | M9: 剑道 | O9: 5 | R9: 90010 | S9: 15001001 | Y9: 40004 | Z9: 装备 | AA9: 大类_基础装备 | AB9: 小类_A炼气 | AC9: 仙品 | AD9: 4 | AE9: 无 | AF9: 默认 | AG9: TRUE | AH9: FALSE | AI9: 无 | AJ9: 攻击上限 | AK9: 6 | BN9: 11900102 | BO9: 0 | BP9: 50000400 | BQ9: 50000400 | BR9: 50000400 | BS9: 50000400 | BT9: 0 | BU9: 480 | BV9: 1000001 | CI9: 70004 | CK9: 装备 | CL9: 炼气级 | CM9: 常规上限 | CN9: 散件 | CO9: 寒星剑，剑身经反复锻炼，以锋刃承载攻伐之力。 | CP9: 剑意藏锋，出鞘见真。 | CQ9: 【开发试配】常规上限；器法：养锋·2。数值、被动与词条均待正式平衡；美术沿用占位。
B10: =50000000+INDEX(编号表!$D$2:$D$37,MATCH(G10,编号表!$C$2:$C$37,0))*100000+INDEX(编号表!$F$2:$F$24,MATCH(H10,编号表!$E$2:$E$24,0))*1000+INDEX(编号表!$B$2:$B$7,MATCH(I10,编号表!$A$2:$A$7,0))*100+K10 -> 50001100 | C10: 铜印 | D10: 180 | E10: 1-10 | F10: 1 | G10: 炼气 | H10: 印绶 | I10: 凡品 | J10: =COUNTIFS($G$5:G10,G10,$H$5:H10,H10,$I$5:I10,I10)-1 -> 0 | K10: 0 | L10: 0 | M10: 通用 | O10: 5 | R10: 90012 | S10: 15001001 | Y10: 40001 | Z10: 装备 | AA10: 大类_基础装备 | AB10: 小类_A炼气 | AC10: 凡品 | AD10: 1 | AE10: 无 | AF10: 默认 | AG10: TRUE | AH10: FALSE | AI10: 无 | AJ10: 攻击上限 | AK10: 1 | AL10: 生命值 | AM10: 1 | AN10: 物防上限 | AO10: 1 | AP10: 法防上限 | AQ10: 2 | AR10: 灵力值 | AS10: 1 | BN10: 0 | BO10: 0 | BP10: 50001100 | BQ10: 50001100 | BR10: 50001100 | BS10: 50001100 | BT10: 0 | BU10: 8 | BV10: 1000001 | CI10: 70001 | CK10: 装备 | CL10: 炼气级 | CM10: 过渡 | CN10: 散件 | CO10: 铜印，印体凝聚灵机，兼顾攻伐与护身。 | CP10: 掌中方寸，亦有沉重。 | CQ10: 【开发试配】过渡；过渡装备无固定器法。数值、被动与词条均待正式平衡；美术沿用占位。
B11: =50000000+INDEX(编号表!$D$2:$D$37,MATCH(G11,编号表!$C$2:$C$37,0))*100000+INDEX(编号表!$F$2:$F$24,MATCH(H11,编号表!$E$2:$E$24,0))*1000+INDEX(编号表!$B$2:$B$7,MATCH(I11,编号表!$A$2:$A$7,0))*100+K11 -> 50001200 | C11: 玄铁印 | D11: 180 | E11: 1-10 | F11: 1 | G11: 炼气 | H11: 印绶 | I11: 灵品 | J11: =COUNTIFS($G$5:G11,G11,$H$5:H11,H11,$I$5:I11,I11)-1 -> 0 | K11: 0 | L11: 0 | M11: 通用 | O11: 5 | R11: 90012 | S11: 15001001 | Y11: 40002 | Z11: 装备 | AA11: 大类_基础装备 | AB11: 小类_A炼气 | AC11: 灵品 | AD11: 2 | AE11: 无 | AF11: 默认 | AG11: TRUE | AH11: FALSE | AI11: 无 | AJ11: 攻击上限 | AK11: 1 | AL11: 生命值 | AM11: 1 | AN11: 物防上限 | AO11: 2 | AP11: 法防上限 | AQ11: 2 | AR11: 灵力值 | AS11: 1 | BN11: 0 | BO11: 0 | BP11: 50001200 | BQ11: 50001200 | BR11: 50001200 | BS11: 50001200 | BT11: 0 | BU11: 24 | BV11: 1000001 | CI11: 70002 | CK11: 装备 | CL11: 炼气级 | CM11: 过渡 | CN11: 散件 | CO11: 玄铁印，印体凝聚灵机，兼顾攻伐与护身。 | CP11: 掌中方寸，亦有沉重。 | CQ11: 【开发试配】过渡；过渡装备无固定器法。数值、被动与词条均待正式平衡；美术沿用占位。
B12: =50000000+INDEX(编号表!$D$2:$D$37,MATCH(G12,编号表!$C$2:$C$37,0))*100000+INDEX(编号表!$F$2:$F$24,MATCH(H12,编号表!$E$2:$E$24,0))*1000+INDEX(编号表!$B$2:$B$7,MATCH(I12,编号表!$A$2:$A$7,0))*100+K12 -> 50001300 | C12: 赤焰印 | D12: 180 | E12: 1-10 | F12: 1 | G12: 炼气 | H12: 印绶 | I12: 玄品 | J12: =COUNTIFS($G$5:G12,G12,$H$5:H12,H12,$I$5:I12,I12)-1 -> 0 | K12: 0 | L12: 0 | M12: 火行 | O12: 5 | R12: 90012 | S12: 15001001 | Y12: 40003 | Z12: 装备 | AA12: 大类_基础装备 | AB12: 小类_A炼气 | AC12: 玄品 | AD12: 3 | AE12: 无 | AF12: 默认 | AG12: TRUE | AH12: FALSE | AI12: 无 | AJ12: 攻击上限 | AK12: 1 | AL12: 生命值 | AM12: 1 | AN12: 物防上限 | AO12: 2 | AP12: 法防上限 | AQ12: 3 | AR12: 灵力值 | AS12: 1 | AT12: 火行增幅 | AU12: 400 | BN12: 11901101 | BO12: 0 | BP12: 50001300 | BQ12: 50001300 | BR12: 50001300 | BS12: 50001300 | BT12: 0 | BU12: 96 | BV12: 1000001 | CI12: 70003 | CK12: 装备 | CL12: 炼气级 | CM12: 主力 | CN12: 散件 | CO12: 赤焰印，印体凝聚灵机，兼顾攻伐与护身，偏重火行伤害。 | CP12: 一印既落，心意自定。 | CQ12: 【开发试配】主力；器法：镇压·1。数值、被动与词条均待正式平衡；美术沿用占位。
B13: =50000000+INDEX(编号表!$D$2:$D$37,MATCH(G13,编号表!$C$2:$C$37,0))*100000+INDEX(编号表!$F$2:$F$24,MATCH(H13,编号表!$E$2:$E$24,0))*1000+INDEX(编号表!$B$2:$B$7,MATCH(I13,编号表!$A$2:$A$7,0))*100+K13 -> 50001301 | C13: 镇岳印 | D13: 180 | E13: 1-10 | F13: 1 | G13: 炼气 | H13: 印绶 | I13: 玄品 | J13: =COUNTIFS($G$5:G13,G13,$H$5:H13,H13,$I$5:I13,I13)-1 -> 1 | K13: 1 | L13: 0 | M13: 土行 | O13: 5 | R13: 90012 | S13: 15001001 | Y13: 40003 | Z13: 装备 | AA13: 大类_基础装备 | AB13: 小类_A炼气 | AC13: 玄品 | AD13: 3 | AE13: 无 | AF13: 默认 | AG13: TRUE | AH13: FALSE | AI13: 无 | AJ13: 攻击上限 | AK13: 1 | AL13: 生命值 | AM13: 1 | AN13: 物防上限 | AO13: 1 | AP13: 法防上限 | AQ13: 3 | AR13: 灵力值 | AS13: 1 | AT13: 土行增幅 | AU13: 400 | BN13: 11901201 | BO13: 0 | BP13: 50001301 | BQ13: 50001301 | BR13: 50001301 | BS13: 50001301 | BT13: 0 | BU13: 96 | BV13: 1000001 | CI13: 70003 | CK13: 装备 | CL13: 炼气级 | CM13: 主力 | CN13: 散件 | CO13: 镇岳印，印体凝聚灵机，兼顾攻伐与护身，偏重土行伤害。 | CP13: 一印既落，心意自定。 | CQ13: 【开发试配】主力；器法：破势·1。数值、被动与词条均待正式平衡；美术沿用占位。
B14: =50000000+INDEX(编号表!$D$2:$D$37,MATCH(G14,编号表!$C$2:$C$37,0))*100000+INDEX(编号表!$F$2:$F$24,MATCH(H14,编号表!$E$2:$E$24,0))*1000+INDEX(编号表!$B$2:$B$7,MATCH(I14,编号表!$A$2:$A$7,0))*100+K14 -> 50001400 | C14: 伏妖印 | D14: 180 | E14: 1-10 | F14: 1 | G14: 炼气 | H14: 印绶 | I14: 仙品 | J14: =COUNTIFS($G$5:G14,G14,$H$5:H14,H14,$I$5:I14,I14)-1 -> 0 | K14: 0 | L14: 0 | M14: 水行 | O14: 5 | R14: 90012 | S14: 15001001 | Y14: 40004 | Z14: 装备 | AA14: 大类_基础装备 | AB14: 小类_A炼气 | AC14: 仙品 | AD14: 4 | AE14: 无 | AF14: 默认 | AG14: TRUE | AH14: FALSE | AI14: 无 | AJ14: 攻击上限 | AK14: 2 | AL14: 生命值 | AM14: 2 | AN14: 物防上限 | AO14: 2 | AP14: 法防上限 | AQ14: 4 | AR14: 灵力值 | AS14: 1 | AT14: 水行增幅 | AU14: 600 | BN14: 11901102 | BO14: 11901702 | BP14: 50001400 | BQ14: 50001400 | BR14: 50001400 | BS14: 50001400 | BT14: 0 | BU14: 480 | BV14: 1000001 | CI14: 70004 | CK14: 装备 | CL14: 炼气级 | CM14: 常规上限 | CN14: 散件 | CO14: 伏妖印，印体凝聚灵机，兼顾攻伐与护身，偏重水行伤害。 | CP14: 山河有形，道心无界。 | CQ14: 【开发试配】常规上限；器法：镇压·2。数值、被动与词条均待正式平衡；美术沿用占位。
B15: =50000000+INDEX(编号表!$D$2:$D$37,MATCH(G15,编号表!$C$2:$C$37,0))*100000+INDEX(编号表!$F$2:$F$24,MATCH(H15,编号表!$E$2:$E$24,0))*1000+INDEX(编号表!$B$2:$B$7,MATCH(I15,编号表!$A$2:$A$7,0))*100+K15 -> 50003100 | C15: 草履 | D15: 180 | E15: 1-10 | F15: 1 | G15: 炼气 | H15: 鞋履 | I15: 凡品 | J15: =COUNTIFS($G$5:G15,G15,$H$5:H15,H15,$I$5:I15,I15)-1 -> 0 | K15: 0 | L15: 0 | M15: 通用 | O15: 5 | R15: 90013 | S15: 15001001 | Y15: 40001 | Z15: 装备 | AA15: 大类_基础装备 | AB15: 小类_A炼气 | AC15: 凡品 | AD15: 1 | AE15: 无 | AF15: 默认 | AG15: TRUE | AH15: FALSE | AI15: 无 | AJ15: 生命值 | AK15: 1 | AL15: 物防上限 | AM15: 1 | AN15: 法防上限 | AO15: 1 | AP15: 灵力值 | AQ15: 1 | BN15: 0 | BO15: 0 | BP15: 50003100 | BQ15: 50003100 | BR15: 50003100 | BS15: 50003100 | BT15: 0 | BU15: 8 | BV15: 1000001 | CI15: 70001 | CK15: 装备 | CL15: 炼气级 | CM15: 过渡 | CN15: 散件 | CO15: 草履，履底纹理稳固，随行护持周身。 | CP15: 尘路虽长，行者不息。 | CQ15: 【开发试配】过渡；过渡装备无固定器法。数值、被动与词条均待正式平衡；美术沿用占位。
B16: =50000000+INDEX(编号表!$D$2:$D$37,MATCH(G16,编号表!$C$2:$C$37,0))*100000+INDEX(编号表!$F$2:$F$24,MATCH(H16,编号表!$E$2:$E$24,0))*1000+INDEX(编号表!$B$2:$B$7,MATCH(I16,编号表!$A$2:$A$7,0))*100+K16 -> 50003200 | C16: 软底履 | D16: 180 | E16: 1-10 | F16: 1 | G16: 炼气 | H16: 鞋履 | I16: 灵品 | J16: =COUNTIFS($G$5:G16,G16,$H$5:H16,H16,$I$5:I16,I16)-1 -> 0 | K16: 0 | L16: 0 | M16: 通用 | O16: 5 | R16: 90013 | S16: 15001001 | Y16: 40002 | Z16: 装备 | AA16: 大类_基础装备 | AB16: 小类_A炼气 | AC16: 灵品 | AD16: 2 | AE16: 无 | AF16: 默认 | AG16: TRUE | AH16: FALSE | AI16: 无 | AJ16: 生命值 | AK16: 1 | AL16: 物防上限 | AM16: 2 | AN16: 法防上限 | AO16: 1 | AP16: 灵力值 | AQ16: 1 | BN16: 0 | BO16: 0 | BP16: 50003200 | BQ16: 50003200 | BR16: 50003200 | BS16: 50003200 | BT16: 0 | BU16: 24 | BV16: 1000001 | CI16: 70002 | CK16: 装备 | CL16: 炼气级 | CM16: 过渡 | CN16: 散件 | CO16: 软底履，履底纹理稳固，随行护持周身。 | CP16: 尘路虽长，行者不息。 | CQ16: 【开发试配】过渡；过渡装备无固定器法。数值、被动与词条均待正式平衡；美术沿用占位。
B17: =50000000+INDEX(编号表!$D$2:$D$37,MATCH(G17,编号表!$C$2:$C$37,0))*100000+INDEX(编号表!$F$2:$F$24,MATCH(H17,编号表!$E$2:$E$24,0))*1000+INDEX(编号表!$B$2:$B$7,MATCH(I17,编号表!$A$2:$A$7,0))*100+K17 -> 50003300 | C17: 逐风履 | D17: 180 | E17: 1-10 | F17: 1 | G17: 炼气 | H17: 鞋履 | I17: 玄品 | J17: =COUNTIFS($G$5:G17,G17,$H$5:H17,H17,$I$5:I17,I17)-1 -> 0 | K17: 0 | L17: 0 | M17: 通用 | O17: 5 | R17: 90013 | S17: 15001001 | Y17: 40003 | Z17: 装备 | AA17: 大类_基础装备 | AB17: 小类_A炼气 | AC17: 玄品 | AD17: 3 | AE17: 无 | AF17: 默认 | AG17: TRUE | AH17: FALSE | AI17: 无 | AJ17: 生命值 | AK17: 1 | AL17: 物防上限 | AM17: 2 | AN17: 法防上限 | AO17: 1 | AP17: 灵力值 | AQ17: 1 | AR17: 移动速度 | AS17: 5 | BN17: 11900401 | BO17: 0 | BP17: 50003300 | BQ17: 50003300 | BR17: 50003300 | BS17: 50003300 | BT17: 0 | BU17: 96 | BV17: 1000001 | CI17: 70003 | CK17: 装备 | CL17: 炼气级 | CM17: 主力 | CN17: 散件 | CO17: 逐风履，履底纹理稳固，随行护持周身。 | CP17: 风在足下，路在云间。 | CQ17: 【开发试配】主力；器法：疾行·1。数值、被动与词条均待正式平衡；美术沿用占位。
B18: =50000000+INDEX(编号表!$D$2:$D$37,MATCH(G18,编号表!$C$2:$C$37,0))*100000+INDEX(编号表!$F$2:$F$24,MATCH(H18,编号表!$E$2:$E$24,0))*1000+INDEX(编号表!$B$2:$B$7,MATCH(I18,编号表!$A$2:$A$7,0))*100+K18 -> 50003301 | C18: 青冥履 | D18: 180 | E18: 1-10 | F18: 1 | G18: 炼气 | H18: 鞋履 | I18: 玄品 | J18: =COUNTIFS($G$5:G18,G18,$H$5:H18,H18,$I$5:I18,I18)-1 -> 1 | K18: 1 | L18: 1 | M18: 通用 | O18: 5 | R18: 90013 | S18: 15001001 | Y18: 40003 | Z18: 装备 | AA18: 大类_基础装备 | AB18: 小类_A炼气 | AC18: 玄品 | AD18: 3 | AE18: 无 | AF18: 默认 | AG18: TRUE | AH18: FALSE | AI18: 无 | AJ18: 生命值 | AK18: 1 | AL18: 物防上限 | AM18: 3 | AN18: 法防上限 | AO18: 1 | AP18: 灵力值 | AQ18: 1 | AR18: 移动速度 | AS18: 5 | AT18: 闪避 | AU18: 200 | BN18: 11900501 | BO18: 0 | BP18: 50003301 | BQ18: 50003301 | BR18: 50003301 | BS18: 50003301 | BT18: 0 | BU18: 96 | BV18: 1000001 | CI18: 70003 | CK18: 装备 | CL18: 炼气级 | CM18: 主力 | CN18: 套装 | CO18: 青冥履，履底纹理稳固，随行护持周身，步履轻灵，利于闪避。 | CP18: 风在足下，路在云间。 | CQ18: 【开发试配】主力；器法：轻灵·1。数值、被动与词条均待正式平衡；美术沿用占位。
B19: =50000000+INDEX(编号表!$D$2:$D$37,MATCH(G19,编号表!$C$2:$C$37,0))*100000+INDEX(编号表!$F$2:$F$24,MATCH(H19,编号表!$E$2:$E$24,0))*1000+INDEX(编号表!$B$2:$B$7,MATCH(I19,编号表!$A$2:$A$7,0))*100+K19 -> 50003400 | C19: 凌波履 | D19: 180 | E19: 1-10 | F19: 1 | G19: 炼气 | H19: 鞋履 | I19: 仙品 | J19: =COUNTIFS($G$5:G19,G19,$H$5:H19,H19,$I$5:I19,I19)-1 -> 0 | K19: 0 | L19: 0 | M19: 通用 | O19: 5 | R19: 90013 | S19: 15001001 | Y19: 40004 | Z19: 装备 | AA19: 大类_基础装备 | AB19: 小类_A炼气 | AC19: 仙品 | AD19: 4 | AE19: 无 | AF19: 默认 | AG19: TRUE | AH19: FALSE | AI19: 无 | AJ19: 生命值 | AK19: 2 | AL19: 物防上限 | AM19: 2 | AN19: 法防上限 | AO19: 1 | AP19: 灵力值 | AQ19: 1 | AR19: 移动速度 | AS19: 8 | BN19: 11900402 | BO19: 0 | BP19: 50003400 | BQ19: 50003400 | BR19: 50003400 | BS19: 50003400 | BT19: 0 | BU19: 480 | BV19: 1000001 | CI19: 70004 | CK19: 装备 | CL19: 炼气级 | CM19: 常规上限 | CN19: 散件 | CO19: 凌波履，履底纹理稳固，随行护持周身。 | CP19: 去留随意，踏月无声。 | CQ19: 【开发试配】常规上限；器法：疾行·2。数值、被动与词条均待正式平衡；美术沿用占位。
B20: =50000000+INDEX(编号表!$D$2:$D$37,MATCH(G20,编号表!$C$2:$C$37,0))*100000+INDEX(编号表!$F$2:$F$24,MATCH(H20,编号表!$E$2:$E$24,0))*1000+INDEX(编号表!$B$2:$B$7,MATCH(I20,编号表!$A$2:$A$7,0))*100+K20 -> 50005100 | C20: 麻布袍 | D20: 180 | E20: 1-10 | F20: 1 | G20: 炼气 | H20: 法袍 | I20: 凡品 | J20: =COUNTIFS($G$5:G20,G20,$H$5:H20,H20,$I$5:I20,I20)-1 -> 0 | K20: 0 | L20: 0 | M20: 通用 | O20: 5 | R20: 90009 | S20: 15001001 | Y20: 40001 | Z20: 装备 | AA20: 大类_基础装备 | AB20: 小类_A炼气 | AC20: 凡品 | AD20: 1 | AE20: 无 | AF20: 默认 | AG20: TRUE | AH20: FALSE | AI20: 无 | AJ20: 生命值 | AK20: 1 | AL20: 物防上限 | AM20: 2 | AN20: 法防上限 | AO20: 1 | AP20: 灵力值 | AQ20: 1 | BN20: 0 | BO20: 0 | BP20: 50005100 | BQ20: 50005100 | BR20: 50005100 | BS20: 50005100 | BT20: 0 | BU20: 8 | BV20: 1000001 | CI20: 70001 | CK20: 装备 | CL20: 炼气级 | CM20: 过渡 | CN20: 散件 | CO20: 麻布袍，袍内灵纹相连，护持周身气机。 | CP20: 粗衣亦可挡风，初心自能御寒。 | CQ20: 【开发试配】过渡；过渡装备无固定器法。数值、被动与词条均待正式平衡；美术沿用占位。
B21: =50000000+INDEX(编号表!$D$2:$D$37,MATCH(G21,编号表!$C$2:$C$37,0))*100000+INDEX(编号表!$F$2:$F$24,MATCH(H21,编号表!$E$2:$E$24,0))*1000+INDEX(编号表!$B$2:$B$7,MATCH(I21,编号表!$A$2:$A$7,0))*100+K21 -> 50005200 | C21: 青布袍 | D21: 180 | E21: 1-10 | F21: 1 | G21: 炼气 | H21: 法袍 | I21: 灵品 | J21: =COUNTIFS($G$5:G21,G21,$H$5:H21,H21,$I$5:I21,I21)-1 -> 0 | K21: 0 | L21: 0 | M21: 通用 | O21: 5 | R21: 90009 | S21: 15001001 | Y21: 40002 | Z21: 装备 | AA21: 大类_基础装备 | AB21: 小类_A炼气 | AC21: 灵品 | AD21: 2 | AE21: 无 | AF21: 默认 | AG21: TRUE | AH21: FALSE | AI21: 无 | AJ21: 生命值 | AK21: 2 | AL21: 物防上限 | AM21: 2 | AN21: 法防上限 | AO21: 2 | AP21: 灵力值 | AQ21: 1 | BN21: 0 | BO21: 0 | BP21: 50005200 | BQ21: 50005200 | BR21: 50005200 | BS21: 50005200 | BT21: 0 | BU21: 24 | BV21: 1000001 | CI21: 70002 | CK21: 装备 | CL21: 炼气级 | CM21: 过渡 | CN21: 散件 | CO21: 青布袍，袍内灵纹相连，护持周身气机。 | CP21: 粗衣亦可挡风，初心自能御寒。 | CQ21: 【开发试配】过渡；过渡装备无固定器法。数值、被动与词条均待正式平衡；美术沿用占位。
B22: =50000000+INDEX(编号表!$D$2:$D$37,MATCH(G22,编号表!$C$2:$C$37,0))*100000+INDEX(编号表!$F$2:$F$24,MATCH(H22,编号表!$E$2:$E$24,0))*1000+INDEX(编号表!$B$2:$B$7,MATCH(I22,编号表!$A$2:$A$7,0))*100+K22 -> 50005300 | C22: 青冥法袍 | D22: 180 | E22: 1-10 | F22: 1 | G22: 炼气 | H22: 法袍 | I22: 玄品 | J22: =COUNTIFS($G$5:G22,G22,$H$5:H22,H22,$I$5:I22,I22)-1 -> 0 | K22: 0 | L22: 1 | M22: 通用 | O22: 5 | R22: 90009 | S22: 15001001 | Y22: 40003 | Z22: 装备 | AA22: 大类_基础装备 | AB22: 小类_A炼气 | AC22: 玄品 | AD22: 3 | AE22: 无 | AF22: 默认 | AG22: TRUE | AH22: FALSE | AI22: 无 | AJ22: 生命值 | AK22: 2 | AL22: 物防上限 | AM22: 3 | AN22: 法防上限 | AO22: 2 | AP22: 灵力值 | AQ22: 1 | BN22: 11900701 | BO22: 0 | BP22: 50005300 | BQ22: 50005300 | BR22: 50005300 | BS22: 50005300 | BT22: 0 | BU22: 96 | BV22: 1000001 | CI22: 70003 | CK22: 装备 | CL22: 炼气级 | CM22: 主力 | CN22: 套装 | CO22: 青冥法袍，袍内灵纹相连，护持周身气机。 | CP22: 一袭护身，静候风雷。 | CQ22: 【开发试配】主力；器法：厚甲·1。数值、被动与词条均待正式平衡；美术沿用占位。
B23: =50000000+INDEX(编号表!$D$2:$D$37,MATCH(G23,编号表!$C$2:$C$37,0))*100000+INDEX(编号表!$F$2:$F$24,MATCH(H23,编号表!$E$2:$E$24,0))*1000+INDEX(编号表!$B$2:$B$7,MATCH(I23,编号表!$A$2:$A$7,0))*100+K23 -> 50005400 | C23: 流云法袍 | D23: 180 | E23: 1-10 | F23: 1 | G23: 炼气 | H23: 法袍 | I23: 仙品 | J23: =COUNTIFS($G$5:G23,G23,$H$5:H23,H23,$I$5:I23,I23)-1 -> 0 | K23: 0 | L23: 0 | M23: 通用 | O23: 5 | R23: 90009 | S23: 15001001 | Y23: 40004 | Z23: 装备 | AA23: 大类_基础装备 | AB23: 小类_A炼气 | AC23: 仙品 | AD23: 4 | AE23: 无 | AF23: 默认 | AG23: TRUE | AH23: FALSE | AI23: 无 | AJ23: 生命值 | AK23: 3 | AL23: 物防上限 | AM23: 4 | AN23: 法防上限 | AO23: 2 | AP23: 灵力值 | AQ23: 1 | BN23: 11900702 | BO23: 0 | BP23: 50005400 | BQ23: 50005400 | BR23: 50005400 | BS23: 50005400 | BT23: 0 | BU23: 480 | BV23: 1000001 | CI23: 70004 | CK23: 装备 | CL23: 炼气级 | CM23: 常规上限 | CN23: 散件 | CO23: 流云法袍，袍内灵纹相连，护持周身气机。 | CP23: 衣纹如水，心定如山。 | CQ23: 【开发试配】常规上限；器法：厚甲·2。数值、被动与词条均待正式平衡；美术沿用占位。
B24: =50000000+INDEX(编号表!$D$2:$D$37,MATCH(G24,编号表!$C$2:$C$37,0))*100000+INDEX(编号表!$F$2:$F$24,MATCH(H24,编号表!$E$2:$E$24,0))*1000+INDEX(编号表!$B$2:$B$7,MATCH(I24,编号表!$A$2:$A$7,0))*100+K24 -> 50006100 | C24: 布巾 | D24: 180 | E24: 1-10 | F24: 1 | G24: 炼气 | H24: 冠 | I24: 凡品 | J24: =COUNTIFS($G$5:G24,G24,$H$5:H24,H24,$I$5:I24,I24)-1 -> 0 | K24: 0 | L24: 0 | M24: 通用 | O24: 5 | R24: 90008 | S24: 15001001 | Y24: 40001 | Z24: 装备 | AA24: 大类_基础装备 | AB24: 小类_A炼气 | AC24: 凡品 | AD24: 1 | AE24: 无 | AF24: 默认 | AG24: TRUE | AH24: FALSE | AI24: 无 | AJ24: 生命值 | AK24: 1 | AL24: 物防上限 | AM24: 1 | AN24: 法防上限 | AO24: 1 | AP24: 灵力值 | AQ24: 1 | BN24: 0 | BO24: 0 | BP24: 50006100 | BQ24: 50006100 | BR24: 50006100 | BS24: 50006100 | BT24: 0 | BU24: 8 | BV24: 1000001 | CI24: 70001 | CK24: 装备 | CL24: 炼气级 | CM24: 过渡 | CN24: 散件 | CO24: 布巾，冠中灵纹清明，护持修士心神。 | CP24: 束发整衣，自此问道。 | CQ24: 【开发试配】过渡；过渡装备无固定器法。数值、被动与词条均待正式平衡；美术沿用占位。
B25: =50000000+INDEX(编号表!$D$2:$D$37,MATCH(G25,编号表!$C$2:$C$37,0))*100000+INDEX(编号表!$F$2:$F$24,MATCH(H25,编号表!$E$2:$E$24,0))*1000+INDEX(编号表!$B$2:$B$7,MATCH(I25,编号表!$A$2:$A$7,0))*100+K25 -> 50006200 | C25: 束发冠 | D25: 180 | E25: 1-10 | F25: 1 | G25: 炼气 | H25: 冠 | I25: 灵品 | J25: =COUNTIFS($G$5:G25,G25,$H$5:H25,H25,$I$5:I25,I25)-1 -> 0 | K25: 0 | L25: 0 | M25: 通用 | O25: 5 | R25: 90008 | S25: 15001001 | Y25: 40002 | Z25: 装备 | AA25: 大类_基础装备 | AB25: 小类_A炼气 | AC25: 灵品 | AD25: 2 | AE25: 无 | AF25: 默认 | AG25: TRUE | AH25: FALSE | AI25: 无 | AJ25: 生命值 | AK25: 1 | AL25: 物防上限 | AM25: 1 | AN25: 法防上限 | AO25: 2 | AP25: 灵力值 | AQ25: 1 | BN25: 0 | BO25: 0 | BP25: 50006200 | BQ25: 50006200 | BR25: 50006200 | BS25: 50006200 | BT25: 0 | BU25: 24 | BV25: 1000001 | CI25: 70002 | CK25: 装备 | CL25: 炼气级 | CM25: 过渡 | CN25: 散件 | CO25: 束发冠，冠中灵纹清明，护持修士心神。 | CP25: 束发整衣，自此问道。 | CQ25: 【开发试配】过渡；过渡装备无固定器法。数值、被动与词条均待正式平衡；美术沿用占位。
B26: =50000000+INDEX(编号表!$D$2:$D$37,MATCH(G26,编号表!$C$2:$C$37,0))*100000+INDEX(编号表!$F$2:$F$24,MATCH(H26,编号表!$E$2:$E$24,0))*1000+INDEX(编号表!$B$2:$B$7,MATCH(I26,编号表!$A$2:$A$7,0))*100+K26 -> 50006300 | C26: 青冥冠 | D26: 180 | E26: 1-10 | F26: 1 | G26: 炼气 | H26: 冠 | I26: 玄品 | J26: =COUNTIFS($G$5:G26,G26,$H$5:H26,H26,$I$5:I26,I26)-1 -> 0 | K26: 0 | L26: 1 | M26: 通用 | O26: 5 | R26: 90008 | S26: 15001001 | Y26: 40003 | Z26: 装备 | AA26: 大类_基础装备 | AB26: 小类_A炼气 | AC26: 玄品 | AD26: 3 | AE26: 无 | AF26: 默认 | AG26: TRUE | AH26: FALSE | AI26: 无 | AJ26: 生命值 | AK26: 1 | AL26: 物防上限 | AM26: 1 | AN26: 法防上限 | AO26: 2 | AP26: 灵力值 | AQ26: 1 | AR26: 神识 | AS26: 1 | BN26: 11900901 | BO26: 0 | BP26: 50006300 | BQ26: 50006300 | BR26: 50006300 | BS26: 50006300 | BT26: 0 | BU26: 96 | BV26: 1000001 | CI26: 70003 | CK26: 装备 | CL26: 炼气级 | CM26: 主力 | CN26: 套装 | CO26: 青冥冠，冠中灵纹清明，护持修士心神，并有助于凝聚神识。 | CP26: 外物纷纭，一念澄明。 | CQ26: 【开发试配】主力；器法：凝神·1。数值、被动与词条均待正式平衡；美术沿用占位。
B27: =50000000+INDEX(编号表!$D$2:$D$37,MATCH(G27,编号表!$C$2:$C$37,0))*100000+INDEX(编号表!$F$2:$F$24,MATCH(H27,编号表!$E$2:$E$24,0))*1000+INDEX(编号表!$B$2:$B$7,MATCH(I27,编号表!$A$2:$A$7,0))*100+K27 -> 50006400 | C27: 紫霞冠 | D27: 180 | E27: 1-10 | F27: 1 | G27: 炼气 | H27: 冠 | I27: 仙品 | J27: =COUNTIFS($G$5:G27,G27,$H$5:H27,H27,$I$5:I27,I27)-1 -> 0 | K27: 0 | L27: 0 | M27: 通用 | O27: 5 | R27: 90008 | S27: 15001001 | Y27: 40004 | Z27: 装备 | AA27: 大类_基础装备 | AB27: 小类_A炼气 | AC27: 仙品 | AD27: 4 | AE27: 无 | AF27: 默认 | AG27: TRUE | AH27: FALSE | AI27: 无 | AJ27: 生命值 | AK27: 2 | AL27: 物防上限 | AM27: 1 | AN27: 法防上限 | AO27: 2 | AP27: 灵力值 | AQ27: 2 | AR27: 神识 | AS27: 1 | BN27: 11900902 | BO27: 0 | BP27: 50006400 | BQ27: 50006400 | BR27: 50006400 | BS27: 50006400 | BT27: 0 | BU27: 480 | BV27: 1000001 | CI27: 70004 | CK27: 装备 | CL27: 炼气级 | CM27: 常规上限 | CN27: 散件 | CO27: 紫霞冠，冠中灵纹清明，护持修士心神，并有助于凝聚神识。 | CP27: 仰观星斗，静守寸心。 | CQ27: 【开发试配】常规上限；器法：凝神·2。数值、被动与词条均待正式平衡；美术沿用占位。
B28: =50000000+INDEX(编号表!$D$2:$D$37,MATCH(G28,编号表!$C$2:$C$37,0))*100000+INDEX(编号表!$F$2:$F$24,MATCH(H28,编号表!$E$2:$E$24,0))*1000+INDEX(编号表!$B$2:$B$7,MATCH(I28,编号表!$A$2:$A$7,0))*100+K28 -> 50019100 | C28: 木佩 | D28: 180 | E28: 1-10 | F28: 1 | G28: 炼气 | H28: 玉佩 | I28: 凡品 | J28: =COUNTIFS($G$5:G28,G28,$H$5:H28,H28,$I$5:I28,I28)-1 -> 0 | K28: 0 | L28: 0 | M28: 通用 | O28: 5 | R28: 90011 | S28: 15001001 | Y28: 40001 | Z28: 装备 | AA28: 大类_基础装备 | AB28: 小类_A炼气 | AC28: 凡品 | AD28: 1 | AE28: 无 | AF28: 默认 | AG28: TRUE | AH28: FALSE | AI28: 无 | AJ28: 攻击上限 | AK28: 1 | AL28: 生命值 | AM28: 1 | AN28: 物防上限 | AO28: 1 | AP28: 法防上限 | AQ28: 1 | AR28: 灵力值 | AS28: 1 | BN28: 0 | BO28: 0 | BP28: 50019100 | BQ28: 50019100 | BR28: 50019100 | BS28: 50019100 | BT28: 0 | BU28: 8 | BV28: 1000001 | CI28: 70001 | CK28: 装备 | CL28: 炼气级 | CM28: 过渡 | CN28: 散件 | CO28: 木佩，佩中灵机温润，攻守间自成助益。 | CP28: 佩玉无言，与君同行。 | CQ28: 【开发试配】过渡；过渡装备无固定器法。数值、被动与词条均待正式平衡；美术沿用占位。
B29: =50000000+INDEX(编号表!$D$2:$D$37,MATCH(G29,编号表!$C$2:$C$37,0))*100000+INDEX(编号表!$F$2:$F$24,MATCH(H29,编号表!$E$2:$E$24,0))*1000+INDEX(编号表!$B$2:$B$7,MATCH(I29,编号表!$A$2:$A$7,0))*100+K29 -> 50019200 | C29: 青石佩 | D29: 180 | E29: 1-10 | F29: 1 | G29: 炼气 | H29: 玉佩 | I29: 灵品 | J29: =COUNTIFS($G$5:G29,G29,$H$5:H29,H29,$I$5:I29,I29)-1 -> 0 | K29: 0 | L29: 0 | M29: 通用 | O29: 5 | R29: 90011 | S29: 15001001 | Y29: 40002 | Z29: 装备 | AA29: 大类_基础装备 | AB29: 小类_A炼气 | AC29: 灵品 | AD29: 2 | AE29: 无 | AF29: 默认 | AG29: TRUE | AH29: FALSE | AI29: 无 | AJ29: 攻击上限 | AK29: 1 | AL29: 生命值 | AM29: 1 | AN29: 物防上限 | AO29: 1 | AP29: 法防上限 | AQ29: 2 | AR29: 灵力值 | AS29: 1 | BN29: 0 | BO29: 0 | BP29: 50019200 | BQ29: 50019200 | BR29: 50019200 | BS29: 50019200 | BT29: 0 | BU29: 24 | BV29: 1000001 | CI29: 70002 | CK29: 装备 | CL29: 炼气级 | CM29: 过渡 | CN29: 散件 | CO29: 青石佩，佩中灵机温润，攻守间自成助益。 | CP29: 佩玉无言，与君同行。 | CQ29: 【开发试配】过渡；过渡装备无固定器法。数值、被动与词条均待正式平衡；美术沿用占位。
B30: =50000000+INDEX(编号表!$D$2:$D$37,MATCH(G30,编号表!$C$2:$C$37,0))*100000+INDEX(编号表!$F$2:$F$24,MATCH(H30,编号表!$E$2:$E$24,0))*1000+INDEX(编号表!$B$2:$B$7,MATCH(I30,编号表!$A$2:$A$7,0))*100+K30 -> 50019300 | C30: 聚锋佩 | D30: 180 | E30: 1-10 | F30: 1 | G30: 炼气 | H30: 玉佩 | I30: 玄品 | J30: =COUNTIFS($G$5:G30,G30,$H$5:H30,H30,$I$5:I30,I30)-1 -> 0 | K30: 0 | L30: 0 | M30: 金行 | O30: 5 | R30: 90011 | S30: 15001001 | Y30: 40003 | Z30: 装备 | AA30: 大类_基础装备 | AB30: 小类_A炼气 | AC30: 玄品 | AD30: 3 | AE30: 无 | AF30: 默认 | AG30: TRUE | AH30: FALSE | AI30: 无 | AJ30: 攻击上限 | AK30: 1 | AL30: 生命值 | AM30: 1 | AN30: 物防上限 | AO30: 1 | AP30: 法防上限 | AQ30: 2 | AR30: 灵力值 | AS30: 1 | AT30: 金行增幅 | AU30: 400 | BN30: 11901501 | BO30: 0 | BP30: 50019300 | BQ30: 50019300 | BR30: 50019300 | BS30: 50019300 | BT30: 0 | BU30: 96 | BV30: 1000001 | CI30: 70003 | CK30: 装备 | CL30: 炼气级 | CM30: 主力 | CN30: 散件 | CO30: 聚锋佩，佩中灵机温润，攻守间自成助益，偏重金行伤害。 | CP30: 鸣玉在侧，灵意长存。 | CQ30: 【开发试配】主力；器法：金曜·1。数值、被动与词条均待正式平衡；美术沿用占位。
B31: =50000000+INDEX(编号表!$D$2:$D$37,MATCH(G31,编号表!$C$2:$C$37,0))*100000+INDEX(编号表!$F$2:$F$24,MATCH(H31,编号表!$E$2:$E$24,0))*1000+INDEX(编号表!$B$2:$B$7,MATCH(I31,编号表!$A$2:$A$7,0))*100+K31 -> 50019301 | C31: 长青佩 | D31: 180 | E31: 1-10 | F31: 1 | G31: 炼气 | H31: 玉佩 | I31: 玄品 | J31: =COUNTIFS($G$5:G31,G31,$H$5:H31,H31,$I$5:I31,I31)-1 -> 1 | K31: 1 | L31: 0 | M31: 木行 | O31: 5 | R31: 90011 | S31: 15001001 | Y31: 40003 | Z31: 装备 | AA31: 大类_基础装备 | AB31: 小类_A炼气 | AC31: 玄品 | AD31: 3 | AE31: 无 | AF31: 默认 | AG31: TRUE | AH31: FALSE | AI31: 无 | AJ31: 攻击上限 | AK31: 1 | AL31: 生命值 | AM31: 1 | AN31: 物防上限 | AO31: 2 | AP31: 法防上限 | AQ31: 1 | AR31: 灵力值 | AS31: 1 | AT31: 木行增幅 | AU31: 400 | AV31: 暴击率 | AW31: 200 | BN31: 11900301 | BO31: 0 | BP31: 50019301 | BQ31: 50019301 | BR31: 50019301 | BS31: 50019301 | BT31: 0 | BU31: 96 | BV31: 1000001 | CI31: 70003 | CK31: 装备 | CL31: 炼气级 | CM31: 主力 | CN31: 散件 | CO31: 长青佩，佩中灵机温润，攻守间自成助益，偏重木行伤害，有助于把握攻伐时机。 | CP31: 鸣玉在侧，灵意长存。 | CQ31: 【开发试配】主力；器法：破军·1。数值、被动与词条均待正式平衡；美术沿用占位。
B32: =50000000+INDEX(编号表!$D$2:$D$37,MATCH(G32,编号表!$C$2:$C$37,0))*100000+INDEX(编号表!$F$2:$F$24,MATCH(H32,编号表!$E$2:$E$24,0))*1000+INDEX(编号表!$B$2:$B$7,MATCH(I32,编号表!$A$2:$A$7,0))*100+K32 -> 50019302 | C32: 回澜佩 | D32: 180 | E32: 1-10 | F32: 1 | G32: 炼气 | H32: 玉佩 | I32: 玄品 | J32: =COUNTIFS($G$5:G32,G32,$H$5:H32,H32,$I$5:I32,I32)-1 -> 2 | K32: 2 | L32: 0 | M32: 水行 | O32: 5 | R32: 90011 | S32: 15001001 | Y32: 40003 | Z32: 装备 | AA32: 大类_基础装备 | AB32: 小类_A炼气 | AC32: 玄品 | AD32: 3 | AE32: 无 | AF32: 默认 | AG32: TRUE | AH32: FALSE | AI32: 无 | AJ32: 攻击上限 | AK32: 1 | AL32: 生命值 | AM32: 1 | AN32: 物防上限 | AO32: 1 | AP32: 法防上限 | AQ32: 2 | AR32: 灵力值 | AS32: 1 | AT32: 水行增幅 | AU32: 400 | AV32: 神识 | AW32: 1 | BN32: 11901401 | BO32: 0 | BP32: 50019302 | BQ32: 50019302 | BR32: 50019302 | BS32: 50019302 | BT32: 0 | BU32: 96 | BV32: 1000001 | CI32: 70003 | CK32: 装备 | CL32: 炼气级 | CM32: 主力 | CN32: 散件 | CO32: 回澜佩，佩中灵机温润，攻守间自成助益，偏重水行伤害，并有助于凝聚神识。 | CP32: 鸣玉在侧，灵意长存。 | CQ32: 【开发试配】主力；器法：凝元·1。数值、被动与词条均待正式平衡；美术沿用占位。
B33: =50000000+INDEX(编号表!$D$2:$D$37,MATCH(G33,编号表!$C$2:$C$37,0))*100000+INDEX(编号表!$F$2:$F$24,MATCH(H33,编号表!$E$2:$E$24,0))*1000+INDEX(编号表!$B$2:$B$7,MATCH(I33,编号表!$A$2:$A$7,0))*100+K33 -> 50019303 | C33: 青冥玉佩 | D33: 180 | E33: 1-10 | F33: 1 | G33: 炼气 | H33: 玉佩 | I33: 玄品 | J33: =COUNTIFS($G$5:G33,G33,$H$5:H33,H33,$I$5:I33,I33)-1 -> 3 | K33: 3 | L33: 1 | M33: 金行 | O33: 5 | R33: 90011 | S33: 15001001 | Y33: 40003 | Z33: 装备 | AA33: 大类_基础装备 | AB33: 小类_A炼气 | AC33: 玄品 | AD33: 3 | AE33: 无 | AF33: 默认 | AG33: TRUE | AH33: FALSE | AI33: 无 | AJ33: 攻击上限 | AK33: 1 | AL33: 生命值 | AM33: 1 | AN33: 物防上限 | AO33: 1 | AP33: 法防上限 | AQ33: 2 | AR33: 灵力值 | AS33: 1 | AT33: 金行增幅 | AU33: 400 | BN33: 11901501 | BO33: 0 | BP33: 50019303 | BQ33: 50019303 | BR33: 50019303 | BS33: 50019303 | BT33: 0 | BU33: 96 | BV33: 1000001 | CI33: 70003 | CK33: 装备 | CL33: 炼气级 | CM33: 主力 | CN33: 套装 | CO33: 青冥玉佩，佩中灵机温润，攻守间自成助益，偏重金行伤害。 | CP33: 鸣玉在侧，灵意长存。 | CQ33: 【开发试配】主力；器法：金曜·1。数值、被动与词条均待正式平衡；美术沿用占位。
B34: =50000000+INDEX(编号表!$D$2:$D$37,MATCH(G34,编号表!$C$2:$C$37,0))*100000+INDEX(编号表!$F$2:$F$24,MATCH(H34,编号表!$E$2:$E$24,0))*1000+INDEX(编号表!$B$2:$B$7,MATCH(I34,编号表!$A$2:$A$7,0))*100+K34 -> 50019400 | C34: 凝碧佩 | D34: 180 | E34: 1-10 | F34: 1 | G34: 炼气 | H34: 玉佩 | I34: 仙品 | J34: =COUNTIFS($G$5:G34,G34,$H$5:H34,H34,$I$5:I34,I34)-1 -> 0 | K34: 0 | L34: 0 | M34: 木行 | O34: 5 | R34: 90011 | S34: 15001001 | Y34: 40004 | Z34: 装备 | AA34: 大类_基础装备 | AB34: 小类_A炼气 | AC34: 仙品 | AD34: 4 | AE34: 无 | AF34: 默认 | AG34: TRUE | AH34: FALSE | AI34: 无 | AJ34: 攻击上限 | AK34: 1 | AL34: 生命值 | AM34: 1 | AN34: 物防上限 | AO34: 1 | AP34: 法防上限 | AQ34: 2 | AR34: 灵力值 | AS34: 1 | AT34: 木行增幅 | AU34: 600 | BN34: 11901602 | BO34: 0 | BP34: 50019400 | BQ34: 50019400 | BR34: 50019400 | BS34: 50019400 | BT34: 0 | BU34: 480 | BV34: 1000001 | CI34: 70004 | CK34: 装备 | CL34: 炼气级 | CM34: 常规上限 | CN34: 散件 | CO34: 凝碧佩，佩中灵机温润，攻守间自成助益，偏重木行伤害。 | CP34: 一握温凉，照见本心。 | CQ34: 【开发试配】常规上限；器法：青荣·2。数值、被动与词条均待正式平衡；美术沿用占位。
B35: =50000000+INDEX(编号表!$D$2:$D$37,MATCH(G35,编号表!$C$2:$C$37,0))*100000+INDEX(编号表!$F$2:$F$24,MATCH(H35,编号表!$E$2:$E$24,0))*1000+INDEX(编号表!$B$2:$B$7,MATCH(I35,编号表!$A$2:$A$7,0))*100+K35 -> 50500100 | C35: 百锻剑 | D35: 180 | E35: 11-20 | F35: 11 | G35: 筑基 | H35: 武器 | I35: 凡品 | J35: =COUNTIFS($G$5:G35,G35,$H$5:H35,H35,$I$5:I35,I35)-1 -> 0 | K35: 0 | L35: 0 | M35: 剑道 | O35: 5 | R35: 90010 | S35: 15001001 | Y35: 40001 | Z35: 装备 | AA35: 大类_基础装备 | AB35: 小类_B筑基 | AC35: 凡品 | AD35: 1 | AE35: 无 | AF35: 默认 | AG35: TRUE | AH35: FALSE | AI35: 无 | AJ35: 攻击上限 | AK35: 5 | BN35: 0 | BO35: 0 | BP35: 50500100 | BQ35: 50500100 | BR35: 50500100 | BS35: 50500100 | BT35: 0 | BU35: 40 | BV35: 1000001 | CI35: 70001 | CK35: 装备 | CL35: 筑基级 | CM35: 过渡 | CN35: 散件 | CO35: 百锻剑，剑身经反复锻炼，以锋刃承载攻伐之力。 | CP35: 锋芒初露，先问前路。 | CQ35: 【开发试配】过渡；过渡装备无固定器法。数值、被动与词条均待正式平衡；美术沿用占位。
B36: =50000000+INDEX(编号表!$D$2:$D$37,MATCH(G36,编号表!$C$2:$C$37,0))*100000+INDEX(编号表!$F$2:$F$24,MATCH(H36,编号表!$E$2:$E$24,0))*1000+INDEX(编号表!$B$2:$B$7,MATCH(I36,编号表!$A$2:$A$7,0))*100+K36 -> 50500200 | C36: 玄铁剑 | D36: 180 | E36: 11-20 | F36: 11 | G36: 筑基 | H36: 武器 | I36: 灵品 | J36: =COUNTIFS($G$5:G36,G36,$H$5:H36,H36,$I$5:I36,I36)-1 -> 0 | K36: 0 | L36: 0 | M36: 剑道 | O36: 5 | R36: 90010 | S36: 15001001 | Y36: 40002 | Z36: 装备 | AA36: 大类_基础装备 | AB36: 小类_B筑基 | AC36: 灵品 | AD36: 2 | AE36: 无 | AF36: 默认 | AG36: TRUE | AH36: FALSE | AI36: 无 | AJ36: 攻击上限 | AK36: 7 | BN36: 0 | BO36: 0 | BP36: 50500200 | BQ36: 50500200 | BR36: 50500200 | BS36: 50500200 | BT36: 0 | BU36: 120 | BV36: 1000001 | CI36: 70002 | CK36: 装备 | CL36: 筑基级 | CM36: 过渡 | CN36: 散件 | CO36: 玄铁剑，剑身经反复锻炼，以锋刃承载攻伐之力。 | CP36: 锋芒初露，先问前路。 | CQ36: 【开发试配】过渡；过渡装备无固定器法。数值、被动与词条均待正式平衡；美术沿用占位。
B37: =50000000+INDEX(编号表!$D$2:$D$37,MATCH(G37,编号表!$C$2:$C$37,0))*100000+INDEX(编号表!$F$2:$F$24,MATCH(H37,编号表!$E$2:$E$24,0))*1000+INDEX(编号表!$B$2:$B$7,MATCH(I37,编号表!$A$2:$A$7,0))*100+K37 -> 50500300 | C37: 凝霜剑 | D37: 180 | E37: 11-20 | F37: 11 | G37: 筑基 | H37: 武器 | I37: 玄品 | J37: =COUNTIFS($G$5:G37,G37,$H$5:H37,H37,$I$5:I37,I37)-1 -> 0 | K37: 0 | L37: 0 | M37: 剑道 | O37: 5 | R37: 90010 | S37: 15001001 | Y37: 40003 | Z37: 装备 | AA37: 大类_基础装备 | AB37: 小类_B筑基 | AC37: 玄品 | AD37: 3 | AE37: 无 | AF37: 默认 | AG37: TRUE | AH37: FALSE | AI37: 无 | AJ37: 攻击上限 | AK37: 9 | BN37: 11900101 | BO37: 0 | BP37: 50500300 | BQ37: 50500300 | BR37: 50500300 | BS37: 50500300 | BT37: 0 | BU37: 480 | BV37: 1000001 | CI37: 70003 | CK37: 装备 | CL37: 筑基级 | CM37: 主力 | CN37: 散件 | CO37: 凝霜剑，剑身经反复锻炼，以锋刃承载攻伐之力。 | CP37: 剑意藏锋，出鞘见真。 | CQ37: 【开发试配】主力；器法：养锋·1。数值、被动与词条均待正式平衡；美术沿用占位。
B38: =50000000+INDEX(编号表!$D$2:$D$37,MATCH(G38,编号表!$C$2:$C$37,0))*100000+INDEX(编号表!$F$2:$F$24,MATCH(H38,编号表!$E$2:$E$24,0))*1000+INDEX(编号表!$B$2:$B$7,MATCH(I38,编号表!$A$2:$A$7,0))*100+K38 -> 50500301 | C38: 流霞拂尘 | D38: 180 | E38: 11-20 | F38: 11 | G38: 筑基 | H38: 武器 | I38: 玄品 | J38: =COUNTIFS($G$5:G38,G38,$H$5:H38,H38,$I$5:I38,I38)-1 -> 1 | K38: 1 | L38: 0 | M38: 五行 | O38: 5 | R38: 90010 | S38: 15001001 | Y38: 40003 | Z38: 装备 | AA38: 大类_基础装备 | AB38: 小类_B筑基 | AC38: 玄品 | AD38: 3 | AE38: 无 | AF38: 默认 | AG38: TRUE | AH38: FALSE | AI38: 无 | AJ38: 攻击上限 | AK38: 9 | BN38: 11900201 | BO38: 0 | BP38: 50500301 | BQ38: 50500301 | BR38: 50500301 | BS38: 50500301 | BT38: 0 | BU38: 480 | BV38: 1000001 | CI38: 70003 | CK38: 装备 | CL38: 筑基级 | CM38: 主力 | CN38: 散件 | CO38: 流霞拂尘，丝缕聚散随心，以器身引导攻伐之力。 | CP38: 尘丝拂尽，灵机自明。 | CQ38: 【开发试配】主力；器法：引灵·1。数值、被动与词条均待正式平衡；美术沿用占位。
B39: =50000000+INDEX(编号表!$D$2:$D$37,MATCH(G39,编号表!$C$2:$C$37,0))*100000+INDEX(编号表!$F$2:$F$24,MATCH(H39,编号表!$E$2:$E$24,0))*1000+INDEX(编号表!$B$2:$B$7,MATCH(I39,编号表!$A$2:$A$7,0))*100+K39 -> 50500400 | C39: 斩霞剑 | D39: 180 | E39: 11-20 | F39: 11 | G39: 筑基 | H39: 武器 | I39: 仙品 | J39: =COUNTIFS($G$5:G39,G39,$H$5:H39,H39,$I$5:I39,I39)-1 -> 0 | K39: 0 | L39: 0 | M39: 剑道 | O39: 5 | R39: 90010 | S39: 15001001 | Y39: 40004 | Z39: 装备 | AA39: 大类_基础装备 | AB39: 小类_B筑基 | AC39: 仙品 | AD39: 4 | AE39: 无 | AF39: 默认 | AG39: TRUE | AH39: FALSE | AI39: 无 | AJ39: 攻击上限 | AK39: 11 | BN39: 11900102 | BO39: 0 | BP39: 50500400 | BQ39: 50500400 | BR39: 50500400 | BS39: 50500400 | BT39: 0 | BU39: 2400 | BV39: 1000001 | CI39: 70004 | CK39: 装备 | CL39: 筑基级 | CM39: 常规上限 | CN39: 散件 | CO39: 斩霞剑，剑身经反复锻炼，以锋刃承载攻伐之力。 | CP39: 剑意藏锋，出鞘见真。 | CQ39: 【开发试配】常规上限；器法：养锋·2。数值、被动与词条均待正式平衡；美术沿用占位。
B40: =50000000+INDEX(编号表!$D$2:$D$37,MATCH(G40,编号表!$C$2:$C$37,0))*100000+INDEX(编号表!$F$2:$F$24,MATCH(H40,编号表!$E$2:$E$24,0))*1000+INDEX(编号表!$B$2:$B$7,MATCH(I40,编号表!$A$2:$A$7,0))*100+K40 -> 50500401 | C40: 流火羽扇 | D40: 180 | E40: 11-20 | F40: 11 | G40: 筑基 | H40: 武器 | I40: 仙品 | J40: =COUNTIFS($G$5:G40,G40,$H$5:H40,H40,$I$5:I40,I40)-1 -> 1 | K40: 1 | L40: 0 | M40: 五行 | O40: 5 | R40: 90010 | S40: 15001001 | Y40: 40004 | Z40: 装备 | AA40: 大类_基础装备 | AB40: 小类_B筑基 | AC40: 仙品 | AD40: 4 | AE40: 无 | AF40: 默认 | AG40: TRUE | AH40: FALSE | AI40: 无 | AJ40: 攻击上限 | AK40: 11 | BN40: 11900202 | BO40: 0 | BP40: 50500401 | BQ40: 50500401 | BR40: 50500401 | BS40: 50500401 | BT40: 0 | BU40: 2400 | BV40: 1000001 | CI40: 70004 | CK40: 装备 | CL40: 筑基级 | CM40: 常规上限 | CN40: 散件 | CO40: 流火羽扇，扇骨羽纹相合，以灵气催动攻伐之力。 | CP40: 尘丝拂尽，灵机自明。 | CQ40: 【开发试配】常规上限；器法：引灵·2。数值、被动与词条均待正式平衡；美术沿用占位。
...

Sheet 强化
A1: ##var | B1: reinforcement_id | G1: level_max | H1: upgrades
A2: ##type | B2: int | G2: int | H2: array,EquipUpgrade
A3: ##group
A4: ## | B4: 强化ID | C4: 装备名 | D4: 装备位 | E4: 推荐等级 | F4: 推荐品质 | G4: 最高强化等级 | H4: 升级1材料ID1 | I4: 升级1材料数量1 | J4: 升级1材料ID2 | K4: 升级1材料数量2 | L4: 升级1材料ID3 | M4: 升级1材料数量3 | N4: 分隔符 | O4: 升级1属性名 | P4: 升级1属性值 | Q4: 升级1成功率 | R4: 升级2材料ID1 | S4: 升级2材料数量1 | T4: 升级2材料ID2 | U4: 升级2材料数量2 | V4: 升级2材料ID3 | W4: 升级2材料数量3 | X4: 分隔符 | Y4: 升级2属性名 | Z4: 升级2属性值 | AA4: 升级2成功率 | AB4: 升级3材料ID1 | AC4: 升级3材料数量1 | AD4: 升级3材料ID2 | AE4: 升级3材料数量2 | AF4: 升级3材料ID3 | AG4: 升级3材料数量3 | AH4: 分隔符 | AI4: 升级3属性名 | AJ4: 升级3属性值 | AK4: 升级3成功率 | AL4: 升级4材料ID1 | AM4: 升级4材料数量1 | AN4: 升级4材料ID2 | AO4: 升级4材料数量2 | AP4: 升级4材料ID3 | AQ4: 升级4材料数量3 | AR4: 分隔符 | AS4: 升级4属性名 | AT4: 升级4属性值 | AU4: 升级4成功率 | AV4: 升级5材料ID1 | AW4: 升级5材料数量1 | AX4: 升级5材料ID2 | AY4: 升级5材料数量2 | AZ4: 升级5材料ID3 | BA4: 升级5材料数量3 | BB4: 分隔符 | BC4: 升级5属性名 | BD4: 升级5属性值 | BE4: 升级5成功率 | BF4: 升级6材料ID1 | BG4: 升级6材料数量1 | BH4: 升级6材料ID2 | BI4: 升级6材料数量2 | BJ4: 升级6材料ID3 | BK4: 升级6材料数量3 | BL4: 分隔符 | BM4: 升级6属性名 | BN4: 升级6属性值 | BO4: 升级6成功率 | BP4: 升级7材料ID1 | BQ4: 升级7材料数量1 | BR4: 升级7材料ID2 | BS4: 升级7材料数量2 | BT4: 升级7材料ID3 | BU4: 升级7材料数量3 | BV4: 分隔符 | BW4: 升级7属性名 | BX4: 升级7属性值 | BY4: 升级7成功率 | BZ4: 强化灵材名称（辅助） | CA4: 高阶补充灵材（辅助） | CB4: 试配说明（不导出）
B5: 50000100 | C5: 粗铁剑 | D5: 武器 | E5: 炼气 | F5: 凡品 | G5: 7 | H5: 12321013 | I5: 5 | J5: 12821010 | K5: 5 | L5: 1000001 | M5: 20 | N5: } | O5: 攻击上限 | P5: 1 | Q5: 8000 | R5: 12321013 | S5: 5 | T5: 12821010 | U5: 5 | V5: 1000001 | W5: 20 | X5: } | Y5: 攻击上限 | Z5: 1 | AA5: 7000 | AB5: 12321013 | AC5: 10 | AD5: 12821010 | AE5: 5 | AF5: 1000001 | AG5: 40 | AH5: } | AI5: 攻击上限 | AJ5: 1 | AK5: 6000 | AL5: 12322013 | AM5: 10 | AN5: 12522012 | AO5: 10 | AP5: 1000001 | AQ5: 40 | AR5: } | AS5: 攻击上限 | AT5: 1 | AU5: 5000 | AV5: 12322013 | AW5: 15 | AX5: 12522012 | AY5: 10 | AZ5: 1000001 | BA5: 60 | BB5: } | BC5: 攻击上限 | BD5: 1 | BE5: 4000 | BF5: 12322013 | BG5: 20 | BH5: 12522012 | BI5: 10 | BJ5: 1000001 | BK5: 80 | BL5: } | BM5: 攻击上限 | BN5: 2 | BO5: 3000 | BP5: 12322013 | BQ5: 25 | BR5: 12522012 | BS5: 15 | BT5: 1000001 | BU5: 100 | BV5: } | BW5: 攻击上限 | BX5: 2 | BY5: 2000 | BZ5: 玄铁 | CA5: 分阶段材料2：足年灵兽骨、足年灵兽獠牙 | CB5: 【开发试配】每级增量；失败同额扣费、不掉级；灵石按货币余额扣。
B6: 50000200 | C6: 精铁剑 | D6: 武器 | E6: 炼气 | F6: 灵品 | G6: 7 | H6: 12321013 | I6: 5 | J6: 12821010 | K6: 5 | L6: 1000001 | M6: 20 | N6: } | O6: 攻击上限 | P6: 1 | Q6: 8000 | R6: 12321013 | S6: 5 | T6: 12821010 | U6: 5 | V6: 1000001 | W6: 20 | X6: } | Y6: 攻击上限 | Z6: 1 | AA6: 7000 | AB6: 12321013 | AC6: 10 | AD6: 12821010 | AE6: 5 | AF6: 1000001 | AG6: 40 | AH6: } | AI6: 攻击上限 | AJ6: 1 | AK6: 6000 | AL6: 12322013 | AM6: 10 | AN6: 12522012 | AO6: 10 | AP6: 1000001 | AQ6: 40 | AR6: } | AS6: 攻击上限 | AT6: 1 | AU6: 5000 | AV6: 12322013 | AW6: 15 | AX6: 12522012 | AY6: 10 | AZ6: 1000001 | BA6: 60 | BB6: } | BC6: 攻击上限 | BD6: 1 | BE6: 4000 | BF6: 12322013 | BG6: 20 | BH6: 12522012 | BI6: 10 | BJ6: 1000001 | BK6: 80 | BL6: } | BM6: 攻击上限 | BN6: 2 | BO6: 3000 | BP6: 12322013 | BQ6: 25 | BR6: 12522012 | BS6: 15 | BT6: 1000001 | BU6: 100 | BV6: } | BW6: 攻击上限 | BX6: 2 | BY6: 2000 | BZ6: 玄铁 | CA6: 分阶段材料2：足年灵兽骨、足年灵兽獠牙 | CB6: 【开发试配】每级增量；失败同额扣费、不掉级；灵石按货币余额扣。
B7: 50000300 | C7: 清风剑 | D7: 武器 | E7: 炼气 | F7: 玄品 | G7: 7 | H7: 12321013 | I7: 5 | J7: 12821010 | K7: 5 | L7: 1000001 | M7: 40 | N7: } | O7: 攻击上限 | P7: 1 | Q7: 8000 | R7: 12321013 | S7: 5 | T7: 12821010 | U7: 5 | V7: 1000001 | W7: 40 | X7: } | Y7: 攻击上限 | Z7: 1 | AA7: 7000 | AB7: 12321013 | AC7: 10 | AD7: 12821010 | AE7: 5 | AF7: 1000001 | AG7: 80 | AH7: } | AI7: 攻击上限 | AJ7: 1 | AK7: 6000 | AL7: 12322013 | AM7: 10 | AN7: 12522012 | AO7: 10 | AP7: 1000001 | AQ7: 80 | AR7: } | AS7: 攻击上限 | AT7: 1 | AU7: 5000 | AV7: 12322013 | AW7: 15 | AX7: 12522012 | AY7: 10 | AZ7: 1000001 | BA7: 120 | BB7: } | BC7: 攻击上限 | BD7: 1 | BE7: 4000 | BF7: 12322013 | BG7: 20 | BH7: 12522012 | BI7: 10 | BJ7: 1000001 | BK7: 160 | BL7: } | BM7: 攻击上限 | BN7: 2 | BO7: 3000 | BP7: 12322013 | BQ7: 25 | BR7: 12522012 | BS7: 15 | BT7: 1000001 | BU7: 200 | BV7: } | BW7: 攻击上限 | BX7: 2 | BY7: 2000 | BZ7: 玄铁 | CA7: 分阶段材料2：足年灵兽骨、足年灵兽獠牙 | CB7: 【开发试配】每级增量；失败同额扣费、不掉级；灵石按货币余额扣。
B8: 50000301 | C8: 五气拂尘 | D8: 武器 | E8: 炼气 | F8: 玄品 | G8: 7 | H8: 12321013 | I8: 5 | J8: 12821010 | K8: 5 | L8: 1000001 | M8: 40 | N8: } | O8: 攻击上限 | P8: 1 | Q8: 8000 | R8: 12321013 | S8: 5 | T8: 12821010 | U8: 5 | V8: 1000001 | W8: 40 | X8: } | Y8: 攻击上限 | Z8: 1 | AA8: 7000 | AB8: 12321013 | AC8: 10 | AD8: 12821010 | AE8: 5 | AF8: 1000001 | AG8: 80 | AH8: } | AI8: 攻击上限 | AJ8: 1 | AK8: 6000 | AL8: 12322013 | AM8: 10 | AN8: 12522012 | AO8: 10 | AP8: 1000001 | AQ8: 80 | AR8: } | AS8: 攻击上限 | AT8: 1 | AU8: 5000 | AV8: 12322013 | AW8: 15 | AX8: 12522012 | AY8: 10 | AZ8: 1000001 | BA8: 120 | BB8: } | BC8: 攻击上限 | BD8: 1 | BE8: 4000 | BF8: 12322013 | BG8: 20 | BH8: 12522012 | BI8: 10 | BJ8: 1000001 | BK8: 160 | BL8: } | BM8: 攻击上限 | BN8: 2 | BO8: 3000 | BP8: 12322013 | BQ8: 25 | BR8: 12522012 | BS8: 15 | BT8: 1000001 | BU8: 200 | BV8: } | BW8: 攻击上限 | BX8: 2 | BY8: 2000 | BZ8: 玄铁 | CA8: 分阶段材料2：足年灵兽骨、足年灵兽獠牙 | CB8: 【开发试配】每级增量；失败同额扣费、不掉级；灵石按货币余额扣。
B9: 50000400 | C9: 寒星剑 | D9: 武器 | E9: 炼气 | F9: 仙品 | G9: 7 | H9: 12321013 | I9: 5 | J9: 12821010 | K9: 5 | L9: 1000001 | M9: 60 | N9: } | O9: 攻击上限 | P9: 1 | Q9: 8000 | R9: 12321013 | S9: 5 | T9: 12821010 | U9: 5 | V9: 1000001 | W9: 60 | X9: } | Y9: 攻击上限 | Z9: 1 | AA9: 7000 | AB9: 12321013 | AC9: 10 | AD9: 12821010 | AE9: 5 | AF9: 1000001 | AG9: 120 | AH9: } | AI9: 攻击上限 | AJ9: 1 | AK9: 6000 | AL9: 12322013 | AM9: 10 | AN9: 12522012 | AO9: 10 | AP9: 1000001 | AQ9: 120 | AR9: } | AS9: 攻击上限 | AT9: 1 | AU9: 5000 | AV9: 12322013 | AW9: 15 | AX9: 12522012 | AY9: 10 | AZ9: 1000001 | BA9: 180 | BB9: } | BC9: 攻击上限 | BD9: 1 | BE9: 4000 | BF9: 12322013 | BG9: 20 | BH9: 12522012 | BI9: 10 | BJ9: 1000001 | BK9: 240 | BL9: } | BM9: 攻击上限 | BN9: 2 | BO9: 3000 | BP9: 12322013 | BQ9: 25 | BR9: 12522012 | BS9: 15 | BT9: 1000001 | BU9: 300 | BV9: } | BW9: 攻击上限 | BX9: 2 | BY9: 2000 | BZ9: 玄铁 | CA9: 分阶段材料2：足年灵兽骨、足年灵兽獠牙 | CB9: 【开发试配】每级增量；失败同额扣费、不掉级；灵石按货币余额扣。
B10: 50001100 | C10: 铜印 | D10: 印绶 | E10: 炼气 | F10: 凡品 | G10: 7 | H10: 12321013 | I10: 5 | J10: 12821010 | K10: 5 | L10: 1000001 | M10: 20 | N10: } | O10: 攻击上限 | P10: 1 | Q10: 8000 | R10: 12321013 | S10: 5 | T10: 12821010 | U10: 5 | V10: 1000001 | W10: 20 | X10: } | Y10: 攻击上限 | Z10: 1 | AA10: 7000 | AB10: 12321013 | AC10: 10 | AD10: 12821010 | AE10: 5 | AF10: 1000001 | AG10: 40 | AH10: } | AI10: 攻击上限 | AJ10: 1 | AK10: 6000 | AL10: 12322013 | AM10: 10 | AN10: 12822010 | AO10: 10 | AP10: 1000001 | AQ10: 40 | AR10: } | AS10: 攻击上限 | AT10: 1 | AU10: 5000 | AV10: 12322013 | AW10: 15 | AX10: 12822010 | AY10: 10 | AZ10: 1000001 | BA10: 60 | BB10: } | BC10: 攻击上限 | BD10: 1 | BE10: 4000 | BF10: 12322013 | BG10: 20 | BH10: 12822010 | BI10: 10 | BJ10: 1000001 | BK10: 80 | BL10: } | BM10: 攻击上限 | BN10: 2 | BO10: 3000 | BP10: 12322013 | BQ10: 25 | BR10: 12822010 | BS10: 15 | BT10: 1000001 | BU10: 100 | BV10: } | BW10: 攻击上限 | BX10: 2 | BY10: 2000 | BZ10: 玄铁 | CA10: 分阶段材料2：足年灵兽骨 | CB10: 【开发试配】每级增量；失败同额扣费、不掉级；灵石按货币余额扣。
B11: 50001200 | C11: 玄铁印 | D11: 印绶 | E11: 炼气 | F11: 灵品 | G11: 7 | H11: 12321013 | I11: 5 | J11: 12821010 | K11: 5 | L11: 1000001 | M11: 20 | N11: } | O11: 攻击上限 | P11: 1 | Q11: 8000 | R11: 12321013 | S11: 5 | T11: 12821010 | U11: 5 | V11: 1000001 | W11: 20 | X11: } | Y11: 攻击上限 | Z11: 1 | AA11: 7000 | AB11: 12321013 | AC11: 10 | AD11: 12821010 | AE11: 5 | AF11: 1000001 | AG11: 40 | AH11: } | AI11: 攻击上限 | AJ11: 1 | AK11: 6000 | AL11: 12322013 | AM11: 10 | AN11: 12822010 | AO11: 10 | AP11: 1000001 | AQ11: 40 | AR11: } | AS11: 攻击上限 | AT11: 1 | AU11: 5000 | AV11: 12322013 | AW11: 15 | AX11: 12822010 | AY11: 10 | AZ11: 1000001 | BA11: 60 | BB11: } | BC11: 攻击上限 | BD11: 1 | BE11: 4000 | BF11: 12322013 | BG11: 20 | BH11: 12822010 | BI11: 10 | BJ11: 1000001 | BK11: 80 | BL11: } | BM11: 攻击上限 | BN11: 2 | BO11: 3000 | BP11: 12322013 | BQ11: 25 | BR11: 12822010 | BS11: 15 | BT11: 1000001 | BU11: 100 | BV11: } | BW11: 攻击上限 | BX11: 2 | BY11: 2000 | BZ11: 玄铁 | CA11: 分阶段材料2：足年灵兽骨 | CB11: 【开发试配】每级增量；失败同额扣费、不掉级；灵石按货币余额扣。
B12: 50001300 | C12: 赤焰印 | D12: 印绶 | E12: 炼气 | F12: 玄品 | G12: 7 | H12: 12321013 | I12: 5 | J12: 12821010 | K12: 5 | L12: 1000001 | M12: 40 | N12: } | O12: 攻击上限 | P12: 1 | Q12: 8000 | R12: 12321013 | S12: 5 | T12: 12821010 | U12: 5 | V12: 1000001 | W12: 40 | X12: } | Y12: 攻击上限 | Z12: 1 | AA12: 7000 | AB12: 12321013 | AC12: 10 | AD12: 12821010 | AE12: 5 | AF12: 1000001 | AG12: 80 | AH12: } | AI12: 攻击上限 | AJ12: 1 | AK12: 6000 | AL12: 12322013 | AM12: 10 | AN12: 12822010 | AO12: 10 | AP12: 1000001 | AQ12: 80 | AR12: } | AS12: 攻击上限 | AT12: 1 | AU12: 5000 | AV12: 12322013 | AW12: 15 | AX12: 12822010 | AY12: 10 | AZ12: 1000001 | BA12: 120 | BB12: } | BC12: 攻击上限 | BD12: 1 | BE12: 4000 | BF12: 12322013 | BG12: 20 | BH12: 12822010 | BI12: 10 | BJ12: 1000001 | BK12: 160 | BL12: } | BM12: 攻击上限 | BN12: 2 | BO12: 3000 | BP12: 12322013 | BQ12: 25 | BR12: 12822010 | BS12: 15 | BT12: 1000001 | BU12: 200 | BV12: } | BW12: 攻击上限 | BX12: 2 | BY12: 2000 | BZ12: 玄铁 | CA12: 分阶段材料2：足年灵兽骨 | CB12: 【开发试配】每级增量；失败同额扣费、不掉级；灵石按货币余额扣。
B13: 50001301 | C13: 镇岳印 | D13: 印绶 | E13: 炼气 | F13: 玄品 | G13: 7 | H13: 12321013 | I13: 5 | J13: 12821010 | K13: 5 | L13: 1000001 | M13: 40 | N13: } | O13: 攻击上限 | P13: 1 | Q13: 8000 | R13: 12321013 | S13: 5 | T13: 12821010 | U13: 5 | V13: 1000001 | W13: 40 | X13: } | Y13: 攻击上限 | Z13: 1 | AA13: 7000 | AB13: 12321013 | AC13: 10 | AD13: 12821010 | AE13: 5 | AF13: 1000001 | AG13: 80 | AH13: } | AI13: 攻击上限 | AJ13: 1 | AK13: 6000 | AL13: 12322013 | AM13: 10 | AN13: 12822010 | AO13: 10 | AP13: 1000001 | AQ13: 80 | AR13: } | AS13: 攻击上限 | AT13: 1 | AU13: 5000 | AV13: 12322013 | AW13: 15 | AX13: 12822010 | AY13: 10 | AZ13: 1000001 | BA13: 120 | BB13: } | BC13: 攻击上限 | BD13: 1 | BE13: 4000 | BF13: 12322013 | BG13: 20 | BH13: 12822010 | BI13: 10 | BJ13: 1000001 | BK13: 160 | BL13: } | BM13: 攻击上限 | BN13: 2 | BO13: 3000 | BP13: 12322013 | BQ13: 25 | BR13: 12822010 | BS13: 15 | BT13: 1000001 | BU13: 200 | BV13: } | BW13: 攻击上限 | BX13: 2 | BY13: 2000 | BZ13: 玄铁 | CA13: 分阶段材料2：足年灵兽骨 | CB13: 【开发试配】每级增量；失败同额扣费、不掉级；灵石按货币余额扣。
B14: 50001400 | C14: 伏妖印 | D14: 印绶 | E14: 炼气 | F14: 仙品 | G14: 7 | H14: 12321013 | I14: 5 | J14: 12821010 | K14: 5 | L14: 1000001 | M14: 60 | N14: } | O14: 攻击上限 | P14: 1 | Q14: 8000 | R14: 12321013 | S14: 5 | T14: 12821010 | U14: 5 | V14: 1000001 | W14: 60 | X14: } | Y14: 攻击上限 | Z14: 1 | AA14: 7000 | AB14: 12321013 | AC14: 10 | AD14: 12821010 | AE14: 5 | AF14: 1000001 | AG14: 120 | AH14: } | AI14: 攻击上限 | AJ14: 1 | AK14: 6000 | AL14: 12322013 | AM14: 10 | AN14: 12822010 | AO14: 10 | AP14: 1000001 | AQ14: 120 | AR14: } | AS14: 攻击上限 | AT14: 1 | AU14: 5000 | AV14: 12322013 | AW14: 15 | AX14: 12822010 | AY14: 10 | AZ14: 1000001 | BA14: 180 | BB14: } | BC14: 攻击上限 | BD14: 1 | BE14: 4000 | BF14: 12322013 | BG14: 20 | BH14: 12822010 | BI14: 10 | BJ14: 1000001 | BK14: 240 | BL14: } | BM14: 攻击上限 | BN14: 2 | BO14: 3000 | BP14: 12322013 | BQ14: 25 | BR14: 12822010 | BS14: 15 | BT14: 1000001 | BU14: 300 | BV14: } | BW14: 攻击上限 | BX14: 2 | BY14: 2000 | BZ14: 玄铁 | CA14: 分阶段材料2：足年灵兽骨 | CB14: 【开发试配】每级增量；失败同额扣费、不掉级；灵石按货币余额扣。
B15: 50003100 | C15: 草履 | D15: 鞋履 | E15: 炼气 | F15: 凡品 | G15: 7 | H15: 12321011 | I15: 5 | J15: 12521019 | K15: 5 | L15: 1000001 | M15: 20 | N15: } | O15: 物防上限 | P15: 1 | Q15: 8000 | R15: 12321011 | S15: 5 | T15: 12521019 | U15: 5 | V15: 1000001 | W15: 20 | X15: } | Y15: 物防上限 | Z15: 1 | AA15: 7000 | AB15: 12321011 | AC15: 10 | AD15: 12521019 | AE15: 5 | AF15: 1000001 | AG15: 40 | AH15: } | AI15: 物防上限 | AJ15: 1 | AK15: 6000 | AL15: 12322011 | AM15: 10 | AN15: 12522002 | AO15: 10 | AP15: 1000001 | AQ15: 40 | AR15: } | AS15: 物防上限 | AT15: 1 | AU15: 5000 | AV15: 12322011 | AW15: 15 | AX15: 12522002 | AY15: 10 | AZ15: 1000001 | BA15: 60 | BB15: } | BC15: 物防上限 | BD15: 1 | BE15: 4000 | BF15: 12322011 | BG15: 20 | BH15: 12522002 | BI15: 10 | BJ15: 1000001 | BK15: 80 | BL15: } | BM15: 物防上限 | BN15: 2 | BO15: 3000 | BP15: 12322011 | BQ15: 25 | BR15: 12522002 | BS15: 15 | BT15: 1000001 | BU15: 100 | BV15: } | BW15: 物防上限 | BX15: 2 | BY15: 2000 | BZ15: 足年灵兽皮 | CA15: 分阶段材料2：足年灵木树脂、足年灵禽翎羽 | CB15: 【开发试配】每级增量；失败同额扣费、不掉级；灵石按货币余额扣。
B16: 50003200 | C16: 软底履 | D16: 鞋履 | E16: 炼气 | F16: 灵品 | G16: 7 | H16: 12321011 | I16: 5 | J16: 12521019 | K16: 5 | L16: 1000001 | M16: 20 | N16: } | O16: 物防上限 | P16: 1 | Q16: 8000 | R16: 12321011 | S16: 5 | T16: 12521019 | U16: 5 | V16: 1000001 | W16: 20 | X16: } | Y16: 物防上限 | Z16: 1 | AA16: 7000 | AB16: 12321011 | AC16: 10 | AD16: 12521019 | AE16: 5 | AF16: 1000001 | AG16: 40 | AH16: } | AI16: 物防上限 | AJ16: 1 | AK16: 6000 | AL16: 12322011 | AM16: 10 | AN16: 12522002 | AO16: 10 | AP16: 1000001 | AQ16: 40 | AR16: } | AS16: 物防上限 | AT16: 1 | AU16: 5000 | AV16: 12322011 | AW16: 15 | AX16: 12522002 | AY16: 10 | AZ16: 1000001 | BA16: 60 | BB16: } | BC16: 物防上限 | BD16: 1 | BE16: 4000 | BF16: 12322011 | BG16: 20 | BH16: 12522002 | BI16: 10 | BJ16: 1000001 | BK16: 80 | BL16: } | BM16: 物防上限 | BN16: 2 | BO16: 3000 | BP16: 12322011 | BQ16: 25 | BR16: 12522002 | BS16: 15 | BT16: 1000001 | BU16: 100 | BV16: } | BW16: 物防上限 | BX16: 2 | BY16: 2000 | BZ16: 足年灵兽皮 | CA16: 分阶段材料2：足年灵木树脂、足年灵禽翎羽 | CB16: 【开发试配】每级增量；失败同额扣费、不掉级；灵石按货币余额扣。
... B332: 53519600 | C332: 两忘佩 | D332: 玉佩 | E332: 大乘 | F332: 道品 | G332: 7 | H332: 12382027 | I332: 5 | J332: 12382029 | K332: 5 | L332: 1000001 | M332: 10240 | N332: } | O332: 攻击上限 | P332: 3 | Q332: 8000 | R332: 12382027 | S332: 5 | T332: 12382029 | U332: 5 | V332: 1000001 | W332: 10240 | X332: } | Y332: 攻击上限 | Z332: 3 | AA332: 7000 | AB332: 12382027 | AC332: 10 | AD332: 12382029 | AE332: 5 | AF332: 1000001 | AG332: 20480 | AH332: } | AI332: 攻击上限 | AJ332: 3 | AK332: 6000 | AL332: 12382027 | AM332: 10 | AN332: 12582034 | AO332: 10 | AP332: 1000001 | AQ332: 20480 | AR332: } | AS332: 攻击上限 | AT332: 3 | AU332: 5000 | AV332: 12382027 | AW332: 15 | AX332: 12582034 | AY332: 10 | AZ332: 1000001 | BA332: 30720 | BB332: } | BC332: 攻击上限 | BD332: 3 | BE332: 4000 | BF332: 12382027 | BG332: 20 | BH332: 12582035 | BI332: 10 | BJ332: 1000001 | BK332: 40960 | BL332: } | BM332: 攻击上限 | BN332: 6 | BO332: 3000 | BP332: 12382027 | BQ332: 25 | BR332: 12582035 | BS332: 15 | BT332: 1000001 | BU332: 51200 | BV332: } | BW332: 攻击上限 | BX332: 6 | BY332: 2000 | BZ332: 太玄玉母 | CA332: 分阶段材料2：百万载灵木芯、百万载地脉灵液、百万载石乳 | CB332: 【开发试配】每级增量；失败同额扣费、不掉级；灵石按货币余额扣。

Sheet 灵蕴
A1: ##var | B1: hidden_attribute | G1: prob | H1: attr_drops
A2: ##type | B2: int | G2: int | H2: array,EquipAttrDrop
A3: ##group
A4: ## | B4: 灵蕴方案ID | C4: 装备名 | D4: 装备位 | E4: 阶级 | F4: 颜色 | G4: 掉落概率 | H4: 属性1类型 | I4: 属性1数值下限 | J4: 属性1数值上限 | K4: 属性1掉落权重 | L4: 属性2类型 | M4: 属性2数值下限 | N4: 属性2数值上限 | O4: 属性2掉落权重 | P4: 属性3类型 | Q4: 属性3数值下限 | R4: 属性3数值上限 | S4: 属性3掉落权重 | T4: 属性4类型 | U4: 属性4数值下限 | V4: 属性4数值上限 | W4: 属性4掉落权重 | X4: 属性5类型 | Y4: 属性5数值下限 | Z4: 属性5数值上限 | AA4: 属性5掉落权重 | AB4: 属性6类型 | AC4: 属性6数值下限 | AD4: 属性6数值上限 | AE4: 属性6掉落权重 | AF4: 属性7类型 | AG4: 属性7数值下限 | AH4: 属性7数值上限 | AI4: 属性7掉落权重 | AJ4: 属性8类型 | AK4: 属性8数值下限 | AL4: 属性8数值上限 | AM4: 属性8掉落权重 | AN4: 试配说明（不导出）
B5: 50000100 | C5: 粗铁剑 | D5: 武器 | E5: 炼气 | F5: 凡品 | G5: 2000 | H5: 攻击上限 | I5: 1 | J5: 2 | K5: 6000 | L5: 攻击上限 | M5: 2 | N5: 3 | O5: 2000 | P5: 攻击上限 | Q5: 3 | R5: 4 | S5: 1000 | T5: 攻击上限 | U5: 4 | V5: 5 | W5: 500 | X5: 暴击率 | Y5: 50 | Z5: 150 | AA5: 250 | AB5: 攻击速度 | AC5: 1 | AD5: 2 | AE5: 150 | AF5: 金行增幅 | AG5: 100 | AH5: 300 | AI5: 75 | AJ5: 攻击上限 | AK5: 7 | AL5: 8 | AM5: 25 | AN5: 【开发试配】先判出现，再抽一个候选；末位为稀有顶档；仅生成时抽取。
B6: 50000200 | C6: 精铁剑 | D6: 武器 | E6: 炼气 | F6: 灵品 | G6: 2000 | H6: 攻击上限 | I6: 1 | J6: 2 | K6: 6000 | L6: 攻击上限 | M6: 2 | N6: 3 | O6: 2000 | P6: 攻击上限 | Q6: 3 | R6: 4 | S6: 1000 | T6: 攻击上限 | U6: 4 | V6: 5 | W6: 500 | X6: 暴击率 | Y6: 50 | Z6: 150 | AA6: 250 | AB6: 攻击速度 | AC6: 1 | AD6: 2 | AE6: 150 | AF6: 金行增幅 | AG6: 100 | AH6: 300 | AI6: 75 | AJ6: 攻击上限 | AK6: 7 | AL6: 8 | AM6: 25 | AN6: 【开发试配】先判出现，再抽一个候选；末位为稀有顶档；仅生成时抽取。
B7: 50000300 | C7: 清风剑 | D7: 武器 | E7: 炼气 | F7: 玄品 | G7: 3500 | H7: 攻击上限 | I7: 1 | J7: 2 | K7: 6000 | L7: 攻击上限 | M7: 2 | N7: 3 | O7: 2000 | P7: 攻击上限 | Q7: 3 | R7: 4 | S7: 1000 | T7: 攻击上限 | U7: 4 | V7: 5 | W7: 500 | X7: 暴击率 | Y7: 50 | Z7: 150 | AA7: 250 | AB7: 攻击速度 | AC7: 1 | AD7: 2 | AE7: 150 | AF7: 金行增幅 | AG7: 100 | AH7: 300 | AI7: 75 | AJ7: 攻击上限 | AK7: 7 | AL7: 8 | AM7: 25 | AN7: 【开发试配】先判出现，再抽一个候选；末位为稀有顶档；仅生成时抽取。
B8: 50000301 | C8: 五气拂尘 | D8: 武器 | E8: 炼气 | F8: 玄品 | G8: 3500 | H8: 攻击上限 | I8: 1 | J8: 2 | K8: 6000 | L8: 攻击上限 | M8: 2 | N8: 3 | O8: 2000 | P8: 攻击上限 | Q8: 3 | R8: 4 | S8: 1000 | T8: 攻击上限 | U8: 4 | V8: 5 | W8: 500 | X8: 暴击率 | Y8: 50 | Z8: 150 | AA8: 250 | AB8: 攻击速度 | AC8: 1 | AD8: 2 | AE8: 150 | AF8: 金行增幅 | AG8: 100 | AH8: 300 | AI8: 75 | AJ8: 攻击上限 | AK8: 7 | AL8: 8 | AM8: 25 | AN8: 【开发试配】先判出现，再抽一个候选；末位为稀有顶档；仅生成时抽取。
B9: 50000400 | C9: 寒星剑 | D9: 武器 | E9: 炼气 | F9: 仙品 | G9: 5000 | H9: 攻击上限 | I9: 1 | J9: 2 | K9: 6000 | L9: 攻击上限 | M9: 2 | N9: 3 | O9: 2000 | P9: 攻击上限 | Q9: 3 | R9: 4 | S9: 1000 | T9: 攻击上限 | U9: 4 | V9: 5 | W9: 500 | X9: 暴击率 | Y9: 50 | Z9: 150 | AA9: 250 | AB9: 攻击速度 | AC9: 1 | AD9: 2 | AE9: 150 | AF9: 金行增幅 | AG9: 100 | AH9: 300 | AI9: 75 | AJ9: 攻击上限 | AK9: 7 | AL9: 8 | AM9: 25 | AN9: 【开发试配】先判出现，再抽一个候选；末位为稀有顶档；仅生成时抽取。
B10: 50001100 | C10: 铜印 | D10: 印绶 | E10: 炼气 | F10: 凡品 | G10: 2000 | H10: 攻击上限 | I10: 1 | J10: 2 | K10: 6000 | L10: 攻击上限 | M10: 2 | N10: 3 | O10: 2000 | P10: 攻击上限 | Q10: 3 | R10: 4 | S10: 1000 | T10: 攻击上限 | U10: 4 | V10: 5 | W10: 500 | X10: 神识 | Y10: 1 | Z10: 2 | AA10: 250 | AB10: 法防上限 | AC10: 1 | AD10: 2 | AE10: 150 | AF10: 金行增幅 | AG10: 100 | AH10: 300 | AI10: 75 | AJ10: 攻击上限 | AK10: 7 | AL10: 8 | AM10: 25 | AN10: 【开发试配】先判出现，再抽一个候选；末位为稀有顶档；仅生成时抽取。
B11: 50001200 | C11: 玄铁印 | D11: 印绶 | E11: 炼气 | F11: 灵品 | G11: 2000 | H11: 攻击上限 | I11: 1 | J11: 2 | K11: 6000 | L11: 攻击上限 | M11: 2 | N11: 3 | O11: 2000 | P11: 攻击上限 | Q11: 3 | R11: 4 | S11: 1000 | T11: 攻击上限 | U11: 4 | V11: 5 | W11: 500 | X11: 神识 | Y11: 1 | Z11: 2 | AA11: 250 | AB11: 法防上限 | AC11: 1 | AD11: 2 | AE11: 150 | AF11: 金行增幅 | AG11: 100 | AH11: 300 | AI11: 75 | AJ11: 攻击上限 | AK11: 7 | AL11: 8 | AM11: 25 | AN11: 【开发试配】先判出现，再抽一个候选；末位为稀有顶档；仅生成时抽取。
B12: 50001300 | C12: 赤焰印 | D12: 印绶 | E12: 炼气 | F12: 玄品 | G12: 3500 | H12: 攻击上限 | I12: 1 | J12: 2 | K12: 6000 | L12: 攻击上限 | M12: 2 | N12: 3 | O12: 2000 | P12: 攻击上限 | Q12: 3 | R12: 4 | S12: 1000 | T12: 攻击上限 | U12: 4 | V12: 5 | W12: 500 | X12: 神识 | Y12: 1 | Z12: 2 | AA12: 250 | AB12: 法防上限 | AC12: 1 | AD12: 2 | AE12: 150 | AF12: 火行增幅 | AG12: 100 | AH12: 300 | AI12: 75 | AJ12: 攻击上限 | AK12: 7 | AL12: 8 | AM12: 25 | AN12: 【开发试配】先判出现，再抽一个候选；末位为稀有顶档；仅生成时抽取。
B13: 50001301 | C13: 镇岳印 | D13: 印绶 | E13: 炼气 | F13: 玄品 | G13: 3500 | H13: 攻击上限 | I13: 1 | J13: 2 | K13: 6000 | L13: 攻击上限 | M13: 2 | N13: 3 | O13: 2000 | P13: 攻击上限 | Q13: 3 | R13: 4 | S13: 1000 | T13: 攻击上限 | U13: 4 | V13: 5 | W13: 500 | X13: 神识 | Y13: 1 | Z13: 2 | AA13: 250 | AB13: 法防上限 | AC13: 1 | AD13: 2 | AE13: 150 | AF13: 土行增幅 | AG13: 100 | AH13: 300 | AI13: 75 | AJ13: 攻击上限 | AK13: 7 | AL13: 8 | AM13: 25 | AN13: 【开发试配】先判出现，再抽一个候选；末位为稀有顶档；仅生成时抽取。
B14: 50001400 | C14: 伏妖印 | D14: 印绶 | E14: 炼气 | F14: 仙品 | G14: 5000 | H14: 攻击上限 | I14: 1 | J14: 2 | K14: 6000 | L14: 攻击上限 | M14: 2 | N14: 3 | O14: 2000 | P14: 攻击上限 | Q14: 3 | R14: 4 | S14: 1000 | T14: 攻击上限 | U14: 4 | V14: 5 | W14: 500 | X14: 神识 | Y14: 1 | Z14: 2 | AA14: 250 | AB14: 法防上限 | AC14: 1 | AD14: 2 | AE14: 150 | AF14: 水行增幅 | AG14: 100 | AH14: 300 | AI14: 75 | AJ14: 攻击上限 | AK14: 7 | AL14: 8 | AM14: 25 | AN14: 【开发试配】先判出现，再抽一个候选；末位为稀有顶档；仅生成时抽取。
B15: 50003100 | C15: 草履 | D15: 鞋履 | E15: 炼气 | F15: 凡品 | G15: 2000 | H15: 物防上限 | I15: 1 | J15: 2 | K15: 6000 | L15: 物防上限 | M15: 2 | N15: 3 | O15: 2000 | P15: 物防上限 | Q15: 3 | R15: 4 | S15: 1000 | T15: 物防上限 | U15: 4 | V15: 5 | W15: 500 | X15: 闪避 | Y15: 50 | Z15: 150 | AA15: 250 | AB15: 法防上限 | AC15: 1 | AD15: 2 | AE15: 150 | AF15: 金行增幅 | AG15: 100 | AH15: 300 | AI15: 75 | AJ15: 物防上限 | AK15: 7 | AL15: 8 | AM15: 25 | AN15: 【开发试配】先判出现，再抽一个候选；末位为稀有顶档；仅生成时抽取。
B16: 50003200 | C16: 软底履 | D16: 鞋履 | E16: 炼气 | F16: 灵品 | G16: 2000 | H16: 物防上限 | I16: 1 | J16: 2 | K16: 6000 | L16: 物防上限 | M16: 2 | N16: 3 | O16: 2000 | P16: 物防上限 | Q16: 3 | R16: 4 | S16: 1000 | T16: 物防上限 | U16: 4 | V16: 5 | W16: 500 | X16: 闪避 | Y16: 50 | Z16: 150 | AA16: 250 | AB16: 法防上限 | AC16: 1 | AD16: 2 | AE16: 150 | AF16: 金行增幅 | AG16: 100 | AH16: 300 | AI16: 75 | AJ16: 物防上限 | AK16: 7 | AL16: 8 | AM16: 25 | AN16: 【开发试配】先判出现，再抽一个候选；末位为稀有顶档；仅生成时抽取。
... B332: 53519600 | C332: 两忘佩 | D332: 玉佩 | E332: 大乘 | F332: 道品 | G332: 6500 | H332: 攻击上限 | I332: 3 | J332: 6 | K332: 6000 | L332: 攻击上限 | M332: 6 | N332: 9 | O332: 2000 | P332: 攻击上限 | Q332: 9 | R332: 12 | S332: 1000 | T332: 攻击上限 | U332: 12 | V332: 15 | W332: 500 | X332: 神识 | Y332: 1 | Z332: 2 | AA332: 250 | AB332: 法防上限 | AC332: 3 | AD332: 6 | AE332: 150 | AF332: 土行增幅 | AG332: 100 | AH332: 300 | AI332: 75 | AJ332: 攻击上限 | AK332: 21 | AL332: 24 | AM332: 25 | AN332: 【开发试配】先判出现，再抽一个候选；末位为稀有顶档；仅生成时抽取。

Sheet 炼化
A1: ##var | B1: refine_id | G1: refine_items | M1: affix_drops
A2: ##type | B2: int | G2: array,RecMaterial | M2: array,AffixDrop
A3: ##group
A4: ## | B4: 炼化方案ID | C4: 装备名 | D4: 装备位 | E4: 阶级 | F4: 颜色 | G4: 炼化材料1 | H4: 材料1数量 | I4: 炼化材料2 | J4: 材料2数量 | K4: 炼化材料3 | L4: 材料3数量 | M4: 效果词条1 | N4: 词条1掉落权重 | O4: 效果词条2 | P4: 词条2掉落权重 | Q4: 效果词条3 | R4: 词条3掉落权重 | S4: 效果词条4 | T4: 词条4掉落权重 | U4: 效果词条5 | V4: 词条5掉落权重 | W4: 效果词条6 | X4: 词条6掉落权重 | Y4: 效果词条7 | Z4: 词条7掉落权重 | AA4: 效果词条8 | AB4: 词条8掉落权重 | AC4: 效果词条9 | AD4: 词条9掉落权重 | AE4: 效果词条10 | AF4: 词条10掉落权重 | AG4: 炼化灵材名称（辅助） | AH4: 补充灵材名称（辅助） | AI4: 试配说明（不导出）
B5: 50000100 | C5: 粗铁剑 | D5: 武器 | E5: 炼气 | F5: 凡品 | G5: 12623003 | H5: 2 | I5: 12623005 | J5: 1 | K5: 1000001 | L5: 40 | M5: 60001 | N5: 4000 | O5: 60002 | P5: 2500 | Q5: 60005 | R5: 1500 | S5: 60006 | T5: 1000 | U5: 60007 | V5: 500 | W5: 60008 | X5: 300 | AG5: 足年灵兽毒囊 | AH5: 一转金精 | AI5: 【开发试配】扣费必出一个候选；保留不退费，采用不再扣费；费用含灵石。
B6: 50000200 | C6: 精铁剑 | D6: 武器 | E6: 炼气 | F6: 灵品 | G6: 12623003 | H6: 2 | I6: 12623005 | J6: 1 | K6: 1000001 | L6: 40 | M6: 60001 | N6: 4000 | O6: 60002 | P6: 2500 | Q6: 60005 | R6: 1500 | S6: 60006 | T6: 1000 | U6: 60007 | V6: 500 | W6: 60008 | X6: 300 | AG6: 足年灵兽毒囊 | AH6: 一转金精 | AI6: 【开发试配】扣费必出一个候选；保留不退费，采用不再扣费；费用含灵石。
B7: 50000300 | C7: 清风剑 | D7: 武器 | E7: 炼气 | F7: 玄品 | G7: 12623003 | H7: 2 | I7: 12623005 | J7: 1 | K7: 1000001 | L7: 80 | M7: 60101 | N7: 4000 | O7: 60001 | P7: 2500 | Q7: 60002 | R7: 1500 | S7: 60005 | T7: 1000 | U7: 60006 | V7: 500 | W7: 60007 | X7: 300 | Y7: 60008 | Z7: 150 | AG7: 足年灵兽毒囊 | AH7: 一转金精 | AI7: 【开发试配】扣费必出一个候选；保留不退费，采用不再扣费；费用含灵石。
B8: 50000301 | C8: 五气拂尘 | D8: 武器 | E8: 炼气 | F8: 玄品 | G8: 12623003 | H8: 2 | I8: 12623005 | J8: 1 | K8: 1000001 | L8: 80 | M8: 60102 | N8: 4000 | O8: 60005 | P8: 2500 | Q8: 60006 | R8: 1500 | S8: 60007 | T8: 1000 | U8: 60009 | V8: 500 | W8: 60011 | X8: 300 | Y8: 60013 | Z8: 150 | AA8: 60015 | AB8: 50 | AG8: 足年灵兽毒囊 | AH8: 一转金精 | AI8: 【开发试配】扣费必出一个候选；保留不退费，采用不再扣费；费用含灵石。
B9: 50000400 | C9: 寒星剑 | D9: 武器 | E9: 炼气 | F9: 仙品 | G9: 12623003 | H9: 2 | I9: 12623005 | J9: 1 | K9: 1000001 | L9: 120 | M9: 60101 | N9: 4000 | O9: 60001 | P9: 2500 | Q9: 60002 | R9: 1500 | S9: 60005 | T9: 1000 | U9: 60006 | V9: 500 | W9: 60007 | X9: 300 | Y9: 60008 | Z9: 150 | AG9: 足年灵兽毒囊 | AH9: 一转金精 | AI9: 【开发试配】扣费必出一个候选；保留不退费，采用不再扣费；费用含灵石。
B10: 50001100 | C10: 铜印 | D10: 印绶 | E10: 炼气 | F10: 凡品 | G10: 12623001 | H10: 2 | I10: 12623009 | J10: 1 | K10: 1000001 | L10: 40 | M10: 60007 | N10: 4000 | O10: 60008 | P10: 2500 | Q10: 60005 | R10: 1500 | S10: 60006 | T10: 1000 | AG10: 足年灵兽妖丹 | AH10: 一转土元珠 | AI10: 【开发试配】扣费必出一个候选；保留不退费，采用不再扣费；费用含灵石。
B11: 50001200 | C11: 玄铁印 | D11: 印绶 | E11: 炼气 | F11: 灵品 | G11: 12623001 | H11: 2 | I11: 12623009 | J11: 1 | K11: 1000001 | L11: 40 | M11: 60007 | N11: 4000 | O11: 60008 | P11: 2500 | Q11: 60005 | R11: 1500 | S11: 60006 | T11: 1000 | AG11: 足年灵兽妖丹 | AH11: 一转土元珠 | AI11: 【开发试配】扣费必出一个候选；保留不退费，采用不再扣费；费用含灵石。
B12: 50001300 | C12: 赤焰印 | D12: 印绶 | E12: 炼气 | F12: 玄品 | G12: 12623001 | H12: 2 | I12: 12623009 | J12: 1 | K12: 1000001 | L12: 80 | M12: 60111 | N12: 4000 | O12: 60013 | P12: 2500 | Q12: 60014 | R12: 1500 | S12: 60005 | T12: 1000 | U12: 60006 | V12: 500 | AG12: 足年灵兽妖丹 | AH12: 一转土元珠 | AI12: 【开发试配】扣费必出一个候选；保留不退费，采用不再扣费；费用含灵石。
B13: 50001301 | C13: 镇岳印 | D13: 印绶 | E13: 炼气 | F13: 玄品 | G13: 12623001 | H13: 2 | I13: 12623009 | J13: 1 | K13: 1000001 | L13: 80 | M13: 60112 | N13: 4000 | O13: 60015 | P13: 2500 | Q13: 60016 | R13: 1500 | S13: 60005 | T13: 1000 | U13: 60006 | V13: 500 | AG13: 足年灵兽妖丹 | AH13: 一转土元珠 | AI13: 【开发试配】扣费必出一个候选；保留不退费，采用不再扣费；费用含灵石。
B14: 50001400 | C14: 伏妖印 | D14: 印绶 | E14: 炼气 | F14: 仙品 | G14: 12623001 | H14: 2 | I14: 12623009 | J14: 1 | K14: 1000001 | L14: 120 | M14: 60111 | N14: 4000 | O14: 60011 | P14: 2500 | Q14: 60012 | R14: 1500 | S14: 60005 | T14: 1000 | U14: 60006 | V14: 500 | W14: 60117 | X14: 300 | AG14: 足年灵兽妖丹 | AH14: 一转土元珠 | AI14: 【开发试配】扣费必出一个候选；保留不退费，采用不再扣费；费用含灵石。
